Workbook

Sheet Table of Contents
A1: Table of Contents
A2: Section | B2: Open | C2: Description
A3: Primary workflow
A4: =HYPERLINK("#'Executive Briefing'!A1","Executive Briefing") | B4: =HYPERLINK("#'Executive Briefing'!A1","Open") | C4: Primary executive landing: KPI cards, charts, owner triage, and navigation.
A5: =HYPERLINK("#'Summary'!A1","Summary") | B5: =HYPERLINK("#'Summary'!A1","Open") | C5: Aggregated issue counts, AEO opportunities, and top critical URLs from the run.
A6: =HYPERLINK("#'Priority URLs'!A1","Priority URLs") | B6: =HYPERLINK("#'Priority URLs'!A1","Open") | C6: High-value pages requiring immediate attention based on business risk.
A7: =HYPERLINK("#'FixPlan'!A1","FixPlan") | B7: =HYPERLINK("#'FixPlan'!A1","Open") | C7: Prioritized list of technical and content fixes with estimated effort.
A8: =HYPERLINK("#'Quick Wins'!A1","Quick Wins") | B8: =HYPERLINK("#'Quick Wins'!A1","Open") | C8: Top 15 high-impact, low-effort fixes ranked by traffic and business risk.
A9: =HYPERLINK("#'Content Optimisation Hub'!A1","Content Optimisation Hub") | B9: =HYPERLINK("#'Content Optimisation Hub'!A1","Open") | C9: Diagnostic command center: live title, meta, and H1–H6 health plus on-page score.
A10: =HYPERLINK("#'Content Planner'!A1","Content Planner") | B10: =HYPERLINK("#'Content Planner'!A1","Open") | C10: Page-level workflow tracker: nav/footer site structure with copywriting, design, and client sign-off status columns.
A11: =HYPERLINK("#'Content Hub Metrics'!A1","Content Hub Metrics") | B11: =HYPERLINK("#'Content Hub Metrics'!A1","Open") | C11: Per-URL crawl metrics (JS/rendered words, field CWV), anchor diversity, and executive ROI estimates aligned with the Content Hub URL set.
A12: =HYPERLINK("#'Main'!A1","Main") | B12: =HYPERLINK("#'Main'!A1","Open") | C12: Primary URL inventory with titles, meta descriptions, and crawl signals.
A13: =HYPERLINK("#'AIOSEO Recommendations'!A1","AIOSEO Recommendations") | B13: =HYPERLINK("#'AIOSEO Recommendations'!A1","Open") | C13: Plugin-aligned recommendations and edit links for AIOSEO users.
A14: =HYPERLINK("#'Link Inventory'!A1","Link Inventory") | B14: =HYPERLINK("#'Link Inventory'!A1","Open") | C14: Every anchor-level outbound link with type, rel attributes, status codes, and generic-anchor flags.
A15: =HYPERLINK("#'Broken Link Impact'!A1","Broken Link Impact") | B15: =HYPERLINK("#'Broken Link Impact'!A1","Open") | C15: Broken destinations ranked by inbound link count and source-page GSC clicks.
A16: =HYPERLINK("#'SitemapQA'!A1","SitemapQA") | B16: =HYPERLINK("#'SitemapQA'!A1","Open") | C16: Sitemap coverage, URL membership checks, and sitemap metadata QA.
A17: =HYPERLINK("#'Template & Duplication Risks'!A1","Template & Duplication Risks") | B17: =HYPERLINK("#'Template & Duplication Risks'!A1","Open") | C17: Duplicate titles/meta, draft/copy pages, and folder-level template pattern risks.
A18: =HYPERLINK("#'Playbook'!A1","Playbook") | B18: =HYPERLINK("#'Playbook'!A1","Open") | C18: Client education reference: editorial standards plus per-issue playbooks with what/why/fix/verify guidance.
A19: Technical & Historical (Advanced) — tabs hidden; use Open links or right-click tab bar → Unhide Sheet
A20: =HYPERLINK("#'Issue Register'!A1","Issue Register") | B20: =HYPERLINK("#'Issue Register'!A1","Open") | C20: Tracked issue backlog with first-seen dates, days open, assignment fields, and client notes. Unified rollups from Summary plus per-URL issue rows.
A21: =HYPERLINK("#'Technical Diagnostics'!A1","Technical Diagnostics") | B21: =HYPERLINK("#'Technical Diagnostics'!A1","Open") | C21: Per-URL technical, indexability, redirect, security, PSI, and Search Console signals.
A22: =HYPERLINK("#'Content & AI Readiness'!A1","Content & AI Readiness") | B22: =HYPERLINK("#'Content & AI Readiness'!A1","Open") | C22: Per-URL content depth, schema, media, and answer-engine readiness metrics.
A23: =HYPERLINK("#'Link Intelligence'!A1","Link Intelligence") | B23: =HYPERLINK("#'Link Intelligence'!A1","Open") | C23: Per-URL internal link summary rows plus anchor-level detail for broken-link triage.
A24: =HYPERLINK("#'CMS Action URLs'!A1","CMS Action URLs") | B24: =HYPERLINK("#'CMS Action URLs'!A1","Open") | C24: WooCommerce and other CMS action-parameter URLs discovered during the crawl (for example add-to-cart) that were withheld from the crawl queue.
A25: =HYPERLINK("#'Redirects'!A1","Redirects") | B25: =HYPERLINK("#'Redirects'!A1","Open") | C25: Redirect chains, hop lists, HTTPS upgrades, and loop detection.
A26: =HYPERLINK("#'Redirect Map'!A1","Redirect Map") | B26: =HYPERLINK("#'Redirect Map'!A1","Open") | C26: Per-source redirect chains with hop status codes, 302 flags, and SEO risk notes.
A27: =HYPERLINK("#'Robots.txt Analysis'!A1","Robots.txt Analysis") | B27: =HYPERLINK("#'Robots.txt Analysis'!A1","Open") | C27: Parsed robots.txt content, user-agent rules, blocked URLs, and sitemap conflicts.
A28: =HYPERLINK("#'Crawl Log'!A1","Crawl Log") | B28: =HYPERLINK("#'Crawl Log'!A1","Open") | C28: Errors and warnings from fetch, render, PSI, and GSC phases for this audit run.
A29: =HYPERLINK("#'Link Equity Map'!A1","Link Equity Map") | B29: =HYPERLINK("#'Link Equity Map'!A1","Open") | C29: Internal PageRank distribution: inlink/outlink counts and equity flow per URL.
A30: =HYPERLINK("#'Anchor Text Audit'!A1","Anchor Text Audit") | B30: =HYPERLINK("#'Anchor Text Audit'!A1","Open") | C30: Anchor-text profile per destination: distribution, generic-anchor share, and diversity.
A31: =HYPERLINK("#'Snippet Opportunities'!A1","Snippet Opportunities") | B31: =HYPERLINK("#'Snippet Opportunities'!A1","Open") | C31: Pages with answer-block potential for featured snippets and AI answer extraction.
A32: =HYPERLINK("#'Script Inventory'!A1","Script Inventory") | B32: =HYPERLINK("#'Script Inventory'!A1","Open") | C32: Third-party and first-party scripts per URL with blocking and privacy implications.
A33: =HYPERLINK("#'Image Inventory'!A1","Image Inventory") | B33: =HYPERLINK("#'Image Inventory'!A1","Open") | C33: Every image with alt-text coverage, filename quality, dimensions, and mixed-content flags.
A34: =HYPERLINK("#'ResolvedIssues'!A1","ResolvedIssues") | B34: =HYPERLINK("#'ResolvedIssues'!A1","Open") | C34: Issues marked resolved when compared to the previous export. First runs show a baseline note when no previous export was supplied.
A35: =HYPERLINK("#'DeltaFromPreviousRun'!A1","DeltaFromPreviousRun") | B35: =HYPERLINK("#'DeltaFromPreviousRun'!A1","Open") | C35: New, resolved, and persistent issues compared to a prior audit workbook or delta JSON. Sections: summary counts, new issues, resolved issues, metric changes, and SEO health trend. First runs show a baseline note when no previous export was supplied.
A36: =HYPERLINK("#'Audit Run Details'!A1","Audit Run Details") | B36: =HYPERLINK("#'Audit Run Details'!A1","Open") | C36: Run configuration, timestamps, and environment notes.

Sheet Executive Briefing
A1: 🐸 HYPE FROG: SEO & AEO Intelligence Report
A2: SEO health is 61% across 83 crawled URLs. 80 URL(s) (96%) carry Critical or Warning badges. If those were cleared, blended SEO health could reach ~95% (+34 pts) — an illustrative ceiling from the export model (90% of remaining headroom × open-issue share). Technical, PSI, and AEO components use the same conservative formula in the chart below; they are not guaranteed to move in lockstep. Source tables: row 114+.
A3: =IFERROR(INDEX('Audit Run Details'!$B:$B,MATCH("Total URLs",'Audit Run Details'!$A:$A,0)),"") & " URLs crawled"
A4: Audit Run Details | B4: Value
A5: Run Date | B5: =IFERROR(INDEX('Audit Run Details'!$B:$B,MATCH("Run Timestamp",'Audit Run Details'!$A:$A,0)),"")
A7: SEO Health (now) | C7: SEO Health (illustrative projected) | E7: AEO Readiness | G7: Critical URLs | I7: Traffic Lift (est.) | K7: Performance (PSI)
A8: 61% | C8: 95% | E8: 92% | G8: 17 | I8: 0 | K8: 88
A9: Key insights: 17 URL(s) carry a Critical badge and need urgent attention. | 63 URL(s) are in Warning state — schedule fixes before they escalate. | Largest theme: "Render Blocking Resources" touches 83 URL(s) (see Fix Plan). | 6 URL(s) returned 4xx/5xx during the crawl.
A10: Health & illustrative projection
A29: Issue distribution — unique URLs vs issue instances (see source row 60+)
A48: Priority pages & content readiness
A67: Top issues to fix first (by affected URLs)
G88: OWNER ISSUE SUMMARY | M88: Quick Navigation | N88: Open
G89: Owner | H89: Issue Rows | I89: Affected URLs | J89: Critical | K89: Warning | M89: Issue Summary | N89: =HYPERLINK("#Summary!A1","Open")
G90: =HYPERLINK("#'FixPlan'!A1","Copy Writer") | H90: =COUNTIF(OFFSET('FixPlan'!$A$1,2,MATCH("Owner",'FixPlan'!$2:$2,0)-1,99998,1),"Copy Writer") | I90: =SUMIF(OFFSET('FixPlan'!$A$1,2,MATCH("Owner",'FixPlan'!$2:$2,0)-1,99998,1),"Copy Writer",OFFSET('FixPlan'!$A$1,2,MATCH("Affected Count",'FixPlan'!$2:$2,0)-1,99998,1)) | J90: =COUNTIFS(OFFSET('FixPlan'!$A$1,2,MATCH("Owner",'FixPlan'!$2:$2,0)-1,99998,1),"Copy Writer",OFFSET('FixPlan'!$A$1,2,MATCH("Severity",'FixPlan'!$2:$2,0)-1,99998,1),"Critical") | K90: =COUNTIFS(OFFSET('FixPlan'!$A$1,2,MATCH("Owner",'FixPlan'!$2:$2,0)-1,99998,1),"Copy Writer",OFFSET('FixPlan'!$A$1,2,MATCH("Severity",'FixPlan'!$2:$2,0)-1,99998,1),"Warning")+COUNTIFS(OFFSET('FixPlan'!$A$1,2,MATCH("Owner",'FixPlan'!$2:$2,0)-1,99998,1),"Copy Writer",OFFSET('FixPlan'!$A$1,2,MATCH("Severity",'FixPlan'!$2:$2,0)-1,99998,1),"Needs Work") | M90: Fix Plan | N90: =HYPERLINK("#FixPlan!A1","Open")
G91: =HYPERLINK("#'FixPlan'!A1","Dev") | H91: =COUNTIF(OFFSET('FixPlan'!$A$1,2,MATCH("Owner",'FixPlan'!$2:$2,0)-1,99998,1),"Dev") | I91: =SUMIF(OFFSET('FixPlan'!$A$1,2,MATCH("Owner",'FixPlan'!$2:$2,0)-1,99998,1),"Dev",OFFSET('FixPlan'!$A$1,2,MATCH("Affected Count",'FixPlan'!$2:$2,0)-1,99998,1)) | J91: =COUNTIFS(OFFSET('FixPlan'!$A$1,2,MATCH("Owner",'FixPlan'!$2:$2,0)-1,99998,1),"Dev",OFFSET('FixPlan'!$A$1,2,MATCH("Severity",'FixPlan'!$2:$2,0)-1,99998,1),"Critical") | K91: =COUNTIFS(OFFSET('FixPlan'!$A$1,2,MATCH("Owner",'FixPlan'!$2:$2,0)-1,99998,1),"Dev",OFFSET('FixPlan'!$A$1,2,MATCH("Severity",'FixPlan'!$2:$2,0)-1,99998,1),"Warning")+COUNTIFS(OFFSET('FixPlan'!$A$1,2,MATCH("Owner",'FixPlan'!$2:$2,0)-1,99998,1),"Dev",OFFSET('FixPlan'!$A$1,2,MATCH("Severity",'FixPlan'!$2:$2,0)-1,99998,1),"Needs Work") | M91: Main URL Data | N91: =HYPERLINK("#Main!A1","Open")
G92: =HYPERLINK("#'FixPlan'!A1","Server/Host") | H92: =COUNTIF(OFFSET('FixPlan'!$A$1,2,MATCH("Owner",'FixPlan'!$2:$2,0)-1,99998,1),"Server/Host") | I92: =SUMIF(OFFSET('FixPlan'!$A$1,2,MATCH("Owner",'FixPlan'!$2:$2,0)-1,99998,1),"Server/Host",OFFSET('FixPlan'!$A$1,2,MATCH("Affected Count",'FixPlan'!$2:$2,0)-1,99998,1)) | J92: =COUNTIFS(OFFSET('FixPlan'!$A$1,2,MATCH("Owner",'FixPlan'!$2:$2,0)-1,99998,1),"Server/Host",OFFSET('FixPlan'!$A$1,2,MATCH("Severity",'FixPlan'!$2:$2,0)-1,99998,1),"Critical") | K92: =COUNTIFS(OFFSET('FixPlan'!$A$1,2,MATCH("Owner",'FixPlan'!$2:$2,0)-1,99998,1),"Server/Host",OFFSET('FixPlan'!$A$1,2,MATCH("Severity",'FixPlan'!$2:$2,0)-1,99998,1),"Warning")+COUNTIFS(OFFSET('FixPlan'!$A$1,2,MATCH("Owner",'FixPlan'!$2:$2,0)-1,99998,1),"Server/Host",OFFSET('FixPlan'!$A$1,2,MATCH("Severity",'FixPlan'!$2:$2,0)-1,99998,1),"Needs Work") | M92: Technical Diagnostics | N92: =HYPERLINK("#'Technical Diagnostics'!A1","Open")
M93: Indexability | N93: =HYPERLINK("#'Technical Diagnostics'!A1","Open")
M94: AEO Opportunities | N94: =HYPERLINK("#'Content & AI Readiness'!A1","Open")
M95: AIOSEO Recommendations | N95: =HYPERLINK("#'AIOSEO Recommendations'!A1","Open")
M96: Content Hub | N96: =HYPERLINK("#'Content Optimisation Hub'!A1","Open")
M98: Advanced Sheets
M99: Technical & historical tabs are hidden to reduce clutter. Use the links below or Home → Format → Hide & Unhide → Unhide Sheet.
M101: Issue Register (canonical backlog) | N101: =HYPERLINK("#'Issue Register'!A1","Open")
M102: Technical Diagnostics | N102: =HYPERLINK("#'Technical Diagnostics'!A1","Open")
M103: Content & AI Readiness | N103: =HYPERLINK("#'Content & AI Readiness'!A1","Open")
M104: Link Intelligence | N104: =HYPERLINK("#'Link Intelligence'!A1","Open")
M105: CMS Action URLs | N105: =HYPERLINK("#'CMS Action URLs'!A1","Open")
M106: Redirects | N106: =HYPERLINK("#'Redirects'!A1","Open")
M107: Redirect Map | N107: =HYPERLINK("#'Redirect Map'!A1","Open")
M108: Robots.txt Analysis | N108: =HYPERLINK("#'Robots.txt Analysis'!A1","Open")
M109: Crawl Log | N109: =HYPERLINK("#'Crawl Log'!A1","Open")
M110: Audit Run Details | N110: =HYPERLINK("#'Audit Run Details'!A1","Open")
M111: Resolved Issues | N111: =HYPERLINK("#'ResolvedIssues'!A1","Open")
A112: ▼ Chart source data begins row 114 (columns A–C) | M112: Delta From Previous Run | N112: =HYPERLINK("#'DeltaFromPreviousRun'!A1","Open")
A114: Chart source data (scroll down — used by charts above)
A115: Health comparison
A116: Metric | B116: Current | C116: Illustrative projected
A117: SEO Health | B117: 61.3 | C117: 94.9
A118: Technical Health | B118: 61.3 | C118: 94.9
...

Sheet Summary
A1: ← Return to Executive Briefing | C1: =IFERROR(INDEX('Audit Run Details'!$B:$B,MATCH("Target Site",'Audit Run Details'!$A:$A,0)),"") & " — " & IFERROR(INDEX('Audit Run Details'!$B:$B,MATCH("Total URLs",'Audit Run Details'!$A:$A,0)),"") & " URLs crawled — " & LEFT(IFERROR(INDEX('Audit Run Details'!$B:$B,MATCH("Run Timestamp",'Audit Run Details'!$A:$A,0)),""),10)
A2: Section | B2: Severity | C2: Issue | D2: Affected URL Count | E2: Reference Tab | F2: Affected URLs (sample)
A3: AEO Opportunities | B3: Warning | C3: Low AEO Readiness Score | D3: 9 | E3: Content & AI Readiness | F3: https://africanmarketingconfederation.org/smoke-archive/page-9 | https://africanmarketingconfederation.org/smoke-archive/page-18 | https://africanmarketingconfederation.org/smoke-archive/page-27 | https://africanmarketingconfederation.org/smoke-archive/page-36 | https://africanmarketingconfederation.org/smoke-archive/page-45 | https://africanmarketingconfederation.org/smoke-archive/page-54 | https://africanmarketingconfederation.org/smoke-archive/page-63 | https://africanmarketingconfederation.org/smoke-archive/page-72 | https://africanmarketingconfederation.org/discovered-via-bfs-1 || Full list: see Content & AI Readiness tab
A4: AEO Opportunities | B4: Warning | C4: Missing FAQ/QA Schema | D4: 0 | E4: Content & AI Readiness | F4: || Full list: see Content & AI Readiness tab
A5: AEO Opportunities | B5: Observation | C5: No 40-60 Word Answer Paragraphs | D5: 9 | E5: Content & AI Readiness | F5: https://africanmarketingconfederation.org/smoke-archive/page-9 | https://africanmarketingconfederation.org/smoke-archive/page-18 | https://africanmarketingconfederation.org/smoke-archive/page-27 | https://africanmarketingconfederation.org/smoke-archive/page-36 | https://africanmarketingconfederation.org/smoke-archive/page-45 | https://africanmarketingconfederation.org/smoke-archive/page-54 | https://africanmarketingconfederation.org/smoke-archive/page-63 | https://africanmarketingconfederation.org/smoke-archive/page-72 | https://africanmarketingconfederation.org/discovered-via-bfs-1 || Full list: see Content & AI Readiness tab
A6: AEO Opportunities | B6: Observation | C6: No Answer-Friendly Structure | D6: 9 | E6: Content & AI Readiness | F6: https://africanmarketingconfederation.org/smoke-archive/page-9 | https://africanmarketingconfederation.org/smoke-archive/page-18 | https://africanmarketingconfederation.org/smoke-archive/page-27 | https://africanmarketingconfederation.org/smoke-archive/page-36 | https://africanmarketingconfederation.org/smoke-archive/page-45 | https://africanmarketingconfederation.org/smoke-archive/page-54 | https://africanmarketingconfederation.org/smoke-archive/page-63 | https://africanmarketingconfederation.org/smoke-archive/page-72 | https://africanmarketingconfederation.org/discovered-via-bfs-1 || Full list: see Content & AI Readiness tab
A7: AEO Opportunities | B7: Observation | C7: No Question Headings | D7: 9 | E7: Content & AI Readiness | F7: https://africanmarketingconfederation.org/smoke-archive/page-9 | https://africanmarketingconfederation.org/smoke-archive/page-18 | https://africanmarketingconfederation.org/smoke-archive/page-27 | https://africanmarketingconfederation.org/smoke-archive/page-36 | https://africanmarketingconfederation.org/smoke-archive/page-45 | https://africanmarketingconfederation.org/smoke-archive/page-54 | https://africanmarketingconfederation.org/smoke-archive/page-63 | https://africanmarketingconfederation.org/smoke-archive/page-72 | https://africanmarketingconfederation.org/discovered-via-bfs-1 || Full list: see Content & AI Readiness tab
A8: AEO Opportunities | F8: Detailed rows: see Content & AI Readiness tab
A9: Issue Counts | B9: Critical | C9: Non-200 Status | D9: 11 | E9: Technical Diagnostics | F9: https://africanmarketingconfederation.org/ | https://africanmarketingconfederation.org/smoke-archive/page-13 | https://africanmarketingconfederation.org/smoke-archive/page-17 | https://africanmarketingconfederation.org/smoke-archive/page-26 | https://africanmarketingconfederation.org/smoke-archive/page-34 | https://africanmarketingconfederation.org/smoke-archive/page-39 | https://africanmarketingconfederation.org/smoke-archive/page-51 | https://africanmarketingconfederation.org/smoke-archive/page-52 | https://africanmarketingconfederation.org/smoke-archive/page-65 | https://africanmarketingconfederation.org/smoke-archive/page-68 | https://africanmarketingconfederation.org/smoke-archive/page-78 || Full list: see Technical Diagnostics / Link Intelligence tabs
A10: Issue Counts | B10: Critical | C10: No Schema Markup | D10: 6 | E10: Technical Diagnostics | F10: https://africanmarketingconfederation.org/smoke-archive/page-12 | https://africanmarketingconfederation.org/smoke-archive/page-24 | https://africanmarketingconfederation.org/smoke-archive/page-36 | https://africanmarketingconfederation.org/smoke-archive/page-48 | https://africanmarketingconfederation.org/smoke-archive/page-60 | https://africanmarketingconfederation.org/smoke-archive/page-72 || Full list: see Technical Diagnostics / Link Intelligence tabs
A11: Issue Counts | B11: Critical | C11: Blocked by Googlebot | D11: 0 | E11: Technical Diagnostics | F11: || Full list: see Technical Diagnostics / Link Intelligence tabs
A12: Issue Counts | B12: Critical | C12: Broken Internal Links | D12: 0 | E12: Link Intelligence | F12: || Full list: see Technical Diagnostics / Link Intelligence tabs
A13: Issue Counts | B13: Critical | C13: CWV LCP Above 4.0s (Field Data) | D13: 0 | E13: Technical Diagnostics | F13: || Full list: see Technical Diagnostics / Link Intelligence tabs
A14: Issue Counts | B14: Critical | C14: Canonical Loop | D14: 0 | E14: Technical Diagnostics | F14: || Full list: see Technical Diagnostics / Link Intelligence tabs
A15: Issue Counts | B15: Critical | C15: Canonical Points Elsewhere | D15: 0 | E15: Technical Diagnostics | F15: || Full list: see Technical Diagnostics / Link Intelligence tabs
A16: Issue Counts | B16: Critical | C16: Canonical Points to Broken URL | D16: 0 | E16: Technical Diagnostics | F16: || Full list: see Technical Diagnostics / Link Intelligence tabs
A17: Issue Counts | B17: Critical | C17: High Broken Image Count (>3) | D17: 0 | E17: Technical Diagnostics | F17: || Full list: see Technical Diagnostics / Link Intelligence tabs
A18: Issue Counts | B18: Critical | C18: In Sitemap but Blocked by Googlebot | D18: 0 | E18: Technical Diagnostics | F18: || Full list: see Technical Diagnostics / Link Intelligence tabs
A19: Issue Counts | B19: Critical | C19: Lab LCP Above 4.0s (Mobile) | D19: 0 | E19: Technical Diagnostics | F19: || Full list: see Technical Diagnostics / Link Intelligence tabs
A20: Issue Counts | B20: Critical | C20: Missing Title | D20: 0 | E20: Technical Diagnostics | F20: || Full list: see Technical Diagnostics / Link Intelligence tabs
... A107: Issue Counts | B107: Observation | C107: llms.txt Missing | D107: 0 | E107: Technical Diagnostics | F107: || Full list: see Technical Diagnostics / Link Intelligence tabs
A108: Issue Counts
A109: Top 10 Critical URLs
A110: Top 10 Critical URLs | B110: Critical | C110: #1 https://africanmarketingconfederation.org/ | D110: 1 | E110: Priority URLs | F110: Non-200 Status
A111: Top 10 Critical URLs | B111: Critical | C111: #2 https://africanmarketingconfederation.org/smoke-archive/page-13 | D111: 1 | E111: Priority URLs | F111: Non-200 Status
A112: Top 10 Critical URLs | B112: Critical | C112: #3 https://africanmarketingconfederation.org/smoke-archive/page-17 | D112: 1 | E112: Priority URLs | F112: Non-200 Status
A113: Top 10 Critical URLs | B113: Critical | C113: #4 https://africanmarketingconfederation.org/smoke-archive/page-26 | D113: 1 | E113: Priority URLs | F113: Non-200 Status
A114: Top 10 Critical URLs | B114: Critical | C114: #5 https://africanmarketingconfederation.org/smoke-archive/page-34 | D114: 1 | E114: Priority URLs | F114: Non-200 Status
A115: Top 10 Critical URLs | B115: Critical | C115: #6 https://africanmarketingconfederation.org/smoke-archive/page-39 | D115: 1 | E115: Priority URLs | F115: Non-200 Status
A116: Top 10 Critical URLs | B116: Critical | C116: #7 https://africanmarketingconfederation.org/smoke-archive/page-51 | D116: 1 | E116: Priority URLs | F116: Non-200 Status
A117: Top 10 Critical URLs | B117: Critical | C117: #8 https://africanmarketingconfederation.org/smoke-archive/page-52 | D117: 1 | E117: Priority URLs | F117: Non-200 Status
A118: Top 10 Critical URLs | B118: Critical | C118: #9 https://africanmarketingconfederation.org/smoke-archive/page-65 | D118: 1 | E118: Priority URLs | F118: Non-200 Status
A119: Top 10 Critical URLs | B119: Critical | C119: #10 https://africanmarketingconfederation.org/smoke-archive/page-68 | D119: 1 | E119: Priority URLs | F119: Non-200 Status
A120: Top Issues by Template
A121: Top Issues by Template | B121: Observation | C121: /smoke-archive/ -> No Consent Manager Detected | D121: 69 | E121: Template & Duplication Risks
A122: Top Issues by Template | B122: Observation | C122: /smoke-archive/ -> Lab TBT 150ms–300ms (Mobile) | D122: 69 | E122: Template & Duplication Risks
A123: Top Issues by Template | B123: Observation | C123: /smoke-archive/ -> Moderate Lighthouse Performance Mobile (50–89) | D123: 69 | E123: Template & Duplication Risks
A124: Top Issues by Template | B124: Observation | C124: /smoke-archive/ -> Render Blocking Resources | D124: 69 | E124: Template & Duplication Risks
A125: Top Issues by Template | B125: Observation | C125: /smoke-archive/ -> Missing OG Image | D125: 52 | E125: Template & Duplication Risks
A126: Top Issues by Template | B126: Observation | C126: /smoke-archive/ -> Missing Meta Description | D126: 14 | E126: Template & Duplication Risks
...

Sheet Priority URLs
A1: ← Return to Executive Briefing | C1: =IFERROR(INDEX('Audit Run Details'!$B:$B,MATCH("Target Site",'Audit Run Details'!$A:$A,0)),"") & " — " & IFERROR(INDEX('Audit Run Details'!$B:$B,MATCH("Total URLs",'Audit Run Details'!$A:$A,0)),"") & " URLs crawled — " & LEFT(IFERROR(INDEX('Audit Run Details'!$B:$B,MATCH("Run Timestamp",'Audit Run Details'!$A:$A,0)),""),10)
A2: URL | B2: Business Risk Score | C2: Severity Badge | D2: SEO Health Score | E2: GSC Impressions | F2: GSC CTR | G2: GSC Data Freshness | H2: GSC Coverage Note | I2: Revenue Intent | J2: Critical Issues Count | K2: Warning Issues Count | L2: Action Needed | M2: Why Prioritized | N2: Owner | O2: Status | P2: Sprint | Q2: Indexability Reason | R2: Broken Internal Links Count | S2: Canonical Type | T2: Open in Main | U2: Open in Technical
A3: https://africanmarketingconfederation.org/ | B3: 130 | C3: Critical | D3: 0 | E3: 1524 | F3: 0.0341 | G3: 2026-06-01 to 2026-06-30 (30-day window; excludes today; typical GSC lag ~48h) | H3: Matched in GSC — Search Analytics (30-day window) | I3: Standard | J3: 1 | K3: 0 | L3: Yes | M3: Has critical issues | N3: Dev | O3: Open | R3: 0 | T3: =IFERROR(HYPERLINK("#'Main'!B"&MATCH(TRIM(A3),'Main'!B:B,0),"Open"),HYPERLINK("#'Main'!B1","Open")) | U3: =IFERROR(HYPERLINK("#'Technical Diagnostics'!A"&MATCH(A3,'Technical Diagnostics'!A:A,0),"Open"),HYPERLINK("#'Technical Diagnostics'!A1","Open"))
A4: https://africanmarketingconfederation.org/smoke-archive/page-13 | B4: 130 | C4: Critical | D4: 0 | F4: 0 | G4: 2026-06-01 to 2026-06-30 (30-day window; excludes today; typical GSC lag ~48h) | H4: No Search Analytics row matched this URL in the 30-day export (compare Final URL with the page URL shown in GSC) | I4: Standard | J4: 1 | K4: 0 | L4: Yes | M4: Has critical issues | N4: Dev | O4: Open | R4: 0 | T4: =IFERROR(HYPERLINK("#'Main'!B"&MATCH(TRIM(A4),'Main'!B:B,0),"Open"),HYPERLINK("#'Main'!B1","Open")) | U4: =IFERROR(HYPERLINK("#'Technical Diagnostics'!A"&MATCH(A4,'Technical Diagnostics'!A:A,0),"Open"),HYPERLINK("#'Technical Diagnostics'!A1","Open"))
A5: https://africanmarketingconfederation.org/smoke-archive/page-17 | B5: 130 | C5: Critical | D5: 0 | F5: 0 | G5: 2026-06-01 to 2026-06-30 (30-day window; excludes today; typical GSC lag ~48h) | H5: No Search Analytics row matched this URL in the 30-day export (compare Final URL with the page URL shown in GSC) | I5: Standard | J5: 1 | K5: 0 | L5: Yes | M5: Has critical issues | N5: Dev | O5: Open | R5: 0 | T5: =IFERROR(HYPERLINK("#'Main'!B"&MATCH(TRIM(A5),'Main'!B:B,0),"Open"),HYPERLINK("#'Main'!B1","Open")) | U5: =IFERROR(HYPERLINK("#'Technical Diagnostics'!A"&MATCH(A5,'Technical Diagnostics'!A:A,0),"Open"),HYPERLINK("#'Technical Diagnostics'!A1","Open"))
A6: https://africanmarketingconfederation.org/smoke-archive/page-26 | B6: 130 | C6: Critical | D6: 0 | F6: 0 | G6: 2026-06-01 to 2026-06-30 (30-day window; excludes today; typical GSC lag ~48h) | H6: No Search Analytics row matched this URL in the 30-day export (compare Final URL with the page URL shown in GSC) | I6: Standard | J6: 1 | K6: 0 | L6: Yes | M6: Has critical issues | N6: Dev | O6: Open | R6: 0 | T6: =IFERROR(HYPERLINK("#'Main'!B"&MATCH(TRIM(A6),'Main'!B:B,0),"Open"),HYPERLINK("#'Main'!B1","Open")) | U6: =IFERROR(HYPERLINK("#'Technical Diagnostics'!A"&MATCH(A6,'Technical Diagnostics'!A:A,0),"Open"),HYPERLINK("#'Technical Diagnostics'!A1","Open"))
A7: https://africanmarketingconfederation.org/smoke-archive/page-34 | B7: 130 | C7: Critical | D7: 0 | F7: 0 | G7: 2026-06-01 to 2026-06-30 (30-day window; excludes today; typical GSC lag ~48h) | H7: No Search Analytics row matched this URL in the 30-day export (compare Final URL with the page URL shown in GSC) | I7: Standard | J7: 1 | K7: 0 | L7: Yes | M7: Has critical issues | N7: Dev | O7: Open | R7: 0 | T7: =IFERROR(HYPERLINK("#'Main'!B"&MATCH(TRIM(A7),'Main'!B:B,0),"Open"),HYPERLINK("#'Main'!B1","Open")) | U7: =IFERROR(HYPERLINK("#'Technical Diagnostics'!A"&MATCH(A7,'Technical Diagnostics'!A:A,0),"Open"),HYPERLINK("#'Technical Diagnostics'!A1","Open"))
A8: https://africanmarketingconfederation.org/smoke-archive/page-39 | B8: 130 | C8: Critical | D8: 0 | F8: 0 | G8: 2026-06-01 to 2026-06-30 (30-day window; excludes today; typical GSC lag ~48h) | H8: No Search Analytics row matched this URL in the 30-day export (compare Final URL with the page URL shown in GSC) | I8: Standard | J8: 1 | K8: 0 | L8: Yes | M8: Has critical issues | N8: Dev | O8: Open | R8: 0 | T8: =IFERROR(HYPERLINK("#'Main'!B"&MATCH(TRIM(A8),'Main'!B:B,0),"Open"),HYPERLINK("#'Main'!B1","Open")) | U8: =IFERROR(HYPERLINK("#'Technical Diagnostics'!A"&MATCH(A8,'Technical Diagnostics'!A:A,0),"Open"),HYPERLINK("#'Technical Diagnostics'!A1","Open"))
A9: https://africanmarketingconfederation.org/smoke-archive/page-51 | B9: 130 | C9: Critical | D9: 0 | F9: 0 | G9: 2026-06-01 to 2026-06-30 (30-day window; excludes today; typical GSC lag ~48h) | H9: No Search Analytics row matched this URL in the 30-day export (compare Final URL with the page URL shown in GSC) | I9: Standard | J9: 1 | K9: 0 | L9: Yes | M9: Has critical issues | N9: Dev | O9: Open | R9: 0 | T9: =IFERROR(HYPERLINK("#'Main'!B"&MATCH(TRIM(A9),'Main'!B:B,0),"Open"),HYPERLINK("#'Main'!B1","Open")) | U9: =IFERROR(HYPERLINK("#'Technical Diagnostics'!A"&MATCH(A9,'Technical Diagnostics'!A:A,0),"Open"),HYPERLINK("#'Technical Diagnostics'!A1","Open"))
A10: https://africanmarketingconfederation.org/smoke-archive/page-52 | B10: 130 | C10: Critical | D10: 0 | F10: 0 | G10: 2026-06-01 to 2026-06-30 (30-day window; excludes today; typical GSC lag ~48h) | H10: No Search Analytics row matched this URL in the 30-day export (compare Final URL with the page URL shown in GSC) | I10: Standard | J10: 1 | K10: 0 | L10: Yes | M10: Has critical issues | N10: Dev | O10: Open | R10: 0 | T10: =IFERROR(HYPERLINK("#'Main'!B"&MATCH(TRIM(A10),'Main'!B:B,0),"Open"),HYPERLINK("#'Main'!B1","Open")) | U10: =IFERROR(HYPERLINK("#'Technical Diagnostics'!A"&MATCH(A10,'Technical Diagnostics'!A:A,0),"Open"),HYPERLINK("#'Technical Diagnostics'!A1","Open"))
A11: https://africanmarketingconfederation.org/smoke-archive/page-65 | B11: 130 | C11: Critical | D11: 0 | F11: 0 | G11: 2026-06-01 to 2026-06-30 (30-day window; excludes today; typical GSC lag ~48h) | H11: No Search Analytics row matched this URL in the 30-day export (compare Final URL with the page URL shown in GSC) | I11: Standard | J11: 1 | K11: 0 | L11: Yes | M11: Has critical issues | N11: Dev | O11: Open | R11: 0 | T11: =IFERROR(HYPERLINK("#'Main'!B"&MATCH(TRIM(A11),'Main'!B:B,0),"Open"),HYPERLINK("#'Main'!B1","Open")) | U11: =IFERROR(HYPERLINK("#'Technical Diagnostics'!A"&MATCH(A11,'Technical Diagnostics'!A:A,0),"Open"),HYPERLINK("#'Technical Diagnostics'!A1","Open"))
A12: https://africanmarketingconfederation.org/smoke-archive/page-68 | B12: 130 | C12: Critical | D12: 0 | F12: 0 | G12: 2026-06-01 to 2026-06-30 (30-day window; excludes today; typical GSC lag ~48h) | H12: No Search Analytics row matched this URL in the 30-day export (compare Final URL with the page URL shown in GSC) | I12: Standard | J12: 1 | K12: 0 | L12: Yes | M12: Has critical issues | N12: Dev | O12: Open | R12: 0 | T12: =IFERROR(HYPERLINK("#'Main'!B"&MATCH(TRIM(A12),'Main'!B:B,0),"Open"),HYPERLINK("#'Main'!B1","Open")) | U12: =IFERROR(HYPERLINK("#'Technical Diagnostics'!A"&MATCH(A12,'Technical Diagnostics'!A:A,0),"Open"),HYPERLINK("#'Technical Diagnostics'!A1","Open"))
A13: https://africanmarketingconfederation.org/smoke-archive/page-78 | B13: 130 | C13: Critical | D13: 0 | F13: 0 | G13: 2026-06-01 to 2026-06-30 (30-day window; excludes today; typical GSC lag ~48h) | H13: No Search Analytics row matched this URL in the 30-day export (compare Final URL with the page URL shown in GSC) | I13: Standard | J13: 1 | K13: 0 | L13: Yes | M13: Has critical issues | N13: Dev | O13: Open | R13: 0 | T13: =IFERROR(HYPERLINK("#'Main'!B"&MATCH(TRIM(A13),'Main'!B:B,0),"Open"),HYPERLINK("#'Main'!B1","Open")) | U13: =IFERROR(HYPERLINK("#'Technical Diagnostics'!A"&MATCH(A13,'Technical Diagnostics'!A:A,0),"Open"),HYPERLINK("#'Technical Diagnostics'!A1","Open"))
A14: https://africanmarketingconfederation.org/smoke-archive/page-60 | B14: 125 | C14: Critical | D14: 35 | F14: 0 | G14: 2026-06-01 to 2026-06-30 (30-day window; excludes today; typical GSC lag ~48h) | H14: No Search Analytics row matched this URL in the 30-day export (compare Final URL with the page URL shown in GSC) | I14: Standard | J14: 1 | K14: 3 | L14: Yes | M14: Has critical issues | N14: Dev | O14: Open | R14: 0 | S14: self | T14: =IFERROR(HYPERLINK("#'Main'!B"&MATCH(TRIM(A14),'Main'!B:B,0),"Open"),HYPERLINK("#'Main'!B1","Open")) | U14: =IFERROR(HYPERLINK("#'Technical Diagnostics'!A"&MATCH(A14,'Technical Diagnostics'!A:A,0),"Open"),HYPERLINK("#'Technical Diagnostics'!A1","Open"))
A15: https://africanmarketingconfederation.org/smoke-archive/page-72 | B15: 125 | C15: Critical | D15: 35 | F15: 0 | G15: 2026-06-01 to 2026-06-30 (30-day window; excludes today; typical GSC lag ~48h) | H15: No Search Analytics row matched this URL in the 30-day export (compare Final URL with the page URL shown in GSC) | I15: Standard | J15: 1 | K15: 3 | L15: Yes | M15: Has critical issues | N15: Dev | O15: Open | R15: 0 | S15: self | T15: =IFERROR(HYPERLINK("#'Main'!B"&MATCH(TRIM(A15),'Main'!B:B,0),"Open"),HYPERLINK("#'Main'!B1","Open")) | U15: =IFERROR(HYPERLINK("#'Technical Diagnostics'!A"&MATCH(A15,'Technical Diagnostics'!A:A,0),"Open"),HYPERLINK("#'Technical Diagnostics'!A1","Open"))
A16: https://africanmarketingconfederation.org/smoke-archive/page-24 | B16: 105 | C16: Critical | D16: 45 | F16: 0 | G16: 2026-06-01 to 2026-06-30 (30-day window; excludes today; typical GSC lag ~48h) | H16: No Search Analytics row matched this URL in the 30-day export (compare Final URL with the page URL shown in GSC) | I16: Standard | J16: 1 | K16: 2 | L16: Yes | M16: Has critical issues | N16: Dev | O16: Open | R16: 0 | S16: self | T16: =IFERROR(HYPERLINK("#'Main'!B"&MATCH(TRIM(A16),'Main'!B:B,0),"Open"),HYPERLINK("#'Main'!B1","Open")) | U16: =IFERROR(HYPERLINK("#'Technical Diagnostics'!A"&MATCH(A16,'Technical Diagnostics'!A:A,0),"Open"),HYPERLINK("#'Technical Diagnostics'!A1","Open"))
A17: https://africanmarketingconfederation.org/smoke-archive/page-36 | B17: 105 | C17: Critical | D17: 45 | F17: 0 | G17: 2026-06-01 to 2026-06-30 (30-day window; excludes today; typical GSC lag ~48h) | H17: No Search Analytics row matched this URL in the 30-day export (compare Final URL with the page URL shown in GSC) | I17: Standard | J17: 1 | K17: 2 | L17: Yes | M17: Has critical issues | N17: Dev | O17: Open | R17: 0 | S17: self | T17: =IFERROR(HYPERLINK("#'Main'!B"&MATCH(TRIM(A17),'Main'!B:B,0),"Open"),HYPERLINK("#'Main'!B1","Open")) | U17: =IFERROR(HYPERLINK("#'Technical Diagnostics'!A"&MATCH(A17,'Technical Diagnostics'!A:A,0),"Open"),HYPERLINK("#'Technical Diagnostics'!A1","Open"))
A18: https://africanmarketingconfederation.org/smoke-archive/page-48 | B18: 105 | C18: Critical | D18: 45 | F18: 0 | G18: 2026-06-01 to 2026-06-30 (30-day window; excludes today; typical GSC lag ~48h) | H18: No Search Analytics row matched this URL in the 30-day export (compare Final URL with the page URL shown in GSC) | I18: Standard | J18: 1 | K18: 2 | L18: Yes | M18: Has critical issues | N18: Dev | O18: Open | R18: 0 | S18: self | T18: =IFERROR(HYPERLINK("#'Main'!B"&MATCH(TRIM(A18),'Main'!B:B,0),"Open"),HYPERLINK("#'Main'!B1","Open")) | U18: =IFERROR(HYPERLINK("#'Technical Diagnostics'!A"&MATCH(A18,'Technical Diagnostics'!A:A,0),"Open"),HYPERLINK("#'Technical Diagnostics'!A1","Open"))
A19: https://africanmarketingconfederation.org/smoke-archive/page-30 | B19: 90 | C19: Warning | D19: 50 | F19: 0 | G19: 2026-06-01 to 2026-06-30 (30-day window; excludes today; typical GSC lag ~48h) | H19: No Search Analytics row matched this URL in the 30-day export (compare Final URL with the page URL shown in GSC) | I19: Standard | J19: 0 | K19: 4 | L19: Yes | M19: Monitor | N19: Copy Writer | O19: Open | R19: 0 | S19: self | T19: =IFERROR(HYPERLINK("#'Main'!B"&MATCH(TRIM(A19),'Main'!B:B,0),"Open"),HYPERLINK("#'Main'!B1","Open")) | U19: =IFERROR(HYPERLINK("#'Technical Diagnostics'!A"&MATCH(A19,'Technical Diagnostics'!A:A,0),"Open"),HYPERLINK("#'Technical Diagnostics'!A1","Open"))
A20: https://africanmarketingconfederation.org/smoke-archive/page-35 | B20: 90 | C20: Warning | D20: 50 | F20: 0 | G20: 2026-06-01 to 2026-06-30 (30-day window; excludes today; typical GSC lag ~48h) | H20: No Search Analytics row matched this URL in the 30-day export (compare Final URL with the page URL shown in GSC) | I20: Standard | J20: 0 | K20: 4 | L20: Yes | M20: Monitor | N20: Copy Writer | O20: Open | R20: 0 | S20: self | T20: =IFERROR(HYPERLINK("#'Main'!B"&MATCH(TRIM(A20),'Main'!B:B,0),"Open"),HYPERLINK("#'Main'!B1","Open")) | U20: =IFERROR(HYPERLINK("#'Technical Diagnostics'!A"&MATCH(A20,'Technical Diagnostics'!A:A,0),"Open"),HYPERLINK("#'Technical Diagnostics'!A1","Open"))
A21: https://africanmarketingconfederation.org/smoke-archive/page-45 | B21: 90 | C21: Warning | D21: 50 | F21: 0 | G21: 2026-06-01 to 2026-06-30 (30-day window; excludes today; typical GSC lag ~48h) | H21: No Search Analytics row matched this URL in the 30-day export (compare Final URL with the page URL shown in GSC) | I21: Standard | J21: 0 | K21: 4 | L21: Yes | M21: Monitor | N21: Copy Writer | O21: Open | R21: 0 | S21: self | T21: =IFERROR(HYPERLINK("#'Main'!B"&MATCH(TRIM(A21),'Main'!B:B,0),"Open"),HYPERLINK("#'Main'!B1","Open")) | U21: =IFERROR(HYPERLINK("#'Technical Diagnostics'!A"&MATCH(A21,'Technical Diagnostics'!A:A,0),"Open"),HYPERLINK("#'Technical Diagnostics'!A1","Open"))
A22: https://africanmarketingconfederation.org/smoke-archive/page-70 | B22: 90 | C22: Warning | D22: 50 | F22: 0 | G22: 2026-06-01 to 2026-06-30 (30-day window; excludes today; typical GSC lag ~48h) | H22: No Search Analytics row matched this URL in the 30-day export (compare Final URL with the page URL shown in GSC) | I22: Standard | J22: 0 | K22: 4 | L22: Yes | M22: Monitor | N22: Copy Writer | O22: Open | R22: 0 | S22: self | T22: =IFERROR(HYPERLINK("#'Main'!B"&MATCH(TRIM(A22),'Main'!B:B,0),"Open"),HYPERLINK("#'Main'!B1","Open")) | U22: =IFERROR(HYPERLINK("#'Technical Diagnostics'!A"&MATCH(A22,'Technical Diagnostics'!A:A,0),"Open"),HYPERLINK("#'Technical Diagnostics'!A1","Open"))
A23: https://africanmarketingconfederation.org/smoke-archive/page-12 | B23: 85 | C23: Critical | D23: 55 | F23: 0 | G23: 2026-06-01 to 2026-06-30 (30-day window; excludes today; typical GSC lag ~48h) | H23: No Search Analytics row matched this URL in the 30-day export (compare Final URL with the page URL shown in GSC) | I23: Standard | J23: 1 | K23: 1 | L23: Yes | M23: Has critical issues | N23: Dev | O23: Open | R23: 0 | S23: self | T23: =IFERROR(HYPERLINK("#'Main'!B"&MATCH(TRIM(A23),'Main'!B:B,0),"Open"),HYPERLINK("#'Main'!B1","Open")) | U23: =IFERROR(HYPERLINK("#'Technical Diagnostics'!A"&MATCH(A23,'Technical Diagnostics'!A:A,0),"Open"),HYPERLINK("#'Technical Diagnostics'!A1","Open"))
A24: https://africanmarketingconfederation.org/smoke-archive/page-5 | B24: 70 | C24: Warning | D24: 60 | F24: 0 | G24: 2026-06-01 to 2026-06-30 (30-day window; excludes today; typical GSC lag ~48h) | H24: No Search Analytics row matched this URL in the 30-day export (compare Final URL with the page URL shown in GSC) | I24: Standard | J24: 0 | K24: 3 | L24: Yes | M24: Monitor | N24: Copy Writer | O24: Open | R24: 0 | S24: self | T24: =IFERROR(HYPERLINK("#'Main'!B"&MATCH(TRIM(A24),'Main'!B:B,0),"Open"),HYPERLINK("#'Main'!B1","Open")) | U24: =IFERROR(HYPERLINK("#'Technical Diagnostics'!A"&MATCH(A24,'Technical Diagnostics'!A:A,0),"Open"),HYPERLINK("#'Technical Diagnostics'!A1","Open"))
A25: https://africanmarketingconfederation.org/smoke-archive/page-10 | B25: 70 | C25: Warning | D25: 60 | F25: 0 | G25: 2026-06-01 to 2026-06-30 (30-day window; excludes today; typical GSC lag ~48h) | H25: No Search Analytics row matched this URL in the 30-day export (compare Final URL with the page URL shown in GSC) | I25: Standard | J25: 0 | K25: 3 | L25: Yes | M25: Monitor | N25: Copy Writer | O25: Open | R25: 0 | S25: self | T25: =IFERROR(HYPERLINK("#'Main'!B"&MATCH(TRIM(A25),'Main'!B:B,0),"Open"),HYPERLINK("#'Main'!B1","Open")) | U25: =IFERROR(HYPERLINK("#'Technical Diagnostics'!A"&MATCH(A25,'Technical Diagnostics'!A:A,0),"Open"),HYPERLINK("#'Technical Diagnostics'!A1","Open"))
... A32: https://africanmarketingconfederation.org/smoke-archive/page-54 | B32: 70 | C32: Warning | D32: 60 | F32: 0 | G32: 2026-06-01 to 2026-06-30 (30-day window; excludes today; typical GSC lag ~48h) | H32: No Search Analytics row matched this URL in the 30-day export (compare Final URL with the page URL shown in GSC) | I32: Standard | J32: 0 | K32: 3 | L32: Yes | M32: Monitor | N32: Copy Writer | O32: Open | R32: 0 | S32: self | T32: =IFERROR(HYPERLINK("#'Main'!B"&MATCH(TRIM(A32),'Main'!B:B,0),"Open"),HYPERLINK("#'Main'!B1","Open")) | U32: =IFERROR(HYPERLINK("#'Technical Diagnostics'!A"&MATCH(A32,'Technical Diagnostics'!A:A,0),"Open"),HYPERLINK("#'Technical Diagnostics'!A1","Open"))
A33: https://africanmarketingconfederation.org/smoke-archive/page-55 | B33: 70 | C33: Warning | D33: 60 | F33: 0 | G33: 2026-06-01 to 2026-06-30 (30-day window; excludes today; typical GSC lag ~48h) | H33: No Search Analytics row matched this URL in the 30-day export (compare Final URL with the page URL shown in GSC) | I33: Standard | J33: 0 | K33: 3 | L33: Yes | M33: Monitor | N33: Copy Writer | O33: Open | R33: 0 | T33: =IFERROR(HYPERLINK("#'Main'!B"&MATCH(TRIM(A33),'Main'!B:B,0),"Open"),HYPERLINK("#'Main'!B1","Open")) | U33: =IFERROR(HYPERLINK("#'Technical Diagnostics'!A"&MATCH(A33,'Technical Diagnostics'!A:A,0),"Open"),HYPERLINK("#'Technical Diagnostics'!A1","Open"))
A34: https://africanmarketingconfederation.org/smoke-archive/page-63 | B34: 70 | C34: Warning | D34: 60 | F34: 0 | G34: 2026-06-01 to 2026-06-30 (30-day window; excludes today; typical GSC lag ~48h) | H34: No Search Analytics row matched this URL in the 30-day export (compare Final URL with the page URL shown in GSC) | I34: Standard | J34: 0 | K34: 3 | L34: Yes | M34: Monitor | N34: Copy Writer | O34: Open | R34: 0 | S34: self | T34: =IFERROR(HYPERLINK("#'Main'!B"&MATCH(TRIM(A34),'Main'!B:B,0),"Open"),HYPERLINK("#'Main'!B1","Open")) | U34: =IFERROR(HYPERLINK("#'Technical Diagnostics'!A"&MATCH(A34,'Technical Diagnostics'!A:A,0),"Open"),HYPERLINK("#'Technical Diagnostics'!A1","Open"))
A35: https://africanmarketingconfederation.org/smoke-archive/page-75 | B35: 70 | C35: Warning | D35: 60 | F35: 0 | G35: 2026-06-01 to 2026-06-30 (30-day window; excludes today; typical GSC lag ~48h) | H35: No Search Analytics row matched this URL in the 30-day export (compare Final URL with the page URL shown in GSC) | I35: Standard | J35: 0 | K35: 3 | L35: Yes | M35: Monitor | N35: Copy Writer | O35: Open | R35: 0 | S35: self | T35: =IFERROR(HYPERLINK("#'Main'!B"&MATCH(TRIM(A35),'Main'!B:B,0),"Open"),HYPERLINK("#'Main'!B1","Open")) | U35: =IFERROR(HYPERLINK("#'Technical Diagnostics'!A"&MATCH(A35,'Technical Diagnostics'!A:A,0),"Open"),HYPERLINK("#'Technical Diagnostics'!A1","Open"))
A36: https://africanmarketingconfederation.org/smoke-archive/page-6 | B36: 50 | C36: Warning | D36: 70 | F36: 0 | G36: 2026-06-01 to 2026-06-30 (30-day window; excludes today; typical GSC lag ~48h) | H36: No Search Analytics row matched this URL in the 30-day export (compare Final URL with the page URL shown in GSC) | I36: Standard | J36: 0 | K36: 2 | L36: Yes | M36: Monitor | N36: Copy Writer | O36: Open | R36: 0 | S36: self | T36: =IFERROR(HYPERLINK("#'Main'!B"&MATCH(TRIM(A36),'Main'!B:B,0),"Open"),HYPERLINK("#'Main'!B1","Open")) | U36: =IFERROR(HYPERLINK("#'Technical Diagnostics'!A"&MATCH(A36,'Technical Diagnostics'!A:A,0),"Open"),HYPERLINK("#'Technical Diagnostics'!A1","Open"))
A37: https://africanmarketingconfederation.org/smoke-archive/page-7 | B37: 50 | C37: Warning | D37: 70 | F37: 0 | G37: 2026-06-01 to 2026-06-30 (30-day window; excludes today; typical GSC lag ~48h) | H37: No Search Analytics row matched this URL in the 30-day export (compare Final URL with the page URL shown in GSC) | I37: Standard | J37: 0 | K37: 2 | L37: Yes | M37: Monitor | N37: Copy Writer | O37: Open | R37: 0 | S37: self | T37: =IFERROR(HYPERLINK("#'Main'!B"&MATCH(TRIM(A37),'Main'!B:B,0),"Open"),HYPERLINK("#'Main'!B1","Open")) | U37: =IFERROR(HYPERLINK("#'Technical Diagnostics'!A"&MATCH(A37,'Technical Diagnostics'!A:A,0),"Open"),HYPERLINK("#'Technical Diagnostics'!A1","Open"))
A38: https://africanmarketingconfederation.org/smoke-archive/page-9 | B38: 50 | C38: Warning | D38: 70 | F38: 0 | G38: 2026-06-01 to 2026-06-30 (30-day window; excludes today; typical GSC lag ~48h) | H38: No Search Analytics row matched this URL in the 30-day export (compare Final URL with the page URL shown in GSC) | I38: Standard | J38: 0 | K38: 2 | L38: Yes | M38: Monitor | N38: Copy Writer | O38: Open | R38: 0 | S38: self | T38: =IFERROR(HYPERLINK("#'Main'!B"&MATCH(TRIM(A38),'Main'!B:B,0),"Open"),HYPERLINK("#'Main'!B1","Open")) | U38: =IFERROR(HYPERLINK("#'Technical Diagnostics'!A"&MATCH(A38,'Technical Diagnostics'!A:A,0),"Open"),HYPERLINK("#'Technical Diagnostics'!A1","Open"))
A39: https://africanmarketingconfederation.org/smoke-archive/page-14 | B39: 50 | C39: Warning | D39: 70 | F39: 0 | G39: 2026-06-01 to 2026-06-30 (30-day window; excludes today; typical GSC lag ~48h) | H39: No Search Analytics row matched this URL in the 30-day export (compare Final URL with the page URL shown in GSC) | I39: Standard | J39: 0 | K39: 2 | L39: Yes | M39: Monitor | N39: Copy Writer | O39: Open | R39: 0 | S39: self | T39: =IFERROR(HYPERLINK("#'Main'!B"&MATCH(TRIM(A39),'Main'!B:B,0),"Open"),HYPERLINK("#'Main'!B1","Open")) | U39: =IFERROR(HYPERLINK("#'Technical Diagnostics'!A"&MATCH(A39,'Technical Diagnostics'!A:A,0),"Open"),HYPERLINK("#'Technical Diagnostics'!A1","Open"))
A40: https://africanmarketingconfederation.org/smoke-archive/page-20 | B40: 50 | C40: Warning | D40: 70 | F40: 0 | G40: 2026-06-01 to 2026-06-30 (30-day window; excludes today; typical GSC lag ~48h) | H40: No Search Analytics row matched this URL in the 30-day export (compare Final URL with the page URL shown in GSC) | I40: Standard | J40: 0 | K40: 2 | L40: Yes | M40: Monitor | N40: Copy Writer | O40: Open | R40: 0 | S40: self | T40: =IFERROR(HYPERLINK("#'Main'!B"&MATCH(TRIM(A40),'Main'!B:B,0),"Open"),HYPERLINK("#'Main'!B1","Open")) | U40: =IFERROR(HYPERLINK("#'Technical Diagnostics'!A"&MATCH(A40,'Technical Diagnostics'!A:A,0),"Open"),HYPERLINK("#'Technical Diagnostics'!A1","Open"))
A41: https://africanmarketingconfederation.org/smoke-archive/page-21 | B41: 50 | C41: Warning | D41: 70 | F41: 0 | G41: 2026-06-01 to 2026-06-30 (30-day window; excludes today; typical GSC lag ~48h) | H41: No Search Analytics row matched this URL in the 30-day export (compare Final URL with the page URL shown in GSC) | I41: Standard | J41: 0 | K41: 2 | L41: Yes | M41: Monitor | N41: Copy Writer | O41: Open | R41: 0 | S41: self | T41: =IFERROR(HYPERLINK("#'Main'!B"&MATCH(TRIM(A41),'Main'!B:B,0),"Open"),HYPERLINK("#'Main'!B1","Open")) | U41: =IFERROR(HYPERLINK("#'Technical Diagnostics'!A"&MATCH(A41,'Technical Diagnostics'!A:A,0),"Open"),HYPERLINK("#'Technical Diagnostics'!A1","Open"))
A42: https://africanmarketingconfederation.org/smoke-archive/page-27 | B42: 50 | C42: Warning | D42: 70 | F42: 0 | G42: 2026-06-01 to 2026-06-30 (30-day window; excludes today; typical GSC lag ~48h) | H42: No Search Analytics row matched this URL in the 30-day export (compare Final URL with the page URL shown in GSC) | I42: Standard | J42: 0 | K42: 2 | L42: Yes | M42: Monitor | N42: Copy Writer | O42: Open | R42: 0 | S42: self | T42: =IFERROR(HYPERLINK("#'Main'!B"&MATCH(TRIM(A42),'Main'!B:B,0),"Open"),HYPERLINK("#'Main'!B1","Open")) | U42: =IFERROR(HYPERLINK("#'Technical Diagnostics'!A"&MATCH(A42,'Technical Diagnostics'!A:A,0),"Open"),HYPERLINK("#'Technical Diagnostics'!A1","Open"))
A43: https://africanmarketingconfederation.org/smoke-archive/page-49 | B43: 50 | C43: Warning | D43: 70 | F43: 0 | G43: 2026-06-01 to 2026-06-30 (30-day window; excludes today; typical GSC lag ~48h) | H43: No Search Analytics row matched this URL in the 30-day export (compare Final URL with the page URL shown in GSC) | I43: Standard | J43: 0 | K43: 2 | L43: Yes | M43: Monitor | N43: Copy Writer | O43: Open | R43: 0 | S43: self | T43: =IFERROR(HYPERLINK("#'Main'!B"&MATCH(TRIM(A43),'Main'!B:B,0),"Open"),HYPERLINK("#'Main'!B1","Open")) | U43: =IFERROR(HYPERLINK("#'Technical Diagnostics'!A"&MATCH(A43,'Technical Diagnostics'!A:A,0),"Open"),HYPERLINK("#'Technical Diagnostics'!A1","Open"))
A44: https://africanmarketingconfederation.org/smoke-archive/page-56 | B44: 50 | C44: Warning | D44: 70 | F44: 0 | G44: 2026-06-01 to 2026-06-30 (30-day window; excludes today; typical GSC lag ~48h) | H44: No Search Analytics row matched this URL in the 30-day export (compare Final URL with the page URL shown in GSC) | I44: Standard | J44: 0 | K44: 2 | L44: Yes | M44: Monitor | N44: Copy Writer | O44: Open | R44: 0 | S44: self | T44: =IFERROR(HYPERLINK("#'Main'!B"&MATCH(TRIM(A44),'Main'!B:B,0),"Open"),HYPERLINK("#'Main'!B1","Open")) | U44: =IFERROR(HYPERLINK("#'Technical Diagnostics'!A"&MATCH(A44,'Technical Diagnostics'!A:A,0),"Open"),HYPERLINK("#'Technical Diagnostics'!A1","Open"))
A45: https://africanmarketingconfederation.org/smoke-archive/page-66 | B45: 50 | C45: Warning | D45: 70 | F45: 0 | G45: 2026-06-01 to 2026-06-30 (30-day window; excludes today; typical GSC lag ~48h) | H45: No Search Analytics row matched this URL in the 30-day export (compare Final URL with the page URL shown in GSC) | I45: Standard | J45: 0 | K45: 2 | L45: Yes | M45: Monitor | N45: Copy Writer | O45: Open | R45: 0 | T45: =IFERROR(HYPERLINK("#'Main'!B"&MATCH(TRIM(A45),'Main'!B:B,0),"Open"),HYPERLINK("#'Main'!B1","Open")) | U45: =IFERROR(HYPERLINK("#'Technical Diagnostics'!A"&MATCH(A45,'Technical Diagnostics'!A:A,0),"Open"),HYPERLINK("#'Technical Diagnostics'!A1","Open"))
A46: https://africanmarketingconfederation.org/smoke-archive/page-77 | B46: 50 | C46: Warning | D46: 70 | F46: 0 | G46: 2026-06-01 to 2026-06-30 (30-day window; excludes today; typical GSC lag ~48h) | H46: No Search Analytics row matched this URL in the 30-day export (compare Final URL with the page URL shown in GSC) | I46: Standard | J46: 0 | K46: 2 | L46: Yes | M46: Monitor | N46: Copy Writer | O46: Open | R46: 0 | T46: =IFERROR(HYPERLINK("#'Main'!B"&MATCH(TRIM(A46),'Main'!B:B,0),"Open"),HYPERLINK("#'Main'!B1","Open")) | U46: =IFERROR(HYPERLINK("#'Technical Diagnostics'!A"&MATCH(A46,'Technical Diagnostics'!A:A,0),"Open"),HYPERLINK("#'Technical Diagnostics'!A1","Open"))
...

Sheet FixPlan
A1: ← Return to Executive Briefing | C1: =IFERROR(INDEX('Audit Run Details'!$B:$B,MATCH("Target Site",'Audit Run Details'!$A:$A,0)),"") & " — " & IFERROR(INDEX('Audit Run Details'!$B:$B,MATCH("Total URLs",'Audit Run Details'!$A:$A,0)),"") & " URLs crawled — " & LEFT(IFERROR(INDEX('Audit Run Details'!$B:$B,MATCH("Run Timestamp",'Audit Run Details'!$A:$A,0)),""),10)
A2: Issue Type | B2: Severity | C2: Priority Score | D2: Affected Count | E2: Affected URLs | F2: Detail Reference Tab | G2: Resolution Type | H2: URL | I2: Recommended Fix | J2: Likely Root Cause | K2: Owner | L2: Agency Owner | M2: Effort | N2: Est. Hours | O2: Est. Sprint Points | P2: Aging/Priority | Q2: Status | R2: Verified By | S2: Date Resolved | T2: Revenue Risk | U2: Action Needed | V2: Jump to Details | W2: Sprint | X2: Category | Y2: Open in Main | Z2: Hub Status (Content Hub)
A3: No Consent Manager Detected | B3: Observation | C3: 37 | D3: 83 | E3: SEE DETAILS IN Technical Diagnostics | F3: Technical Diagnostics | G3: Site Config | H3: https://africanmarketingconfederation.org/ | I3: Apply fix based on issue type and re-run audit. | J3: Template/technical implementation quality issue. | K3: Copy Writer | L3: Agency SEO | M3: S | N3: 4 | O3: 2 | P3: Backlog | Q3: In Review | T3: Monitor | U3: No | V3: Open in Main Tab | X3: SEO | Y3: =IFERROR(HYPERLINK("#'Main'!B"&MATCH(TRIM(H3),'Main'!B:B,0),"Open"),HYPERLINK("#'Main'!B1","Open")) | Z3: =IFERROR(INDEX('Content Optimisation Hub'!F3:F10000,MATCH(H3,'Content Optimisation Hub'!I3:I10000,0)),"Not in Hub")
A4: Lab TBT 150ms–300ms (Mobile) | B4: Observation | C4: 40 | D4: 83 | E4: SEE DETAILS IN Technical Diagnostics | F4: Technical Diagnostics | G4: Global Template | H4: https://africanmarketingconfederation.org/ | I4: Apply fix based on issue type and re-run audit. | J4: Template/technical implementation quality issue. | K4: Dev | L4: Agency Dev | M4: M | N4: 10 | O4: 5 | P4: Backlog | Q4: In Review | T4: Monitor | U4: No | V4: Open in Main Tab | X4: SEO | Y4: =IFERROR(HYPERLINK("#'Main'!B"&MATCH(TRIM(H4),'Main'!B:B,0),"Open"),HYPERLINK("#'Main'!B1","Open")) | Z4: =IFERROR(INDEX('Content Optimisation Hub'!F3:F10000,MATCH(H4,'Content Optimisation Hub'!I3:I10000,0)),"Not in Hub")
A5: Moderate Lighthouse Performance Mobile (50–89) | B5: Observation | C5: 40 | D5: 83 | E5: SEE DETAILS IN Technical Diagnostics | F5: Technical Diagnostics | G5: Global Template | H5: https://africanmarketingconfederation.org/ | I5: Apply fix based on issue type and re-run audit. | J5: Template/technical implementation quality issue. | K5: Dev | L5: Agency Dev | M5: M | N5: 10 | O5: 5 | P5: Backlog | Q5: In Review | T5: Monitor | U5: No | V5: Open in Main Tab | X5: SEO | Y5: =IFERROR(HYPERLINK("#'Main'!B"&MATCH(TRIM(H5),'Main'!B:B,0),"Open"),HYPERLINK("#'Main'!B1","Open")) | Z5: =IFERROR(INDEX('Content Optimisation Hub'!F3:F10000,MATCH(H5,'Content Optimisation Hub'!I3:I10000,0)),"Not in Hub")
A6: Render Blocking Resources | B6: Observation | C6: 40 | D6: 83 | E6: SEE DETAILS IN Technical Diagnostics | F6: Technical Diagnostics | G6: Global Template | H6: https://africanmarketingconfederation.org/ | I6: Apply fix based on issue type and re-run audit. | J6: Template/technical implementation quality issue. | K6: Dev | L6: Agency Dev | M6: M | N6: 10 | O6: 5 | P6: Backlog | Q6: In Review | T6: Monitor | U6: No | V6: Open in Main Tab | X6: SEO | Y6: =IFERROR(HYPERLINK("#'Main'!B"&MATCH(TRIM(H6),'Main'!B:B,0),"Open"),HYPERLINK("#'Main'!B1","Open")) | Z6: =IFERROR(INDEX('Content Optimisation Hub'!F3:F10000,MATCH(H6,'Content Optimisation Hub'!I3:I10000,0)),"Not in Hub")
A7: Missing OG Image | B7: Warning | C7: 73 | D7: 63 | E7: SEE DETAILS IN Technical Diagnostics | F7: Technical Diagnostics | G7: Global Template | H7: https://africanmarketingconfederation.org/smoke-archive/page-1 | I7: Apply fix based on issue type and re-run audit. | J7: Template/technical implementation quality issue. | K7: Copy Writer | L7: Agency SEO | M7: L | N7: 16 | O7: 8 | P7: Next Sprint | Q7: To Do | T7: Medium Risk | U7: Yes | V7: Open in Main Tab | X7: SEO | Y7: =IFERROR(HYPERLINK("#'Main'!B"&MATCH(TRIM(H7),'Main'!B:B,0),"Open"),HYPERLINK("#'Main'!B1","Open")) | Z7: =IFERROR(INDEX('Content Optimisation Hub'!F3:F10000,MATCH(H7,'Content Optimisation Hub'!I3:I10000,0)),"Not in Hub")
A8: Missing Meta Description | B8: Warning | C8: 70 | D8: 15 | E8: SEE DETAILS IN Technical Diagnostics | F8: Technical Diagnostics | G8: Global Template | H8: https://africanmarketingconfederation.org/smoke-archive/page-5 | I8: Add concise unique description aligned with user intent. | J8: Meta description missing or empty. | K8: Copy Writer | L8: Agency SEO | M8: M | N8: 10 | O8: 5 | P8: Next Sprint | Q8: To Do | T8: Medium Risk | U8: Yes | V8: Open in Main Tab | X8: SEO | Y8: =IFERROR(HYPERLINK("#'Main'!B"&MATCH(TRIM(H8),'Main'!B:B,0),"Open"),HYPERLINK("#'Main'!B1","Open")) | Z8: =IFERROR(INDEX('Content Optimisation Hub'!F3:F10000,MATCH(H8,'Content Optimisation Hub'!I3:I10000,0)),"Not in Hub")
A9: Missing OG Description | B9: Warning | C9: 70 | D9: 15 | E9: SEE DETAILS IN Technical Diagnostics | F9: Technical Diagnostics | G9: Global Template | H9: https://africanmarketingconfederation.org/smoke-archive/page-5 | I9: Apply fix based on issue type and re-run audit. | J9: Template/technical implementation quality issue. | K9: Copy Writer | L9: Agency SEO | M9: M | N9: 10 | O9: 5 | P9: Next Sprint | Q9: To Do | T9: Medium Risk | U9: Yes | V9: Open in Main Tab | X9: SEO | Y9: =IFERROR(HYPERLINK("#'Main'!B"&MATCH(TRIM(H9),'Main'!B:B,0),"Open"),HYPERLINK("#'Main'!B1","Open")) | Z9: =IFERROR(INDEX('Content Optimisation Hub'!F3:F10000,MATCH(H9,'Content Optimisation Hub'!I3:I10000,0)),"Not in Hub")
A10: Low Image Alt Coverage | B10: Warning | C10: 70 | D10: 13 | E10: SEE DETAILS IN Technical Diagnostics | F10: Technical Diagnostics | G10: Global Template | H10: https://africanmarketingconfederation.org/smoke-archive/page-6 | I10: Apply fix based on issue type and re-run audit. | J10: Template/technical implementation quality issue. | K10: Copy Writer | L10: Agency SEO | M10: M | N10: 10 | O10: 5 | P10: Next Sprint | Q10: To Do | T10: Medium Risk | U10: Yes | V10: Open in Main Tab | X10: SEO | Y10: =IFERROR(HYPERLINK("#'Main'!B"&MATCH(TRIM(H10),'Main'!B:B,0),"Open"),HYPERLINK("#'Main'!B1","Open")) | Z10: =IFERROR(INDEX('Content Optimisation Hub'!F3:F10000,MATCH(H10,'Content Optimisation Hub'!I3:I10000,0)),"Not in Hub")
A11: Non-200 Status | B11: Critical | C11: 102 | D11: 11 | E11: SEE DETAILS IN Technical Diagnostics | F11: Technical Diagnostics | G11: Global Template | H11: https://africanmarketingconfederation.org/ | I11: Fix status code, restore page, or implement correct redirect to canonical destination. | J11: URL returns 4xx/5xx or equivalent failure. | K11: Server/Host | L11: Agency Dev | M11: S | N11: 4 | O11: 2 | P11: Immediate (Current Sprint) | Q11: To Do | T11: High Risk | U11: Yes | V11: Open in Main Tab | X11: SEO | Y11: =IFERROR(HYPERLINK("#'Main'!B"&MATCH(TRIM(H11),'Main'!B:B,0),"Open"),HYPERLINK("#'Main'!B1","Open")) | Z11: =IFERROR(INDEX('Content Optimisation Hub'!F3:F10000,MATCH(H11,'Content Optimisation Hub'!I3:I10000,0)),"Not in Hub")
A12: No Author Attribution | B12: Observation | C12: 37 | D12: 11 | E12: SEE DETAILS IN Technical Diagnostics | F12: Technical Diagnostics | G12: Global Template | H12: https://africanmarketingconfederation.org/smoke-archive/page-7 | I12: Apply fix based on issue type and re-run audit. | J12: Template/technical implementation quality issue. | K12: Copy Writer | L12: Agency SEO | M12: S | N12: 4 | O12: 2 | P12: Backlog | Q12: In Review | T12: Monitor | U12: No | V12: Open in Main Tab | X12: SEO | Y12: =IFERROR(HYPERLINK("#'Main'!B"&MATCH(TRIM(H12),'Main'!B:B,0),"Open"),HYPERLINK("#'Main'!B1","Open")) | Z12: =IFERROR(INDEX('Content Optimisation Hub'!F3:F10000,MATCH(H12,'Content Optimisation Hub'!I3:I10000,0)),"Not in Hub")
A13: Low E-E-A-T Signal Score (<3) | B13: Warning | C13: 67 | D13: 11 | E13: SEE DETAILS IN Technical Diagnostics | F13: Technical Diagnostics | G13: Global Template | H13: https://africanmarketingconfederation.org/smoke-archive/page-7 | I13: Apply fix based on issue type and re-run audit. | J13: Template/technical implementation quality issue. | K13: Copy Writer | L13: Agency SEO | M13: S | N13: 4 | O13: 2 | P13: Next Sprint | Q13: To Do | T13: Medium Risk | U13: Yes | V13: Open in Main Tab | X13: SEO | Y13: =IFERROR(HYPERLINK("#'Main'!B"&MATCH(TRIM(H13),'Main'!B:B,0),"Open"),HYPERLINK("#'Main'!B1","Open")) | Z13: =IFERROR(INDEX('Content Optimisation Hub'!F3:F10000,MATCH(H13,'Content Optimisation Hub'!I3:I10000,0)),"Not in Hub")
A14: No Question Headings | B14: Observation | C14: 37 | D14: 9 | E14: https://africanmarketingconfederation.org/smoke-archive/page-9 https://africanmarketingconfederation.org/smoke-archive/page-18 https://africanmarketingconfederation.org/smoke-archive/page-27 https://africanmarketingconfederation.org/smoke-archive/page-36 https://africanmarketingconfederation.org/smoke-archive/page-45 https://africanmarketingconfederation.org/smoke-archive/page-54 https://africanmarketingconfederation.org/smoke-archive/page-63 https://africanmarketingconfederation.org/smoke-archive/page-72 https://africanmarketingconfederation.org/discovered-via-bfs-1 | F14: Content & AI Readiness | G14: Manual Content | H14: https://africanmarketingconfederation.org/smoke-archive/page-9 | I14: Rewrite priority H2/H3 headings into natural-language questions (Who/What/How) so the following paragraph can serve as a direct extractable answer. | J14: Headings are not phrased as user questions. | K14: Copy Writer | L14: Agency SEO | M14: S | N14: 4 | O14: 2 | P14: Backlog | Q14: In Review | T14: Monitor | U14: No | V14: Open in Main Tab | X14: AEO | Y14: =IFERROR(HYPERLINK("#'Main'!B"&MATCH(TRIM(H14),'Main'!B:B,0),"Open"),HYPERLINK("#'Main'!B1","Open")) | Z14: =IFERROR(INDEX('Content Optimisation Hub'!F3:F10000,MATCH(H14,'Content Optimisation Hub'!I3:I10000,0)),"Not in Hub")
