Workbook

Sheet Table of Contents
A1: Table of Contents | B1: Unnamed: 1 | C1: Unnamed: 2
A2: Section | B2: Open | C2: Description
A3: Dashboard | B3: Open | C3: Primary columns: Executive SEO & AEO Performance Report, Unnamed: 1, Unnamed: 2, Unnamed: 3, Unnamed: 4, Unnamed: 5, Unnamed: 6, Unnamed: 7, Unnamed: 8, Unnamed: 9
A4: Content Optimization Hub | B4: Open | C4: Primary columns: CONTENT HUB INSTRUCTIONS: 1. Draft in 'Proposed' columns. | 2. Watch 'Count' for Green. | 3. Click 'Elementor' link. | 4. Mark 'Status' as 'Completed'. | NOTE: If images show '#BLOCKED!', click the 'Sec…
A5: Quick Reference Guide | B5: Open | C5: Primary columns: Section, Item, Guideline, Why It Matters, BACK TO DASHBOARD, BACK TO DASHBOARD_1
A6: FixPlan | B6: Open | C6: Primary columns: Issue Type, Severity, Priority Score, Affected Count, Affected URLs, Detail Reference Tab, Resolution Type, URL, Recommended Fix, Likely Root Cause
A7: Main | B7: Open | C7: Primary columns: Health Icon, URL, Status Code, Indexability, Load Time (s), Title, Meta Description, Word Count (Body), SEO Health Score, Severity Badge
A8: Technical | B8: Open | C8: Primary columns: URL, Status Code, Status Class, SEO Health Score, Severity Badge, Action Needed, Indexability Reason, TTFB (ms), Total Request Time (ms), Final URL
A9: PSI Performance | B9: Open | C9: Primary columns: URL, Desktop Score, Mobile Score, Mobile LCP, Mobile CLS, Mobile TTFB, Open in Main, BACK TO DASHBOARD, BACK TO DASHBOARD_1
A10: Content | B10: Open | C10: Primary columns: URL, Word Count, Word Count Band, Readability (Rough Flesch), H1 Count, Missing H1 Flag, Multiple H1 Flag, Title Missing, Meta Description Missing, Thin Content Flag
A11: AEO | B11: Open | C11: Primary columns: URL, AEO Readiness Score, AEO Badge, Why It Matters, FAQ Section Count, Question Heading Count, Paragraphs 40-60 Words Count, QAPage/FAQ Schema Present, Speakable Schema Present, HowTo Signal
A12: Schema & Metadata | B12: Open | C12: Primary columns: URL, Schema Types Found, Schema Types Count, Schema Parse Errors, OG Title, OG Description, OG Image, Open Graph Complete, Twitter Card Type, Open in Main
... A30: SitemapQA | B30: Open | C30: Primary columns: Sitemap URL, Final URL, Status Code, Found via Crawl, Found via Sitemap, Discovery Source, In Sitemap but Non-200, Sitemap URL Redirects, In Sitemap but Canonicalized Elsewhere, Missing <lastmod>

Sheet Dashboard
A1: Executive SEO & AEO Performance Report | B1: Unnamed: 1 | C1: Unnamed: 2 | D1: Unnamed: 3 | E1: Unnamed: 4 | F1: Unnamed: 5 | G1: Unnamed: 6 | H1: Unnamed: 7 | I1: Unnamed: 8 | J1: Unnamed: 9 | K1: Unnamed: 10
A2: Executive SEO & AEO Dashboard
A4: EXECUTIVE METRICS | B4: Value | D4: Status | E4: Count | G4: OWNER ISSUE SUMMARY
A5: Total URLs | B5: 10 | D5: 200 OK | E5: 10 | G5: Owner | H5: Issue Rows | I5: Affected URLs | J5: Critical | K5: Warning
A6: Overall Health Score | B6: =IFERROR(100.0/100,0) | D6: 3xx Redirects | E6: 0 | G6: =HYPERLINK("#'FixPlan'!A1","Dev") | H6: 9 | I6: 0 | J6: 4 | K6: 4
A7: SEO Pass Rate % | B7: =IFERROR(10/10,0) | D7: 4xx Errors | E7: 0 | G7: =HYPERLINK("#'FixPlan'!A1","Server/Host") | H7: 5 | I7: 0 | J7: 2 | K7: 0
A8: Pass URLs | B8: 10 | D8: 5xx Errors | E8: 0 | G8: =HYPERLINK("#'FixPlan'!A1","Copy Writer") | H8: 20 | I8: 0 | J8: 1 | K8: 8
A9: Critical URLs | B9: 0 | D9: Other | E9: 0
A10: Warning URLs | B10: 0
A11: Error Rate % (4xx/5xx) | B11: =IFERROR(0/10,0)
A12: Crawl Success Rate % (2xx) | B12: =IFERROR(10/10,0) | D12: Severity | E12: Count | J12: Quick Navigation | K12: Open
A13: Critical URL Rate % | B13: =IFERROR(0/10,0) | D13: Critical | E13: 7 | J13: Fix Plan | K13: =HYPERLINK("#FixPlan!A1","Open")
A14: Warning URL Rate % | B14: =IFERROR(0/10,0) | D14: Warning | E14: 12 | J14: Main URL Data | K14: =HYPERLINK("#Main!A1","Open")
A15: Projected Health Score % (if all To Do done) | B15: 1 | D15: Medium | E15: 0 | J15: Technical Diagnostics | K15: =HYPERLINK("#Technical!A1","Open")
A16: Projected Pass Rate % (if all To Do done) | B16: 1 | D16: Low | E16: 15 | J16: Indexability | K16: =HYPERLINK("#Indexability!A1","Open")
A17: Content Hub Readiness (%) | B17: 0 | J17: AEO Opportunities | K17: =HYPERLINK("#AEO!A1","Open")
A18: URLs with Schema | B18: 0 | J18: AIOSEO Action Queue | K18: =HYPERLINK("#AIOSEO!A1","Open")
A19: Broken Internal Links | B19: 0
E20: Traditional SEO vs. 2026 AEO Readiness | J20: BUSINESS IMPACT SUMMARY
E21: Dimension | F21: Score | J21: 0 error URLs detected (0 4xx / 0 5xx). Critical issue volume is 0 URLs and warning volume is 0. Top blocker: N/A affecting 0 URLs.
E22: Traditional SEO | F22: 1
E23: 2026 AEO Readiness | F23: 0
E24: Strategic Narrative
E25: High SEO / Low AEO suggests the site is visible to humans but invisible to AI answer engines.
B44: TOP ISSUES TO FIX FIRST | C44: Affected URLs
B45: =HYPERLINK("#FixPlan!A8","Broken Internal Links") | C45: 0
B46: =HYPERLINK("#FixPlan!A7","CWV LCP Above 4.0s") | C46: 0
B47: =HYPERLINK("#FixPlan!A5","Canonical Points Elsewhere") | C47: 0
B48: =HYPERLINK("#FixPlan!A3","Missing Title") | C48: 0
B49: =HYPERLINK("#FixPlan!A4","Noindex Directive") | C49: 0

Sheet Content Optimization Hub
A1: CONTENT HUB INSTRUCTIONS: 1. Draft in 'Proposed' columns. | 2. Watch 'Count' for Green. | 3. Click 'Elementor' link. | 4. Mark 'Status' as 'Completed'. | NOTE: If images show '#BLOCKED!', click the 'Security Warning' bar at the top of Excel and select 'Enable Content'.
A2: CONTENT HUB INSTRUCTIONS: 1. Draft in 'Proposed' columns. | 2. Watch 'Count' for Green. | 3. Click 'Elementor' link. | 4. Mark 'Status' as 'Completed'. | NOTE: If images show '#BLOCKED!', click the 'Security Warning' bar at the top of Excel and select 'En | B2: Unnamed: 1 | C2: Unnamed: 2 | D2: Unnamed: 3 | E2: Unnamed: 4 | F2: Unnamed: 5 | G2: Unnamed: 6 | H2: Unnamed: 7 | I2: Unnamed: 8 | J2: Unnamed: 9 | K2: Unnamed: 10 | L2: Unnamed: 11 | M2: Unnamed: 12 | N2: Unnamed: 13 | O2: Unnamed: 14 | P2: Unnamed: 15 | Q2: Unnamed: 16 | R2: Unnamed: 17 | S2: Unnamed: 18 | T2: Unnamed: 19 | U2: Unnamed: 20 | V2: Unnamed: 21 | W2: Unnamed: 22 | X2: Unnamed: 23 | Y2: Unnamed: 24
A3: Action Required | B3: Status | C3: Assigned Owner | D3: Content Cluster ID | E3: URL | F3: Elementor Builder Link | G3: Target Keywords | H3: Current Page Copy Snippet | I3: Current Title | J3: Proposed Title (50-60 Chars) | K3: Title Count | L3: Current Meta Desc | M3: Proposed Meta Desc (120-160 Chars) | N3: Desc Count | O3: Current H-Tag Structure | P3: Proposed H-Tag Fixes | Q3: AEO Answer Block Draft | R3: FAQ/QA Draft | S3: Current OG-Image URL | T3: OG Image Preview | U3: Social Share Note | V3: SEO Score | W3: Technical Health | X3: Copy Score | Y3: Open in Main
A4: Needs Copy | B4: To Do | C4: Unassigned | D4: home-african-marketing-confed | E4: https://africanmarketingconfederation.org/ | F4: https://africanmarketingconfederation.org/wp-admin/post.php?post=8&action=elementor | H4: European marketers gather to choose their top achievers for 2026 Marketing associations from across Europe nominated national champions, with 10 finalists competing for the Marketer of the Year title. Read More » April 30, 2026 | I4: African Marketing Confederation - Uniting Marketers for Excellence | L4: The African Marketing Confederation is the ground-breaking Pan-African body driving the development of top marketing standards across Africa and beyond. | O4: H1: ABOUT The African Marketing Confederation H2: The 2026 AMC Conference H2: Meets the Mighty Victoria Falls H2: 23-25 September | Livingstone, Zambia H2: The 2026 AMC Conference H2: Meets the Mighty Victoria Falls | S4: https://africanmarketingconfederation.org/wp-content/uploads/2026/03/og-image.png | V4: 18.75 | W4: 0 | X4: 75 | Y4: Open
A5: Needs Copy | B5: To Do | C5: Unassigned | D5: about-us-african-marketing-confed | E5: https://africanmarketingconfederation.org/about-us | F5: https://africanmarketingconfederation.org/wp-admin/post.php?post=84&action=elementor | G5: About Us | H5: Skip to content ABOUT The African Marketing Confederation The African Marketing Confederation is the ground-breaking Pan African body of marketing professionals spearheading the ongoing development of the highest possible standards of marketing acro... | I5: African Marketing Confederation – The Leading Marketing Professional Body – African Marketing Confederation | L5: ABOUT The African Marketing Confederation The African Marketing Confederation is the ground-breaking Pan African body of marketing professionals spearheading the ongoing development of the highest possible standards of marketing across Africa. Founded in 2011, the AMC is a collaboration between the African national marketing bodies and associations to exchange expertise and information, and to promote | O5: H1: ABOUT The African Marketing Confederation H3: African Marketing Confederation PRESIDENT’S COUNCIL H2: Helen McIntee H2: President and Co-founder H2: David Balikuddembe H2: Secretary General | S5: https://africanmarketingconfederation.org/wp-content/uploads/2026/03/og-image.png | V5: 18.75 | W5: 0 | X5: 75 | Y5: Open
A6: Needs Copy | B6: To Do | C6: Unassigned | D6: african-marketing-confederation-tourism-chapter-african-marketing-confed | E6: https://africanmarketingconfederation.org/african-marketing-confederation-tourism-chapter | F6: https://africanmarketingconfederation.org/wp-admin/post.php?post=28165&action=elementor | G6: African Marketing Confederation Tourism Chapter | H6: Skip to content African Marketing Confederation Tourism Chapter Shaping Africa’s Tourism Narrative Through Strategic Marketing Tourism is one of Africa’s most powerful economic engines – generating jobs, stimulating investment, and fostering cultural... | I6: African Marketing Confederation Tourism Chapter – African Marketing Confederation | L6: African Marketing Confederation Tourism Chapter Shaping Africa’s Tourism Narrative Through Strategic Marketing Tourism is one of Africa’s most powerful economic engines - generating jobs, stimulating investment, and fostering cultural exchange.The African Marketing Confederation is proud to launch the Tourism Chapter, a bold initiative to elevate African tourism through the lens of world-class marketing. Launched at the | O6: H1: African Marketing Confederation Tourism Chapter H3: Shaping Africa’s Tourism Narrative Through Strategic Marketing H2: Charting the Course: Purpose, Mission & Vision for Africa’s Tourism Future H2: Our Goals and Objectives: | S6: https://africanmarketingconfederation.org/wp-content/uploads/2026/03/og-image.png | V6: 25 | W6: 0 | X6: 100 | Y6: Open
A7: Needs Copy | B7: To Do | C7: Unassigned | D7: amc-awards-2024-amc-awards-{n}-–-african | E7: https://africanmarketingconfederation.org/amc-awards-2024 | F7: https://africanmarketingconfederation.org/wp-admin/post.php?post=16125&action=elementor | G7: Amc Awards 2024 | H7: English Français Português Español Igbo Deutsch Kiswahili ພາສາລາວ العربية Afsoomaali Sesotho 简体中文 Русский Zulu en NOMINATIONS are Open ! AMC Awards The African Marketing Confederation Awards event is held annually as part of the African Marketing Con... | I7: AMC Awards 2024 – African Marketing Confederation | L7: NOMINATIONS are Open ! AMC Awards The African Marketing Confederation Awards event is held annually as part of the African Marketing Confederation Forum. This distinguished event celebrates and acknowledges outstanding marketing campaigns and the visionary individuals behind them. The awards presented honor not only the groundbreaking strategies and creative brilliance that set these campaigns apart but | O7: H1: NOMINATIONS are Open ! H2: Awards Categories H2: Tourism & Destination Marketing Campaign H2: of the Year H2: Best Social Media Campaign of the Year H2: Best Social Media Campaign | S7: https://africanmarketingconfederation.org/wp-content/uploads/2021/08/amc_faw.png | V7: 25 | W7: 0 | X7: 100 | Y7: Open
A8: Needs Copy | B8: To Do | C8: Unassigned | D8: amc-conference-2022-amc-conference-{n}-–-afr | E8: https://africanmarketingconfederation.org/amc-conference-2022 | F8: https://africanmarketingconfederation.org/wp-admin/post.php?post=4494&action=elementor | G8: Amc Conference 2022 | H8: AMC officially welcomes new member associations into the fold October 8, 2024 No Comments Angola, Botswana, Ethiopia, Mozambique and Tanzania receive their membership certificates. AMC now has 16 members. Read More » | I8: AMC Conference 2022 – African Marketing Confederation | L8: corinna kopf onlyfans leaks AMC Conference 2022 Thank you for attending19 - 22 October 2022 The African Marketing Confederation's Annual Conference brought together the best collection of marketing leaders from top companies, marketing bodies and associations to share tactics and best practices on how to build the next generation of marketing. Event Highlights Thank you for Attending! | O8: H2: AMC Conference 2022 H2: Event Highlights H3: AMC officially welcomes new member associations into the fold H3: Marketers are placing the ads where consumers don’t want to see them H3: Time for Africa to control its own narrative and image, delegates told H3: Excitement as Ghana announced as host of 2025 AMC marketing conference | S8: https://africanmarketingconfederation.org/wp-content/uploads/2026/03/og-image.png | V8: 11.25 | W8: 0 | X8: 45 | Y8: Open
A9: Needs Copy | B9: To Do | C9: Unassigned | D9: amc-conference-2022-prospectus-amc-conference-{n}-–-pro | E9: https://africanmarketingconfederation.org/amc-conference-2022-prospectus | F9: https://africanmarketingconfederation.org/wp-admin/post.php?post=5619&action=elementor | G9: Amc Conference 2022 Prospectus | H9: Skip to content AMC Conference 2022 23 - 24 March 2022 Navigating Africa’s Unique Marketing Mix BOOK NOW 00 Days 00 Hours 00 Minutes 00 Seconds download prospectus To download the AMC 2022 Conference Prospectus please complete the form below: First ... | I9: AMC Conference 2022 – Prospectus – African Marketing Confederation | L9: AMC Conference 2022 23 - 24 March 2022 Navigating Africa's Unique Marketing Mix BOOK NOW Days Hours Minutes Seconds download prospectus To download the AMC 2022 Conference Prospectus please complete the form below: First Name Last Name Email Mobile Company I've read and agree to the Privacy Policy BOOK NOW FOR THE AMC CONFERENCE 2022 | O9: H2: AMC Conference 2022 H2: download prospectus H2: BOOK NOW FOR THE AMC CONFERENCE 2022 | S9: https://africanmarketingconfederation.org/wp-content/uploads/2026/03/og-image.png | V9: 11.25 | W9: 0 | X9: 45 | Y9: Open
A10: Needs Copy | B10: To Do | C10: Unassigned | D10: amc-conference-2022-thank-you-amc-conference-{n}-–-tha | E10: https://africanmarketingconfederation.org/amc-conference-2022-thank-you | F10: https://africanmarketingconfederation.org/wp-admin/post.php?post=4941&action=elementor | G10: Amc Conference 2022 Thank You | H10: Skip to content AMC Conference 2022 23 - 24 March 2022 Navigating Africa’s Unique Marketing Mix ENQUIRE NOW 00 Days 00 Hours 00 Minutes 00 Seconds Success! Thank you for completing the enquiry form. Our team will contact you shortly! × The AMC Confer... | I10: AMC Conference 2022 – Thank You – African Marketing Confederation | L10: AMC Conference 2022 23 - 24 March 2022 Navigating Africa's Unique Marketing Mix ENQUIRE NOW Days Hours Minutes Seconds Success! Thank you for completing the enquiry form. Our team will contact you shortly! × Dismiss alert The AMC Conference is the must attend Pan African event for marketing professionals. It will focus on solutions for | O10: H2: AMC Conference 2022 H2: WHO SHOULD ATTEND H2: Countries Participating H3: South Africa H3: Nigeria H3: Morocco | S10: https://africanmarketingconfederation.org/wp-content/uploads/2026/03/og-image.png | V10: 17.5 | W10: 0 | X10: 70 | Y10: Open
A11: Needs Copy | B11: To Do | C11: Unassigned | D11: amc-conference-2023-amc-conference-{n}-–-afr | E11: https://africanmarketingconfederation.org/amc-conference-2023 | F11: https://africanmarketingconfederation.org/wp-admin/post.php?post=12371&action=elementor | G11: Amc Conference 2023 | H11: AMC Conference 6 - 9 September 2023 Imperial Botanical Beach Hotel, Entebbe, Uganda Thank you for joining us! View Presentations 2nd Annual African Marketing Confederation Conference Africa's $3.4 trillion Economy: Opportunities for Marketers Welcome... | I11: AMC Conference 2023 – African Marketing Confederation | L11: AMC Conference 6 - 9 September 2023 Imperial Botanical Beach Hotel, Entebbe, Uganda Thank you for joining us! View Presentations 2nd Annual African Marketing Confederation Conference Africa's $3.4 trillion Economy: Opportunities for Marketers Welcome to the Recap of the 2nd Annual African Marketing Conference: Unveiling Africa's $3.4 Trillion EconomyOur conference was a remarkable exploration of | O11: H1: AMC Conference H2: Africa's $3.4 trillion Economy: Opportunities for Marketers H2: Thank you for joining us! H2: Topics covered H3: Africa Free Trade Area H3: Business Intelligence | S11: https://africanmarketingconfederation.org/wp-content/uploads/2021/08/amc_faw.png | V11: 25 | W11: 0 | X11: 100 | Y11: Open
A12: Needs Copy | B12: To Do | C12: Unassigned | D12: amc-conference-2023-amc-awards-–-african-mar | E12: https://africanmarketingconfederation.org/amc-conference-2023/amc-awards | F12: https://africanmarketingconfederation.org/wp-admin/post.php?post=12954&action=elementor | G12: Amc Awards | H12: Skip to content AMC Awards Welcome to the prestigious African Marketing Confederation Awards, a distinguished event that celebrates and acknowledges the remarkable achievements, cutting-edge innovations, and exceptional leadership demonstrated by out... | I12: AMC Awards – African Marketing Confederation | L12: AMC Awards Welcome to the prestigious African Marketing Confederation Awards, a distinguished event that celebrates and acknowledges the remarkable achievements, cutting-edge innovations, and exceptional leadership demonstrated by outstanding individuals within the dynamic realm of marketing across the expansive African region.During the 2nd Annual African Marketing Confederation Conference, held from 6th to 9th September at the | O12: H1: AMC Awards H2: AMC AWARD Winners | S12: https://africanmarketingconfederation.org/wp-content/uploads/2021/08/amc_faw.png | V12: 25 | W12: 0 | X12: 100 | Y12: Open
A13: Needs Copy | B13: To Do | C13: Unassigned | D13: amc-conference-2023-amc-awards-|-book-now-–- | E13: https://africanmarketingconfederation.org/amc-conference-2023/amc-awards-book-now | F13: https://africanmarketingconfederation.org/wp-admin/post.php?post=13164&action=elementor | G13: Amc Awards Book Now | H13: Skip to content English Français Português Español Igbo Deutsch Kiswahili ພາສາລາວ العربية Afsoomaali Sesotho 简体中文 Русский Zulu en 0 Your Cart Your cart is empty Return to Shop Continue Shopping Notifications | I13: AMC Awards | Book Now – African Marketing Confederation | L13: MISSING DESCRIPTION | S13: https://africanmarketingconfederation.org/wp-content/uploads/2021/08/amc_faw.png | V13: 6.25 | W13: 0 | X13: 25 | Y13: Open

Sheet Quick Reference Guide
A1: Section | B1: Item | C1: Guideline | D1: Why It Matters | E1: BACK TO DASHBOARD | F1: BACK TO DASHBOARD_1
A2: [Meta Data Standards]
B3: Meta Title | C3: 50-60 characters. Place primary keyword at the front. Avoid brand repetition unless there is space. | D3: Improves clarity and reduces SERP truncation risk.
B4: Meta Description | C4: 120-160 characters. Must contain a clear Call-To-Action (CTA) and active verbs. | D4: Supports stronger click-through and intent alignment.
B5: Target Keywords | C5: 1 Primary, 2 Secondary per page. Do not keyword stuff; focus on user intent. | D5: Keeps copy focused on topical relevance over keyword density.
A7: [On-Page Structure (H-Tags)]
B8: H1 Tag | C8: Exactly ONE per page. Must contain the primary topic/keyword. Think of it as the 'Book Title'. | D8: Provides the clearest top-level topical signal.
B9: H2 Tags | C9: Main sections. Use question formats (Who, What, How) to trigger Answer Engine extraction. | D9: Improves structured scannability for users and LLMs.
B10: H3 Tags | C10: Sub-sections under H2s. Use for lists, steps, or detailed breakdowns. | D10: Strengthens hierarchy and supports extraction-ready formatting.
B11: H4-H6 Tags | C11: Use sparingly. Only for granular formatting within complex H3 topics. | D11: Avoids over-nesting while preserving semantic structure.
A13: [AEO (Answer Engine Optimization) & Content]
B14: AEO Answer Blocks | C14: 40-60 words. Placed directly beneath an H2 question. Must be factual, objective, and devoid of marketing fluff (e.g., 'The best way to...'). | D14: Optimizes direct extraction for answer engines and voice search.
B15: FAQ Schema | C15: Minimum 2-3 questions per informational page. Answers must be direct and stand alone without needing the rest of the page for context. | D15: Improves machine readability and rich-answer eligibility.
B16: Content Readability | C16: Keep sentences under 20 words. Use bullet points for any list of 3 or more items. | D16: Increases comprehension and snippet usability.
A18: [Visual & Social Branding]
B19: OG Image | C19: 1200 x 630 pixels. Keep text centered (safe zone) so it isn't cropped by mobile devices on LinkedIn/X. | D19: Ensures consistent social card presentation.
B20: Social Share Note | C20: Customize the message for the platform. LinkedIn = Professional insight. X (Twitter) = Quick hook. Facebook = Conversational. | D20: Improves engagement by matching platform context.

Sheet FixPlan
A1: Issue Type | B1: Severity | C1: Priority Score | D1: Affected Count | E1: Affected URLs | F1: Detail Reference Tab | G1: Resolution Type | H1: URL | I1: Recommended Fix | J1: Likely Root Cause | K1: Owner | L1: Agency Owner | M1: Effort | N1: Est. Hours | O1: Est. Sprint Points | P1: Aging/Priority | Q1: Status | R1: Verified By | S1: Date Resolved | T1: Revenue Risk | U1: Action Needed | V1: Jump to Details | W1: Sprint | X1: Category | Y1: Fix Type | Z1: Estimated Traffic Impact | AA1: Fix Effort | AB1: ROI Score | AC1: Exact Action | AD1: Open in Main | AE1: Hub Status (Content Hub) | AF1: BACK TO DASHBOARD | AG1: BACK TO DASHBOARD_1
A2: Non-200 Status | B2: Critical | C2: 105 | D2: 0 | F2: Technical | G2: Manual Content | I2: Fix status code, restore page, or implement correct redirect to canonical destination. | J2: URL returns 4xx/5xx or equivalent failure. | K2: Server/Host | L2: Server/Host | M2: M | N2: 10 | O2: 5 | P2: Immediate (Current Sprint) | Q2: To Do | T2: High Risk | U2: Yes | V2: Open in Main Tab | X2: SEO | Y2: Technical | Z2: Low | AA2: 10 | AB2: 0 | AC2: Resolve 'Non-200 Status' using technical best practices and validate in the related detail tab. | AD2: Open | AE2: =IFERROR(INDEX('Content Optimization Hub'!A:A,MATCH(H2,'Content Optimization Hub'!C:C,0)),"Not in Hub")
A3: Missing Title | B3: Critical | C3: 105 | D3: 0 | F3: Technical | G3: Manual Content | I3: Add unique descriptive title on affected template/page type. | J3: Template/page missing title tag. | K3: Copy Writer | L3: Copy Writer | M3: M | N3: 10 | O3: 5 | P3: Immediate (Current Sprint) | Q3: To Do | T3: High Risk | U3: Yes | V3: Open in Main Tab | X3: SEO | Y3: Content | Z3: Low | AA3: 10 | AB3: 0 | AC3: Resolve 'Missing Title' using content best practices and validate in the related detail tab. | AD3: Open | AE3: =IFERROR(INDEX('Content Optimization Hub'!A:A,MATCH(H3,'Content Optimization Hub'!C:C,0)),"Not in Hub")
A4: Noindex Directive | B4: Critical | C4: 105 | D4: 0 | F4: Indexability | G4: Manual Content | I4: Remove unintended noindex directives on index-worthy URLs. | J4: Meta robots or X-Robots-Tag contains noindex. | K4: Dev | L4: Dev | M4: M | N4: 10 | O4: 5 | P4: Immediate (Current Sprint) | Q4: To Do | T4: High Risk | U4: Yes | V4: Open in Main Tab | X4: SEO | Y4: Technical | Z4: Low | AA4: 10 | AB4: 0 | AC4: Resolve 'Noindex Directive' using technical best practices and validate in the related detail tab. | AD4: Open | AE4: =IFERROR(INDEX('Content Optimization Hub'!A:A,MATCH(H4,'Content Optimization Hub'!C:C,0)),"Not in Hub")
A5: Canonical Points Elsewhere | B5: Critical | C5: 105 | D5: 0 | F5: Indexability | G5: Global Template | I5: Align canonical to preferred final URL and ensure internal links use canonical target. | J5: Canonical targets a different URL variant. | K5: Dev | L5: Dev | M5: M | N5: 10 | O5: 5 | P5: Immediate (Current Sprint) | Q5: To Do | T5: High Risk | U5: Yes | V5: Open in Main Tab | X5: SEO | Y5: Technical | Z5: Low | AA5: 10 | AB5: 0 | AC5: Resolve 'Canonical Points Elsewhere' using technical best practices and validate in the related detail tab. | AD5: Open | AE5: =IFERROR(INDEX('Content Optimization Hub'!A:A,MATCH(H5,'Content Optimization Hub'!C:C,0)),"Not in Hub")
A6: Robots.txt Disallow Root | B6: Critical | C6: 105 | D6: 0 | F6: Technical | G6: Global Template | I6: Apply fix based on issue type and re-run audit. | J6: Template/technical implementation quality issue. | K6: Server/Host | L6: Server/Host | M6: M | N6: 10 | O6: 5 | P6: Immediate (Current Sprint) | Q6: To Do | T6: High Risk | U6: Yes | V6: Open in Main Tab | X6: SEO | Y6: Content | Z6: Low | AA6: 10 | AB6: 0 | AC6: Resolve 'Robots.txt Disallow Root' using content best practices and validate in the related detail tab. | AD6: Open | AE6: =IFERROR(INDEX('Content Optimization Hub'!A:A,MATCH(H6,'Content Optimization Hub'!C:C,0)),"Not in Hub")
A7: CWV LCP Above 4.0s | B7: Critical | C7: 105 | D7: 0 | F7: Technical | G7: Global Template | I7: Apply fix based on issue type and re-run audit. | J7: Template/technical implementation quality issue. | K7: Dev | L7: Dev | M7: M | N7: 10 | O7: 5 | P7: Immediate (Current Sprint) | Q7: To Do | T7: High Risk | U7: Yes | V7: Open in Main Tab | X7: SEO | Y7: Content | Z7: Low | AA7: 10 | AB7: 0 | AC7: Resolve 'CWV LCP Above 4.0s' using content best practices and validate in the related detail tab. | AD7: Open | AE7: =IFERROR(INDEX('Content Optimization Hub'!A:A,MATCH(H7,'Content Optimization Hub'!C:C,0)),"Not in Hub")
A8: Broken Internal Links | B8: Critical | C8: 105 | D8: 0 | F8: Links | G8: Manual Content | I8: Update internal links to valid URLs and remove dead references. | J8: Internal links resolve to missing or error pages. | K8: Dev | L8: Dev | M8: M | N8: 10 | O8: 5 | P8: Immediate (Current Sprint) | Q8: To Do | T8: High Risk | U8: Yes | V8: Open in Main Tab | X8: SEO | Y8: Content | Z8: Low | AA8: 10 | AB8: 0 | AC8: Resolve 'Broken Internal Links' using content best practices and validate in the related detail tab. | AD8: Open | AE8: =IFERROR(INDEX('Content Optimization Hub'!A:A,MATCH(H8,'Content Optimization Hub'!C:C,0)),"Not in Hub")
A9: Redirect Chains | B9: Warning | C9: 67 | D9: 0 | F9: Technical | G9: Global Template | I9: Apply fix based on issue type and re-run audit. | J9: Template/technical implementation quality issue. | K9: Dev | L9: Dev | M9: S | N9: 4 | O9: 2 | P9: Next Sprint | Q9: To Do | T9: Medium Risk | U9: Yes | V9: Open in Main Tab | X9: SEO | Y9: Technical | Z9: Low | AA9: 4 | AB9: 0 | AC9: Resolve 'Redirect Chains' using technical best practices and validate in the related detail tab. | AD9: Open | AE9: =IFERROR(INDEX('Content Optimization Hub'!A:A,MATCH(H9,'Content Optimization Hub'!C:C,0)),"Not in Hub")
A10: Missing Meta Description | B10: Warning | C10: 67 | D10: 0 | F10: Technical | G10: Manual Content | I10: Add concise unique description aligned with user intent. | J10: Meta description missing or empty. | K10: Copy Writer | L10: Copy Writer | M10: S | N10: 4 | O10: 2 | P10: Next Sprint | Q10: To Do | T10: Medium Risk | U10: Yes | V10: Open in Main Tab | X10: SEO | Y10: Content | Z10: Low | AA10: 4 | AB10: 0 | AC10: Resolve 'Missing Meta Description' using content best practices and validate in the related detail tab. | AD10: Open | AE10: =IFERROR(INDEX('Content Optimization Hub'!A:A,MATCH(H10,'Content Optimization Hub'!C:C,0)),"Not in Hub")
A11: Missing H1 | B11: Warning | C11: 67 | D11: 0 | F11: Technical | G11: Manual Content | I11: Apply fix based on issue type and re-run audit. | J11: Template/technical implementation quality issue. | K11: Copy Writer | L11: Copy Writer | M11: S | N11: 4 | O11: 2 | P11: Next Sprint | Q11: To Do | T11: Medium Risk | U11: Yes | V11: Open in Main Tab | X11: SEO | Y11: Content | Z11: Low | AA11: 4 | AB11: 0 | AC11: Resolve 'Missing H1' using content best practices and validate in the related detail tab. | AD11: Open | AE11: =IFERROR(INDEX('Content Optimization Hub'!A:A,MATCH(H11,'Content Optimization Hub'!C:C,0)),"Not in Hub")
A12: Multiple H1 | B12: Warning | C12: 67 | D12: 0 | F12: Technical | G12: Manual Content | I12: Apply fix based on issue type and re-run audit. | J12: Template/technical implementation quality issue. | K12: Copy Writer | L12: Copy Writer | M12: S | N12: 4 | O12: 2 | P12: Next Sprint | Q12: To Do | T12: Medium Risk | U12: Yes | V12: Open in Main Tab | X12: SEO | Y12: Content | Z12: Low | AA12: 4 | AB12: 0 | AC12: Resolve 'Multiple H1' using content best practices and validate in the related detail tab. | AD12: Open | AE12: =IFERROR(INDEX('Content Optimization Hub'!A:A,MATCH(H12,'Content Optimization Hub'!C:C,0)),"Not in Hub")
A13: CWV LCP Needs Improvement (2.5-4.0s) | B13: Warning | C13: 67 | D13: 0 | F13: Technical | G13: Global Template | I13: Apply fix based on issue type and re-run audit. | J13: Template/technical implementation quality issue. | K13: Copy Writer | L13: Copy Writer | M13: S | N13: 4 | O13: 2 | P13: Next Sprint | Q13: To Do | T13: Medium Risk | U13: Yes | V13: Open in Main Tab | X13: SEO | Y13: Content | Z13: Low | AA13: 4 | AB13: 0 | AC13: Resolve 'CWV LCP Needs Improvement (2.5-4.0s)' using content best practices and validate in the related detail tab. | AD13: Open | AE13: =IFERROR(INDEX('Content Optimization Hub'!A:A,MATCH(H13,'Content Optimization Hub'!C:C,0)),"Not in Hub")
... A35: AI Crawlers Not Explicitly Allowed | B35: Observation | C35: 37 | D35: 0 | F35: Technical | G35: Manual Content | I35: Apply fix based on issue type and re-run audit. | J35: Template/technical implementation quality issue. | K35: Copy Writer | L35: Copy Writer | M35: S | N35: 4 | O35: 2 | P35: Backlog | Q35: In Review | T35: Monitor | U35: No | V35: Open in Main Tab | X35: SEO | Y35: Content | Z35: Low | AA35: 4 | AB35: 0 | AC35: Resolve 'AI Crawlers Not Explicitly Allowed' using content best practices and validate in the related detail tab. | AD35: Open | AE35: =IFERROR(INDEX('Content Optimization Hub'!A:A,MATCH(H35,'Content Optimization Hub'!C:C,0)),"Not in Hub")

Sheet Main
A1: Health Icon | B1: URL | C1: Status Code | D1: Indexability | E1: Load Time (s) | F1: Title | G1: Meta Description | H1: Word Count (Body) | I1: SEO Health Score | J1: Severity Badge | K1: Extraction State | L1: Extraction Source | M1: Title Length | N1: Meta Desc Length | O1: OG-Image | P1: Has Valid JSON-LD | Q1: H1 Content | R1: H1 Length | S1: H2 Content | T1: H2 Length | U1: H3 Content | V1: H3 Length | W1: H4 Content | X1: H4 Length | Y1: H5 Content | Z1: H5 Length | AA1: H6 Content | AB1: H6 Length | AC1: CWV LCP (s) | AD1: CWV CLS | AE1: Field vs Lab | AF1: Regional Authority Score | AG1: Desktop PSI Score | AH1: Mobile PSI Score | AI1: Mobile LCP (s) | AJ1: Mobile CLS | AK1: Mobile TTFB (s) | AL1: GSC Clicks | AM1: GSC Impressions | AN1: GSC CTR | AO1: GSC Avg Position | AP1: Click Depth | AQ1: Orphan Pages | AR1: Internal PageRank | AS1: Found via Sitemap | AT1: Found via Crawl | AU1: Discovery Source | AV1: Technical Health | AW1: Copy Score | AX1: SEO Score | AY1: Technical View | AZ1: BACK TO DASHBOARD | BA1: Technical View_1 | BB1: BACK TO DASHBOARD_1
A2: UNMEASURED | B2: https://africanmarketingconfederation.org/ | C2: 200 | D2: Indexable | E2: 2.214 | F2: African Marketing Confederation - Uniting Marketers for Excellence | G2: The African Marketing Confederation is the ground-breaking Pan-African body driving the development of top marketing standards across Africa and beyond. | H2: 35 | J2: Unmeasured | K2: partial | L2: rendered_browser | M2: 66 | N2: 152 | O2: https://africanmarketingconfederation.org/wp-content/uploads/2026/03/og-image.png | P2: FALSE | R2: 0 | T2: 0 | V2: 0 | X2: 0 | Z2: 0 | AB2: 0 | AC2: 0 | AE2: Lab | AF2: 100 | AG2: 0 | AH2: 0 | AI2: 0 | AJ2: 0 | AK2: 0 | AL2: 60 | AM2: 1108 | AN2: 0.054151625 | AO2: 5.9296029 | AP2: 0 | AQ2: FALSE | AR2: 0.287449 | AS2: TRUE | AT2: TRUE | AU2: Both | AV2: 0 | AW2: 75 | AX2: 18.75 | AY2: Open Technical | BA2: =IFERROR(HYPERLINK("#Technical!A"&MATCH(B2,Technical!A:A,0),"Open Technical"),HYPERLINK("#Technical!A1","Open Technical"))
A3: UNMEASURED | B3: https://africanmarketingconfederation.org/about-us | C3: 200 | D3: Indexable | E3: 0.085 | F3: African Marketing Confederation – The Leading Marketing Professional Body – African Marketing Confederation | G3: ABOUT The African Marketing Confederation The African Marketing Confederation is the ground-breaking Pan African body of marketing professionals spearheading the ongoing development of the highest possible standards of marketing across Africa. Founded in 2011, the AMC is a collaboration between the African national marketing bodies and associations to exchange expertise and information, and to promote | H3: 235 | J3: Unmeasured | K3: partial | L3: rendered_browser | M3: 107 | N3: 405 | O3: https://africanmarketingconfederation.org/wp-content/uploads/2026/03/og-image.png | P3: FALSE | R3: 0 | T3: 0 | V3: 0 | X3: 0 | Z3: 0 | AB3: 0 | AC3: 0 | AE3: Lab | AF3: 70 | AG3: 0 | AH3: 0 | AI3: 0 | AJ3: 0 | AK3: 0 | AL3: 7 | AM3: 200 | AN3: 0.035 | AO3: 3.255 | AP3: 1 | AQ3: FALSE | AR3: 0.271899 | AS3: TRUE | AT3: TRUE | AU3: Both | AV3: 0 | AW3: 75 | AX3: 18.75 | AY3: Open Technical | BA3: =IFERROR(HYPERLINK("#Technical!A"&MATCH(B3,Technical!A:A,0),"Open Technical"),HYPERLINK("#Technical!A1","Open Technical"))
A4: UNMEASURED | B4: https://africanmarketingconfederation.org/african-marketing-confederation-tourism-chapter | C4: 200 | D4: Indexable | E4: 0.086 | F4: African Marketing Confederation Tourism Chapter – African Marketing Confederation | G4: African Marketing Confederation Tourism Chapter Shaping Africa’s Tourism Narrative Through Strategic Marketing Tourism is one of Africa’s most powerful economic engines - generating jobs, stimulating investment, and fostering cultural exchange.The African Marketing Confederation is proud to launch the Tourism Chapter, a bold initiative to elevate African tourism through the lens of world-class marketing. Launched at the | H4: 355 | J4: Unmeasured | K4: partial | L4: rendered_browser | M4: 81 | N4: 423 | O4: https://africanmarketingconfederation.org/wp-content/uploads/2026/03/og-image.png | P4: FALSE | R4: 0 | T4: 0 | V4: 0 | X4: 0 | Z4: 0 | AB4: 0 | AC4: 0 | AE4: Lab | AF4: 60 | AG4: 0 | AH4: 0 | AI4: 0 | AJ4: 0 | AK4: 0 | AL4: 0 | AM4: 8 | AN4: 0 | AO4: 5 | AP4: 1 | AQ4: FALSE | AR4: 0.271899 | AS4: TRUE | AT4: TRUE | AU4: Both | AV4: 0 | AW4: 100 | AX4: 25 | AY4: Open Technical | BA4: =IFERROR(HYPERLINK("#Technical!A"&MATCH(B4,Technical!A:A,0),"Open Technical"),HYPERLINK("#Technical!A1","Open Technical"))
A5: UNMEASURED | B5: https://africanmarketingconfederation.org/amc-awards-2024 | C5: 200 | D5: Indexable | E5: 0.078 | F5: AMC Awards 2024 – African Marketing Confederation | G5: NOMINATIONS are Open ! AMC Awards The African Marketing Confederation Awards event is held annually as part of the African Marketing Confederation Forum. This distinguished event celebrates and acknowledges outstanding marketing campaigns and the visionary individuals behind them. The awards presented honor not only the groundbreaking strategies and creative brilliance that set these campaigns apart but | H5: 1668 | J5: Unmeasured | K5: partial | L5: rendered_browser | M5: 49 | N5: 406 | O5: https://africanmarketingconfederation.org/wp-content/uploads/2021/08/amc_faw.png | P5: FALSE | R5: 0 | T5: 0 | V5: 0 | X5: 0 | Z5: 0 | AB5: 0 | AC5: 0 | AE5: Lab | AF5: 100 | AG5: 0 | AH5: 0 | AI5: 0 | AJ5: 0 | AK5: 0 | AL5: 0 | AM5: 0 | AN5: 0 | AO5: 0 | AQ5: TRUE | AR5: 0.019665 | AS5: TRUE | AT5: TRUE | AU5: Both | AV5: 0 | AW5: 100 | AX5: 25 | AY5: Open Technical | BA5: =IFERROR(HYPERLINK("#Technical!A"&MATCH(B5,Technical!A:A,0),"Open Technical"),HYPERLINK("#Technical!A1","Open Technical"))
A6: UNMEASURED | B6: https://africanmarketingconfederation.org/amc-conference-2022 | C6: 200 | D6: Indexable | E6: 2.318 | F6: AMC Conference 2022 – African Marketing Confederation | G6: corinna kopf onlyfans leaks AMC Conference 2022 Thank you for attending19 - 22 October 2022 The African Marketing Confederation's Annual Conference brought together the best collection of marketing leaders from top companies, marketing bodies and associations to share tactics and best practices on how to build the next generation of marketing. Event Highlights Thank you for Attending! | H6: 32 | J6: Unmeasured | K6: partial | L6: rendered_browser | M6: 53 | N6: 387 | O6: https://africanmarketingconfederation.org/wp-content/uploads/2026/03/og-image.png | P6: FALSE | R6: 0 | T6: 0 | V6: 0 | X6: 0 | Z6: 0 | AB6: 0 | AC6: 0 | AE6: Lab | AF6: 100 | AG6: 0 | AH6: 0 | AI6: 0 | AJ6: 0 | AK6: 0 | AL6: 0 | AM6: 10 | AN6: 0 | AO6: 6.1 | AQ6: TRUE | AR6: 0.019665 | AS6: TRUE | AT6: TRUE | AU6: Both | AV6: 0 | AW6: 45 | AX6: 11.25 | AY6: Open Technical | BA6: =IFERROR(HYPERLINK("#Technical!A"&MATCH(B6,Technical!A:A,0),"Open Technical"),HYPERLINK("#Technical!A1","Open Technical"))
A7: UNMEASURED | B7: https://africanmarketingconfederation.org/amc-conference-2022-prospectus | C7: 200 | D7: Indexable | E7: 3.629 | F7: AMC Conference 2022 – Prospectus – African Marketing Confederation | G7: AMC Conference 2022 23 - 24 March 2022 Navigating Africa's Unique Marketing Mix BOOK NOW Days Hours Minutes Seconds download prospectus To download the AMC 2022 Conference Prospectus please complete the form below: First Name Last Name Email Mobile Company I've read and agree to the Privacy Policy BOOK NOW FOR THE AMC CONFERENCE 2022 | H7: 120 | J7: Unmeasured | K7: partial | L7: rendered_browser | M7: 66 | N7: 335 | O7: https://africanmarketingconfederation.org/wp-content/uploads/2026/03/og-image.png | P7: FALSE | R7: 0 | T7: 0 | V7: 0 | X7: 0 | Z7: 0 | AB7: 0 | AC7: 0 | AE7: Lab | AF7: 30 | AG7: 0 | AH7: 0 | AI7: 0 | AJ7: 0 | AK7: 0 | AL7: 0 | AM7: 0 | AN7: 0 | AO7: 0 | AQ7: TRUE | AR7: 0.019665 | AS7: TRUE | AT7: TRUE | AU7: Both | AV7: 0 | AW7: 45 | AX7: 11.25 | AY7: Open Technical | BA7: =IFERROR(HYPERLINK("#Technical!A"&MATCH(B7,Technical!A:A,0),"Open Technical"),HYPERLINK("#Technical!A1","Open Technical"))
A8: UNMEASURED | B8: https://africanmarketingconfederation.org/amc-conference-2022-thank-you | C8: 200 | D8: Indexable | E8: 3.88 | F8: AMC Conference 2022 – Thank You – African Marketing Confederation | G8: AMC Conference 2022 23 - 24 March 2022 Navigating Africa's Unique Marketing Mix ENQUIRE NOW Days Hours Minutes Seconds Success! Thank you for completing the enquiry form. Our team will contact you shortly! × Dismiss alert The AMC Conference is the must attend Pan African event for marketing professionals. It will focus on solutions for | H8: 367 | J8: Unmeasured | K8: partial | L8: rendered_browser | M8: 65 | N8: 337 | O8: https://africanmarketingconfederation.org/wp-content/uploads/2026/03/og-image.png | P8: FALSE | R8: 0 | T8: 0 | V8: 0 | X8: 0 | Z8: 0 | AB8: 0 | AC8: 0 | AE8: Lab | AF8: 100 | AG8: 0 | AH8: 0 | AI8: 0 | AJ8: 0 | AK8: 0 | AL8: 0 | AM8: 0 | AN8: 0 | AO8: 0 | AQ8: TRUE | AR8: 0.019665 | AS8: TRUE | AT8: TRUE | AU8: Both | AV8: 0 | AW8: 70 | AX8: 17.5 | AY8: Open Technical | BA8: =IFERROR(HYPERLINK("#Technical!A"&MATCH(B8,Technical!A:A,0),"Open Technical"),HYPERLINK("#Technical!A1","Open Technical"))
A9: UNMEASURED | B9: https://africanmarketingconfederation.org/amc-conference-2023 | C9: 200 | D9: Indexable | E9: 3.016 | F9: AMC Conference 2023 – African Marketing Confederation | G9: AMC Conference 6 - 9 September 2023 Imperial Botanical Beach Hotel, Entebbe, Uganda Thank you for joining us! View Presentations 2nd Annual African Marketing Confederation Conference Africa's $3.4 trillion Economy: Opportunities for Marketers Welcome to the Recap of the 2nd Annual African Marketing Conference: Unveiling Africa's $3.4 Trillion EconomyOur conference was a remarkable exploration of | H9: 415 | J9: Unmeasured | K9: partial | L9: rendered_browser | M9: 53 | N9: 398 | O9: https://africanmarketingconfederation.org/wp-content/uploads/2021/08/amc_faw.png | P9: FALSE | R9: 0 | T9: 0 | V9: 0 | X9: 0 | Z9: 0 | AB9: 0 | AC9: 0 | AE9: Lab | AF9: 80 | AG9: 0 | AH9: 0 | AI9: 0 | AJ9: 0 | AK9: 0 | AL9: 1 | AM9: 24 | AN9: 0.041666667 | AO9: 14.583333 | AQ9: FALSE | AR9: 0.035214 | AS9: TRUE | AT9: TRUE | AU9: Both | AV9: 0 | AW9: 100 | AX9: 25 | AY9: Open Technical | BA9: =IFERROR(HYPERLINK("#Technical!A"&MATCH(B9,Technical!A:A,0),"Open Technical"),HYPERLINK("#Technical!A1","Open Technical"))
A10: UNMEASURED | B10: https://africanmarketingconfederation.org/amc-conference-2023/amc-awards | C10: 200 | D10: Indexable | E10: 2.673 | F10: AMC Awards – African Marketing Confederation | G10: AMC Awards Welcome to the prestigious African Marketing Confederation Awards, a distinguished event that celebrates and acknowledges the remarkable achievements, cutting-edge innovations, and exceptional leadership demonstrated by outstanding individuals within the dynamic realm of marketing across the expansive African region.During the 2nd Annual African Marketing Confederation Conference, held from 6th to 9th September at the | H10: 326 | J10: Unmeasured | K10: partial | L10: rendered_browser | M10: 44 | N10: 432 | O10: https://africanmarketingconfederation.org/wp-content/uploads/2021/08/amc_faw.png | P10: FALSE | R10: 0 | T10: 0 | V10: 0 | X10: 0 | Z10: 0 | AB10: 0 | AC10: 0 | AE10: Lab | AF10: 40 | AG10: 0 | AH10: 0 | AI10: 0 | AJ10: 0 | AK10: 0 | AL10: 2 | AM10: 34 | AN10: 0.058823529 | AO10: 4.2352941 | AQ10: FALSE | AR10: 0.035214 | AS10: TRUE | AT10: TRUE | AU10: Both | AV10: 0 | AW10: 100 | AX10: 25 | AY10: Open Technical | BA10: =IFERROR(HYPERLINK("#Technical!A"&MATCH(B10,Technical!A:A,0),"Open Technical"),HYPERLINK("#Technical!A1","Open Technical"))
A11: UNMEASURED | B11: https://africanmarketingconfederation.org/amc-conference-2023/amc-awards-book-now | C11: 200 | D11: Indexable | E11: 2.668 | F11: AMC Awards | Book Now – African Marketing Confederation | H11: 31 | J11: Unmeasured | K11: partial | L11: rendered_browser | M11: 55 | N11: 0 | O11: https://africanmarketingconfederation.org/wp-content/uploads/2021/08/amc_faw.png | P11: FALSE | R11: 0 | T11: 0 | V11: 0 | X11: 0 | Z11: 0 | AB11: 0 | AC11: 0 | AE11: Lab | AF11: 30 | AG11: 0 | AH11: 0 | AI11: 0 | AJ11: 0 | AK11: 0 | AL11: 0 | AM11: 0 | AN11: 0 | AO11: 0 | AQ11: TRUE | AR11: 0.019665 | AS11: TRUE | AT11: TRUE | AU11: Both | AV11: 0 | AW11: 25 | AX11: 6.25 | AY11: Open Technical | BA11: =IFERROR(HYPERLINK("#Technical!A"&MATCH(B11,Technical!A:A,0),"Open Technical"),HYPERLINK("#Technical!A1","Open Technical"))

Sheet Technical
A1: URL | B1: Status Code | C1: Status Class | D1: SEO Health Score | E1: Severity Badge | F1: Action Needed | G1: Indexability Reason | H1: TTFB (ms) | I1: Total Request Time (ms) | J1: Final URL | K1: Canonical URL | L1: Canonical Type | M1: Owner | N1: Status | O1: Sprint | P1: Extraction State | Q1: Extraction Source | R1: Health Icon | S1: SEO Score | T1: Technical Health | U1: Copy Score | V1: Protocol | W1: Redirect Chain Length | X1: Redirect Target | Y1: Redirect Hops | Z1: HTTP->HTTPS Redirect | AA1: Content-Type | AB1: HTTP Version | AC1: HTML Size (KB) | AD1: Compression Enabled | AE1: Cache-Control | AF1: ETag | AG1: X-Robots-Tag | AH1: Meta Robots Raw | AI1: Canonical Matches Final URL | AJ1: Canonical Absolute URL | AK1: Canonical in Sitemap Match | AL1: Hreflang Present | AM1: Hreflang Count | AN1: Hreflang Self Reference | AO1: Hreflang Reciprocal Check | AP1: Hreflang Canonical Consistency | AQ1: x-default Present | AR1: Pagination rel=next | AS1: Pagination rel=prev | AT1: Last-Modified | AU1: Published Date | AV1: Modified Date | AW1: Last Updated | AX1: Change Frequency | AY1: Priority | AZ1: Schema Types Count | BA1: Schema Types Found | BB1: Internal Links Count | BC1: Unique Internal Links Count | BD1: External Links Count | BE1: AI Crawlers Allowed (GPTBot/ClaudeBot/PerplexityBot) | BF1: llms.txt Present | BG1: Desktop PSI Score | BH1: Mobile PSI Score | BI1: Mobile LCP (s) | BJ1: Mobile CLS | BK1: Mobile TTFB (s) | BL1: CWV LCP (s) | BM1: CWV CLS | BN1: CWV Data Source | BO1: Field vs Lab | BP1: GSC Clicks | BQ1: GSC Impressions | BR1: GSC CTR | BS1: GSC Avg Position | BT1: Click Depth | BU1: Internal Inlinks | BV1: Orphan Pages | BW1: Internal PageRank | BX1: Regional Authority Score | BY1: Regional Entity Hits | BZ1: Answer Block Detected (First 60 Words) | CA1: AEO Extractability Score | CB1: Critical Issues Count | CC1: Warning Issues Count | CD1: Observation Issues Count | CE1: Inlinks Bucket | CF1: Important But Underlinked | CG1: SERP Title Truncation Risk | CH1: SERP Meta Truncation Risk | CI1: SERP Title Pixel Approx | CJ1: SERP Meta Pixel Approx | CK1: Cannibalization Hint | CL1: Stable Issue IDs | CM1: URL Depth | CN1: Param URL Flag | CO1: Open in Main | CP1: BACK TO DASHBOARD | CQ1: BACK TO DASHBOARD_1
A2: https://africanmarketingconfederation.org/ | B2: 200 | C2: 2xx | E2: Unmeasured | G2: Indexable | H2: 34.75 | I2: 36971.04 | J2: https://africanmarketingconfederation.org/ | K2: https://africanmarketingconfederation.org/ | L2: self | M2: Dev | N2: Open | P2: partial | Q2: rendered_browser | R2: UNMEASURED | S2: 18.75 | T2: 0 | U2: 75 | V2: https | W2: 0 | Z2: FALSE | AA2: text/html; charset=UTF-8 | AB2: HTTP/1.1 | AC2: 558.4 | AD2: TRUE | AE2: max-age=0 | AH2: max-image-preview:large | AI2: TRUE | AJ2: https://africanmarketingconfederation.org/ | AK2: TRUE | AL2: FALSE | AM2: 0 | AN2: FALSE | AQ2: FALSE | AR2: FALSE | AS2: FALSE | AW2: 2026-04-29T08:23:06+00:00 | AX2: always | AY2: 1 | AZ2: 0 | BB2: 63 | BC2: 22 | BD2: 2 | BE2: FALSE | BF2: TRUE | BG2: 0 | BH2: 0 | BI2: 0 | BJ2: 0 | BK2: 0 | BL2: 0 | BN2: Lab | BO2: Lab | BP2: 60 | BQ2: 1108 | BR2: 0.054151625 | BS2: 5.9296029 | BT2: 0 | BU2: 8 | BV2: FALSE | BW2: 0.287449 | BX2: 100 | BY2: 16 | BZ2: FALSE | CA2: Medium | CE2: 3-10 | CG2: FALSE | CH2: FALSE | CI2: 475 | CJ2: 942 | CM2: 0 | CN2: FALSE | CO2: Open
A3: https://africanmarketingconfederation.org/about-us | B3: 200 | C3: 2xx | E3: Unmeasured | G3: Indexable | H3: 84.99 | I3: 39053.33 | J3: https://africanmarketingconfederation.org/about-us | K3: https://africanmarketingconfederation.org/about-us | L3: self | M3: Dev | N3: Open | P3: partial | Q3: rendered_browser | R3: UNMEASURED | S3: 18.75 | T3: 0 | U3: 75 | V3: https | W3: 0 | Z3: FALSE | AA3: text/html; charset=UTF-8 | AB3: HTTP/1.1 | AC3: 321.92 | AD3: TRUE | AE3: max-age=0 | AH3: max-image-preview:large | AI3: TRUE | AJ3: https://africanmarketingconfederation.org/about-us | AK3: TRUE | AL3: FALSE | AM3: 0 | AN3: FALSE | AQ3: FALSE | AR3: FALSE | AS3: FALSE | AW3: 2026-04-17T08:53:24+00:00 | AX3: weekly | AY3: 0.7 | AZ3: 0 | BB3: 32 | BC3: 14 | BD3: 7 | BE3: FALSE | BF3: TRUE | BG3: 0 | BH3: 0 | BI3: 0 | BJ3: 0 | BK3: 0 | BL3: 0 | BN3: Lab | BO3: Lab | BP3: 7 | BQ3: 200 | BR3: 0.035 | BS3: 3.255 | BT3: 1 | BU3: 6 | BV3: FALSE | BW3: 0.271899 | BX3: 70 | BY3: 5 | BZ3: FALSE | CA3: Medium | CE3: 3-10 | CG3: FALSE | CH3: FALSE | CI3: 770 | CJ3: 2511 | CM3: 1 | CN3: FALSE | CO3: Open
A4: https://africanmarketingconfederation.org/african-marketing-confederation-tourism-chapter | B4: 200 | C4: 2xx | E4: Unmeasured | G4: Indexable | H4: 86 | I4: 39506.96 | J4: https://africanmarketingconfederation.org/african-marketing-confederation-tourism-chapter | K4: https://africanmarketingconfederation.org/african-marketing-confederation-tourism-chapter | L4: self | M4: Dev | N4: Open | P4: partial | Q4: rendered_browser | R4: UNMEASURED | S4: 25 | T4: 0 | U4: 100 | V4: https | W4: 0 | Z4: FALSE | AA4: text/html; charset=UTF-8 | AB4: HTTP/1.1 | AC4: 337.63 | AD4: TRUE | AE4: max-age=0 | AH4: max-image-preview:large | AI4: TRUE | AJ4: https://africanmarketingconfederation.org/african-marketing-confederation-tourism-chapter | AK4: TRUE | AL4: FALSE | AM4: 0 | AN4: FALSE | AQ4: FALSE | AR4: FALSE | AS4: FALSE | AW4: 2026-04-17T08:55:48+00:00 | AX4: weekly | AY4: 0.7 | AZ4: 0 | BB4: 58 | BC4: 15 | BD4: 3 | BE4: FALSE | BF4: TRUE | BG4: 0 | BH4: 0 | BI4: 0 | BJ4: 0 | BK4: 0 | BL4: 0 | BN4: Lab | BO4: Lab | BP4: 0 | BQ4: 8 | BR4: 0 | BS4: 5 | BT4: 1 | BU4: 6 | BV4: FALSE | BW4: 0.271899 | BX4: 60 | BY4: 4 | BZ4: FALSE | CA4: Medium | CE4: 3-10 | CG4: FALSE | CH4: FALSE | CI4: 583 | CJ4: 2622 | CM4: 1 | CN4: FALSE | CO4: Open
A5: https://africanmarketingconfederation.org/amc-awards-2024 | B5: 200 | C5: 2xx | E5: Unmeasured | G5: Indexable | H5: 78.4 | I5: 18282.83 | J5: https://africanmarketingconfederation.org/amc-awards-2024 | K5: https://africanmarketingconfederation.org/amc-awards-2024 | L5: self | M5: Dev | N5: Open | P5: partial | Q5: rendered_browser | R5: UNMEASURED | S5: 25 | T5: 0 | U5: 100 | V5: https | W5: 0 | Z5: FALSE | AA5: text/html; charset=UTF-8 | AB5: HTTP/1.1 | AC5: 513.32 | AD5: TRUE | AE5: max-age=0 | AH5: max-image-preview:large | AI5: TRUE | AJ5: https://africanmarketingconfederation.org/amc-awards-2024 | AK5: TRUE | AL5: FALSE | AM5: 0 | AN5: FALSE | AQ5: FALSE | AR5: FALSE | AS5: FALSE | AW5: 2025-04-24T13:54:46+00:00 | AX5: weekly | AY5: 0.7 | AZ5: 0 | BB5: 16 | BC5: 9 | BD5: 4 | BE5: FALSE | BF5: TRUE | BG5: 0 | BH5: 0 | BI5: 0 | BJ5: 0 | BK5: 0 | BL5: 0 | BN5: Lab | BO5: Lab | BP5: 0 | BQ5: 0 | BR5: 0 | BS5: 0 | BU5: 0 | BV5: TRUE | BW5: 0.019665 | BX5: 100 | BY5: 16 | BZ5: TRUE | CA5: Medium | CE5: 0 | CG5: FALSE | CH5: FALSE | CI5: 352 | CJ5: 2517 | CM5: 1 | CN5: FALSE | CO5: Open
A6: https://africanmarketingconfederation.org/amc-conference-2022 | B6: 200 | C6: 2xx | E6: Unmeasured | G6: Indexable | H6: 2317.69 | I6: 20124.52 | J6: https://africanmarketingconfederation.org/amc-conference-2022 | K6: https://africanmarketingconfederation.org/amc-conference-2022 | L6: self | M6: Dev | N6: Open | P6: partial | Q6: rendered_browser | R6: UNMEASURED | S6: 11.25 | T6: 0 | U6: 45 | V6: https | W6: 0 | Z6: FALSE | AA6: text/html; charset=UTF-8 | AB6: HTTP/1.1 | AC6: 341.93 | AD6: TRUE | AE6: max-age=0 | AH6: max-image-preview:large | AI6: TRUE | AJ6: https://africanmarketingconfederation.org/amc-conference-2022 | AK6: TRUE | AL6: FALSE | AM6: 0 | AN6: FALSE | AQ6: FALSE | AR6: FALSE | AS6: FALSE | AW6: 2026-01-21T00:07:32+00:00 | AX6: weekly | AY6: 0.7 | AZ6: 0 | BB6: 99 | BC6: 64 | BD6: 3 | BE6: FALSE | BF6: TRUE | BG6: 0 | BH6: 0 | BI6: 0 | BJ6: 0 | BK6: 0 | BL6: 0 | BN6: Lab | BO6: Lab | BP6: 0 | BQ6: 10 | BR6: 0 | BS6: 6.1 | BU6: 0 | BV6: TRUE | BW6: 0.019665 | BX6: 100 | BY6: 9 | BZ6: FALSE | CA6: Medium | CE6: 0 | CG6: FALSE | CH6: FALSE | CI6: 381 | CJ6: 2399 | CM6: 1 | CN6: FALSE | CO6: Open
A7: https://africanmarketingconfederation.org/amc-conference-2022-prospectus | B7: 200 | C7: 2xx | E7: Unmeasured | G7: Indexable | H7: 3628.71 | I7: 21740.58 | J7: https://africanmarketingconfederation.org/amc-conference-2022-prospectus | K7: https://africanmarketingconfederation.org/amc-conference-2022-prospectus | L7: self | M7: Dev | N7: Open | P7: partial | Q7: rendered_browser | R7: UNMEASURED | S7: 11.25 | T7: 0 | U7: 45 | V7: https | W7: 0 | Z7: FALSE | AA7: text/html; charset=UTF-8 | AB7: HTTP/1.1 | AC7: 279.86 | AD7: TRUE | AE7: max-age=0 | AH7: max-image-preview:large | AI7: TRUE | AJ7: https://africanmarketingconfederation.org/amc-conference-2022-prospectus | AK7: TRUE | AL7: FALSE | AM7: 0 | AN7: FALSE | AQ7: FALSE | AR7: FALSE | AS7: FALSE | AW7: 2025-07-14T07:22:03+00:00 | AX7: weekly | AY7: 0.7 | AZ7: 0 | BB7: 32 | BC7: 14 | BD7: 4 | BE7: FALSE | BF7: TRUE | BG7: 0 | BH7: 0 | BI7: 0 | BJ7: 0 | BK7: 0 | BL7: 0 | BN7: Lab | BO7: Lab | BP7: 0 | BQ7: 0 | BR7: 0 | BS7: 0 | BU7: 0 | BV7: TRUE | BW7: 0.019665 | BX7: 30 | BY7: 3 | BZ7: FALSE | CA7: Medium | CE7: 0 | CG7: FALSE | CH7: FALSE | CI7: 475 | CJ7: 2077 | CM7: 1 | CN7: FALSE | CO7: Open
A8: https://africanmarketingconfederation.org/amc-conference-2022-thank-you | B8: 200 | C8: 2xx | E8: Unmeasured | G8: Indexable | H8: 3879.66 | I8: 22165.22 | J8: https://africanmarketingconfederation.org/amc-conference-2022-thank-you | K8: https://africanmarketingconfederation.org/amc-conference-2022-thank-you | L8: self | M8: Dev | N8: Open | P8: partial | Q8: rendered_browser | R8: UNMEASURED | S8: 17.5 | T8: 0 | U8: 70 | V8: https | W8: 0 | Z8: FALSE | AA8: text/html; charset=UTF-8 | AB8: HTTP/1.1 | AC8: 341.57 | AD8: TRUE | AE8: max-age=0 | AH8: max-image-preview:large | AI8: TRUE | AJ8: https://africanmarketingconfederation.org/amc-conference-2022-thank-you | AK8: TRUE | AL8: FALSE | AM8: 0 | AN8: FALSE | AQ8: FALSE | AR8: FALSE | AS8: FALSE | AW8: 2021-11-26T08:41:00+00:00 | AX8: weekly | AY8: 0.7 | AZ8: 0 | BB8: 32 | BC8: 15 | BD8: 2 | BE8: FALSE | BF8: TRUE | BG8: 0 | BH8: 0 | BI8: 0 | BJ8: 0 | BK8: 0 | BL8: 0 | BN8: Lab | BO8: Lab | BP8: 0 | BQ8: 0 | BR8: 0 | BS8: 0 | BU8: 0 | BV8: TRUE | BW8: 0.019665 | BX8: 100 | BY8: 8 | BZ8: FALSE | CA8: Medium | CE8: 0 | CG8: FALSE | CH8: FALSE | CI8: 468 | CJ8: 2089 | CM8: 1 | CN8: FALSE | CO8: Open
A9: https://africanmarketingconfederation.org/amc-conference-2023 | B9: 200 | C9: 2xx | E9: Unmeasured | G9: Indexable | H9: 3016.19 | I9: 20985.18 | J9: https://africanmarketingconfederation.org/amc-conference-2023 | K9: https://africanmarketingconfederation.org/amc-conference-2023 | L9: self | M9: Dev | N9: Open | P9: partial | Q9: rendered_browser | R9: UNMEASURED | S9: 25 | T9: 0 | U9: 100 | V9: https | W9: 0 | Z9: FALSE | AA9: text/html; charset=UTF-8 | AB9: HTTP/1.1 | AC9: 370.99 | AD9: TRUE | AE9: max-age=0 | AH9: max-image-preview:large | AI9: TRUE | AJ9: https://africanmarketingconfederation.org/amc-conference-2023 | AK9: TRUE | AL9: FALSE | AM9: 0 | AN9: FALSE | AQ9: FALSE | AR9: FALSE | AS9: FALSE | AW9: 2025-03-03T07:59:34+00:00 | AX9: weekly | AY9: 0.7 | AZ9: 0 | BB9: 41 | BC9: 33 | BD9: 13 | BE9: FALSE | BF9: TRUE | BG9: 0 | BH9: 0 | BI9: 0 | BJ9: 0 | BK9: 0 | BL9: 0 | BN9: Lab | BO9: Lab | BP9: 1 | BQ9: 24 | BR9: 0.041666667 | BS9: 14.583333 | BU9: 2 | BV9: FALSE | BW9: 0.035214 | BX9: 80 | BY9: 6 | BZ9: FALSE | CA9: Medium | CE9: 1-2 | CG9: FALSE | CH9: FALSE | CI9: 381 | CJ9: 2467 | CM9: 1 | CN9: FALSE | CO9: Open
A10: https://africanmarketingconfederation.org/amc-conference-2023/amc-awards | B10: 200 | C10: 2xx | E10: Unmeasured | G10: Indexable | H10: 2673.27 | I10: 20610.13 | J10: https://africanmarketingconfederation.org/amc-conference-2023/amc-awards | K10: https://africanmarketingconfederation.org/amc-conference-2023/amc-awards | L10: self | M10: Dev | N10: Open | P10: partial | Q10: rendered_browser | R10: UNMEASURED | S10: 25 | T10: 0 | U10: 100 | V10: https | W10: 0 | Z10: FALSE | AA10: text/html; charset=UTF-8 | AB10: HTTP/1.1 | AC10: 272.63 | AD10: TRUE | AE10: max-age=0 | AH10: max-image-preview:large | AI10: TRUE | AJ10: https://africanmarketingconfederation.org/amc-conference-2023/amc-awards | AK10: TRUE | AL10: FALSE | AM10: 0 | AN10: FALSE | AQ10: FALSE | AR10: FALSE | AS10: FALSE | AW10: 2023-11-23T11:51:22+00:00 | AX10: weekly | AY10: 0.7 | AZ10: 0 | BB10: 19 | BC10: 10 | BD10: 2 | BE10: FALSE | BF10: TRUE | BG10: 0 | BH10: 0 | BI10: 0 | BJ10: 0 | BK10: 0 | BL10: 0 | BN10: Lab | BO10: Lab | BP10: 2 | BQ10: 34 | BR10: 0.058823529 | BS10: 4.2352941 | BU10: 2 | BV10: FALSE | BW10: 0.035214 | BX10: 40 | BY10: 4 | BZ10: FALSE | CA10: Medium | CE10: 1-2 | CG10: FALSE | CH10: FALSE | CI10: 316 | CJ10: 2678 | CM10: 2 | CN10: FALSE | CO10: Open
A11: https://africanmarketingconfederation.org/amc-conference-2023/amc-awards-book-now | B11: 200 | C11: 2xx | E11: Unmeasured | G11: Indexable | H11: 2667.9 | I11: 20777.82 | J11: https://africanmarketingconfederation.org/amc-conference-2023/amc-awards-book-now | K11: https://africanmarketingconfederation.org/amc-conference-2023/amc-awards-book-now | L11: self | M11: Dev | N11: Open | P11: partial | Q11: rendered_browser | R11: UNMEASURED | S11: 6.25 | T11: 0 | U11: 25 | V11: https | W11: 0 | Z11: FALSE | AA11: text/html; charset=UTF-8 | AB11: HTTP/1.1 | AC11: 239.75 | AD11: TRUE | AE11: max-age=0 | AH11: max-image-preview:large | AI11: TRUE | AJ11: https://africanmarketingconfederation.org/amc-conference-2023/amc-awards-book-now | AK11: TRUE | AL11: FALSE | AM11: 0 | AN11: FALSE | AQ11: FALSE | AR11: FALSE | AS11: FALSE | AW11: 2023-08-22T14:14:41+00:00 | AX11: weekly | AY11: 0.7 | AZ11: 0 | BB11: 19 | BC11: 10 | BD11: 2 | BE11: FALSE | BF11: TRUE | BG11: 0 | BH11: 0 | BI11: 0 | BJ11: 0 | BK11: 0 | BL11: 0 | BN11: Lab | BO11: Lab | BP11: 0 | BQ11: 0 | BR11: 0 | BS11: 0 | BU11: 0 | BV11: TRUE | BW11: 0.019665 | BX11: 30 | BY11: 3 | BZ11: FALSE | CA11: Medium | CE11: 0 | CG11: FALSE | CH11: FALSE | CI11: 396 | CJ11: 0 | CM11: 2 | CN11: FALSE | CO11: Open

Sheet Content
A1: URL | B1: Word Count | C1: Word Count Band | D1: Readability (Rough Flesch) | E1: H1 Count | F1: Missing H1 Flag | G1: Multiple H1 Flag | H1: Title Missing | I1: Meta Description Missing | J1: Thin Content Flag | K1: Sentence Count | L1: Body Text-to-HTML Ratio | M1: Open in Main | N1: BACK TO DASHBOARD | O1: BACK TO DASHBOARD_1
A2: https://africanmarketingconfederation.org/about-us | B2: 235 | C2: Thin | D2: 172.76 | E2: 1 | F2: FALSE | G2: FALSE | H2: FALSE | I2: FALSE | J2: TRUE | K2: 7 | M2: Open
A3: https://africanmarketingconfederation.org/ | B3: 35 | C3: Thin | D3: 189.07 | E3: 5 | F3: FALSE | G3: TRUE | H3: FALSE | I3: FALSE | J3: TRUE | K3: 2 | M3: Open
A4: https://africanmarketingconfederation.org/african-marketing-confederation-tourism-chapter | B4: 355 | C4: OK | D4: 179.12 | E4: 2 | F4: FALSE | G4: TRUE | H4: FALSE | I4: FALSE | J4: FALSE | K4: 13 | M4: Open
A5: https://africanmarketingconfederation.org/amc-awards-2024 | B5: 1668 | C5: Strong | D5: 178.62 | E5: 2 | F5: FALSE | G5: TRUE | H5: FALSE | I5: FALSE | J5: FALSE | K5: 60 | M5: Open
A6: https://africanmarketingconfederation.org/amc-conference-2022-prospectus | B6: 120 | C6: Thin | D6: 145.94 | E6: 0 | F6: TRUE | G6: FALSE | H6: FALSE | I6: FALSE | J6: TRUE | K6: 2 | M6: Open
A7: https://africanmarketingconfederation.org/amc-conference-2022-thank-you | B7: 367 | C7: OK | D7: 178.18 | E7: 0 | F7: TRUE | G7: FALSE | H7: FALSE | I7: FALSE | J7: FALSE | K7: 13 | M7: Open
A8: https://africanmarketingconfederation.org/amc-conference-2022 | B8: 32 | C8: Thin | D8: 196.01 | E8: 0 | F8: TRUE | G8: FALSE | H8: FALSE | I8: FALSE | J8: TRUE | K8: 3 | M8: Open
A9: https://africanmarketingconfederation.org/amc-conference-2023 | B9: 415 | C9: OK | D9: 168.54 | E9: 1 | F9: FALSE | G9: FALSE | H9: FALSE | I9: FALSE | J9: FALSE | K9: 11 | M9: Open
A10: https://africanmarketingconfederation.org/amc-conference-2023/amc-awards-book-now | B10: 31 | C10: Thin | D10: 175.37 | E10: 0 | F10: TRUE | G10: FALSE | H10: FALSE | I10: TRUE | J10: TRUE | K10: 1 | M10: Open
A11: https://africanmarketingconfederation.org/amc-conference-2023/amc-awards | B11: 326 | C11: OK | D11: 176.75 | E11: 1 | F11: FALSE | G11: FALSE | H11: FALSE | I11: FALSE | J11: FALSE | K11: 11 | M11: Open

Sheet AEO
A1: URL | B1: AEO Readiness Score | C1: AEO Badge | D1: Why It Matters | E1: FAQ Section Count | F1: Question Heading Count | G1: Paragraphs 40-60 Words Count | H1: QAPage/FAQ Schema Present | I1: Speakable Schema Present | J1: HowTo Signal | K1: Definition Signal | L1: List/Table Answer Signal | M1: Answer Block Detected (First 60 Words) | N1: AEO Extractability Score | O1: Snippet Preview Mockup | P1: Title Missing | Q1: Meta Description Missing | R1: Open in Main | S1: BACK TO DASHBOARD | T1: BACK TO DASHBOARD_1
