Workbook

Sheet Table of Contents
A1: Table of Contents
A2: Section | B2: Open
A3: Dashboard | B3: =HYPERLINK("#Dashboard!A1","Open") -> Open
A4: Content Optimization Hub | B4: =HYPERLINK("#Content Optimization Hub!A1","Open") -> Open
A5: FixPlan | B5: =HYPERLINK("#FixPlan!A1","Open") -> Open
A6: Main | B6: =HYPERLINK("#Main!A1","Open") -> Open
A7: Technical | B7: =HYPERLINK("#Technical!A1","Open") -> Open
A8: Content | B8: =HYPERLINK("#Content!A1","Open") -> Open
A9: AEO | B9: =HYPERLINK("#AEO!A1","Open") -> Open
A10: Schema & Metadata | B10: =HYPERLINK("#Schema & Metadata!A1","Open") -> Open
A11: Links | B11: =HYPERLINK("#Links!A1","Open") -> Open
A12: Indexability | B12: =HYPERLINK("#Indexability!A1","Open") -> Open
A13: Redirects | B13: =HYPERLINK("#Redirects!A1","Open") -> Open
A14: Priority URLs | B14: =HYPERLINK("#Priority URLs!A1","Open") -> Open
A15: AIOSEO | B15: =HYPERLINK("#AIOSEO!A1","Open") -> Open
A16: Security | B16: =HYPERLINK("#Security!A1","Open") -> Open
A17: Summary | B17: =HYPERLINK("#Summary!A1","Open") -> Open
A18: Legend | B18: =HYPERLINK("#Legend!A1","Open") -> Open
A19: LinksDetail | B19: =HYPERLINK("#LinksDetail!A1","Open") -> Open
A20: Media | B20: =HYPERLINK("#Media!A1","Open") -> Open
A21: Duplicates | B21: =HYPERLINK("#Duplicates!A1","Open") -> Open
A22: TemplateClusters | B22: =HYPERLINK("#TemplateClusters!A1","Open") -> Open
A23: IssueInventory | B23: =HYPERLINK("#IssueInventory!A1","Open") -> Open
A24: RunMetadata | B24: =HYPERLINK("#RunMetadata!A1","Open") -> Open
A25: DeltaFromPreviousRun | B25: =HYPERLINK("#DeltaFromPreviousRun!A1","Open") -> Open
A26: ResolvedIssues | B26: =HYPERLINK("#ResolvedIssues!A1","Open") -> Open
A27: CrawlGraph | B27: =HYPERLINK("#CrawlGraph!A1","Open") -> Open
A28: SitemapQA | B28: =HYPERLINK("#SitemapQA!A1","Open") -> Open

Sheet Dashboard
A1: Metric | B1: Executive SEO & AEO Dashboard | C1: Column_3 | D1: Column_4 | E1: Column_5 | F1: Column_6 | G1: Column_7 | H1: Column_8 | I1: Column_9 | J1: Column_10 | K1: Column_11 | L1: Column_12 | M1: Column_13 | N1: Column_14 | O1: Column_15 | P1: Column_16 | Q1: Column_17 | R1: Column_18 | S1: Column_19 | T1: Column_20 | U1: Column_21 | V1: Column_22 | W1: Column_23 | X1: Column_24 | Y1: Column_25
A2: URLs Crawled | B2: Executive SEO & AEO Performance Report
A3: Pass Rate (%) | B3: 1970-01-01 00:00:00.000000000
A4: Critical URL Count | B4: EXECUTIVE METRICS | C4: Value | E4: OWNER ISSUE SUMMARY (PIVOT)
A5: Warning URL Count | B5: =HYPERLINK("#Main!A1","Total URLs") -> Total URLs | C5: 0 | E5: Owner | F5: Issue Rows | G5: Affected URLs | H5: Critical | I5: Warning | J5: Observation
A6: Status Distribution | B6: =HYPERLINK("#Summary!A1","Overall Health Score") -> Overall Health Score | C6: =IFERROR(59.66/100,0) -> 0.5966 | E6: =HYPERLINK("#FixPlan!A1","Copy Writer") -> Copy Writer | F6: 20 | G6: 530 | H6: 1 | I6: 8 | J6: 11
A7: Score Bands | B7: =HYPERLINK("#Summary!A1","SEO Pass Rate %") -> SEO Pass Rate % | C7: =IFERROR(0/85,0) -> 0 | E7: =HYPERLINK("#FixPlan!A1","Server/Host") -> Server/Host | F7: 5 | G7: 257 | H7: 2 | I7: 0 | J7: 3
B8: =HYPERLINK("#Technical!A1","Pass URLs") -> Pass URLs | C8: 0 | E8: =HYPERLINK("#FixPlan!A1","Dev") -> Dev | F8: 9 | G8: 0 | H8: 4 | I8: 4 | J8: 1
B9: =HYPERLINK("#FixPlan!A1","Critical URLs") -> Critical URLs | C9: 2
B10: =HYPERLINK("#Technical!A1","Warning URLs") -> Warning URLs | C10: 83
B11: =HYPERLINK("#Technical!A1","Error Rate % (4xx/5xx)") -> Error Rate % (4xx/5xx) | C11: =IFERROR(2/85,0) -> 0.023529412
B12: =HYPERLINK("#Technical!A1","Crawl Success Rate % (2xx)") -> Crawl Success Rate % (2xx) | C12: =IFERROR(83/85,0) -> 0.97647059
B13: =HYPERLINK("#Technical!A1","Critical URL Rate %") -> Critical URL Rate % | C13: =IFERROR(2/85,0) -> 0.023529412
B14: =HYPERLINK("#Technical!A1","Warning URL Rate %") -> Warning URL Rate % | C14: =IFERROR(83/85,0) -> 0.97647059
B15: Projected Health Score % (if all To Do done) | C15: 0.83863529
B16: Projected Pass Rate % (if all To Do done) | C16: 0.75588235
B18: Status | C18: Count
B19: 200 OK | C19: 83
B20: 3xx Redirects | C20: 0 | E20: Traditional SEO vs. 2026 AEO Readiness
B21: 4xx Errors | C21: 2 | E21: Dimension | F21: Score
B22: 5xx Errors | C22: 0 | E22: Traditional SEO | F22: 0.7485
B23: Other | C23: 0 | E23: 2026 AEO Readiness | F23: 0
A24: Immediate Actions | E24: Strategic Narrative
A25: Top 5 URLs by Business Risk Score | B25: Severity | C25: Count | E25: High SEO / Low AEO suggests the site is visible to humans but invisible to AI answer engines.
A26: Rank | B26: Critical | C26: 7 | D26: Why Prioritized | G26: Status
A27: 1 | B27: Warning | C27: 12 | D27: Has critical issues | G27: Open
A28: 2 | B28: Medium | C28: 0 | D28: Has critical issues | E28: Yes | F28: Dev | G28: Open
A29: 3 | B29: Low | C29: 15 | D29: Monitor | E29: Yes | F29: Copy Writer | G29: Open
A30: 4 | B30: https://africanmarketingconfederation.org/amc-conference-2023/amc-awards-book-now/ | C30: 84 | D30: Monitor | E30: Yes | F30: Copy Writer | G30: Open
A31: 5 | B31: PRIORITY SNAPSHOT | C31: Value | D31: Monitor | E31: Yes | F31: Copy Writer | G31: Open
B32: Top Blocking Issue | C32: No Compression Header
B33: Top Issue Affected URLs | C33: 85
B34: 4xx/5xx URLs | C34: 2
B35: Avg TTFB (ms) | C35: 250.29
B37: Quick Navigation | C37: Open
B38: Fix Plan | C38: =HYPERLINK("#FixPlan!A1","Open") -> Open
B39: Main URL Data | C39: =HYPERLINK("#Main!A1","Open") -> Open
B40: Technical Diagnostics | C40: =HYPERLINK("#Technical!A1","Open") -> Open
B41: Indexability | C41: =HYPERLINK("#Indexability!A1","Open") -> Open
B42: AEO Opportunities | C42: =HYPERLINK("#AEO!A1","Open") -> Open
...

Sheet Content Optimization Hub
A1: 🚀 CONTENT HUB INSTRUCTIONS: 1. Draft content in 'Proposed' columns. | 2. Ensure 'Count' columns are Green. | 3. Use 'Elementor' link for direct editing. | 4. Update 'Status' to 'Completed' when finished. | 5. Preview branding in 'OG Image Preview' column.
A2: Status | B2: Assigned Owner | C2: Content Cluster ID | D2: URL | E2: Elementor Builder Link | F2: Target Keywords | G2: Current Page Copy Snippet | H2: Current Title | I2: Proposed Title (50-60 Chars) | J2: Title Count | K2: Current Meta Desc | L2: Proposed Meta Desc (120-160 Chars) | M2: Desc Count | N2: Current H-Tag Structure | O2: Proposed H-Tag Fixes | P2: AEO Answer Block Draft | Q2: FAQ/QA Draft | R2: Current OG-Image URL | S2: OG Image Preview | T2: Social Share Note | U2: Open in Main | V2: BACK TO DASHBOARD
A3: To Do | B3: Unassigned | C3: home-african-marketing-confed | D3: https://africanmarketingconfederation.org/ | E3: https://africanmarketingconfederation.org/wp-admin/post.php?post=8&action=elementor | F3: [Auto]: H1 ABOUT The African Marketing Confederation H2 The 2026 AMC Conference H2 Meets the Mighty Victoria Falls H2 23 25 September Livingstone Zambia H2 The 2026 AMC Conference H2 Meets the Mighty Victoria Falls | G3: European marketers gather to choose their top achievers for 2026 Marketing associations from across Europe nominated national champions, with 10 finalists competing for the Marketer of the Year title. Read More » April 30, 2026 | H3: African Marketing Confederation - Uniting Marketers for Excellence | J3: =LEN(I3) -> 0 | K3: The African Marketing Confederation is the ground-breaking Pan-African body driving the development of top marketing standards across Africa and beyond. | M3: =LEN(L3) -> 0 | N3: H1: ABOUT The African Marketing Confederation H2: The 2026 AMC Conference H2: Meets the Mighty Victoria Falls H2: 23-25 September | Livingstone, Zambia H2: The 2026 AMC Conference H2: Meets the Mighty Victoria Falls | S3: =IF(LEN(R3)>0, _xludf.IMAGE(R3), "") | U3: =IFERROR(HYPERLINK("#Main!A"&MATCH(D2,Main!A:A,0),"Open"),HYPERLINK("#Main!A1","Open")) -> Open
A4: To Do | B4: Unassigned | C4: about-us-african-marketing-confed | D4: https://africanmarketingconfederation.org/about-us/ | E4: https://africanmarketingconfederation.org/wp-admin/post.php?post=84&action=elementor | F4: [Auto]: about us | G4: Skip to content ABOUT The African Marketing Confederation​ The African Marketing Confederation is the ground-breaking Pan African body of marketing professionals spearheading the ongoing development of the highest possible standards of marketing acro... | H4: African Marketing Confederation – The Leading Marketing Professional Body – African Marketing Confederation | J4: =LEN(I4) -> 0 | K4: ABOUT The African Marketing Confederation​ The African Marketing Confederation is the ground-breaking Pan African body of marketing professionals spearheading the ongoing development of the highest possible standards of marketing across Africa. Founded in 2011, the AMC is a collaboration between the African national marketing bodies and associations to exchange expertise and information, and to promote | M4: =LEN(L4) -> 0 | N4: H1: ABOUT The African Marketing Confederation​ H3: African Marketing Confederation ​ PRESIDENT’S COUNCIL H2: Helen McIntee H2: President and Co-founder H2: David Balikuddembe H2: Secretary General | S4: =IF(LEN(R4)>0, _xludf.IMAGE(R4), "") | U4: =IFERROR(HYPERLINK("#Main!A"&MATCH(D3,Main!A:A,0),"Open"),HYPERLINK("#Main!A1","Open")) -> Open
A5: To Do | B5: Unassigned | C5: african-marketing-confederation-tourism-chapter-african-marketing-confed | D5: https://africanmarketingconfederation.org/african-marketing-confederation-tourism-chapter/ | E5: https://africanmarketingconfederation.org/wp-admin/post.php?post=28165&action=elementor | F5: [Auto]: african marketing confederation tourism chapter | G5: Skip to content African Marketing Confederation Tourism Chapter Shaping Africa’s Tourism Narrative Through Strategic Marketing Tourism is one of Africa’s most powerful economic engines – generating jobs, stimulating investment, and fostering cultural... | H5: African Marketing Confederation Tourism Chapter – African Marketing Confederation | J5: =LEN(I5) -> 0 | K5: African Marketing Confederation Tourism Chapter Shaping Africa’s Tourism Narrative Through Strategic Marketing Tourism is one of Africa’s most powerful economic engines - generating jobs, stimulating investment, and fostering cultural exchange.The African Marketing Confederation is proud to launch the Tourism Chapter, a bold initiative to elevate African tourism through the lens of world-class marketing. Launched at the | M5: =LEN(L5) -> 0 | N5: H1: African Marketing Confederation Tourism Chapter H3: Shaping Africa’s Tourism Narrative Through Strategic Marketing H2: Charting the Course: Purpose, Mission & Vision for Africa’s Tourism Future H2: Our Goals and Objectives: | S5: =IF(LEN(R5)>0, _xludf.IMAGE(R5), "") | U5: =IFERROR(HYPERLINK("#Main!A"&MATCH(D4,Main!A:A,0),"Open"),HYPERLINK("#Main!A1","Open")) -> Open
A6: To Do | B6: Unassigned | C6: amc-awards-2024-amc-awards-{n}-–-african | D6: https://africanmarketingconfederation.org/amc-awards-2024/ | E6: https://africanmarketingconfederation.org/wp-admin/post.php?post=16125&action=elementor | F6: [Auto]: amc awards 2024 | G6: NOMINATIONS are Open ! AMC Awards The African Marketing Confederation Awards event is held annually as part of the African Marketing Confederation Forum. This distinguished event celebrates and acknowledges outstanding marketing campaigns and the vis... | H6: AMC Awards 2024 – African Marketing Confederation | J6: =LEN(I6) -> 0 | K6: NOMINATIONS are Open ! AMC Awards The African Marketing Confederation Awards event is held annually as part of the African Marketing Confederation Forum. This distinguished event celebrates and acknowledges outstanding marketing campaigns and the visionary individuals behind them. The awards presented honor not only the groundbreaking strategies and creative brilliance that set these campaigns apart but | M6: =LEN(L6) -> 0 | N6: H1: NOMINATIONS are Open ! H2: Awards Categories H2: Tourism & Destination Marketing Campaign H2: of the Year H2: Best Social Media Campaign of the Year H2: Best Social Media Campaign | S6: =IF(LEN(R6)>0, _xludf.IMAGE(R6), "") | U6: =IFERROR(HYPERLINK("#Main!A"&MATCH(D5,Main!A:A,0),"Open"),HYPERLINK("#Main!A1","Open")) -> Open
A7: To Do | B7: Unassigned | C7: amc-conference-2022-prospectus-amc-conference-{n}-–-pro | D7: https://africanmarketingconfederation.org/amc-conference-2022-prospectus/ | E7: https://africanmarketingconfederation.org/wp-admin/post.php?post=5619&action=elementor | F7: [Auto]: amc conference 2022 prospectus | G7: Skip to content AMC Conference 2022 23 - 24 March 2022 Navigating Africa’s Unique Marketing Mix BOOK NOW Days Hours Minutes Seconds download prospectus To download the AMC 2022 Conference Prospectus please complete the form below: First Name Last Na... | H7: AMC Conference 2022 – Prospectus – African Marketing Confederation | J7: =LEN(I7) -> 0 | K7: AMC Conference 2022 23 - 24 March 2022 Navigating Africa's Unique Marketing Mix BOOK NOW Days Hours Minutes Seconds download prospectus To download the AMC 2022 Conference Prospectus please complete the form below: First Name Last Name Email Mobile Company I've read and agree to the Privacy Policy BOOK NOW FOR THE AMC CONFERENCE 2022 | M7: =LEN(L7) -> 0 | N7: H2: AMC Conference 2022 H2: download prospectus H2: BOOK NOW FOR THE AMC CONFERENCE 2022 | S7: =IF(LEN(R7)>0, _xludf.IMAGE(R7), "") | U7: =IFERROR(HYPERLINK("#Main!A"&MATCH(D6,Main!A:A,0),"Open"),HYPERLINK("#Main!A1","Open")) -> Open
A8: To Do | B8: Unassigned | C8: amc-conference-2022-thank-you-amc-conference-{n}-–-tha | D8: https://africanmarketingconfederation.org/amc-conference-2022-thank-you/ | E8: https://africanmarketingconfederation.org/wp-admin/post.php?post=4941&action=elementor | F8: [Auto]: amc conference 2022 thank you | G8: Skip to content AMC Conference 2022 23 - 24 March 2022 Navigating Africa’s Unique Marketing Mix ENQUIRE NOW Days Hours Minutes Seconds Success! Thank you for completing the enquiry form. Our team will contact you shortly! × The AMC Conference is the ... | H8: AMC Conference 2022 – Thank You – African Marketing Confederation | J8: =LEN(I8) -> 0 | K8: AMC Conference 2022 23 - 24 March 2022 Navigating Africa's Unique Marketing Mix ENQUIRE NOW Days Hours Minutes Seconds Success! Thank you for completing the enquiry form. Our team will contact you shortly! × Dismiss alert The AMC Conference is the must attend Pan African event for marketing professionals. It will focus on solutions for | M8: =LEN(L8) -> 0 | N8: H2: AMC Conference 2022 H2: WHO SHOULD ATTEND H2: Countries Participating H3: South Africa H3: Nigeria H3: Morocco | S8: =IF(LEN(R8)>0, _xludf.IMAGE(R8), "") | U8: =IFERROR(HYPERLINK("#Main!A"&MATCH(D7,Main!A:A,0),"Open"),HYPERLINK("#Main!A1","Open")) -> Open
A9: To Do | B9: Unassigned | C9: amc-conference-2022-amc-conference-{n}-–-afr | D9: https://africanmarketingconfederation.org/amc-conference-2022/ | E9: https://africanmarketingconfederation.org/wp-admin/post.php?post=4494&action=elementor | F9: [Auto]: amc conference 2022 | G9: AMC officially welcomes new member associations into the fold October 8, 2024 No Comments Angola, Botswana, Ethiopia, Mozambique and Tanzania receive their membership certificates. AMC now has 16 members. Read More » | H9: AMC Conference 2022 – African Marketing Confederation | J9: =LEN(I9) -> 0 | K9: corinna kopf onlyfans leaks AMC Conference 2022 Thank you for attending19 - 22 October 2022 The African Marketing Confederation's Annual Conference brought together the best collection of marketing leaders from top companies, marketing bodies and associations to share tactics and best practices on how to build the next generation of marketing. Event Highlights Thank you for Attending! | M9: =LEN(L9) -> 0 | N9: H2: AMC Conference 2022 H2: Event Highlights H3: AMC officially welcomes new member associations into the fold H3: Marketers are placing the ads where consumers don’t want to see them H3: Time for Africa to control its own narrative and image, delegates told H3: Excitement as Ghana announced as host of 2025 AMC marketing conference | S9: =IF(LEN(R9)>0, _xludf.IMAGE(R9), "") | U9: =IFERROR(HYPERLINK("#Main!A"&MATCH(D8,Main!A:A,0),"Open"),HYPERLINK("#Main!A1","Open")) -> Open
A10: To Do | B10: Unassigned | C10: amc-conference-2023-amc-conference-{n}-–-afr | D10: https://africanmarketingconfederation.org/amc-conference-2023/ | E10: https://africanmarketingconfederation.org/wp-admin/post.php?post=12371&action=elementor | F10: [Auto]: amc conference 2023 | G10: AMC Conference 6 - 9 September 2023 Imperial Botanical Beach Hotel, Entebbe, Uganda Thank you for joining us! View Presentations 2nd Annual African Marketing Confederation Conference Africa's $3.4 trillion Economy: Opportunities for Marketers Welcome... | H10: AMC Conference 2023 – African Marketing Confederation | J10: =LEN(I10) -> 0 | K10: AMC Conference 6 - 9 September 2023 Imperial Botanical Beach Hotel, Entebbe, Uganda Thank you for joining us! View Presentations 2nd Annual African Marketing Confederation Conference Africa's $3.4 trillion Economy: Opportunities for Marketers Welcome to the Recap of the 2nd Annual African Marketing Conference: Unveiling Africa's $3.4 Trillion EconomyOur conference was a remarkable exploration of | M10: =LEN(L10) -> 0 | N10: H1: AMC Conference H2: Africa's $3.4 trillion Economy: Opportunities for Marketers H2: Thank you for joining us! H2: Topics covered H3: Africa Free Trade Area H3: Business Intelligence | S10: =IF(LEN(R10)>0, _xludf.IMAGE(R10), "") | U10: =IFERROR(HYPERLINK("#Main!A"&MATCH(D9,Main!A:A,0),"Open"),HYPERLINK("#Main!A1","Open")) -> Open
A11: To Do | B11: Unassigned | C11: amc-conference-2023-amc-awards-|-book-now-–- | D11: https://africanmarketingconfederation.org/amc-conference-2023/amc-awards-book-now/ | E11: https://africanmarketingconfederation.org/wp-admin/post.php?post=13164&action=elementor | F11: [Auto]: amc awards book now | G11: Skip to content 0 Your Cart Your cart is empty Return to Shop Continue Shopping | H11: AMC Awards | Book Now – African Marketing Confederation | J11: =LEN(I11) -> 0 | K11: MISSING DESCRIPTION | M11: =LEN(L11) -> 0 | S11: =IF(LEN(R11)>0, _xludf.IMAGE(R11), "") | U11: =IFERROR(HYPERLINK("#Main!A"&MATCH(D10,Main!A:A,0),"Open"),HYPERLINK("#Main!A1","Open")) -> Open
A12: To Do | B12: Unassigned | C12: amc-conference-2023-amc-awards-–-african-mar | D12: https://africanmarketingconfederation.org/amc-conference-2023/amc-awards/ | E12: https://africanmarketingconfederation.org/wp-admin/post.php?post=12954&action=elementor | F12: [Auto]: amc awards | G12: Skip to content AMC Awards Welcome to the prestigious African Marketing Confederation Awards, a distinguished event that celebrates and acknowledges the remarkable achievements, cutting-edge innovations, and exceptional leadership demonstrated by out... | H12: AMC Awards – African Marketing Confederation | J12: =LEN(I12) -> 0 | K12: AMC Awards Welcome to the prestigious African Marketing Confederation Awards, a distinguished event that celebrates and acknowledges the remarkable achievements, cutting-edge innovations, and exceptional leadership demonstrated by outstanding individuals within the dynamic realm of marketing across the expansive African region.During the 2nd Annual African Marketing Confederation Conference, held from 6th to 9th September at the | M12: =LEN(L12) -> 0 | N12: H1: AMC Awards H2: AMC AWARD Winners | S12: =IF(LEN(R12)>0, _xludf.IMAGE(R12), "") | U12: =IFERROR(HYPERLINK("#Main!A"&MATCH(D11,Main!A:A,0),"Open"),HYPERLINK("#Main!A1","Open")) -> Open
A13: To Do | B13: Unassigned | C13: amc-conference-2023-book-now-|-thank-you-–-a | D13: https://africanmarketingconfederation.org/amc-conference-2023/book-now-thank-you/ | E13: https://africanmarketingconfederation.org/wp-admin/post.php?post=12497&action=elementor | F13: [Auto]: book now thank you | G13: Thank you for completing your booking! Congratulations on booking your seat to the 2023 AfricaPro Conference presenting the 2nd Annual African Marketing Confederation Conference and Inaugural Technology Information Confederation Africa Conference! Yo... | H13: Book Now | Thank you – African Marketing Confederation | J13: =LEN(I13) -> 0 | K13: Thank you for completing your booking! Congratulations on booking your seat to the 2023 AfricaPro Conference presenting the 2nd Annual African Marketing Confederation Conference and Inaugural Technology Information Confederation Africa Conference! You will receive your email confirmation shortly with more event information. Be sure to keep an eye on the event website for up to | M13: =LEN(L13) -> 0 | N13: H2: Thank you for completing your booking! | S13: =IF(LEN(R13)>0, _xludf.IMAGE(R13), "") | U13: =IFERROR(HYPERLINK("#Main!A"&MATCH(D12,Main!A:A,0),"Open"),HYPERLINK("#Main!A1","Open")) -> Open
A14: To Do | B14: Unassigned | C14: amc-conference-2023-book-now-–-african-marke | D14: https://africanmarketingconfederation.org/amc-conference-2023/book-now/ | E14: https://africanmarketingconfederation.org/wp-admin/post.php?post=12407&action=elementor | F14: [Auto]: book now | G14: Skip to content Book Now Individual Booking Package Options 1: Full Conference + Accommodation 5 - 9 September 2023 890 USD 3 Day Conference Including Excursions: 5 Sept - Networking evening and light dinner 6 Sept - Official opening and barbecue din... | H14: Book Now – African Marketing Confederation | J14: =LEN(I14) -> 0 | K14: Book Now Individual Booking Package Options 1: Full Conference + Accommodation 5 - 9 September 2023 890 USD 3 Day Conference Including Excursions: 5 Sept - Networking evening and light dinner 6 Sept - Official opening and barbecue dinner 7 Sept - Sunset Cruise on Lake Victoria 8 Sept - Cultural Gala dinner at Ndere | M14: =LEN(L14) -> 0 | N14: H1: Book Now H3: Individual Booking H3: Group Bookings H3: Group Bookings | S14: =IF(LEN(R14)>0, _xludf.IMAGE(R14), "") | U14: =IFERROR(HYPERLINK("#Main!A"&MATCH(D13,Main!A:A,0),"Open"),HYPERLINK("#Main!A1","Open")) -> Open
A15: To Do | B15: Unassigned | C15: amc-conference-2023-download-prospectus-–-af | D15: https://africanmarketingconfederation.org/amc-conference-2023/download-prospectus/ | E15: https://africanmarketingconfederation.org/wp-admin/post.php?post=13098&action=elementor | F15: [Auto]: download prospectus | G15: BOOK NOW Prospectus Download the African Marketing Confederation Prospectus Learn more about the available sponsorship and exhibitor packages and how you can be a part of this exciting event First Name Last Name Email Position Are you a member of a c... | H15: Download Prospectus – African Marketing Confederation | J15: =LEN(I15) -> 0 | K15: BOOK NOW Prospectus Download the African Marketing Confederation Prospectus Learn more about the available sponsorship and exhibitor packages and how you can be a part of this exciting event First Name Last Name Email Position Are you a member of a country member body?--Select--Yes No I would like to receive monthly updates from AMCYes No | M15: =LEN(L15) -> 0 | N15: H1: Prospectus H2: Prospectus | S15: =IF(LEN(R15)>0, _xludf.IMAGE(R15), "") | U15: =IFERROR(HYPERLINK("#Main!A"&MATCH(D14,Main!A:A,0),"Open"),HYPERLINK("#Main!A1","Open")) -> Open
A16: To Do | B16: Unassigned | C16: amc-conference-2023-gallery-–-african-market | D16: https://africanmarketingconfederation.org/amc-conference-2023/gallery/ | E16: https://africanmarketingconfederation.org/wp-admin/post.php?post=13549&action=elementor | F16: [Auto]: gallery | G16: Skip to content Conference Gallery All Day 1 Day 2 Day 3 Night 1 Night 2 Night 3 0 Your Cart Your cart is empty Return to Shop Continue Shopping | H16: Gallery – African Marketing Confederation | J16: =LEN(I16) -> 0 | K16: Conference Gallery sydney sweeney met gala All Day 1 Day 2 Day 3 Night 1 Night 2 Night 3 | M16: =LEN(L16) -> 0 | N16: H1: Conference Gallery | S16: =IF(LEN(R16)>0, _xludf.IMAGE(R16), "") | U16: =IFERROR(HYPERLINK("#Main!A"&MATCH(D15,Main!A:A,0),"Open"),HYPERLINK("#Main!A1","Open")) -> Open
A17: To Do | B17: Unassigned | C17: amc-conference-2023-partners-–-african-marke | D17: https://africanmarketingconfederation.org/amc-conference-2023/partners/ | E17: https://africanmarketingconfederation.org/wp-admin/post.php?post=13282&action=elementor | F17: [Auto]: partners | G17: Skip to content Conference Partners AMC Member Bodies 0 Your Cart Your cart is empty Return to Shop Continue Shopping | H17: Partners – African Marketing Confederation | J17: =LEN(I17) -> 0 | K17: Conference Partners AMC Member Bodies | M17: =LEN(L17) -> 0 | N17: H1: Conference Partners | S17: =IF(LEN(R17)>0, _xludf.IMAGE(R17), "") | U17: =IFERROR(HYPERLINK("#Main!A"&MATCH(D16,Main!A:A,0),"Open"),HYPERLINK("#Main!A1","Open")) -> Open
A18: To Do | B18: Unassigned | C18: amc-conference-2023-programme-–-african-mark | D18: https://africanmarketingconfederation.org/amc-conference-2023/programme/ | E18: https://africanmarketingconfederation.org/wp-admin/post.php?post=12945&action=elementor | F18: [Auto]: programme | G18: Skip to content Programme Download Conference Presentations Are Marketers Intelligent Enough For AI - Fred Kithinzi Taking Africa to the world and bringing the world to Africa - Nondumiso Mabece| Next Media DGCEO Presentation Strategy and Technology:... | H18: Programme – African Marketing Confederation | J18: =LEN(I18) -> 0 | K18: Programme Download Conference Presentations Are Marketers Intelligent Enough For AI - Fred Kithinzi Taking Africa to the world and bringing the world to Africa - Nondumiso Mabece| Next Media DGCEO Presentation Strategy and Technology: Expanding the Success of Pan-African Brands - Prof. Robert Ebo Hinson Winning African Markets - Simon Harvey Culture as the New | M18: =LEN(L18) -> 0 | N18: H1: Programme H2: Download Conference Presentations H2: Conference Day 1 H3: WEDNESDAY | 6 SEPTEMBER 2023 H2: Conference Day 2 H3: THURSDAY | 7 SEPTEMBER 2023 | S18: =IF(LEN(R18)>0, _xludf.IMAGE(R18), "") | U18: =IFERROR(HYPERLINK("#Main!A"&MATCH(D17,Main!A:A,0),"Open"),HYPERLINK("#Main!A1","Open")) -> Open
A19: To Do | B19: Unassigned | C19: amc-conference-2023-speakers-–-african-marke | D19: https://africanmarketingconfederation.org/amc-conference-2023/speakers/ | E19: https://africanmarketingconfederation.org/wp-admin/post.php?post=13179&action=elementor | F19: [Auto]: speakers | G19: Skip to content Speakers Ali Hussein Kassim Kenya CEO - AHK Corp View Bio Cathy Adengo Uganda Head of Sustainability, Stanbic Bank Uganda View Bio Doreen Asaasira Muhangazi Uganda Chief Human Resource Officer View Bio James Sutton United Kingdom Stra... | H19: Speakers – African Marketing Confederation | J19: =LEN(I19) -> 0 | K19: Speakers Ali Hussein Kassim Kenya CEO - AHK Corp View Bio Cathy Adengo Uganda Head of Sustainability, Stanbic Bank Uganda View Bio Doreen Asaasira Muhangazi Uganda Chief Human Resource Officer View Bio James Sutton United Kingdom Strategy and Commercial Director - CIM-UK View Bio Juliet Ziswa Zimbabwe Marketing Director - OK Zimbabwe Limited Group View | M19: =LEN(L19) -> 0 | N19: H1: Speakers H2: Ali Hussein Kassim H3: Kenya H2: Cathy Adengo H3: Uganda H2: Doreen Asaasira Muhangazi | S19: =IF(LEN(R19)>0, _xludf.IMAGE(R19), "") | U19: =IFERROR(HYPERLINK("#Main!A"&MATCH(D18,Main!A:A,0),"Open"),HYPERLINK("#Main!A1","Open")) -> Open
A20: To Do | B20: Unassigned | C20: amc-conference-2024-recap-amc-conference-{n}-recap | D20: https://africanmarketingconfederation.org/amc-conference-2024-recap/ | E20: https://africanmarketingconfederation.org/wp-admin/post.php?post=22401&action=elementor | F20: [Auto]: amc conference 2024 recap | G20: Event Highlights AMC Marketing Conference 2024 Shaping the Future of African Marketing Get 2025 Conference Updates Share Your Experience Conference Day 1 The conference kicked off with insightful addresses, including a keynote from marketing expert ... | H20: AMC Conference 2024 Recap – African Marketing Confederation | J20: =LEN(I20) -> 0 | K20: Event Highlights AMC Marketing Conference 2024 Shaping the Future of African Marketing Get 2025 Conference Updates Share Your Experience Conference Day 1 The conference kicked off with insightful addresses, including a keynote from marketing expert Hermawan Kartajaya. Dr Philip Kotler, the Father of Modern Marketing, delivered a welcome address live from Chicago and we ended | M20: =LEN(L20) -> 0 | N20: H1: Event Highlights H3: Conference Day 1 H3: Conference Day 2 H3: Conference Day 3 H3: Did you attend the 2024 AMC Conference? We’d love to hear about your experience! H3: Countries Represented | S20: =IF(LEN(R20)>0, _xludf.IMAGE(R20), "") | U20: =IFERROR(HYPERLINK("#Main!A"&MATCH(D19,Main!A:A,0),"Open"),HYPERLINK("#Main!A1","Open")) -> Open
A21: To Do | B21: Unassigned | C21: amc-conference-2024-sponsors-packages-sponsors-packages-–-afri | D21: https://africanmarketingconfederation.org/amc-conference-2024-sponsors-packages/ | E21: https://africanmarketingconfederation.org/wp-admin/post.php?post=18318&action=elementor | F21: [Auto]: amc conference 2024 sponsors packages | G21: SPONSORSHIP PACKAGES AMC Full-Conference Package Labadi Beach Hotel Full-day conference attendance 4 nights’ accommodation All breakfasts, lunches, & 3 dinners $ 1550 View Product AMC Full-Conference Package La Palm Royal Beach Hotel Full-day confere... | H21: Sponsors Packages – African Marketing Confederation | J21: =LEN(I21) -> 0 | K21: SPONSORSHIP PACKAGES Diamond Package Overall Anchor and Title Sponsor $50000,00 View Product Platinum Package Industry Leader Sponsor / per Professional Body Stream $20000,00 View Product Silver Package Full Day (Option to Choose Day 1, 2, or 3) Provision of Delegates Apparel in the Form of Golf Shirts and Caps (Day 2 & 3) $12000,00 View | M21: =LEN(L21) -> 0 | N21: H1: SPONSORSHIP PACKAGES H2: AMC Full-Conference Package Labadi Beach Hotel H3: $ 1550 H2: AMC Full-Conference Package La Palm Royal Beach Hotel H3: $ 1330 H2: AMC Day Attendance Package | S21: =IF(LEN(R21)>0, _xludf.IMAGE(R21), "") | U21: =IFERROR(HYPERLINK("#Main!A"&MATCH(D20,Main!A:A,0),"Open"),HYPERLINK("#Main!A1","Open")) -> Open
A22: To Do | B22: Unassigned | C22: amc-conference-2025-highlights-amc-conference-{n}-highl | D22: https://africanmarketingconfederation.org/amc-conference-2025-highlights/ | E22: https://africanmarketingconfederation.org/wp-admin/post.php?post=30257&action=elementor | F22: [Auto]: amc conference 2025 highlights | G22: 2025 Event Highlights AMC Marketing Conference AMC Marketing Conference 250+ Delegates. 29 Countries. One Pan-African Voice. 250+ Delegates. 29 Countries. One Pan-African Marketing Voice. Get 2026 Conference Updates Share Your Experience 2025 Event H... | H22: AMC Conference 2025 Highlights – African Marketing Confederation | J22: =LEN(I22) -> 0 | K22: 2025 Event Highlights AMC Marketing Conference AMC Marketing Conference 250+ Delegates. 29 Countries. One Pan-African Voice.250+ Delegates. 29 Countries.One Pan-African Marketing Voice. Get 2026 Conference Updates Share Your Experience 2025 Event Highlights AMC Marketing Conference 400+ Delegates. 29 Countries.One Pan-African Voice. Get 2026 Conference Updates 2025 Event Highlights AMC Marketing Conference Get 2026 Conference Updates | M22: =LEN(L22) -> 0 | N22: H1: 2025 H2: Moments that Shaped the 2025 AMC Conference H2: Wednesday, 20 August H2: Opening Keynote H2: Back to Basics – Thriving in Tough Times H2: Creating Authentic Connections Through User-Generated & Short-Form Video | S22: =IF(LEN(R22)>0, _xludf.IMAGE(R22), "") | U22: =IFERROR(HYPERLINK("#Main!A"&MATCH(D21,Main!A:A,0),"Open"),HYPERLINK("#Main!A1","Open")) -> Open
A23: To Do | B23: Unassigned | C23: amc-conference-2025-amc-conference-{n} | D23: https://africanmarketingconfederation.org/amc-conference-2025/ | E23: https://africanmarketingconfederation.org/wp-admin/post.php?post=23710&action=elementor | F23: [Auto]: amc conference 2025 | G23: Thriving in Africa’s Evolving Markets: Trust, Trends & Technology AMC Conference 2025 20 – 22 August | Accra, Ghana Meet Our Speakers at the 2025 AMC Africa Conference See Speaker's Bio See Speaker's Bio See Speaker's Bio See Speaker's Bio See Speak... | H23: AMC Conference 2025 | J23: =LEN(I23) -> 0 | K23: Join Africa's top marketers at the AMC Conference 2025 n Accra, Ghana from 20-22 August - 3 days of insights, innovation, and powerful networking. | M23: =LEN(L23) -> 0 | N23: H1: AMC Conference 2025 H2: Meet Our Speakers at the 2025 AMC Africa Conference H2: Attend AMC Conference 2025 in Accra, Ghana H2: 2025 Conference Sponsors H3: AMC Conference 2025 H2: Unmatched Networking | S23: =IF(LEN(R23)>0, _xludf.IMAGE(R23), "") | U23: =IFERROR(HYPERLINK("#Main!A"&MATCH(D22,Main!A:A,0),"Open"),HYPERLINK("#Main!A1","Open")) -> Open
... A27: To Do | B27: Unassigned | C27: amc-conference-programme-hybrid-programme​-–-afri | D27: https://africanmarketingconfederation.org/amc-conference-programme/ | E27: https://africanmarketingconfederation.org/wp-admin/post.php?post=5057&action=elementor | F27: [Auto]: amc conference programme | G27: Skip to content AMC Conference 2022 HYBRID CONFERENCE PROGRAMME​ 23 - 24 March 2022 Navigating Africa’s Unique Marketing Mix Conference day 1 Conference day 2 BOOK NOW FOR THE AMC CONFERENCE 2022 BOOK NOW Conference day 1 Wednesday, 23 March 2022 08h... | H27: HYBRID PROGRAMME​ – African Marketing Confederation | J27: =LEN(I27) -> 0 | K27: AMC Conference 2022 HYBRID CONFERENCE PROGRAMME​ 23 - 24 March 2022 Navigating Africa's Unique Marketing Mix Conference day 1 Conference day 2 BOOK NOW FOR THE AMC CONFERENCE 2022 BOOK NOW Conference day 1 Wednesday, 23 March 2022 08h30 WELCOME | MC Opening Remarks 08h40 AMC STAKEHOLDER WELCOME 08h55 AFRICA MARKETING BAROMETER | Marketing Trends | M27: =LEN(L27) -> 0 | N27: H2: AMC Conference 2022 H2: HYBRID CONFERENCE PROGRAMME​ H2: BOOK NOW FOR THE AMC CONFERENCE 2022 H2: Conference day 1 H2: Conference day 2 H2: BOOK NOW FOR THE AMC CONFERENCE 2022 | S27: =IF(LEN(R27)>0, _xludf.IMAGE(R27), "") | U27: =IFERROR(HYPERLINK("#Main!A"&MATCH(D26,Main!A:A,0),"Open"),HYPERLINK("#Main!A1","Open")) -> Open
A28: To Do | B28: Unassigned | C28: amc-conference-sponsors-untitled | D28: https://africanmarketingconfederation.org/amc-conference-sponsors/ | F28: [Auto]: amc conference sponsors | H28: MISSING TITLE | J28: =LEN(I28) -> 0 | K28: MISSING DESCRIPTION | M28: =LEN(L28) -> 0 | S28: =IF(LEN(R28)>0, _xludf.IMAGE(R28), "") | U28: =IFERROR(HYPERLINK("#Main!A"&MATCH(D27,Main!A:A,0),"Open"),HYPERLINK("#Main!A1","Open")) -> Open
A29: To Do | B29: Unassigned | C29: amc-conference-thank-you-amc-conference-|-thank-y | D29: https://africanmarketingconfederation.org/amc-conference-thank-you/ | E29: https://africanmarketingconfederation.org/wp-admin/post.php?post=12477&action=elementor | F29: [Auto]: amc conference thank you | G29: Back to AMC Website Thank You! Success! Thank you for completing the enquiry form. Our team will contact you shortly! × 2nd Annual African Marketing Confederation Conference Africa's $3.4 trillion Economy: Opportunities for Marketers The African Mark... | H29: AMC Conference | Thank You – African Marketing Confederation | J29: =LEN(I29) -> 0 | K29: Back to AMC Website Thank You! Success! Thank you for completing the enquiry form. Our team will contact you shortly! × Dismiss this alert. 2nd Annual African Marketing Confederation Conference Africa's $3.4 trillion Economy: Opportunities for Marketers The African Marketing Confederation (AMC) and Uganda Marketers Society (UMS) welcome you to the 2nd Annual Conference, themed | M29: =LEN(L29) -> 0 | N29: H1: Thank You! H2: Africa's $3.4 trillion Economy: Opportunities for Marketers H3: Join us at this Conference H2: Topics that will be covered H3: Africa Free Trade Area H3: Business Intelligence | S29: =IF(LEN(R29)>0, _xludf.IMAGE(R29), "") | U29: =IFERROR(HYPERLINK("#Main!A"&MATCH(D28,Main!A:A,0),"Open"),HYPERLINK("#Main!A1","Open")) -> Open
A30: To Do | B30: Unassigned | C30: amc-forum-mombasa-amc-forum-mombasa-–-afri | D30: https://africanmarketingconfederation.org/amc-forum-mombasa/ | E30: https://africanmarketingconfederation.org/wp-admin/post.php?post=21958&action=elementor | F30: [Auto]: amc forum mombasa | G30: AMC Marketing Conference Sarova WhiteSands Beach Resort, Mombasa As a must-attend for all marketing professionals, this year’s marketing forum will address the crucial theme: Brand Resilience Amidst Economic Uncertainty In such tumultuous times acros... | H30: AMC Forum Mombasa – African Marketing Confederation | J30: =LEN(I30) -> 0 | K30: AMC Marketing Conference Sarova WhiteSands Beach Resort, Mombasa As a must-attend for all marketing professionals, this year’s marketing forum will address the crucial theme: Brand Resilience Amidst Economic Uncertainty In such tumultuous times across Africa and the rest of the world, brand resilience is both more important and challenging than ever.This year’s theme will offer | M30: =LEN(L30) -> 0 | N30: H1: AMC Marketing Conference H2: Brand Resilience Amidst Economic Uncertainty H3: Hear From Africa’s Marketing Leaders H2: Sponsors H2: Ali Hussein Kassim H3: Kenya | S30: =IF(LEN(R30)>0, _xludf.IMAGE(R30), "") | U30: =IFERROR(HYPERLINK("#Main!A"&MATCH(D29,Main!A:A,0),"Open"),HYPERLINK("#Main!A1","Open")) -> Open
A31: To Do | B31: Unassigned | C31: amc-forum-payments-amc-forum-payments-–-afr | D31: https://africanmarketingconfederation.org/amc-forum-payments/ | E31: https://africanmarketingconfederation.org/wp-admin/post.php?post=21984&action=elementor | F31: [Auto]: amc forum payments | G31: AMC Conference 2025 Thriving in Africa’s Evolving Markets: Trust, Trends & Technology No products found! PUBLICATIONS Strategic Marketing for Africa Magazine CONTACT INFORMATION info@africanmarketingconfederation.org 0 Your Cart Your cart is empty Re... | H31: AMC Forum Payments – African Marketing Confederation | J31: =LEN(I31) -> 0 | K31: AMC Conference 2025 Thriving in Africa’s Evolving Markets:Trust, Trends & Technology No products found! PUBLICATIONS Strategic Marketing for Africa Magazine CONTACT INFORMATION info@africanmarketingconfederation.org © 2021 by African Marketing Confederation | Privacy Policy | M31: =LEN(L31) -> 0 | N31: H2: AMC Conference 2025 | S31: =IF(LEN(R31)>0, _xludf.IMAGE(R31), "") | U31: =IFERROR(HYPERLINK("#Main!A"&MATCH(D30,Main!A:A,0),"Open"),HYPERLINK("#Main!A1","Open")) -> Open
A32: To Do | B32: Unassigned | C32: amc-launch-event-zambia-thank-you-2026-amc-launch-event-zambia- | D32: https://africanmarketingconfederation.org/amc-launch-event-zambia-thank-you-2026/ | E32: https://africanmarketingconfederation.org/wp-admin/post.php?post=33131&action=elementor | F32: [Auto]: amc launch event zambia thank you 2026 | G32: 2026 AMC Conference Launch Event 16 March 2026 | 10:00 CAT (GMT +2) Thank you for registering to view the live stream of the African Marketing Confederation Conference launch event. You will receive your access link as soon as the live stream becomes... | H32: AMC Launch Event Zambia Thank You 2026 – African Marketing Confederation | J32: =LEN(I32) -> 0 | K32: 2026 AMC Conference Launch Event 16 March 2026 | 10:00 CAT (GMT +2)Thank you for registering to view the live stream of the African Marketing Confederation Conference launch event.You will receive your access link as soon as the live stream becomes available. 00Days 00Hours Secure Your Place Now Kindly use the Registration ID Number sent to your | M32: =LEN(L32) -> 0 | N32: H1: 2026 AMC Conference Launch Event H2: AMC Full-Conference Package Labadi Beach Hotel H2: AMC Full-Conference Package La Palm Royal Beach Hotel H2: AMC Day Attendance Package H2: AMC Conference Only Package | S32: =IF(LEN(R32)>0, _xludf.IMAGE(R32), "") | U32: =IFERROR(HYPERLINK("#Main!A"&MATCH(D31,Main!A:A,0),"Open"),HYPERLINK("#Main!A1","Open")) -> Open
A33: To Do | B33: Unassigned | C33: amc-marketing-conference-2024-amc-forum-mombasa-–-afri | D33: https://africanmarketingconfederation.org/amc-marketing-conference-2024/ | E33: https://africanmarketingconfederation.org/wp-admin/post.php?post=21958&action=elementor | F33: [Auto]: amc marketing conference 2024 | G33: AMC Marketing Conference Sarova WhiteSands Beach Resort, Mombasa As a must-attend for all marketing professionals, this year’s marketing forum will address the crucial theme: Brand Resilience Amidst Economic Uncertainty In such tumultuous times acros... | H33: AMC Forum Mombasa – African Marketing Confederation | J33: =LEN(I33) -> 0 | K33: AMC Marketing Conference Sarova WhiteSands Beach Resort, Mombasa As a must-attend for all marketing professionals, this year’s marketing forum will address the crucial theme: Brand Resilience Amidst Economic Uncertainty In such tumultuous times across Africa and the rest of the world, brand resilience is both more important and challenging than ever.This year’s theme will offer | M33: =LEN(L33) -> 0 | N33: H1: AMC Marketing Conference H2: Brand Resilience Amidst Economic Uncertainty H3: Hear From Africa’s Marketing Leaders H2: Sponsors H2: Ali Hussein Kassim H3: Kenya | S33: =IF(LEN(R33)>0, _xludf.IMAGE(R33), "") | U33: =IFERROR(HYPERLINK("#Main!A"&MATCH(D32,Main!A:A,0),"Open"),HYPERLINK("#Main!A1","Open")) -> Open
A34: To Do | B34: Unassigned | C34: amc-marketing-conference-2024-amc-conference-{n}-ghana | D34: https://africanmarketingconfederation.org/amc-marketing-conference-2024/amc-conference-2025-ghana-sponsors/ | E34: https://africanmarketingconfederation.org/wp-admin/post.php?post=25857&action=elementor | F34: [Auto]: amc conference 2025 ghana sponsors | G34: 2025 AMC conference Thank you for your interest in sponsoring the 2025 AMC Conference. A member of our team will be in touch to discuss available opportunities and next steps. PUBLICATIONS Strategic Marketing for Africa Magazine CONTACT INFORMATION i... | H34: AMC Conference 2025 Ghana Sponsors – African Marketing Confederation | J34: =LEN(I34) -> 0 | K34: 2025 AMC conference Thank you for your interest in sponsoring the 2025 AMC Conference. A member of our team will be in touch to discuss available opportunities and next steps. PUBLICATIONS Strategic Marketing for Africa Magazine CONTACT INFORMATION info@africanmarketingconfederation.org © 2021 by African Marketing Confederation | Privacy Policy | M34: =LEN(L34) -> 0 | N34: H1: 2025 AMC conference | S34: =IF(LEN(R34)>0, _xludf.IMAGE(R34), "") | U34: =IFERROR(HYPERLINK("#Main!A"&MATCH(D33,Main!A:A,0),"Open"),HYPERLINK("#Main!A1","Open")) -> Open
A35: To Do | B35: Unassigned | C35: amc-marketing-conference-2024-amc-launch-event-{n}-–-a | D35: https://africanmarketingconfederation.org/amc-marketing-conference-2024/amc-launch-event-2025/ | E35: https://africanmarketingconfederation.org/wp-admin/post.php?post=25788&action=elementor | F35: [Auto]: amc launch event 2025 | G35: AMC Conference launch 2025 Labadi Beach Hotel or Online 15 May 2025 I 10 AM – 12 PM GMT AMC Conference launch 2025 Name (Required) First Last Email (Required) Enter Email Confirm Email Phone Number (Required) Which country are you from? (Required) A... | H35: AMC Launch Event 2025 – African Marketing Confederation | J35: =LEN(I35) -> 0 | K35: AMC Conference launch 2025 Labadi Beach Hotel or Online15 May 2025 I 10 AM – 12 PM GMT AMC Conference launch 2025 Name(Required) First Last Email(Required) Enter Email Confirm Email Phone Number(Required)Which country are you from?(Required)AfghanistanAlbaniaAlgeriaAmerican SamoaAndorraAngolaAnguillaAntarcticaAntigua and BarbudaArgentinaArmeniaArubaAustraliaAustriaAzerbaijanBahamasBahrainBangladeshBarbadosBelarusBelgiumBelizeBeninBermudaBhutanBoliviaBonaire, Sint Eustatius and SabaBosnia and HerzegovinaBotswanaBouvet IslandBrazilBritish Indian Ocean TerritoryBrunei DarussalamBulgariaBurkina FasoBurundiCabo VerdeCambodiaCameroonCanadaCayman IslandsCentral African RepublicChadChileChinaChristmas | M35: =LEN(L35) -> 0 | N35: H1: AMC Conference launch 2025 H2: AMC Conference launch 2025 | S35: =IF(LEN(R35)>0, _xludf.IMAGE(R35), "") | U35: =IFERROR(HYPERLINK("#Main!A"&MATCH(D34,Main!A:A,0),"Open"),HYPERLINK("#Main!A1","Open")) -> Open
A36: To Do | B36: Unassigned | C36: amc-marketing-conference-2024-amc-preregister-{n}-–-af | D36: https://africanmarketingconfederation.org/amc-marketing-conference-2024/amc-preregister-2025/ | E36: https://africanmarketingconfederation.org/wp-admin/post.php?post=26290&action=elementor | F36: [Auto]: amc preregister 2025 | G36: Pre-register for AMC Conference 2025 20 – 22 August | Accra, Ghana Complete the form below to be notified as soon as final registration and payment options become available. AMC Conference 2025 Name (Required) First Last Email (Required) Enter Email ... | H36: AMC Preregister 2025 – African Marketing Confederation | J36: =LEN(I36) -> 0 | K36: Pre-register for AMC Conference 2025 20 - 22 August | Accra, Ghana Complete the form below to be notified as soon as final registration and payment options become available. AMC Conference 2025 Name(Required) First Last Email(Required) Enter Email Confirm Email Phone Number(Required)Which country are you from?(Required)AfghanistanAlbaniaAlgeriaAmerican SamoaAndorraAngolaAnguillaAntarcticaAntigua and BarbudaArgentinaArmeniaArubaAustraliaAustriaAzerbaijanBahamasBahrainBangladeshBarbadosBelarusBelgiumBelizeBeninBermudaBhutanBoliviaBonaire, Sint Eustatius and SabaBosnia and | M36: =LEN(L36) -> 0 | N36: H1: Pre-register for AMC Conference 2025 H2: AMC Conference 2025 | S36: =IF(LEN(R36)>0, _xludf.IMAGE(R36), "") | U36: =IFERROR(HYPERLINK("#Main!A"&MATCH(D35,Main!A:A,0),"Open"),HYPERLINK("#Main!A1","Open")) -> Open
A37: To Do | B37: Unassigned | C37: amc-marketing-conference-2024-{n}-amc-conference-award | D37: https://africanmarketingconfederation.org/amc-marketing-conference-2024/amc-programme-2025/ | E37: https://africanmarketingconfederation.org/wp-admin/post.php?post=24882&action=elementor | F37: [Auto]: amc programme 2025 | G37: Conference Menu 2025 AMC Conference Programme Day 1 Day 2 Day 3 DOWNLOAD PROGRAMME DAY 1 DOWNLOAD PROGRAMME DAY 2 DOWNLOAD PROGRAMME DAY 3 PUBLICATIONS Strategic Marketing for Africa Magazine CONTACT INFORMATION info@africanmarketingconfederation.org... | H37: 2025 AMC Conference Awards | J37: =LEN(I37) -> 0 | K37: Celebrate excellence at the 2025 AMC Conference Awards as we honour outstanding achievements, innovation and leadership in Africa’s marketing industry. | M37: =LEN(L37) -> 0 | N37: H1: 2025 AMC Conference | S37: =IF(LEN(R37)>0, _xludf.IMAGE(R37), "") | U37: =IFERROR(HYPERLINK("#Main!A"&MATCH(D36,Main!A:A,0),"Open"),HYPERLINK("#Main!A1","Open")) -> Open
A38: To Do | B38: Unassigned | C38: amc-marketing-conference-2024-amc-speakers-presentatio | D38: https://africanmarketingconfederation.org/amc-marketing-conference-2024/amc-speakers-presentations-2024/ | E38: https://africanmarketingconfederation.org/wp-admin/post.php?post=22595&action=elementor | F38: [Auto]: amc speakers presentations 2024 | G38: AMC speakers presentations 2024 Day 1 Day 2 Day 3 PUBLICATIONS Strategic Marketing for Africa Magazine CONTACT INFORMATION info@africanmarketingconfederation.org 0 Your Cart Your cart is empty Return to Shop Continue Shopping | H38: AMC speakers presentations 2024 – African Marketing Confederation | J38: =LEN(I38) -> 0 | K38: AMC speakers presentations 2024 Day 1 https://youtu.be/daWjshF4Bdc Day 2 https://youtu.be/7Qf2P8YLD7I Day 3 PUBLICATIONS Strategic Marketing for Africa Magazine CONTACT INFORMATION info@africanmarketingconfederation.org © 2021 by African Marketing Confederation | Privacy Policy | M38: =LEN(L38) -> 0 | N38: H1: AMC speakers presentations 2024 | S38: =IF(LEN(R38)>0, _xludf.IMAGE(R38), "") | U38: =IFERROR(HYPERLINK("#Main!A"&MATCH(D37,Main!A:A,0),"Open"),HYPERLINK("#Main!A1","Open")) -> Open
A39: To Do | B39: Unassigned | C39: amc-marketing-conference-2024-awards-{n}-–-african-mar | D39: https://africanmarketingconfederation.org/amc-marketing-conference-2024/awards-2025/ | E39: https://africanmarketingconfederation.org/wp-admin/post.php?post=29496&action=elementor | F39: [Auto]: awards 2025 | G39: Conference Menu AMC Conference Awards 2025 AMC Awards 2025 Categories View detailed explanations of each award below. Click on the awards below to view detailed explanations of each criterion. Tourism & Destination Marketing Campaign of the Year Best... | H39: Awards 2025 – African Marketing Confederation | J39: =LEN(I39) -> 0 | K39: Conference Menu AMC Conference Awards 2025 AMC Awards 2025 Categories View detailed explanations of each award below.Click on the awards below to view detailed explanations of each criterion. Tourism & Destination Marketing Campaign of the Year Best Social Media Campaignof the Year Most Effective Campaignof the Year Best Use of Local Insights Best Cause-Related Campaign | M39: =LEN(L39) -> 0 | N39: H1: AMC Conference Awards 2025 H2: AMC Awards 2025 Categories H2: Tourism & Destination Marketing Campaign H2: of the Year H2: Best Social Media Campaign of the Year H2: Best Social Media Campaign | S39: =IF(LEN(R39)>0, _xludf.IMAGE(R39), "") | U39: =IFERROR(HYPERLINK("#Main!A"&MATCH(D38,Main!A:A,0),"Open"),HYPERLINK("#Main!A1","Open")) -> Open
A40: To Do | B40: Unassigned | C40: amc-marketing-conference-2024-programme-{n}-–-african- | D40: https://africanmarketingconfederation.org/amc-marketing-conference-2024/programme-2024/ | E40: https://africanmarketingconfederation.org/wp-admin/post.php?post=16104&action=elementor | F40: [Auto]: programme 2024 | G40: Programme AMC 3rd Annual Conference 2024 Join us for an unparalleled marketing experience at the upcoming conference hosted by the African Marketing Confederation (AMC) in Kenya. From August 28th to 30th, 2024, immerse yourself in insightful discussi... | H40: Programme 2024 – African Marketing Confederation | J40: =LEN(I40) -> 0 | K40: Programme AMC 3rd Annual Conference 2024 Join us for an unparalleled marketing experience at the upcoming conference hosted by the African Marketing Confederation (AMC) in Kenya. From August 28th to 30th, 2024, immerse yourself in insightful discussions, cutting-edge strategies, and industry trends that are shaping the future of marketing across the continent. Engage with top-notch | M40: =LEN(L40) -> 0 | N40: H1: Programme H2: AMC 3rd Annual Conference 2024 H2: Programme TBA H3: Tuesday | 28 August 2024 H2: Conference Day 2 H3: Wednesday | 28th August 2024 | S40: =IF(LEN(R40)>0, _xludf.IMAGE(R40), "") | U40: =IFERROR(HYPERLINK("#Main!A"&MATCH(D39,Main!A:A,0),"Open"),HYPERLINK("#Main!A1","Open")) -> Open
A41: To Do | B41: Unassigned | C41: amc-marketing-conference-2024-untitled | D41: https://africanmarketingconfederation.org/amc-marketing-conference-2024/speakers-2024/ | F41: [Auto]: speakers 2024 | H41: MISSING TITLE | J41: =LEN(I41) -> 0 | K41: MISSING DESCRIPTION | M41: =LEN(L41) -> 0 | S41: =IF(LEN(R41)>0, _xludf.IMAGE(R41), "") | U41: =IFERROR(HYPERLINK("#Main!A"&MATCH(D40,Main!A:A,0),"Open"),HYPERLINK("#Main!A1","Open")) -> Open
A42: To Do | B42: Unassigned | C42: amc-marketing-conference-2024-testimony-thank-you-page | D42: https://africanmarketingconfederation.org/amc-marketing-conference-2024/testimony-thank-you-page/ | E42: https://africanmarketingconfederation.org/wp-admin/post.php?post=23021&action=elementor | F42: [Auto]: testimony thank you page | G42: Thank you For your Feedback Thank you For the Feedback PUBLICATIONS Strategic Marketing for Africa Magazine CONTACT INFORMATION info@africanmarketingconfederation.org 0 Your Cart Your cart is empty Return to Shop Continue Shopping | H42: Testimony Thank you Page – African Marketing Confederation | J42: =LEN(I42) -> 0 | K42: Thank you For your Feedback Thank you For the Feedback PUBLICATIONS Strategic Marketing for Africa Magazine CONTACT INFORMATION info@africanmarketingconfederation.org © 2021 by African Marketing Confederation | Privacy Policy | M42: =LEN(L42) -> 0 | N42: H1: Thank you | S42: =IF(LEN(R42)>0, _xludf.IMAGE(R42), "") | U42: =IFERROR(HYPERLINK("#Main!A"&MATCH(D41,Main!A:A,0),"Open"),HYPERLINK("#Main!A1","Open")) -> Open
A43: To Do | B43: Unassigned | C43: amc-masterclass-bookings-amc-masterclass-|-bookin | D43: https://africanmarketingconfederation.org/amc-masterclass-bookings/ | E43: https://africanmarketingconfederation.org/wp-admin/post.php?post=6816&action=elementor | F43: [Auto]: amc masterclass bookings | G43: Skip to content 0 Your Cart Your cart is empty Return to Shop Continue Shopping | H43: AMC Masterclass | Bookings – African Marketing Confederation | J43: =LEN(I43) -> 0 | K43: MISSING DESCRIPTION | M43: =LEN(L43) -> 0 | S43: =IF(LEN(R43)>0, _xludf.IMAGE(R43), "") | U43: =IFERROR(HYPERLINK("#Main!A"&MATCH(D42,Main!A:A,0),"Open"),HYPERLINK("#Main!A1","Open")) -> Open
...

Sheet FixPlan
A1: Issue Type | B1: Severity | C1: Priority Score | D1: Affected Count | E1: Affected URLs | F1: Detail Reference Tab | G1: Resolution Type | H1: URL | I1: Recommended Fix | J1: Likely Root Cause | K1: Owner | L1: Agency Owner | M1: Effort | N1: Est. Hours | O1: Est. Sprint Points | P1: Aging/Priority | Q1: Status | R1: Verified By | S1: Date Resolved | T1: Revenue Risk | U1: Action Needed | V1: Jump to Details | W1: Sprint | X1: Category | Y1: View Details | Z1: Open in Main | AA1: Hub Status (Content Hub) | AB1: BACK TO DASHBOARD
A2: Noindex Directive | B2: Critical | C2: 105 | D2: 0 | F2: Indexability | G2: Manual Content | I2: Remove unintended noindex directives on index-worthy URLs. | J2: Meta robots or X-Robots-Tag contains noindex. | K2: Dev | L2: Dev | M2: M | N2: 10 | O2: 5 | P2: Immediate (Current Sprint) | Q2: To Do | T2: High Risk | U2: Yes | V2: =HYPERLINK("#Main!A1","Open Main") -> Open Main | X2: SEO | Y2: =IFERROR(HYPERLINK("#Main!A"&MATCH(H2,Main!A:A,0),"View URL Details"),HYPERLINK("#Main!A1","View URL Details")) -> View URL Details | Z2: =IFERROR(HYPERLINK("#Main!A"&MATCH(H2,Main!A:A,0),"Open"),HYPERLINK("#Main!A1","Open")) -> Open | AA2: =IFERROR(INDEX('Content Optimization Hub'!A:A,MATCH(H2,'Content Optimization Hub'!C:C,0)),"Not in Hub") -> Not in Hub
A3: Canonical Points Elsewhere | B3: Critical | C3: 105 | D3: 0 | F3: Indexability | G3: Global Template | I3: Align canonical to preferred final URL and ensure internal links use canonical target. | J3: Canonical targets a different URL variant. | K3: Dev | L3: Dev | M3: M | N3: 10 | O3: 5 | P3: Immediate (Current Sprint) | Q3: To Do | T3: High Risk | U3: Yes | V3: =HYPERLINK("#Main!A1","Open Main") -> Open Main | X3: SEO | Y3: =IFERROR(HYPERLINK("#Main!A"&MATCH(H3,Main!A:A,0),"View URL Details"),HYPERLINK("#Main!A1","View URL Details")) -> View URL Details | Z3: =IFERROR(HYPERLINK("#Main!A"&MATCH(H3,Main!A:A,0),"Open"),HYPERLINK("#Main!A1","Open")) -> Open | AA3: =IFERROR(INDEX('Content Optimization Hub'!A:A,MATCH(H3,'Content Optimization Hub'!C:C,0)),"Not in Hub") -> Not in Hub
A4: Robots.txt Disallow Root | B4: Critical | C4: 105 | D4: 0 | F4: Technical | G4: Global Template | I4: Apply fix based on issue type and re-run audit. | J4: Template/technical implementation quality issue. | K4: Server/Host | L4: Server/Host | M4: M | N4: 10 | O4: 5 | P4: Immediate (Current Sprint) | Q4: To Do | T4: High Risk | U4: Yes | V4: =HYPERLINK("#Main!A1","Open Main") -> Open Main | X4: SEO | Y4: =IFERROR(HYPERLINK("#Main!A"&MATCH(H4,Main!A:A,0),"View URL Details"),HYPERLINK("#Main!A1","View URL Details")) -> View URL Details | Z4: =IFERROR(HYPERLINK("#Main!A"&MATCH(H4,Main!A:A,0),"Open"),HYPERLINK("#Main!A1","Open")) -> Open | AA4: =IFERROR(INDEX('Content Optimization Hub'!A:A,MATCH(H4,'Content Optimization Hub'!C:C,0)),"Not in Hub") -> Not in Hub
A5: CWV LCP Above 4.0s | B5: Critical | C5: 105 | D5: 0 | F5: Technical | G5: Global Template | I5: Apply fix based on issue type and re-run audit. | J5: Template/technical implementation quality issue. | K5: Dev | L5: Dev | M5: M | N5: 10 | O5: 5 | P5: Immediate (Current Sprint) | Q5: To Do | T5: High Risk | U5: Yes | V5: =HYPERLINK("#Main!A1","Open Main") -> Open Main | X5: SEO | Y5: =IFERROR(HYPERLINK("#Main!A"&MATCH(H5,Main!A:A,0),"View URL Details"),HYPERLINK("#Main!A1","View URL Details")) -> View URL Details | Z5: =IFERROR(HYPERLINK("#Main!A"&MATCH(H5,Main!A:A,0),"Open"),HYPERLINK("#Main!A1","Open")) -> Open | AA5: =IFERROR(INDEX('Content Optimization Hub'!A:A,MATCH(H5,'Content Optimization Hub'!C:C,0)),"Not in Hub") -> Not in Hub
A6: Broken Internal Links | B6: Critical | C6: 105 | D6: 0 | F6: Links | G6: Manual Content | I6: Update internal links to valid URLs and remove dead references. | J6: Internal links resolve to missing or error pages. | K6: Dev | L6: Dev | M6: M | N6: 10 | O6: 5 | P6: Immediate (Current Sprint) | Q6: To Do | T6: High Risk | U6: Yes | V6: =HYPERLINK("#Main!A1","Open Main") -> Open Main | X6: SEO | Y6: =IFERROR(HYPERLINK("#Main!A"&MATCH(H6,Main!A:A,0),"View URL Details"),HYPERLINK("#Main!A1","View URL Details")) -> View URL Details | Z6: =IFERROR(HYPERLINK("#Main!A"&MATCH(H6,Main!A:A,0),"Open"),HYPERLINK("#Main!A1","Open")) -> Open | AA6: =IFERROR(INDEX('Content Optimization Hub'!A:A,MATCH(H6,'Content Optimization Hub'!C:C,0)),"Not in Hub") -> Not in Hub
A7: Non-200 Status | B7: Critical | C7: 105 | D7: 2 | E7: https://africanmarketingconfederation.org/amc-conference-sponsors/ https://africanmarketingconfederation.org/amc-marketing-conference-2024/speakers-2024/ | F7: Technical | G7: Manual Content | H7: https://africanmarketingconfederation.org/amc-conference-sponsors/ | I7: Fix status code, restore page, or implement correct redirect to canonical destination. | J7: URL returns 4xx/5xx or equivalent failure. | K7: Server/Host | L7: Server/Host | M7: M | N7: 10 | O7: 5 | P7: Immediate (Current Sprint) | Q7: To Do | T7: High Risk | U7: Yes | V7: =IFERROR(HYPERLINK("#Main!A"&MATCH("https://africanmarketingconfederation.org/amc-conference-sponsors/",Main!A:A,0),"Jump to Main"),HYPERLINK("#Main!A1","Open Main")) -> Open Main | X7: SEO | Y7: =IFERROR(HYPERLINK("#Main!A"&MATCH(H7,Main!A:A,0),"View URL Details"),HYPERLINK("#Main!A1","View URL Details")) -> View URL Details | Z7: =IFERROR(HYPERLINK("#Main!A"&MATCH(H7,Main!A:A,0),"Open"),HYPERLINK("#Main!A1","Open")) -> Open | AA7: =IFERROR(INDEX('Content Optimization Hub'!A:A,MATCH(H7,'Content Optimization Hub'!C:C,0)),"Not in Hub") -> Not in Hub
A8: Missing Title | B8: Critical | C8: 105 | D8: 2 | E8: https://africanmarketingconfederation.org/amc-conference-sponsors/ https://africanmarketingconfederation.org/amc-marketing-conference-2024/speakers-2024/ | F8: Technical | G8: Manual Content | H8: https://africanmarketingconfederation.org/amc-conference-sponsors/ | I8: Add unique descriptive title on affected template/page type. | J8: Template/page missing title tag. | K8: Copy Writer | L8: Copy Writer | M8: M | N8: 10 | O8: 5 | P8: Immediate (Current Sprint) | Q8: To Do | T8: High Risk | U8: Yes | V8: =IFERROR(HYPERLINK("#Main!A"&MATCH("https://africanmarketingconfederation.org/amc-conference-sponsors/",Main!A:A,0),"Jump to Main"),HYPERLINK("#Main!A1","Open Main")) -> Open Main | X8: SEO | Y8: =IFERROR(HYPERLINK("#Main!A"&MATCH(H8,Main!A:A,0),"View URL Details"),HYPERLINK("#Main!A1","View URL Details")) -> View URL Details | Z8: =IFERROR(HYPERLINK("#Main!A"&MATCH(H8,Main!A:A,0),"Open"),HYPERLINK("#Main!A1","Open")) -> Open | AA8: =IFERROR(INDEX('Content Optimization Hub'!A:A,MATCH(H8,'Content Optimization Hub'!C:C,0)),"Not in Hub") -> Not in Hub
