Workbook

Sheet Dashboard
A1: Metric | B1: Technical Audit Dashboard
A2: URLs Crawled | B2: Executive SEO Performance Report
A3: Pass Rate (%) | B3: 0
A4: Critical URL Count | B4: EXECUTIVE METRICS | C4: Value
A5: Warning URL Count | B5: =HYPERLINK("#Main!A1","Total URLs") | C5: 85
A6: Status Distribution | B6: =HYPERLINK("#Summary!A1","Overall Health Score") | C6: =IFERROR(56.81/100,0)
A7: Score Bands | B7: =HYPERLINK("#Summary!A1","SEO Pass Rate %") | C7: =IFERROR(0/85,0)
B8: =HYPERLINK("#Technical!A1","Pass URLs") | C8: 0
B9: =HYPERLINK("#FixPlan!A1","Critical URLs") | C9: 4
A10: Issue Type | B10: =HYPERLINK("#Technical!A1","Warning URLs") | C10: 166 | F10: Status Class | G10: Count | I10: Score Band | J10: Count
A11: No Compression Header | B11: =HYPERLINK("#Technical!A1","Error Rate % (4xx/5xx)") | C11: =IFERROR(2/85,0) | F11: 2xx | G11: 83 | I11: 90-100 | J11: 0
A12: No Cache-Control Header | B12: =HYPERLINK("#Technical!A1","Crawl Success Rate % (2xx)") | C12: =IFERROR(83/85,0) | F12: 4xx | G12: 2 | I12: 70-89 | J12: 0
A13: No ETag Header | B13: =HYPERLINK("#Technical!A1","Critical URL Rate %") | C13: =IFERROR(4/85,0) | I13: <70 | J13: 85
A14: No FAQ/QA Schema | B14: =HYPERLINK("#Technical!A1","Warning URL Rate %") | C14: =IFERROR(166/85,0)
A15: No Question Headings | B15: Info | C15: 85
A16: No Answer-Friendly Structure | B16: Status | C16: Count
A17: No 40-60 Word Answer Paragraphs | B17: 200 OK | C17: 83
A18: Low AEO Readiness Score | B18: 3xx Redirects | C18: 0
A19: Thin Content | B19: 4xx Errors | C19: 2
A20: Missing H1 | B20: 5xx Errors | C20: 0
B21: Other | C21: 0
B23: Severity | C23: Count
B24: Critical | C24: 5
B25: Warning | C25: 11
B26: Medium | C26: 0
B27: Low | C27: 10
B29: PRIORITY SNAPSHOT | C29: Value
B30: Top Blocking Issue | C30: No Compression Header
B31: Top Issue Affected URLs | C31: 85
B32: 4xx/5xx URLs | C32: 2
B33: Avg TTFB (ms) | C33: 252.37
B35: Quick Navigation | C35: Open
B36: Fix Plan | C36: =HYPERLINK("#FixPlan!A1","Open")
B37: Main URL Data | C37: =HYPERLINK("#Main!A1","Open")
B38: Technical Diagnostics | C38: =HYPERLINK("#Technical!A1","Open")
B39: Indexability | C39: =HYPERLINK("#Indexability!A1","Open")
B40: AEO Opportunities | C40: =HYPERLINK("#AEO!A1","Open")
B41: AIOSEO Action Queue | C41: =HYPERLINK("#AIOSEO!A1","Open")
B42: TOP ISSUES TO FIX FIRST | C42: Affected URLs
B43: =HYPERLINK("#FixPlan!A9","Low AEO Readiness Score") | C43: 85
...

Sheet Legend
A1: Section | B1: Term | C1: Meaning | D1: Values/Threshold | E1: Related Tabs | F1: BACK TO DASHBOARD
A2: Severity | B2: Critical | C2: High-impact SEO blocker that should be fixed first. | D2: Immediate action | E2: Summary, FixPlan, Technical
A3: Severity | B3: Warning | C3: Out-of-best-practice issue likely affecting performance. | D3: Plan next sprint | E3: Summary, FixPlan, Technical
A4: Severity | B4: Info | C4: Optimization opportunity or context signal. | D4: Backlog/monitor | E4: Summary, Technical
A5: Scoring | B5: SEO Health Score | C5: Weighted technical SEO quality score per URL. | D5: >=90 green, 70-89 yellow, <70 red | E5: Technical, Priority URLs, Dashboard
A6: Scoring | B6: AEO Readiness Score | C6: Answer Engine Optimization readiness score per URL. | D6: >=80 strong, 60-79 good, 40-59 fair | E6: AEO
A7: Indexing | B7: Indexability Reason | C7: Primary reason URL may not be indexed. | D7: Noindex, non-200, canonical mismatch | E7: Indexability, Technical
A8: Links | B8: Broken Internal Links Count | C8: Internal links returning 4xx/5xx or equivalent failures. | D8: >0 flagged | E8: Links, LinksDetail, Priority URLs
A9: Content | B9: Word Count Band | C9: Body content depth class. | D9: Thin / OK / Strong | E9: Content
A10: AEO | B10: Question Heading Count | C10: Headings phrased as questions to match answer intent. | D10: Higher is generally better | E10: AEO
A11: Color Key | B11: Green | C11: Pass / aligned with best practice. | D11: Good | E11: All
A12: Color Key | B12: Yellow | C12: Warning / needs attention soon. | D12: Medium risk | E12: All
A13: Color Key | B13: Red | C13: Failure / high-priority issue. | D13: High risk | E13: All
A14: Color Key | B14: Purple | C14: Informational edge-case or AEO category signal. | D14: Context | E14: All

Sheet Summary
A1: Section | B1: Severity | C1: Issue | D1: Affected URL Count | E1: Reference Tab | F1: Affected URLs (sample) | G1: BACK TO DASHBOARD
A2: AEO Opportunities | B2: Warning | C2: Low AEO Readiness Score | D2: 85 | E2: AEO | F2: https://africanmarketingconfederation.org/ | https://africanmarketingconfederation.org/publication-download-list/ | https://africanmarketingconfederation.org/launch-event-2026-amc-conference/ | https://africanmarketingconfederation.org/publications-2/ | https://africanmarketingconfederation.org/certified-professional-marketer-africa/ | https://africanmarketingconfederation.org/chartered-marketer-africa/ | https://africanmarketingconfederation.org/amc-conference-2026/ | https://africanmarketingconfederation.org/education/ | https://africanmarketingconfederation.org/awards-2026/ | https://africanmarketingconfederation.org/contact-us/ | https://africanmarketingconfederation.org/news-articles/ | https://africanmarketingconfederation.org/african-marketing-confederation-tourism-chapter/ | https://africanmarketingconfederation.org/sub-committees/ | https://africanmarketingconfederation.org/members/ | https://africanmarketingconfederation.org/about-us/ | https://africanmarketingconfederation.org/awards-2026-1/ | https://africanmarketingconfederation.org/awards-2026-test/ | https://africanmarketingconfederation.org/amc-conference-2026-awards-nominations-thank-you/ | https://africanmarketingconfederation.org/speakers-2025/ | https://africanmarketingconfederation.org/amc-conference-2026-zambia-thank-you/ | https://africanmarketingconfederation.org/amc-launch-event-zambia-thank-you-2026/ | https://africanmarketingconfederation.org/amc-marketing-conference-2024/awards-2025/ | https://africanmarketingconfederation.org/amc-conference-2025-highlights/ | https://africanmarketingconfederation.org/amc-conference-2022/ | https://africanmarketingconfederation.org/amc-conference-2023/gallery/ || Full list: see AEO tab
A3: AEO Opportunities | B3: Info | C3: No 40-60 Word Answer Paragraphs | D3: 85 | E3: AEO | F3: https://africanmarketingconfederation.org/ | https://africanmarketingconfederation.org/publication-download-list/ | https://africanmarketingconfederation.org/launch-event-2026-amc-conference/ | https://africanmarketingconfederation.org/publications-2/ | https://africanmarketingconfederation.org/certified-professional-marketer-africa/ | https://africanmarketingconfederation.org/chartered-marketer-africa/ | https://africanmarketingconfederation.org/amc-conference-2026/ | https://africanmarketingconfederation.org/education/ | https://africanmarketingconfederation.org/awards-2026/ | https://africanmarketingconfederation.org/contact-us/ | https://africanmarketingconfederation.org/news-articles/ | https://africanmarketingconfederation.org/african-marketing-confederation-tourism-chapter/ | https://africanmarketingconfederation.org/sub-committees/ | https://africanmarketingconfederation.org/members/ | https://africanmarketingconfederation.org/about-us/ | https://africanmarketingconfederation.org/awards-2026-1/ | https://africanmarketingconfederation.org/awards-2026-test/ | https://africanmarketingconfederation.org/amc-conference-2026-awards-nominations-thank-you/ | https://africanmarketingconfederation.org/speakers-2025/ | https://africanmarketingconfederation.org/amc-conference-2026-zambia-thank-you/ | https://africanmarketingconfederation.org/amc-launch-event-zambia-thank-you-2026/ | https://africanmarketingconfederation.org/amc-marketing-conference-2024/awards-2025/ | https://africanmarketingconfederation.org/amc-conference-2025-highlights/ | https://africanmarketingconfederation.org/amc-conference-2022/ | https://africanmarketingconfederation.org/amc-conference-2023/gallery/ || Full list: see AEO tab
A4: AEO Opportunities | B4: Info | C4: No Answer-Friendly Structure | D4: 85 | E4: AEO | F4: https://africanmarketingconfederation.org/ | https://africanmarketingconfederation.org/publication-download-list/ | https://africanmarketingconfederation.org/launch-event-2026-amc-conference/ | https://africanmarketingconfederation.org/publications-2/ | https://africanmarketingconfederation.org/certified-professional-marketer-africa/ | https://africanmarketingconfederation.org/chartered-marketer-africa/ | https://africanmarketingconfederation.org/amc-conference-2026/ | https://africanmarketingconfederation.org/education/ | https://africanmarketingconfederation.org/awards-2026/ | https://africanmarketingconfederation.org/contact-us/ | https://africanmarketingconfederation.org/news-articles/ | https://africanmarketingconfederation.org/african-marketing-confederation-tourism-chapter/ | https://africanmarketingconfederation.org/sub-committees/ | https://africanmarketingconfederation.org/members/ | https://africanmarketingconfederation.org/about-us/ | https://africanmarketingconfederation.org/awards-2026-1/ | https://africanmarketingconfederation.org/awards-2026-test/ | https://africanmarketingconfederation.org/amc-conference-2026-awards-nominations-thank-you/ | https://africanmarketingconfederation.org/speakers-2025/ | https://africanmarketingconfederation.org/amc-conference-2026-zambia-thank-you/ | https://africanmarketingconfederation.org/amc-launch-event-zambia-thank-you-2026/ | https://africanmarketingconfederation.org/amc-marketing-conference-2024/awards-2025/ | https://africanmarketingconfederation.org/amc-conference-2025-highlights/ | https://africanmarketingconfederation.org/amc-conference-2022/ | https://africanmarketingconfederation.org/amc-conference-2023/gallery/ || Full list: see AEO tab
A5: AEO Opportunities | B5: Info | C5: No FAQ/QA Schema | D5: 85 | E5: AEO | F5: https://africanmarketingconfederation.org/ | https://africanmarketingconfederation.org/publication-download-list/ | https://africanmarketingconfederation.org/launch-event-2026-amc-conference/ | https://africanmarketingconfederation.org/publications-2/ | https://africanmarketingconfederation.org/certified-professional-marketer-africa/ | https://africanmarketingconfederation.org/chartered-marketer-africa/ | https://africanmarketingconfederation.org/amc-conference-2026/ | https://africanmarketingconfederation.org/education/ | https://africanmarketingconfederation.org/awards-2026/ | https://africanmarketingconfederation.org/contact-us/ | https://africanmarketingconfederation.org/news-articles/ | https://africanmarketingconfederation.org/african-marketing-confederation-tourism-chapter/ | https://africanmarketingconfederation.org/sub-committees/ | https://africanmarketingconfederation.org/members/ | https://africanmarketingconfederation.org/about-us/ | https://africanmarketingconfederation.org/awards-2026-1/ | https://africanmarketingconfederation.org/awards-2026-test/ | https://africanmarketingconfederation.org/amc-conference-2026-awards-nominations-thank-you/ | https://africanmarketingconfederation.org/speakers-2025/ | https://africanmarketingconfederation.org/amc-conference-2026-zambia-thank-you/ | https://africanmarketingconfederation.org/amc-launch-event-zambia-thank-you-2026/ | https://africanmarketingconfederation.org/amc-marketing-conference-2024/awards-2025/ | https://africanmarketingconfederation.org/amc-conference-2025-highlights/ | https://africanmarketingconfederation.org/amc-conference-2022/ | https://africanmarketingconfederation.org/amc-conference-2023/gallery/ || Full list: see AEO tab
A6: AEO Opportunities | B6: Info | C6: No Question Headings | D6: 85 | E6: AEO | F6: https://africanmarketingconfederation.org/ | https://africanmarketingconfederation.org/publication-download-list/ | https://africanmarketingconfederation.org/launch-event-2026-amc-conference/ | https://africanmarketingconfederation.org/publications-2/ | https://africanmarketingconfederation.org/certified-professional-marketer-africa/ | https://africanmarketingconfederation.org/chartered-marketer-africa/ | https://africanmarketingconfederation.org/amc-conference-2026/ | https://africanmarketingconfederation.org/education/ | https://africanmarketingconfederation.org/awards-2026/ | https://africanmarketingconfederation.org/contact-us/ | https://africanmarketingconfederation.org/news-articles/ | https://africanmarketingconfederation.org/african-marketing-confederation-tourism-chapter/ | https://africanmarketingconfederation.org/sub-committees/ | https://africanmarketingconfederation.org/members/ | https://africanmarketingconfederation.org/about-us/ | https://africanmarketingconfederation.org/awards-2026-1/ | https://africanmarketingconfederation.org/awards-2026-test/ | https://africanmarketingconfederation.org/amc-conference-2026-awards-nominations-thank-you/ | https://africanmarketingconfederation.org/speakers-2025/ | https://africanmarketingconfederation.org/amc-conference-2026-zambia-thank-you/ | https://africanmarketingconfederation.org/amc-launch-event-zambia-thank-you-2026/ | https://africanmarketingconfederation.org/amc-marketing-conference-2024/awards-2025/ | https://africanmarketingconfederation.org/amc-conference-2025-highlights/ | https://africanmarketingconfederation.org/amc-conference-2022/ | https://africanmarketingconfederation.org/amc-conference-2023/gallery/ || Full list: see AEO tab
A7: AEO Opportunities | F7: Detailed rows: see AEO tab
A8: Issue Counts | B8: Critical | C8: Non-200 Status | D8: 2 | E8: Technical | F8: https://africanmarketingconfederation.org/amc-marketing-conference-2024/speakers-2024/ | https://africanmarketingconfederation.org/amc-conference-sponsors/ || Full list: see Technical/Links/Indexability tabs
A9: Issue Counts | B9: Critical | C9: Broken Internal Links | D9: 0 | E9: Links | F9: || Full list: see Technical/Links/Indexability tabs
A10: Issue Counts | B10: Critical | C10: Canonical Points Elsewhere | D10: 0 | E10: Indexability | F10: || Full list: see Technical/Links/Indexability tabs
A11: Issue Counts | B11: Critical | C11: Noindex Directive | D11: 0 | E11: Indexability | F11: || Full list: see Technical/Links/Indexability tabs
A12: Issue Counts | B12: Critical | C12: Robots.txt Disallow Root | D12: 0 | E12: Technical | F12: || Full list: see Technical/Links/Indexability tabs
A13: Issue Counts | B13: Warning | C13: Low AEO Readiness Score | D13: 85 | E13: AEO | F13: https://africanmarketingconfederation.org/ | https://africanmarketingconfederation.org/publication-download-list/ | https://africanmarketingconfederation.org/launch-event-2026-amc-conference/ | https://africanmarketingconfederation.org/publications-2/ | https://africanmarketingconfederation.org/certified-professional-marketer-africa/ | https://africanmarketingconfederation.org/chartered-marketer-africa/ | https://africanmarketingconfederation.org/amc-conference-2026/ | https://africanmarketingconfederation.org/education/ | https://africanmarketingconfederation.org/awards-2026/ | https://africanmarketingconfederation.org/contact-us/ | https://africanmarketingconfederation.org/news-articles/ | https://africanmarketingconfederation.org/african-marketing-confederation-tourism-chapter/ | https://africanmarketingconfederation.org/sub-committees/ | https://africanmarketingconfederation.org/members/ | https://africanmarketingconfederation.org/about-us/ | https://africanmarketingconfederation.org/awards-2026-1/ | https://africanmarketingconfederation.org/awards-2026-test/ | https://africanmarketingconfederation.org/amc-conference-2026-awards-nominations-thank-you/ | https://africanmarketingconfederation.org/speakers-2025/ | https://africanmarketingconfederation.org/amc-conference-2026-zambia-thank-you/ | https://africanmarketingconfederation.org/amc-launch-event-zambia-thank-you-2026/ | https://africanmarketingconfederation.org/amc-marketing-conference-2024/awards-2025/ | https://africanmarketingconfederation.org/amc-conference-2025-highlights/ | https://africanmarketingconfederation.org/amc-conference-2022/ | https://africanmarketingconfederation.org/amc-conference-2023/gallery/ || Full list: see Technical/Links/Indexability tabs
A14: Issue Counts | B14: Warning | C14: Thin Content | D14: 41 | E14: Technical | F14: https://africanmarketingconfederation.org/publication-download-list/ | https://africanmarketingconfederation.org/launch-event-2026-amc-conference/ | https://africanmarketingconfederation.org/publications-2/ | https://africanmarketingconfederation.org/about-us/ | https://africanmarketingconfederation.org/amc-conference-2026-awards-nominations-thank-you/ | https://africanmarketingconfederation.org/amc-conference-2026-zambia-thank-you/ | https://africanmarketingconfederation.org/amc-launch-event-zambia-thank-you-2026/ | https://africanmarketingconfederation.org/amc-conference-2023/gallery/ | https://africanmarketingconfederation.org/amc-marketing-conference-2024/amc-programme-2025/ | https://africanmarketingconfederation.org/amc-conference-2022-prospectus/ | https://africanmarketingconfederation.org/test-payment-gate/ | https://africanmarketingconfederation.org/amc-marketing-conference-2024/amc-conference-2025-ghana-sponsors/ | https://africanmarketingconfederation.org/amc-forum-payments/ | https://africanmarketingconfederation.org/checkout/ | https://africanmarketingconfederation.org/amc-marketing-conference-2024/amc-speakers-presentations-2024/ | https://africanmarketingconfederation.org/amc-marketing-conference-2024/testimony-thank-you-page/ | https://africanmarketingconfederation.org/thank-you-for-registering-2024-registrations/ | https://africanmarketingconfederation.org/download-prospectus-2024/ | https://africanmarketingconfederation.org/thank-you-for-registering-2024-registrations-kenya/ | https://africanmarketingconfederation.org/elementor-20341/ | https://africanmarketingconfederation.org/chartered-marketer-africa-final-submission-fee/ | https://africanmarketingconfederation.org/chartered-marketer-africa-programme-fee/ | https://africanmarketingconfederation.org/download-brochure/ | https://africanmarketingconfederation.org/thank-you-for-the-nomination-2024/ | https://africanmarketingconfederation.org/thank-you-for-the-submission-2024/ || Full list: see Technical/Links/Indexability tabs
A15: Issue Counts | B15: Warning | C15: Missing H1 | D15: 32 | E15: Technical | F15: https://africanmarketingconfederation.org/publication-download-list/ | https://africanmarketingconfederation.org/certified-professional-marketer-africa/ | https://africanmarketingconfederation.org/education/ | https://africanmarketingconfederation.org/amc-conference-2022/ | https://africanmarketingconfederation.org/amc-conference-2022-prospectus/ | https://africanmarketingconfederation.org/test-payment-gate/ | https://africanmarketingconfederation.org/amc-forum-payments/ | https://africanmarketingconfederation.org/checkout/ | https://africanmarketingconfederation.org/thank-you-for-registering-2024-registrations/ | https://africanmarketingconfederation.org/download-prospectus-2024/ | https://africanmarketingconfederation.org/thank-you-for-registering-2024-registrations-kenya/ | https://africanmarketingconfederation.org/subscribe/ | https://africanmarketingconfederation.org/elementor-20341/ | https://africanmarketingconfederation.org/download-brochure/ | https://africanmarketingconfederation.org/thank-you-for-the-nomination-2024/ | https://africanmarketingconfederation.org/thank-you-for-the-submission-2024/ | https://africanmarketingconfederation.org/elementor-16548/ | https://africanmarketingconfederation.org/chartered-marketer-africa-thank-you/ | https://africanmarketingconfederation.org/amc-conference-2023/amc-awards-book-now/ | https://africanmarketingconfederation.org/thank-you-for-subscribing/ | https://africanmarketingconfederation.org/amc-conference-2023/book-now-thank-you/ | https://africanmarketingconfederation.org/upcoming-events/ | https://africanmarketingconfederation.org/amc-masterclass/ | https://africanmarketingconfederation.org/amc-relaunch-programme/ | https://africanmarketingconfederation.org/amc-masterclass-thank-you/ || Full list: see Technical/Links/Indexability tabs
A16: Issue Counts | B16: Warning | C16: Multiple H1 | D16: 18 | E16: Technical | F16: https://africanmarketingconfederation.org/ | https://africanmarketingconfederation.org/awards-2026/ | https://africanmarketingconfederation.org/contact-us/ | https://africanmarketingconfederation.org/african-marketing-confederation-tourism-chapter/ | https://africanmarketingconfederation.org/awards-2026-1/ | https://africanmarketingconfederation.org/awards-2026-test/ | https://africanmarketingconfederation.org/amc-conference-2026-awards-nominations-thank-you/ | https://africanmarketingconfederation.org/speakers-2025/ | https://africanmarketingconfederation.org/amc-conference-2026-zambia-thank-you/ | https://africanmarketingconfederation.org/amc-launch-event-zambia-thank-you-2026/ | https://africanmarketingconfederation.org/amc-conference-2025-highlights/ | https://africanmarketingconfederation.org/amc-conference-2024-recap/ | https://africanmarketingconfederation.org/amc-marketing-conference-2024/amc-programme-2025/ | https://africanmarketingconfederation.org/amc-conference-2025/ | https://africanmarketingconfederation.org/amc-awards-2024/ | https://africanmarketingconfederation.org/amc-marketing-conference-2024/amc-speakers-presentations-2024/ | https://africanmarketingconfederation.org/amc-marketing-conference-2024/testimony-thank-you-page/ | https://africanmarketingconfederation.org/privacy-policy/ || Full list: see Technical/Links/Indexability tabs
A17: Issue Counts | B17: Warning | C17: Missing Meta Description | D17: 5 | E17: Technical | F17: https://africanmarketingconfederation.org/amc-marketing-conference-2024/speakers-2024/ | https://africanmarketingconfederation.org/amc-conference-sponsors/ | https://africanmarketingconfederation.org/elementor-20341/ | https://africanmarketingconfederation.org/amc-conference-2023/amc-awards-book-now/ | https://africanmarketingconfederation.org/amc-masterclass-bookings/ || Full list: see Technical/Links/Indexability tabs
A18: Issue Counts | B18: Warning | C18: Missing Title | D18: 2 | E18: Technical | F18: https://africanmarketingconfederation.org/amc-marketing-conference-2024/speakers-2024/ | https://africanmarketingconfederation.org/amc-conference-sponsors/ || Full list: see Technical/Links/Indexability tabs
A19: Issue Counts | B19: Warning | C19: Canonical Missing | D19: 0 | E19: Indexability | F19: || Full list: see Technical/Links/Indexability tabs
... A33: Issue Counts | B33: Info | C33: Uses URL Parameters | D33: 0 | E33: Technical | F33: || Full list: see Technical/Links/Indexability tabs
A34: Issue Counts
A35: Top 10 Critical URLs
A36: Top 10 Critical URLs | B36: Critical | C36: #1 https://africanmarketingconfederation.org/amc-marketing-conference-2024/speakers-2024/ | D36: 1 | E36: Priority URLs | F36: Non-200 Status | Missing Title | Missing Meta Description | Low AEO Readiness Score | No Compression Header | No Cache-Control Header | No ETag Header | No FAQ/QA Schema | No Question Headings | No Answer-Friendly Structure | No 40-60 Word Answer Paragraphs
A37: Top 10 Critical URLs | B37: Critical | C37: #2 https://africanmarketingconfederation.org/amc-conference-sponsors/ | D37: 1 | E37: Priority URLs | F37: Non-200 Status | Missing Title | Missing Meta Description | Low AEO Readiness Score | No Compression Header | No Cache-Control Header | No ETag Header | No FAQ/QA Schema | No Question Headings | No Answer-Friendly Structure | No 40-60 Word Answer Paragraphs
A38: Top Issues by Template
A39: Top Issues by Template | B39: Info | C39: amc-conference-2023 -> Low AEO Readiness Score | D39: 10 | E39: TemplateClusters
A40: Top Issues by Template | B40: Info | C40: amc-conference-2023 -> No Compression Header | D40: 10 | E40: TemplateClusters
A41: Top Issues by Template | B41: Info | C41: amc-conference-2023 -> No Cache-Control Header | D41: 10 | E41: TemplateClusters
A42: Top Issues by Template | B42: Info | C42: amc-conference-2023 -> No ETag Header | D42: 10 | E42: TemplateClusters
A43: Top Issues by Template | B43: Info | C43: amc-conference-2023 -> No FAQ/QA Schema | D43: 10 | E43: TemplateClusters
A44: Top Issues by Template | B44: Info | C44: amc-conference-2023 -> No Question Headings | D44: 10 | E44: TemplateClusters
A45: Top Issues by Template | B45: Info | C45: amc-conference-2023 -> No Answer-Friendly Structure | D45: 10 | E45: TemplateClusters
A46: Top Issues by Template | B46: Info | C46: amc-conference-2023 -> No 40-60 Word Answer Paragraphs | D46: 10 | E46: TemplateClusters
A47: Top Issues by Template | B47: Info | C47: amc-marketing-conference-2024 -> Low AEO Readiness Score | D47: 8 | E47: TemplateClusters
A48: Top Issues by Template | B48: Info | C48: amc-marketing-conference-2024 -> No Compression Header | D48: 8 | E48: TemplateClusters
A49: Top Issues by Template | B49: Info | C49: amc-marketing-conference-2024 -> No Cache-Control Header | D49: 8 | E49: TemplateClusters
A50: Top Issues by Template | B50: Info | C50: amc-marketing-conference-2024 -> No ETag Header | D50: 8 | E50: TemplateClusters
... A58: Top Issues by Template | B58: Info | C58: amc-forum-mombasa -> Low AEO Readiness Score | D58: 2 | E58: TemplateClusters

Sheet Main
A1: URL | B1: Status Code | C1: Indexability | D1: Load Time (s) | E1: Title | F1: Meta Description | G1: Word Count (Body) | H1: SEO Health Score | I1: Severity Badge | J1: Title Length | K1: Meta Desc Length | L1: OG-Image | M1: Has Valid JSON-LD | N1: H1 Content | O1: H1 Length | P1: H2 Content | Q1: H2 Length | R1: H3 Content | S1: H3 Length | T1: H4 Content | U1: H4 Length | V1: H5 Content | W1: H5 Length | X1: H6 Content | Y1: H6 Length | Z1: Health Icon | AA1: Technical View | AB1: BACK TO DASHBOARD
A2: https://africanmarketingconfederation.org/amc-conference-sponsors/ | B2: 404 | C2: Indexable | D2: 3.974 | E2: African Marketing Confederation - Uniting Marketers for Excellence | F2: 0 | G2: 0 | H2: 24 | I2: Critical | J2: 0 | K2: 0 | M2: FALSE | O2: 0 | Q2: 0 | S2: 0 | U2: 0 | W2: 0 | X2: 24 | Y2: 0 | Z2: FAIL 🔴 | AA2: =IFERROR(HYPERLINK("#Technical!A"&MATCH(A2,Technical!A:A,0),"Open Technical"),HYPERLINK("#Technical!A1","Open Technical"))
A3: https://africanmarketingconfederation.org/amc-marketing-conference-2024/speakers-2024/ | B3: 404 | C3: Indexable | D3: 3.906 | E3: Publication Download List – African Marketing Confederation | F3: 0 | G3: 0 | H3: 24 | I3: Critical | J3: 0 | K3: 0 | M3: FALSE | O3: 0 | Q3: 0 | S3: 0 | U3: 0 | W3: 0 | X3: 24 | Y3: 0 | Z3: FAIL 🔴 | AA3: =IFERROR(HYPERLINK("#Technical!A"&MATCH(A3,Technical!A:A,0),"Open Technical"),HYPERLINK("#Technical!A1","Open Technical"))
A4: https://africanmarketingconfederation.org/ | B4: 200 | C4: Indexable | D4: 0.067 | E4: African Marketing Confederation - Uniting Marketers for Excellence | F4: The African Marketing Confederation is the ground-breaking Pan-African body driving the development of top marketing standards across Africa and beyond. | G4: 1105 | H4: 59 | I4: Warning | J4: 66 | K4: 152 | M4: FALSE | O4: 0 | Q4: 0 | S4: 0 | U4: 0 | W4: 0 | X4: 59 | Y4: 0 | Z4: WARN 🟡 | AA4: =IFERROR(HYPERLINK("#Technical!A"&MATCH(A4,Technical!A:A,0),"Open Technical"),HYPERLINK("#Technical!A1","Open Technical"))
A5: https://africanmarketingconfederation.org/about-us/ | B5: 200 | C5: Indexable | D5: 0.054 | E5: African Marketing Confederation – The Leading Marketing Professional Body – African Marketing Confederation | F5: ABOUT The African Marketing Confederation​ The African Marketing Confederation is the ground-breaking Pan African body of marketing professionals spearheading the ongoing development of the highest possible standards of marketing across Africa. Founded in 2011, the AMC is a collaboration between the African national marketing bodies and associations to exchange expertise and information, and to promote | G5: 283 | H5: 59 | I5: Warning | J5: 107 | K5: 405 | M5: FALSE | O5: 0 | Q5: 0 | S5: 0 | U5: 0 | W5: 0 | X5: 59 | Y5: 0 | Z5: WARN 🟡 | AA5: =IFERROR(HYPERLINK("#Technical!A"&MATCH(A5,Technical!A:A,0),"Open Technical"),HYPERLINK("#Technical!A1","Open Technical"))
A6: https://africanmarketingconfederation.org/african-marketing-confederation-tourism-chapter/ | B6: 200 | C6: Indexable | D6: 0.042 | E6: African Marketing Confederation Tourism Chapter – African Marketing Confederation | F6: African Marketing Confederation Tourism Chapter Shaping Africa’s Tourism Narrative Through Strategic Marketing Tourism is one of Africa’s most powerful economic engines - generating jobs, stimulating investment, and fostering cultural exchange.The African Marketing Confederation is proud to launch the Tourism Chapter, a bold initiative to elevate African tourism through the lens of world-class marketing. Launched at the | G6: 449 | H6: 59 | I6: Warning | J6: 81 | K6: 423 | M6: FALSE | O6: 0 | Q6: 0 | S6: 0 | U6: 0 | W6: 0 | X6: 59 | Y6: 0 | Z6: WARN 🟡 | AA6: =IFERROR(HYPERLINK("#Technical!A"&MATCH(A6,Technical!A:A,0),"Open Technical"),HYPERLINK("#Technical!A1","Open Technical"))
A7: https://africanmarketingconfederation.org/amc-awards-2024/ | B7: 200 | C7: Indexable | D7: 0.056 | E7: AMC Awards 2024 – African Marketing Confederation | F7: NOMINATIONS are Open ! AMC Awards The African Marketing Confederation Awards event is held annually as part of the African Marketing Confederation Forum. This distinguished event celebrates and acknowledges outstanding marketing campaigns and the visionary individuals behind them. The awards presented honor not only the groundbreaking strategies and creative brilliance that set these campaigns apart but | G7: 1672 | H7: 59 | I7: Warning | J7: 49 | K7: 406 | M7: FALSE | O7: 0 | Q7: 0 | S7: 0 | U7: 0 | W7: 0 | X7: 59 | Y7: 0 | Z7: WARN 🟡 | AA7: =IFERROR(HYPERLINK("#Technical!A"&MATCH(A7,Technical!A:A,0),"Open Technical"),HYPERLINK("#Technical!A1","Open Technical"))
A8: https://africanmarketingconfederation.org/amc-conference-2022-prospectus/ | B8: 200 | C8: Indexable | D8: 0.079 | E8: AMC Conference 2022 – Prospectus – African Marketing Confederation | F8: AMC Conference 2022 23 - 24 March 2022 Navigating Africa's Unique Marketing Mix BOOK NOW Days Hours Minutes Seconds download prospectus To download the AMC 2022 Conference Prospectus please complete the form below: First Name Last Name Email Mobile Company I've read and agree to the Privacy Policy BOOK NOW FOR THE AMC CONFERENCE 2022 | G8: 164 | H8: 49 | I8: Warning | J8: 66 | K8: 335 | M8: FALSE | O8: 0 | Q8: 0 | S8: 0 | U8: 0 | W8: 0 | X8: 49 | Y8: 0 | Z8: WARN 🟡 | AA8: =IFERROR(HYPERLINK("#Technical!A"&MATCH(A8,Technical!A:A,0),"Open Technical"),HYPERLINK("#Technical!A1","Open Technical"))
A9: https://africanmarketingconfederation.org/amc-conference-2022-thank-you/ | B9: 200 | C9: Indexable | D9: 0.051 | E9: AMC Conference 2022 – Thank You – African Marketing Confederation | F9: AMC Conference 2022 23 - 24 March 2022 Navigating Africa's Unique Marketing Mix ENQUIRE NOW Days Hours Minutes Seconds Success! Thank you for completing the enquiry form. Our team will contact you shortly! × Dismiss alert The AMC Conference is the must attend Pan African event for marketing professionals. It will focus on solutions for | G9: 411 | H9: 59 | I9: Warning | J9: 65 | K9: 337 | M9: FALSE | O9: 0 | Q9: 0 | S9: 0 | U9: 0 | W9: 0 | X9: 59 | Y9: 0 | Z9: WARN 🟡 | AA9: =IFERROR(HYPERLINK("#Technical!A"&MATCH(A9,Technical!A:A,0),"Open Technical"),HYPERLINK("#Technical!A1","Open Technical"))
A10: https://africanmarketingconfederation.org/amc-conference-2022/ | B10: 200 | C10: Indexable | D10: 0.055 | E10: AMC Conference 2022 – African Marketing Confederation | F10: corinna kopf onlyfans leaks AMC Conference 2022 Thank you for attending19 - 22 October 2022 The African Marketing Confederation's Annual Conference brought together the best collection of marketing leaders from top companies, marketing bodies and associations to share tactics and best practices on how to build the next generation of marketing. Event Highlights Thank you for Attending! | G10: 376 | H10: 59 | I10: Warning | J10: 53 | K10: 387 | M10: FALSE | O10: 0 | Q10: 0 | S10: 0 | U10: 0 | W10: 0 | X10: 59 | Y10: 0 | Z10: WARN 🟡 | AA10: =IFERROR(HYPERLINK("#Technical!A"&MATCH(A10,Technical!A:A,0),"Open Technical"),HYPERLINK("#Technical!A1","Open Technical"))
A11: https://africanmarketingconfederation.org/amc-conference-2023/ | B11: 200 | C11: Indexable | D11: 0.051 | E11: AMC Conference 2023 – African Marketing Confederation | F11: AMC Conference 6 - 9 September 2023 Imperial Botanical Beach Hotel, Entebbe, Uganda Thank you for joining us! View Presentations 2nd Annual African Marketing Confederation Conference Africa's $3.4 trillion Economy: Opportunities for Marketers Welcome to the Recap of the 2nd Annual African Marketing Conference: Unveiling Africa's $3.4 Trillion EconomyOur conference was a remarkable exploration of | G11: 434 | H11: 69 | I11: Warning | J11: 53 | K11: 398 | M11: FALSE | O11: 0 | Q11: 0 | S11: 0 | U11: 0 | W11: 0 | X11: 69 | Y11: 0 | Z11: WARN 🟡 | AA11: =IFERROR(HYPERLINK("#Technical!A"&MATCH(A11,Technical!A:A,0),"Open Technical"),HYPERLINK("#Technical!A1","Open Technical"))
A12: https://africanmarketingconfederation.org/amc-conference-2023/amc-awards-book-now/ | B12: 200 | C12: Indexable | D12: 0.086 | E12: AMC Awards | Book Now – African Marketing Confederation | F12: 55 | G12: 67 | H12: 39 | I12: Warning | J12: 55 | K12: 0 | M12: FALSE | O12: 0 | Q12: 0 | S12: 0 | U12: 0 | W12: 0 | X12: 39 | Y12: 0 | Z12: WARN 🟡 | AA12: =IFERROR(HYPERLINK("#Technical!A"&MATCH(A12,Technical!A:A,0),"Open Technical"),HYPERLINK("#Technical!A1","Open Technical"))
A13: https://africanmarketingconfederation.org/amc-conference-2023/amc-awards/ | B13: 200 | C13: Indexable | D13: 0.048 | E13: AMC Awards – African Marketing Confederation | F13: AMC Awards Welcome to the prestigious African Marketing Confederation Awards, a distinguished event that celebrates and acknowledges the remarkable achievements, cutting-edge innovations, and exceptional leadership demonstrated by outstanding individuals within the dynamic realm of marketing across the expansive African region.During the 2nd Annual African Marketing Confederation Conference, held from 6th to 9th September at the | G13: 362 | H13: 69 | I13: Warning | J13: 44 | K13: 432 | M13: FALSE | O13: 0 | Q13: 0 | S13: 0 | U13: 0 | W13: 0 | X13: 69 | Y13: 0 | Z13: WARN 🟡 | AA13: =IFERROR(HYPERLINK("#Technical!A"&MATCH(A13,Technical!A:A,0),"Open Technical"),HYPERLINK("#Technical!A1","Open Technical"))
A14: https://africanmarketingconfederation.org/amc-conference-2023/book-now-thank-you/ | B14: 200 | C14: Indexable | D14: 0.067 | E14: Book Now | Thank you – African Marketing Confederation | F14: Thank you for completing your booking! Congratulations on booking your seat to the 2023 AfricaPro Conference presenting the 2nd Annual African Marketing Confederation Conference and Inaugural Technology Information Confederation Africa Conference! You will receive your email confirmation shortly with more event information. Be sure to keep an eye on the event website for up to | G14: 81 | H14: 49 | I14: Warning | J14: 54 | K14: 379 | M14: FALSE | O14: 0 | Q14: 0 | S14: 0 | U14: 0 | W14: 0 | X14: 49 | Y14: 0 | Z14: WARN 🟡 | AA14: =IFERROR(HYPERLINK("#Technical!A"&MATCH(A14,Technical!A:A,0),"Open Technical"),HYPERLINK("#Technical!A1","Open Technical"))
A15: https://africanmarketingconfederation.org/amc-conference-2023/book-now/ | B15: 200 | C15: Indexable | D15: 0.081 | E15: Book Now – African Marketing Confederation | F15: Book Now Individual Booking Package Options 1: Full Conference + Accommodation 5 - 9 September 2023 890 USD 3 Day Conference Including Excursions: 5 Sept - Networking evening and light dinner 6 Sept - Official opening and barbecue dinner 7 Sept - Sunset Cruise on Lake Victoria 8 Sept - Cultural Gala dinner at Ndere | G15: 231 | H15: 59 | I15: Warning | J15: 42 | K15: 316 | M15: FALSE | O15: 0 | Q15: 0 | S15: 0 | U15: 0 | W15: 0 | X15: 59 | Y15: 0 | Z15: WARN 🟡 | AA15: =IFERROR(HYPERLINK("#Technical!A"&MATCH(A15,Technical!A:A,0),"Open Technical"),HYPERLINK("#Technical!A1","Open Technical"))
A16: https://africanmarketingconfederation.org/amc-conference-2023/download-prospectus/ | B16: 200 | C16: Indexable | D16: 0.07 | E16: Download Prospectus – African Marketing Confederation | F16: BOOK NOW Prospectus Download the African Marketing Confederation Prospectus Learn more about the available sponsorship and exhibitor packages and how you can be a part of this exciting event First Name Last Name Email Position Are you a member of a country member body?--Select--Yes No I would like to receive monthly updates from AMCYes No | G16: 136 | H16: 59 | I16: Warning | J16: 53 | K16: 340 | M16: FALSE | O16: 0 | Q16: 0 | S16: 0 | U16: 0 | W16: 0 | X16: 59 | Y16: 0 | Z16: WARN 🟡 | AA16: =IFERROR(HYPERLINK("#Technical!A"&MATCH(A16,Technical!A:A,0),"Open Technical"),HYPERLINK("#Technical!A1","Open Technical"))
A17: https://africanmarketingconfederation.org/amc-conference-2023/gallery/ | B17: 200 | C17: Indexable | D17: 0.078 | E17: Gallery – African Marketing Confederation | F17: Conference Gallery sydney sweeney met gala All Day 1 Day 2 Day 3 Night 1 Night 2 Night 3 | G17: 82 | H17: 59 | I17: Warning | J17: 41 | K17: 88 | M17: FALSE | O17: 0 | Q17: 0 | S17: 0 | U17: 0 | W17: 0 | X17: 59 | Y17: 0 | Z17: WARN 🟡 | AA17: =IFERROR(HYPERLINK("#Technical!A"&MATCH(A17,Technical!A:A,0),"Open Technical"),HYPERLINK("#Technical!A1","Open Technical"))
A18: https://africanmarketingconfederation.org/amc-conference-2023/partners/ | B18: 200 | C18: Indexable | D18: 0.048 | E18: Partners – African Marketing Confederation | F18: Conference Partners AMC Member Bodies | G18: 72 | H18: 59 | I18: Warning | J18: 42 | K18: 37 | M18: FALSE | O18: 0 | Q18: 0 | S18: 0 | U18: 0 | W18: 0 | X18: 59 | Y18: 0 | Z18: WARN 🟡 | AA18: =IFERROR(HYPERLINK("#Technical!A"&MATCH(A18,Technical!A:A,0),"Open Technical"),HYPERLINK("#Technical!A1","Open Technical"))
A19: https://africanmarketingconfederation.org/amc-conference-2023/programme/ | B19: 200 | C19: Indexable | D19: 0.105 | E19: Programme – African Marketing Confederation | F19: Programme Download Conference Presentations Are Marketers Intelligent Enough For AI - Fred Kithinzi Taking Africa to the world and bringing the world to Africa - Nondumiso Mabece| Next Media DGCEO Presentation Strategy and Technology: Expanding the Success of Pan-African Brands - Prof. Robert Ebo Hinson Winning African Markets - Simon Harvey Culture as the New | G19: 730 | H19: 69 | I19: Warning | J19: 43 | K19: 362 | M19: FALSE | O19: 0 | Q19: 0 | S19: 0 | U19: 0 | W19: 0 | X19: 69 | Y19: 0 | Z19: WARN 🟡 | AA19: =IFERROR(HYPERLINK("#Technical!A"&MATCH(A19,Technical!A:A,0),"Open Technical"),HYPERLINK("#Technical!A1","Open Technical"))
A20: https://africanmarketingconfederation.org/amc-conference-2023/speakers/ | B20: 200 | C20: Indexable | D20: 0.176 | E20: Speakers – African Marketing Confederation | F20: Speakers Ali Hussein Kassim Kenya CEO - AHK Corp View Bio Cathy Adengo Uganda Head of Sustainability, Stanbic Bank Uganda View Bio Doreen Asaasira Muhangazi Uganda Chief Human Resource Officer View Bio James Sutton United Kingdom Strategy and Commercial Director - CIM-UK View Bio Juliet Ziswa Zimbabwe Marketing Director - OK Zimbabwe Limited Group View | G20: 2694 | H20: 69 | I20: Warning | J20: 42 | K20: 354 | M20: FALSE | O20: 0 | Q20: 0 | S20: 0 | U20: 0 | W20: 0 | X20: 69 | Y20: 0 | Z20: WARN 🟡 | AA20: =IFERROR(HYPERLINK("#Technical!A"&MATCH(A20,Technical!A:A,0),"Open Technical"),HYPERLINK("#Technical!A1","Open Technical"))
A21: https://africanmarketingconfederation.org/amc-conference-2024-recap/ | B21: 200 | C21: Indexable | D21: 0.303 | E21: AMC Conference 2024 Recap – African Marketing Confederation | F21: Event Highlights AMC Marketing Conference 2024 Shaping the Future of African Marketing Get 2025 Conference Updates Share Your Experience Conference Day 1 The conference kicked off with insightful addresses, including a keynote from marketing expert Hermawan Kartajaya. Dr Philip Kotler, the Father of Modern Marketing, delivered a welcome address live from Chicago and we ended | G21: 1453 | H21: 59 | I21: Warning | J21: 59 | K21: 377 | M21: FALSE | O21: 0 | Q21: 0 | S21: 0 | U21: 0 | W21: 0 | X21: 59 | Y21: 0 | Z21: WARN 🟡 | AA21: =IFERROR(HYPERLINK("#Technical!A"&MATCH(A21,Technical!A:A,0),"Open Technical"),HYPERLINK("#Technical!A1","Open Technical"))
A22: https://africanmarketingconfederation.org/amc-conference-2024-sponsors-packages/ | B22: 200 | C22: Indexable | D22: 0.06 | E22: Sponsors Packages – African Marketing Confederation | F22: SPONSORSHIP PACKAGES Diamond Package Overall Anchor and Title Sponsor $50000,00 View Product Platinum Package Industry Leader Sponsor / per Professional Body Stream $20000,00 View Product Silver Package Full Day (Option to Choose Day 1, 2, or 3) Provision of Delegates Apparel in the Form of Golf Shirts and Caps (Day 2 & 3) $12000,00 View | G22: 145 | H22: 59 | I22: Warning | J22: 51 | K22: 339 | M22: FALSE | O22: 0 | Q22: 0 | S22: 0 | U22: 0 | W22: 0 | X22: 59 | Y22: 0 | Z22: WARN 🟡 | AA22: =IFERROR(HYPERLINK("#Technical!A"&MATCH(A22,Technical!A:A,0),"Open Technical"),HYPERLINK("#Technical!A1","Open Technical"))
A23: https://africanmarketingconfederation.org/amc-conference-2025-highlights/ | B23: 200 | C23: Indexable | D23: 0.16 | E23: AMC Conference 2025 Highlights – African Marketing Confederation | F23: 2025 Event Highlights AMC Marketing Conference AMC Marketing Conference 250+ Delegates. 29 Countries. One Pan-African Voice.250+ Delegates. 29 Countries.One Pan-African Marketing Voice. Get 2026 Conference Updates Share Your Experience 2025 Event Highlights AMC Marketing Conference 400+ Delegates. 29 Countries.One Pan-African Voice. Get 2026 Conference Updates 2025 Event Highlights AMC Marketing Conference Get 2026 Conference Updates | G23: 1888 | H23: 56 | I23: Warning | J23: 64 | K23: 437 | M23: FALSE | O23: 0 | Q23: 0 | S23: 0 | U23: 0 | W23: 0 | X23: 56 | Y23: 0 | Z23: WARN 🟡 | AA23: =IFERROR(HYPERLINK("#Technical!A"&MATCH(A23,Technical!A:A,0),"Open Technical"),HYPERLINK("#Technical!A1","Open Technical"))
A24: https://africanmarketingconfederation.org/amc-conference-2025/ | B24: 200 | C24: Indexable | D24: 0.077 | E24: AMC Conference 2025 | F24: Join Africa's top marketers at the AMC Conference 2025 n Accra, Ghana from 20-22 August - 3 days of insights, innovation, and powerful networking. | G24: 1242 | H24: 59 | I24: Warning | J24: 19 | K24: 146 | M24: FALSE | O24: 0 | Q24: 0 | S24: 0 | U24: 0 | W24: 0 | X24: 59 | Y24: 0 | Z24: WARN 🟡 | AA24: =IFERROR(HYPERLINK("#Technical!A"&MATCH(A24,Technical!A:A,0),"Open Technical"),HYPERLINK("#Technical!A1","Open Technical"))
... A41: https://africanmarketingconfederation.org/amc-marketing-conference-2024/testimony-thank-you-page/ | B41: 200 | C41: Indexable | D41: 0.178 | E41: Testimony Thank you Page – African Marketing Confederation | F41: Thank you For your Feedback Thank you For the Feedback PUBLICATIONS Strategic Marketing for Africa Magazine CONTACT INFORMATION info@africanmarketingconfederation.org © 2021 by African Marketing Confederation | Privacy Policy | G41: 66 | H41: 49 | I41: Warning | J41: 58 | K41: 225 | M41: FALSE | O41: 0 | Q41: 0 | S41: 0 | U41: 0 | W41: 0 | X41: 49 | Y41: 0 | Z41: WARN 🟡 | AA41: =IFERROR(HYPERLINK("#Technical!A"&MATCH(A41,Technical!A:A,0),"Open Technical"),HYPERLINK("#Technical!A1","Open Technical"))
A42: https://africanmarketingconfederation.org/amc-masterclass-bookings/ | B42: 200 | C42: Indexable | D42: 0.099 | E42: AMC Masterclass | Bookings – African Marketing Confederation | F42: 60 | G42: 79 | H42: 39 | I42: Warning | J42: 60 | K42: 0 | M42: FALSE | O42: 0 | Q42: 0 | S42: 0 | U42: 0 | W42: 0 | X42: 39 | Y42: 0 | Z42: WARN 🟡 | AA42: =IFERROR(HYPERLINK("#Technical!A"&MATCH(A42,Technical!A:A,0),"Open Technical"),HYPERLINK("#Technical!A1","Open Technical"))
A43: https://africanmarketingconfederation.org/amc-masterclass-thank-you/ | B43: 200 | C43: Indexable | D43: 0.053 | E43: AMC Masterclass | Thank you – African Marketing Confederation | F43: AMC VIRTUAL MASTERCLASS 31 May 2022 Thank you for your Booking We received your booking and will contact you shortly! | G43: 32 | H43: 49 | I43: Warning | J43: 61 | K43: 117 | M43: FALSE | O43: 0 | Q43: 0 | S43: 0 | U43: 0 | W43: 0 | X43: 49 | Y43: 0 | Z43: WARN 🟡 | AA43: =IFERROR(HYPERLINK("#Technical!A"&MATCH(A43,Technical!A:A,0),"Open Technical"),HYPERLINK("#Technical!A1","Open Technical"))
A44: https://africanmarketingconfederation.org/amc-masterclass/ | B44: 200 | C44: Indexable | D44: 0.115 | E44: AMC Masterclass – African Marketing Confederation | F44: AMC VIRTUAL MASTERCLASS 31 May 2022 Thank you for attending Building The Perfect Blueprint for Digital and Strategic Marketing Align your digital efforts with your strategic goals and develop strong online marketing capabilities to help your company stay ahead of the curve.Masterclass Outcomes: You will receive all the tools you need to overcome and avoid | G44: 278 | H44: 49 | I44: Warning | J44: 49 | K44: 357 | M44: FALSE | O44: 0 | Q44: 0 | S44: 0 | U44: 0 | W44: 0 | X44: 49 | Y44: 0 | Z44: WARN 🟡 | AA44: =IFERROR(HYPERLINK("#Technical!A"&MATCH(A44,Technical!A:A,0),"Open Technical"),HYPERLINK("#Technical!A1","Open Technical"))
A45: https://africanmarketingconfederation.org/amc-relaunch-programme/ | B45: 200 | C45: Indexable | D45: 0.048 | E45: AMC RELAUNCH – PROGRAMME – African Marketing Confederation | F45: amc relaunch Thank you for joining our first online gathering! WATCH RECORDINGS NOW WATCH NOW AMC RELAUNCH RECORDINGS The AMC relaunch event shared the vision and goals of the AMC, as well as hosting talks and discussions with top marketing thought leaders and professionals. The African Marketing Confederation (AMC) – the ground breaking Pan-African body | G45: 516 | H45: 59 | I45: Warning | J45: 58 | K45: 356 | M45: FALSE | O45: 0 | Q45: 0 | S45: 0 | U45: 0 | W45: 0 | X45: 59 | Y45: 0 | Z45: WARN 🟡 | AA45: =IFERROR(HYPERLINK("#Technical!A"&MATCH(A45,Technical!A:A,0),"Open Technical"),HYPERLINK("#Technical!A1","Open Technical"))
A46: https://africanmarketingconfederation.org/amc-sign-up-now-form-2025/ | B46: 200 | C46: Indexable | D46: 0.053 | E46: AMC Sign up now Form 2025 – African Marketing Confederation | F46: Get Ready for Ghana in 2025! Name(Required) First Last Email(Required) Enter Email Confirm Email Phone Number(Required)CountryAfghanistanAlbaniaAlgeriaAmerican SamoaAndorraAngolaAnguillaAntarcticaAntigua and BarbudaArgentinaArmeniaArubaAustraliaAustriaAzerbaijanBahamasBahrainBangladeshBarbadosBelarusBelgiumBelizeBeninBermudaBhutanBoliviaBonaire, Sint Eustatius and SabaBosnia and HerzegovinaBotswanaBouvet IslandBrazilBritish Indian Ocean TerritoryBrunei DarussalamBulgariaBurkina FasoBurundiCabo VerdeCambodiaCameroonCanadaCayman IslandsCentral African RepublicChadChileChinaChristmas IslandCocos IslandsColombiaComorosCongoCongo, Democratic Republic of theCook IslandsCosta RicaCroatiaCubaCuraçaoCyprusCzechiaCôte d'IvoireDenmarkDjiboutiDominicaDominican RepublicEcuadorEgyptEl SalvadorEquatorial GuineaEritreaEstoniaEswatiniEthiopiaFalkland IslandsFaroe IslandsFijiFinlandFranceFrench GuianaFrench PolynesiaFrench Southern TerritoriesGabonGambiaGeorgiaGermanyGhanaGibraltarGreeceGreenlandGrenadaGuadeloupeGuamGuatemalaGuernseyGuineaGuinea-BissauGuyanaHaitiHeard Island and | G46: 608 | H46: 69 | I46: Warning | J46: 59 | K46: 1077 | M46: FALSE | O46: 0 | Q46: 0 | S46: 0 | U46: 0 | W46: 0 | X46: 69 | Y46: 0 | Z46: WARN 🟡 | AA46: =IFERROR(HYPERLINK("#Technical!A"&MATCH(A46,Technical!A:A,0),"Open Technical"),HYPERLINK("#Technical!A1","Open Technical"))
A47: https://africanmarketingconfederation.org/amc-sponsors-2025/ | B47: 200 | C47: Indexable | D47: 0.065 | E47: Sponsorship Opportunities – 2025 AMC Conference | F47: Explore sponsorship opportunities for AMC Conference 2025 and position your brand alongside Africa’s leading marketers, innovators, and industry decision-makers. | G47: 1213 | H47: 69 | I47: Warning | J47: 47 | K47: 161 | M47: FALSE | O47: 0 | Q47: 0 | S47: 0 | U47: 0 | W47: 0 | X47: 69 | Y47: 0 | Z47: WARN 🟡 | AA47: =IFERROR(HYPERLINK("#Technical!A"&MATCH(A47,Technical!A:A,0),"Open Technical"),HYPERLINK("#Technical!A1","Open Technical"))
A48: https://africanmarketingconfederation.org/amc-testimony-page-2024/ | B48: 200 | C48: Indexable | D48: 0.062 | E48: AMC Testimony page 2024 – African Marketing Confederation | F48: How was your experience at the2024 AMC Conference? Name(Required) First Last Email(Required) Company Name How was your experience at the AMC Conference 2024? We'd love to hear about your key takeaways and memorable moments!What improvements would you recommend for the next AMC Conference to make it even more impactful? Sponsors Previous Next PUBLICATIONS Strategic Marketing | G48: 622 | H48: 69 | I48: Warning | J48: 57 | K48: 376 | M48: FALSE | O48: 0 | Q48: 0 | S48: 0 | U48: 0 | W48: 0 | X48: 69 | Y48: 0 | Z48: WARN 🟡 | AA48: =IFERROR(HYPERLINK("#Technical!A"&MATCH(A48,Technical!A:A,0),"Open Technical"),HYPERLINK("#Technical!A1","Open Technical"))
A49: https://africanmarketingconfederation.org/awards-2026-1/ | B49: 200 | C49: Indexable | D49: 0.051 | E49: 2026 AMC Awards-1 – African Marketing Confederation | F49: The African Marketing Confederation presents the 2026 AMC Awards. Submit your nominations to recognise innovative strategies, impact, and marketing results. | G49: 1108 | H49: 59 | I49: Warning | J49: 51 | K49: 156 | M49: FALSE | O49: 0 | Q49: 0 | S49: 0 | U49: 0 | W49: 0 | X49: 59 | Y49: 0 | Z49: WARN 🟡 | AA49: =IFERROR(HYPERLINK("#Technical!A"&MATCH(A49,Technical!A:A,0),"Open Technical"),HYPERLINK("#Technical!A1","Open Technical"))
A50: https://africanmarketingconfederation.org/awards-2026-test/ | B50: 200 | C50: Indexable | D50: 0.068 | E50: Awards 2026 test – African Marketing Confederation | F50: 2026 AMC AWARDS 2026AMC Awards Submit Your Nomination View Awards Brochure Where Africa’s Boldest Ideas Take the Stage https://africanmarketingconfederation.org/wp-content/uploads/2026/03/16x9-AMC-Awards-Nominations-Video-2026.mp4 Entries Close: 26 July Held annually at the African Marketing Confederation Conference, the AMC Awards stand as the definitive celebration of marketing excellence across the continent. This distinguished platform brings together Africa’s leading minds and boldest work, recognising campaigns and | G50: 1180 | H50: 59 | I50: Warning | J50: 50 | K50: 526 | M50: FALSE | O50: 0 | Q50: 0 | S50: 0 | U50: 0 | W50: 0 | X50: 59 | Y50: 0 | Z50: WARN 🟡 | AA50: =IFERROR(HYPERLINK("#Technical!A"&MATCH(A50,Technical!A:A,0),"Open Technical"),HYPERLINK("#Technical!A1","Open Technical"))
A51: https://africanmarketingconfederation.org/awards-2026/ | B51: 200 | C51: Indexable | D51: 0.061 | E51: 2026 AMC Awards – African Marketing Confederation | F51: The African Marketing Confederation presents the 2026 AMC Awards. Submit your nominations to recognise innovative strategies, impact, and marketing results. | G51: 1132 | H51: 59 | I51: Warning | J51: 49 | K51: 156 | M51: FALSE | O51: 0 | Q51: 0 | S51: 0 | U51: 0 | W51: 0 | X51: 59 | Y51: 0 | Z51: WARN 🟡 | AA51: =IFERROR(HYPERLINK("#Technical!A"&MATCH(A51,Technical!A:A,0),"Open Technical"),HYPERLINK("#Technical!A1","Open Technical"))
A52: https://africanmarketingconfederation.org/certified-professional-marketer-africa/ | B52: 200 | C52: Indexable | D52: 0.069 | E52: Certified Professional Marketer (Africa) – African Marketing Confederation | F52: Certified Professional Marketer (Africa), CPM(A) The only designation of its kind on the continent - built for Africa, by Africa. Strategic Flexible Uniquely Africa Take your place among Africa’s marketing leaders with the Certified Professional Marketer (Africa) – CPM(A) A prestigious, Pan-African designation offered exclusively through the African Marketing Confederation (AMC).This is not just a | G52: 949 | H52: 59 | I52: Warning | J52: 74 | K52: 400 | M52: FALSE | O52: 0 | Q52: 0 | S52: 0 | U52: 0 | W52: 0 | X52: 59 | Y52: 0 | Z52: WARN 🟡 | AA52: =IFERROR(HYPERLINK("#Technical!A"&MATCH(A52,Technical!A:A,0),"Open Technical"),HYPERLINK("#Technical!A1","Open Technical"))
A53: https://africanmarketingconfederation.org/chartered-marketer-africa-final-submission-fee/ | B53: 200 | C53: Indexable | D53: 0.183 | E53: Chartered Marketer (Africa) Final submission fee – African Marketing Confederation | F53: Final Submission Fee Receive a 15% discount on your final submission feeby making payment before 31 August 2024. Add to cart $2190,00 Original price was: $2190,00.$1862,00Current price is: $1862,00. Add to cart | G53: 147 | H53: 59 | I53: Warning | J53: 82 | K53: 210 | M53: FALSE | O53: 0 | Q53: 0 | S53: 0 | U53: 0 | W53: 0 | X53: 59 | Y53: 0 | Z53: WARN 🟡 | AA53: =IFERROR(HYPERLINK("#Technical!A"&MATCH(A53,Technical!A:A,0),"Open Technical"),HYPERLINK("#Technical!A1","Open Technical"))
A54: https://africanmarketingconfederation.org/chartered-marketer-africa-programme-fee/ | B54: 200 | C54: Indexable | D54: 0.068 | E54: Chartered Marketer (Africa) Programme fee – African Marketing Confederation | F54: Programme Fee Receive a 15% discount on your programme fee by making payment before 31 August 2024. Add to cart $810,00 Original price was: $810,00.$689,00Current price is: $689,00. Add to cart | G54: 145 | H54: 59 | I54: Warning | J54: 75 | K54: 193 | M54: FALSE | O54: 0 | Q54: 0 | S54: 0 | U54: 0 | W54: 0 | X54: 59 | Y54: 0 | Z54: WARN 🟡 | AA54: =IFERROR(HYPERLINK("#Technical!A"&MATCH(A54,Technical!A:A,0),"Open Technical"),HYPERLINK("#Technical!A1","Open Technical"))
... A64: https://africanmarketingconfederation.org/elementor-16548/ | B64: 200 | C64: Indexable | D64: 0.061 | E64: Thank you for registering – African Marketing Confederation | F64: SUBMISSION RECEIVED Thank you for submitting your information! We appreciate your interest in the 2024 AMC Conference and will keep you updated with all the details about the upcoming event. Speakers Programme Awards | G64: 113 | H64: 49 | I64: Warning | J64: 59 | K64: 216 | M64: FALSE | O64: 0 | Q64: 0 | S64: 0 | U64: 0 | W64: 0 | X64: 49 | Y64: 0 | Z64: WARN 🟡 | AA64: =IFERROR(HYPERLINK("#Technical!A"&MATCH(A64,Technical!A:A,0),"Open Technical"),HYPERLINK("#Technical!A1","Open Technical"))
A65: https://africanmarketingconfederation.org/elementor-20341/ | B65: 200 | C65: Indexable | D65: 0.067 | E65: Elementor #20341 – African Marketing Confederation | F65: 50 | G65: 79 | H65: 39 | I65: Warning | J65: 50 | K65: 0 | M65: FALSE | O65: 0 | Q65: 0 | S65: 0 | U65: 0 | W65: 0 | X65: 39 | Y65: 0 | Z65: WARN 🟡 | AA65: =IFERROR(HYPERLINK("#Technical!A"&MATCH(A65,Technical!A:A,0),"Open Technical"),HYPERLINK("#Technical!A1","Open Technical"))
...

Sheet Technical
A1: URL | B1: Status Code | C1: Status Class | D1: SEO Health Score | E1: Severity Badge | F1: Action Needed | G1: Indexability Reason | H1: TTFB (ms) | I1: Total Request Time (ms) | J1: Final URL | K1: Canonical URL | L1: Canonical Type | M1: Owner | N1: Status | O1: Sprint | P1: Health Icon | Q1: Protocol | R1: Redirect Chain Length | S1: Redirect Target | T1: Redirect Hops | U1: HTTP->HTTPS Redirect | V1: Content-Type | W1: HTTP Version | X1: HTML Size (KB) | Y1: Compression Enabled | Z1: Cache-Control | AA1: ETag | AB1: X-Robots-Tag | AC1: Meta Robots Raw | AD1: Canonical Matches Final URL | AE1: Canonical Absolute URL | AF1: Canonical in Sitemap Match | AG1: Hreflang Present | AH1: Hreflang Count | AI1: Hreflang Self Reference | AJ1: Hreflang Reciprocal Check | AK1: Hreflang Canonical Consistency | AL1: x-default Present | AM1: Pagination rel=next | AN1: Pagination rel=prev | AO1: Last-Modified | AP1: Published Date | AQ1: Modified Date | AR1: Last Updated | AS1: Change Frequency | AT1: Priority | AU1: Critical Issues Count | AV1: Warning Issues Count | AW1: Info Issues Count | AX1: Inlinks Bucket | AY1: Important But Underlinked | AZ1: SERP Title Truncation Risk | BA1: SERP Meta Truncation Risk | BB1: SERP Title Pixel Approx | BC1: SERP Meta Pixel Approx | BD1: Cannibalization Hint | BE1: Stable Issue IDs | BF1: URL Depth | BG1: Param URL Flag | BH1: Open in Main | BI1: BACK TO DASHBOARD
A2: https://africanmarketingconfederation.org/amc-conference-sponsors/ | B2: 404 | C2: 4xx | D2: 24 | E2: Critical | F2: Yes | G2: HTTP 404 | H2: 3974.15 | I2: 404 | J2: https://africanmarketingconfederation.org/amc-forum-sponsors/ | K2: https | L2: 1 | M2: Server/Host | N2: Open | P2: FAIL 🔴 | Q2: https | R2: 1 | S2: text/html; charset=UTF-8 | T2: HTTP/1.1 | U2: FALSE | V2: text/html; charset=UTF-8 | W2: HTTP/1.1 | X2: 530.71 | Y2: FALSE | AF2: FALSE | AG2: FALSE | AH2: 0 | AI2: FALSE | AK2: FALSE | AL2: FALSE | AM2: FALSE | AN2: FALSE | AQ2: 2024-09-18T12:27:33+00:00 | AR2: 2024-09-18T12:27:33+00:00 | AS2: weekly | AT2: 0.7 | AU2: 1 | AV2: 3 | AW2: 7 | AX2: 0 | AY2: TRUE | AZ2: FALSE | BA2: FALSE | BB2: 0 | BC2: 0 | BE2: https://africanmarketingconfederation.org/amc-conference-sponsors/::non-200_status | https://africanmarketingconfederation.org/amc-conference-sponsors/::missing_title | https://africanmarketingconfederation.org/amc-conference-sponsors/::missing_meta_description | https://africanmarketingconfederation.org/amc-conference-sponsors/::low_aeo_readiness_score | https://africanmarketingconfederation.org/amc-conference-sponsors/::no_compression_header | https://africanmarketingconfederation.org/amc-conference-sponsors/::no_cache-control_header | https://africanmarketingconfederation.org/amc-conference-sponsors/::no_etag_header | https://africanmarketingconfederation.org/amc-conference-sponsors/::no_faq_qa_schema | https://africanmarketingconfederation.org/amc-conference-sponsors/::no_question_headings | https://africanmarketingconfederation.org/amc-conference-sponsors/::no_answer-friendly_structure | https://africanmarketingconfederation.org/amc-conference-sponsors/::no_40-60_word_answer_paragraphs | BF2: 1 | BG2: FALSE | BH2: =IFERROR(HYPERLINK("#Main!A"&MATCH(A2,Main!A:A,0),"Open"),HYPERLINK("#Main!A1","Open"))
