Workbook

Sheet Dashboard
A1: Metric | B1: Technical Audit Dashboard
A2: URLs Crawled | B2: Executive SEO Performance Report
A3: Pass Rate (%) | B3: 0
A4: Critical URL Count | B4: EXECUTIVE METRICS | C4: Value | E4: OWNER ISSUE SUMMARY (PIVOT)
A5: Warning URL Count | B5: =HYPERLINK("#Main!A1","Total URLs") | C5: 15 | E5: Owner | F5: Issue Rows | G5: Affected URLs | H5: Critical | I5: Warning | J5: Info
A6: Status Distribution | B6: =HYPERLINK("#Summary!A1","Overall Health Score") | C6: =IFERROR(60.07/100,0) | E6: =HYPERLINK("#FixPlan!A1","Copy Writer") | F6: 13 | G6: 72 | H6: 0 | I6: 8 | J6: 5
A7: Score Bands | B7: =HYPERLINK("#Summary!A1","SEO Pass Rate %") | C7: =IFERROR(0/15,0) | E7: =HYPERLINK("#FixPlan!A1","Server/Host") | F7: 5 | G7: 45 | H7: 2 | I7: 0 | J7: 3
B8: =HYPERLINK("#Technical!A1","Pass URLs") | C8: 0 | E8: =HYPERLINK("#FixPlan!A1","Dev") | F8: 8 | G8: 15 | H8: 3 | I8: 3 | J8: 2
B9: =HYPERLINK("#FixPlan!A1","Critical URLs") | C9: 0
A10: Issue Type | B10: =HYPERLINK("#Technical!A1","Warning URLs") | C10: 30 | F10: Status Class | G10: Count | I10: Score Band | J10: Count
A11: No Compression Header | B11: =HYPERLINK("#Technical!A1","Error Rate % (4xx/5xx)") | C11: =IFERROR(0/15,0) | F11: 2xx | G11: 15 | I11: 90-100 | J11: 0
A12: No Cache-Control Header | B12: =HYPERLINK("#Technical!A1","Crawl Success Rate % (2xx)") | C12: =IFERROR(15/15,0) | I12: 70-89 | J12: 0
A13: No ETag Header | B13: =HYPERLINK("#Technical!A1","Critical URL Rate %") | C13: =IFERROR(0/15,0) | I13: <70 | J13: 15
A14: No FAQ/QA Schema | B14: =HYPERLINK("#Technical!A1","Warning URL Rate %") | C14: =IFERROR(30/15,0)
A15: No Answer-Friendly Structure | B15: Info | C15: 15
A16: Low AEO Readiness Score | B16: Status | C16: Count
A17: No Question Headings | B17: 200 OK | C17: 15
A18: No 40-60 Word Answer Paragraphs | B18: 3xx Redirects | C18: 0
A19: Thin Content | B19: 4xx Errors | C19: 0
A20: Missing H1 | B20: 5xx Errors | C20: 0
B21: Other | C21: 0
B23: Severity | C23: Count
A24: Immediate Actions | B24: Critical | C24: 5
A25: Top 5 URLs by Business Risk Score | B25: Warning | C25: 11
A26: Rank | B26: Medium | C26: 0 | D26: Why Prioritized | E26: Action Needed | F26: Owner | G26: Status
A27: 1 | B27: Low | C27: 10 | D27: Monitor | E27: Yes | F27: Copy Writer | G27: Open
A28: 2 | B28: https://asconafrica.org/unsubscribe-form/successfully-unsubscribed/ | C28: 81 | D28: Monitor | E28: Yes | F28: Copy Writer | G28: Open
A29: 3 | B29: PRIORITY SNAPSHOT | C29: Value | D29: Monitor | E29: Yes | F29: Copy Writer | G29: Open
A30: 4 | B30: Top Blocking Issue | C30: No Compression Header | D30: Monitor | E30: Yes | F30: Copy Writer | G30: Open
A31: 5 | B31: Top Issue Affected URLs | C31: 15 | D31: Monitor | E31: Yes | F31: Copy Writer | G31: Open
B32: 4xx/5xx URLs | C32: 0
B33: Avg TTFB (ms) | C33: 609.49
B35: Quick Navigation | C35: Open
B36: Fix Plan | C36: =HYPERLINK("#FixPlan!A1","Open")
B37: Main URL Data | C37: =HYPERLINK("#Main!A1","Open")
B38: Technical Diagnostics | C38: =HYPERLINK("#Technical!A1","Open")
B39: Indexability | C39: =HYPERLINK("#Indexability!A1","Open")
B40: AEO Opportunities | C40: =HYPERLINK("#AEO!A1","Open")
B41: AIOSEO Action Queue | C41: =HYPERLINK("#AIOSEO!A1","Open")
B42: TOP ISSUES TO FIX FIRST | C42: Affected URLs
...

Sheet Legend
A1: Section | B1: Term | C1: Meaning | D1: Values/Threshold | E1: Related Tabs | F1: BACK TO DASHBOARD
A2: How To Use | B2: Step 1: Start on Dashboard | C2: Review pass rate, critical URL count, and Immediate Actions to understand overall risk first. | D2: 5-minute executive scan | E2: Dashboard, Priority URLs
A3: How To Use | B3: Step 2: Prioritize and Assign | C3: Use Priority URLs and FixPlan to pick highest-impact items, assign owner, and set status/sprint. | D3: Work top-down by Business Risk Score | E3: Priority URLs, FixPlan
A4: How To Use | B4: Step 3: Execute and Validate | C4: Implement fixes, then verify by checking Technical/Indexability/AEO tabs and rerunning the audit. | D4: Close loop every sprint | E4: Technical, Indexability, AEO, AIOSEO
A5: Orientation | B5: Where to Start | C5: If you're short on time, work only Critical and Warning issues first, then return to Info items. | D5: Critical > Warning > Info | E5: Summary, FixPlan, Technical
A6: Orientation | B6: How to Track Progress | C6: Use Status and Owner columns as your project board; move from To Do -> In Progress -> Fixed. | D6: Update weekly | E6: FixPlan, AIOSEO, Priority URLs
A7: Severity | B7: Critical | C7: High-impact SEO blocker that should be fixed first. | D7: Immediate action | E7: Summary, FixPlan, Technical
A8: Severity | B8: Warning | C8: Out-of-best-practice issue likely affecting performance. | D8: Plan next sprint | E8: Summary, FixPlan, Technical
A9: Severity | B9: Info | C9: Optimization opportunity or context signal. | D9: Backlog/monitor | E9: Summary, Technical
A10: Scoring | B10: SEO Health Score | C10: Weighted technical SEO quality score per URL. | D10: >=90 green, 70-89 orange, <70 red | E10: Technical, Priority URLs, Dashboard
A11: Scoring | B11: AEO Readiness Score | C11: Answer Engine Optimization readiness score per URL. | D11: >=80 strong, 60-79 good, 40-59 fair | E11: AEO
A12: Indexing | B12: Indexability Reason | C12: Primary reason URL may not be indexed. | D12: Noindex, non-200, canonical mismatch | E12: Indexability, Technical
A13: Links | B13: Broken Internal Links Count | C13: Internal links returning 4xx/5xx or equivalent failures. | D13: >0 flagged | E13: Links, LinksDetail, Priority URLs
... A19: Color Key | B19: Purple | C19: Informational edge-case or AEO category signal. | D19: Context | E19: All

Sheet Summary
A1: Section | B1: Severity | C1: Issue | D1: Affected URL Count | E1: Reference Tab | F1: Affected URLs (sample) | G1: BACK TO DASHBOARD
A2: AEO Opportunities | B2: Warning | C2: Low AEO Readiness Score | D2: 15 | E2: AEO | F2: https://asconafrica.org/2026-ascon-awards/ | https://asconafrica.org/ | https://asconafrica.org/news/ | https://asconafrica.org/our-members/ | https://asconafrica.org/2026-ascon-conference/ | https://asconafrica.org/about-us/ | https://asconafrica.org/privacy-policy/ | https://asconafrica.org/2026-ascon-conference/thank-you-for-signing-up/ | https://asconafrica.org/thank-you-for-signing-up-for-updates/ | https://asconafrica.org/launch-event-2026-ascon-conference/thank-you-for-registering-conference-launch/ | https://asconafrica.org/launch-event-2026-ascon-conference/ | https://asconafrica.org/2026-ascon-awards/thank-you-for-your-nomination/ | https://asconafrica.org/unsubscribe-form/ | https://asconafrica.org/unsubscribe-form/successfully-unsubscribed/ | https://asconafrica.org/contact-us/ || Full list: see AEO tab
A3: AEO Opportunities | B3: Info | C3: No Answer-Friendly Structure | D3: 15 | E3: AEO | F3: https://asconafrica.org/2026-ascon-awards/ | https://asconafrica.org/ | https://asconafrica.org/news/ | https://asconafrica.org/our-members/ | https://asconafrica.org/2026-ascon-conference/ | https://asconafrica.org/about-us/ | https://asconafrica.org/privacy-policy/ | https://asconafrica.org/2026-ascon-conference/thank-you-for-signing-up/ | https://asconafrica.org/thank-you-for-signing-up-for-updates/ | https://asconafrica.org/launch-event-2026-ascon-conference/thank-you-for-registering-conference-launch/ | https://asconafrica.org/launch-event-2026-ascon-conference/ | https://asconafrica.org/2026-ascon-awards/thank-you-for-your-nomination/ | https://asconafrica.org/unsubscribe-form/ | https://asconafrica.org/unsubscribe-form/successfully-unsubscribed/ | https://asconafrica.org/contact-us/ || Full list: see AEO tab
A4: AEO Opportunities | B4: Info | C4: No FAQ/QA Schema | D4: 15 | E4: AEO | F4: https://asconafrica.org/2026-ascon-awards/ | https://asconafrica.org/ | https://asconafrica.org/news/ | https://asconafrica.org/our-members/ | https://asconafrica.org/2026-ascon-conference/ | https://asconafrica.org/about-us/ | https://asconafrica.org/privacy-policy/ | https://asconafrica.org/2026-ascon-conference/thank-you-for-signing-up/ | https://asconafrica.org/thank-you-for-signing-up-for-updates/ | https://asconafrica.org/launch-event-2026-ascon-conference/thank-you-for-registering-conference-launch/ | https://asconafrica.org/launch-event-2026-ascon-conference/ | https://asconafrica.org/2026-ascon-awards/thank-you-for-your-nomination/ | https://asconafrica.org/unsubscribe-form/ | https://asconafrica.org/unsubscribe-form/successfully-unsubscribed/ | https://asconafrica.org/contact-us/ || Full list: see AEO tab
A5: AEO Opportunities | B5: Info | C5: No 40-60 Word Answer Paragraphs | D5: 14 | E5: AEO | F5: https://asconafrica.org/2026-ascon-awards/ | https://asconafrica.org/ | https://asconafrica.org/news/ | https://asconafrica.org/our-members/ | https://asconafrica.org/2026-ascon-conference/ | https://asconafrica.org/about-us/ | https://asconafrica.org/2026-ascon-conference/thank-you-for-signing-up/ | https://asconafrica.org/thank-you-for-signing-up-for-updates/ | https://asconafrica.org/launch-event-2026-ascon-conference/thank-you-for-registering-conference-launch/ | https://asconafrica.org/launch-event-2026-ascon-conference/ | https://asconafrica.org/2026-ascon-awards/thank-you-for-your-nomination/ | https://asconafrica.org/unsubscribe-form/ | https://asconafrica.org/unsubscribe-form/successfully-unsubscribed/ | https://asconafrica.org/contact-us/ || Full list: see AEO tab
A6: AEO Opportunities | B6: Info | C6: No Question Headings | D6: 14 | E6: AEO | F6: https://asconafrica.org/2026-ascon-awards/ | https://asconafrica.org/ | https://asconafrica.org/news/ | https://asconafrica.org/our-members/ | https://asconafrica.org/2026-ascon-conference/ | https://asconafrica.org/about-us/ | https://asconafrica.org/2026-ascon-conference/thank-you-for-signing-up/ | https://asconafrica.org/thank-you-for-signing-up-for-updates/ | https://asconafrica.org/launch-event-2026-ascon-conference/thank-you-for-registering-conference-launch/ | https://asconafrica.org/launch-event-2026-ascon-conference/ | https://asconafrica.org/2026-ascon-awards/thank-you-for-your-nomination/ | https://asconafrica.org/unsubscribe-form/ | https://asconafrica.org/unsubscribe-form/successfully-unsubscribed/ | https://asconafrica.org/contact-us/ || Full list: see AEO tab
A7: AEO Opportunities | F7: Detailed rows: see AEO tab
A8: Issue Counts | B8: Critical | C8: Broken Internal Links | D8: 0 | E8: Links | F8: || Full list: see Technical/Links/Indexability tabs
A9: Issue Counts | B9: Critical | C9: Canonical Points Elsewhere | D9: 0 | E9: Indexability | F9: || Full list: see Technical/Links/Indexability tabs
A10: Issue Counts | B10: Critical | C10: Noindex Directive | D10: 0 | E10: Indexability | F10: || Full list: see Technical/Links/Indexability tabs
A11: Issue Counts | B11: Critical | C11: Non-200 Status | D11: 0 | E11: Technical | F11: || Full list: see Technical/Links/Indexability tabs
A12: Issue Counts | B12: Critical | C12: Robots.txt Disallow Root | D12: 0 | E12: Technical | F12: || Full list: see Technical/Links/Indexability tabs
A13: Issue Counts | B13: Warning | C13: Low AEO Readiness Score | D13: 15 | E13: AEO | F13: https://asconafrica.org/2026-ascon-awards/ | https://asconafrica.org/ | https://asconafrica.org/news/ | https://asconafrica.org/our-members/ | https://asconafrica.org/2026-ascon-conference/ | https://asconafrica.org/about-us/ | https://asconafrica.org/privacy-policy/ | https://asconafrica.org/2026-ascon-conference/thank-you-for-signing-up/ | https://asconafrica.org/thank-you-for-signing-up-for-updates/ | https://asconafrica.org/launch-event-2026-ascon-conference/thank-you-for-registering-conference-launch/ | https://asconafrica.org/launch-event-2026-ascon-conference/ | https://asconafrica.org/2026-ascon-awards/thank-you-for-your-nomination/ | https://asconafrica.org/unsubscribe-form/ | https://asconafrica.org/unsubscribe-form/successfully-unsubscribed/ | https://asconafrica.org/contact-us/ || Full list: see Technical/Links/Indexability tabs
A14: Issue Counts | B14: Warning | C14: Thin Content | D14: 8 | E14: Technical | F14: https://asconafrica.org/our-members/ | https://asconafrica.org/2026-ascon-conference/thank-you-for-signing-up/ | https://asconafrica.org/thank-you-for-signing-up-for-updates/ | https://asconafrica.org/launch-event-2026-ascon-conference/thank-you-for-registering-conference-launch/ | https://asconafrica.org/2026-ascon-awards/thank-you-for-your-nomination/ | https://asconafrica.org/unsubscribe-form/ | https://asconafrica.org/unsubscribe-form/successfully-unsubscribed/ | https://asconafrica.org/contact-us/ || Full list: see Technical/Links/Indexability tabs
A15: Issue Counts | B15: Warning | C15: Missing H1 | D15: 6 | E15: Technical | F15: https://asconafrica.org/ | https://asconafrica.org/news/ | https://asconafrica.org/privacy-policy/ | https://asconafrica.org/unsubscribe-form/ | https://asconafrica.org/unsubscribe-form/successfully-unsubscribed/ | https://asconafrica.org/contact-us/ || Full list: see Technical/Links/Indexability tabs
A16: Issue Counts | B16: Warning | C16: Canonical Missing | D16: 0 | E16: Indexability | F16: || Full list: see Technical/Links/Indexability tabs
A17: Issue Counts | B17: Warning | C17: Hreflang Without Reciprocity | D17: 0 | E17: Technical | F17: || Full list: see Technical/Links/Indexability tabs
A18: Issue Counts | B18: Warning | C18: Low Image Alt Coverage | D18: 0 | E18: Technical | F18: || Full list: see Technical/Links/Indexability tabs
A19: Issue Counts | B19: Warning | C19: Missing Meta Description | D19: 0 | E19: Technical | F19: || Full list: see Technical/Links/Indexability tabs
... A33: Issue Counts | B33: Info | C33: Uses URL Parameters | D33: 0 | E33: Technical | F33: || Full list: see Technical/Links/Indexability tabs
A34: Issue Counts
A35: Top 10 Critical URLs
A36: Top Issues by Template
A37: Top Issues by Template | B37: Info | C37: 2026-ascon-awards -> Low AEO Readiness Score | D37: 2 | E37: TemplateClusters
A38: Top Issues by Template | B38: Info | C38: 2026-ascon-awards -> No Compression Header | D38: 2 | E38: TemplateClusters
A39: Top Issues by Template | B39: Info | C39: 2026-ascon-awards -> No Cache-Control Header | D39: 2 | E39: TemplateClusters
A40: Top Issues by Template | B40: Info | C40: 2026-ascon-awards -> No ETag Header | D40: 2 | E40: TemplateClusters
A41: Top Issues by Template | B41: Info | C41: 2026-ascon-awards -> No FAQ/QA Schema | D41: 2 | E41: TemplateClusters
A42: Top Issues by Template | B42: Info | C42: 2026-ascon-awards -> No Question Headings | D42: 2 | E42: TemplateClusters
A43: Top Issues by Template | B43: Info | C43: 2026-ascon-awards -> No Answer-Friendly Structure | D43: 2 | E43: TemplateClusters
A44: Top Issues by Template | B44: Info | C44: 2026-ascon-awards -> No 40-60 Word Answer Paragraphs | D44: 2 | E44: TemplateClusters
A45: Top Issues by Template | B45: Info | C45: 2026-ascon-conference -> Low AEO Readiness Score | D45: 2 | E45: TemplateClusters
A46: Top Issues by Template | B46: Info | C46: 2026-ascon-conference -> No Compression Header | D46: 2 | E46: TemplateClusters
A47: Top Issues by Template | B47: Info | C47: 2026-ascon-conference -> No Cache-Control Header | D47: 2 | E47: TemplateClusters
A48: Top Issues by Template | B48: Info | C48: 2026-ascon-conference -> No ETag Header | D48: 2 | E48: TemplateClusters
... A56: Top Issues by Template | B56: Info | C56: launch-event-2026-ascon-conference -> No ETag Header | D56: 2 | E56: TemplateClusters

Sheet Main
A1: Health Icon | B1: URL | C1: Status Code | D1: Indexability | E1: Load Time (s) | F1: Title | G1: Meta Description | H1: Word Count (Body) | I1: SEO Health Score | J1: Severity Badge | K1: Title Length | L1: Meta Desc Length | M1: OG-Image | N1: Has Valid JSON-LD | O1: H1 Content | P1: H1 Length | Q1: H2 Content | R1: H2 Length | S1: H3 Content | T1: H3 Length | U1: H4 Content | V1: H4 Length | W1: H5 Content | X1: H5 Length | Y1: H6 Content | Z1: H6 Length | AA1: Technical View | AB1: BACK TO DASHBOARD
A2: WARN 🟡 | B2: https://asconafrica.org/ | C2: 200 | D2: Indexable | E2: 3.173 | F2: Home Page - ASCON | G2: African Supply Chain Confederation Unifying Professional Bodies, Empowering African Supply Chains African Supply Chain Confederation Unifying Professional Bodies,Empowering African Supply Chains Who We Are About Us The African Supply Chain Confederation (ASCON) unifies professional African supply chain standards and networks.Through collaboration, education, and advocacy, ASCON aims to foster a cohesive and impactful supply chain ecosystem | H2: 1322 | I2: 59 | J2: Warning | K2: 17 | L2: 443 | M2: 0 | N2: FALSE | O2: 0 | P2: 0 | Q2: 0 | R2: 0 | S2: 0 | T2: 0 | U2: 0 | V2: 0 | W2: 0 | X2: 0 | Y2: Warning | Z2: 0 | AA2: =IFERROR(HYPERLINK("#Technical!A"&MATCH(B2,Technical!A:A,0),"Open Technical"),HYPERLINK("#Technical!A1","Open Technical"))
A3: WARN 🟡 | B3: https://asconafrica.org/2026-ascon-awards/ | C3: 200 | D3: Indexable | E3: 2.662 | F3: 2026 ASCON Awards - ASCON | G3: 2026 Conference 2026 Awards Hamburger Toggle Menu Celebrating the Leaders Shaping Africa’s boardrooms Nominations are Now Open for the 2026 ASCON Awards Submit Your Nomination View the Awards Brochure The Leadership Value Behind the Honour Gain Industry Recognition Boost Your Credibility Strengthen Your Positioning Enhance Your Visibility Join us in Celebrating the Future CEOs of | H3: 1488 | I3: 69 | J3: Warning | K3: 25 | L3: 382 | M3: 0 | N3: FALSE | O3: 0 | P3: 0 | Q3: 0 | R3: 0 | S3: 0 | T3: 0 | U3: 0 | V3: 0 | W3: 0 | X3: 0 | Y3: Warning | Z3: 0 | AA3: =IFERROR(HYPERLINK("#Technical!A"&MATCH(B3,Technical!A:A,0),"Open Technical"),HYPERLINK("#Technical!A1","Open Technical"))
A4: WARN 🟡 | B4: https://asconafrica.org/2026-ascon-awards/thank-you-for-your-nomination/ | C4: 200 | D4: Indexable | E4: 0.582 | F4: Thank You for Your Nomination – ASCON Awards - ASCON | G4: 2026 Launch Event 2026 Conference Hamburger Toggle Menu Thank you for your nomination Recognising the Future CEOs of Africa 2026 ASCON Awards25 September 2026 You’ve helped recognise leadership across Africa’s supply chain. We look forward to seeing you at the 2026 ASCON Conference. | H4: 114 | I4: 59 | J4: Warning | K4: 52 | L4: 283 | M4: 0 | N4: FALSE | O4: 0 | P4: 0 | Q4: 0 | R4: 0 | S4: 0 | T4: 0 | U4: 0 | V4: 0 | W4: 0 | X4: 0 | Y4: Warning | Z4: 0 | AA4: =IFERROR(HYPERLINK("#Technical!A"&MATCH(B4,Technical!A:A,0),"Open Technical"),HYPERLINK("#Technical!A1","Open Technical"))
A5: WARN 🟡 | B5: https://asconafrica.org/2026-ascon-conference/ | C5: 200 | D5: Indexable | E5: 0.022 | F5: 2026 ASCON Conference - ASCON | G5: 2026 Conference Hamburger Toggle Menu 2026 ASCON Conference Conference 0 Days 0 Speakers 0 23-25 September 2026 Livingstone, Zambia Where Africa’s Supply Chain Leaders Shape Tomorrow The ASCON Conference is the premier gathering for supply chain leaders, innovators, and professionals across Africa. This three-day event will advance knowledge, strengthen networks, and accelerate Africa’s integration into global | H5: 1422 | I5: 69 | J5: Warning | K5: 29 | L5: 413 | M5: 0 | N5: FALSE | O5: 0 | P5: 0 | Q5: 0 | R5: 0 | S5: 0 | T5: 0 | U5: 0 | V5: 0 | W5: 0 | X5: 0 | Y5: Warning | Z5: 0 | AA5: =IFERROR(HYPERLINK("#Technical!A"&MATCH(B5,Technical!A:A,0),"Open Technical"),HYPERLINK("#Technical!A1","Open Technical"))
A6: WARN 🟡 | B6: https://asconafrica.org/2026-ascon-conference/thank-you-for-signing-up/ | C6: 200 | D6: Indexable | E6: 0.658 | F6: Thank You for Signing Up – ASCON Conference - ASCON | G6: 2026 Launch Event 2026 Conference Hamburger Toggle Menu You’re now connected to Africa’s supply chain future. 2026 ASCON Conference23-25 September 2026 Thank you for signing up for updates on the 2026 ASCON Conference.A confirmation email is on its way to your inbox. | H6: 113 | I6: 59 | J6: Warning | K6: 51 | L6: 267 | M6: 0 | N6: FALSE | O6: 0 | P6: 0 | Q6: 0 | R6: 0 | S6: 0 | T6: 0 | U6: 0 | V6: 0 | W6: 0 | X6: 0 | Y6: Warning | Z6: 0 | AA6: =IFERROR(HYPERLINK("#Technical!A"&MATCH(B6,Technical!A:A,0),"Open Technical"),HYPERLINK("#Technical!A1","Open Technical"))
A7: WARN 🟡 | B7: https://asconafrica.org/about-us/ | C7: 200 | D7: Indexable | E7: 0.013 | F7: About Us - ASCON | G7: Building Africa’s Supply Chain Future Together By connecting national efforts, supporting institutional growth, and enabling collaboration that accelerates progress across the continent. Who We Are The African Supply Chain Confederation (ASCON) is Africa’s Pan‑African continental body for supply chain excellence, uniting professionals and institutions to build shared standards and stronger capacity across regions. Established in 2025, it | H7: 950 | I7: 69 | J7: Warning | K7: 16 | L7: 441 | M7: 0 | N7: FALSE | O7: 0 | P7: 0 | Q7: 0 | R7: 0 | S7: 0 | T7: 0 | U7: 0 | V7: 0 | W7: 0 | X7: 0 | Y7: Warning | Z7: 0 | AA7: =IFERROR(HYPERLINK("#Technical!A"&MATCH(B7,Technical!A:A,0),"Open Technical"),HYPERLINK("#Technical!A1","Open Technical"))
A8: WARN 🟡 | B8: https://asconafrica.org/contact-us/ | C8: 200 | D8: Indexable | E8: 0.598 | F8: Contact Us - ASCON | G8: Reach Us Anytime Partner with ASCON to advance professionalism, collaboration, and innovation across the continent. Name(Required) First Last Email(Required) Enter Email Confirm Email Comments(Required)Please let us know what's on your mind. Have a question for us? Ask away. Δ National Office Johannesburg Number 2, 3rd Avenue, Parktown, Johannesburg, 2193 info@asconafrica.org | H8: 124 | I8: 49 | J8: Warning | K8: 18 | L8: 378 | M8: 0 | N8: FALSE | O8: 0 | P8: 0 | Q8: 0 | R8: 0 | S8: 0 | T8: 0 | U8: 0 | V8: 0 | W8: 0 | X8: 0 | Y8: Warning | Z8: 0 | AA8: =IFERROR(HYPERLINK("#Technical!A"&MATCH(B8,Technical!A:A,0),"Open Technical"),HYPERLINK("#Technical!A1","Open Technical"))
A9: WARN 🟡 | B9: https://asconafrica.org/launch-event-2026-ascon-conference/ | C9: 200 | D9: Indexable | E9: 0.026 | F9: Launch Event – 2026 ASCON Conference - ASCON | G9: 2026 Launch Event 2026 Conference Hamburger Toggle Menu Africa’s Rise Starts Here Official Launch Event for the2026 ASCON Conference The 2026 ASCON Conferencehas Official been Launched Shape the Future of the Continent The journey toward 2026 has officially begun. If you missed the live launch of the 2026 ASCON Conference, you can now watch the | H9: 747 | I9: 69 | J9: Warning | K9: 44 | L9: 346 | M9: 0 | N9: FALSE | O9: 0 | P9: 0 | Q9: 0 | R9: 0 | S9: 0 | T9: 0 | U9: 0 | V9: 0 | W9: 0 | X9: 0 | Y9: Warning | Z9: 0 | AA9: =IFERROR(HYPERLINK("#Technical!A"&MATCH(B9,Technical!A:A,0),"Open Technical"),HYPERLINK("#Technical!A1","Open Technical"))
A10: WARN 🟡 | B10: https://asconafrica.org/launch-event-2026-ascon-conference/thank-you-for-registering-conference-launch/ | C10: 200 | D10: Indexable | E10: 0.702 | F10: Thank You for Registering – Conference Launch - ASCON | G10: 2026 Launch Event 2026 Conference Hamburger Toggle Menu Africa’s Rise Starts Here Thank you for registering for the 2026 ASCON Conference Launch Event A confirmation email is on its way to your inbox. | H10: 102 | I10: 59 | J10: Warning | K10: 53 | L10: 200 | M10: 0 | N10: FALSE | O10: 0 | P10: 0 | Q10: 0 | R10: 0 | S10: 0 | T10: 0 | U10: 0 | V10: 0 | W10: 0 | X10: 0 | Y10: Warning | Z10: 0 | AA10: =IFERROR(HYPERLINK("#Technical!A"&MATCH(B10,Technical!A:A,0),"Open Technical"),HYPERLINK("#Technical!A1","Open Technical"))
A11: WARN 🟡 | B11: https://asconafrica.org/news/ | C11: 200 | D11: Indexable | E11: 0.017 | F11: News - ASCON | G11: Insights That Shape Africa’s Supply Chain Future Stay informed with the latest updates, thought leadership, and industry trends from ASCON and our member organisations. Featured News Africa Rises as Three Continental Conferences...Three African bodies unite to launch conferences driving marketing, technology and supply chain growth, advancing the continent’s ‘Africa Rising’ vision. February 25, 2026 Read | H11: 313 | I11: 59 | J11: Warning | K11: 12 | L11: 407 | M11: 0 | N11: FALSE | O11: 0 | P11: 0 | Q11: 0 | R11: 0 | S11: 0 | T11: 0 | U11: 0 | V11: 0 | W11: 0 | X11: 0 | Y11: Warning | Z11: 0 | AA11: =IFERROR(HYPERLINK("#Technical!A"&MATCH(B11,Technical!A:A,0),"Open Technical"),HYPERLINK("#Technical!A1","Open Technical"))
A12: WARN 🟡 | B12: https://asconafrica.org/our-members/ | C12: 200 | D12: Indexable | E12: 0.839 | F12: Our Members - ASCON | G12: Our Members United for Africa’s Supply Chain Excellence One Vision. We celebrate the diversity of our membership and recognise the invaluable contributions of both longstanding pioneers and emerging leaders. Every member organisation plays a vital role in shaping Africa’s supply chain future.Ready to join this continental movement? Apply for Membership Today Our Members The African | H12: 208 | I12: 59 | J12: Warning | K12: 19 | L12: 384 | M12: 0 | N12: FALSE | O12: 0 | P12: 0 | Q12: 0 | R12: 0 | S12: 0 | T12: 0 | U12: 0 | V12: 0 | W12: 0 | X12: 0 | Y12: Warning | Z12: 0 | AA12: =IFERROR(HYPERLINK("#Technical!A"&MATCH(B12,Technical!A:A,0),"Open Technical"),HYPERLINK("#Technical!A1","Open Technical"))
A13: WARN 🟡 | B13: https://asconafrica.org/privacy-policy/ | C13: 200 | D13: Indexable | E13: 0.547 | F13: Privacy Policy - ASCON | G13: Privacy Policy Last updated March 26, 2026 This privacy notice for African Supply Chain Confederation (ASCON) ('we', 'us', or 'our'), describes how and why we might collect, store, use, and/or share ('process') your information when you use our services ('Services'), such as when you: Visit our website at https://asconafrica.org/, or any website of ours that links to this privacy notice Engage | H13: 2952 | I13: 65 | J13: Warning | K13: 22 | L13: 396 | M13: 0 | N13: FALSE | O13: 0 | P13: 0 | Q13: 0 | R13: 0 | S13: 0 | T13: 0 | U13: 0 | V13: 0 | W13: 0 | X13: 0 | Y13: Warning | Z13: 0 | AA13: =IFERROR(HYPERLINK("#Technical!A"&MATCH(B13,Technical!A:A,0),"Open Technical"),HYPERLINK("#Technical!A1","Open Technical"))
... A16: WARN 🟡 | B16: https://asconafrica.org/unsubscribe-form/successfully-unsubscribed/ | C16: 200 | D16: Indexable | E16: 0.552 | F16: Successfully Unsubscribed - ASCON | G16: We're sad to see you go You have been successfully unsubscribed.Your details will be removed from our mailing list. | H16: 90 | I16: 49 | J16: Warning | K16: 33 | L16: 115 | M16: 0 | N16: FALSE | O16: 0 | P16: 0 | Q16: 0 | R16: 0 | S16: 0 | T16: 0 | U16: 0 | V16: 0 | W16: 0 | X16: 0 | Y16: Warning | Z16: 0 | AA16: =IFERROR(HYPERLINK("#Technical!A"&MATCH(B16,Technical!A:A,0),"Open Technical"),HYPERLINK("#Technical!A1","Open Technical"))

Sheet Technical
A1: URL | B1: Status Code | C1: Status Class | D1: SEO Health Score | E1: Severity Badge | F1: Action Needed | G1: Indexability Reason | H1: TTFB (ms) | I1: Total Request Time (ms) | J1: Final URL | K1: Canonical URL | L1: Canonical Type | M1: Owner | N1: Status | O1: Sprint | P1: Health Icon | Q1: Protocol | R1: Redirect Chain Length | S1: Redirect Target | T1: Redirect Hops | U1: HTTP->HTTPS Redirect | V1: Content-Type | W1: HTTP Version | X1: HTML Size (KB) | Y1: Compression Enabled | Z1: Cache-Control | AA1: ETag | AB1: X-Robots-Tag | AC1: Meta Robots Raw | AD1: Canonical Matches Final URL | AE1: Canonical Absolute URL | AF1: Canonical in Sitemap Match | AG1: Hreflang Present | AH1: Hreflang Count | AI1: Hreflang Self Reference | AJ1: Hreflang Reciprocal Check | AK1: Hreflang Canonical Consistency | AL1: x-default Present | AM1: Pagination rel=next | AN1: Pagination rel=prev | AO1: Last-Modified | AP1: Published Date | AQ1: Modified Date | AR1: Last Updated | AS1: Change Frequency | AT1: Priority | AU1: Critical Issues Count | AV1: Warning Issues Count | AW1: Info Issues Count | AX1: Inlinks Bucket | AY1: Important But Underlinked | AZ1: SERP Title Truncation Risk | BA1: SERP Meta Truncation Risk | BB1: SERP Title Pixel Approx | BC1: SERP Meta Pixel Approx | BD1: Cannibalization Hint | BE1: Stable Issue IDs | BF1: URL Depth | BG1: Param URL Flag | BH1: Open in Main | BI1: BACK TO DASHBOARD
A2: https://asconafrica.org/ | B2: 200 | C2: 2xx | D2: 59 | E2: Warning | F2: Yes | G2: Indexable | H2: 726.78 | I2: 767.94 | J2: https://asconafrica.org/ | K2: https | L2: 0 | M2: Copy Writer | N2: Open | P2: WARN 🟡 | Q2: https | R2: 0 | S2: text/html; charset=UTF-8 | T2: HTTP/1.1 | U2: FALSE | V2: text/html; charset=UTF-8 | W2: HTTP/1.1 | X2: 232.08 | Y2: FALSE | AF2: FALSE | AG2: FALSE | AH2: 0 | AI2: FALSE | AK2: FALSE | AL2: FALSE | AM2: FALSE | AN2: FALSE | AQ2: 2026-04-16T11:37:51+00:00 | AR2: 2026-04-16T11:37:51+00:00 | AS2: always | AT2: 1 | AU2: 0 | AV2: 2 | AW2: 7 | AX2: 0 | AY2: TRUE | AZ2: FALSE | BA2: FALSE | BB2: 122 | BC2: 2746 | BE2: https://asconafrica.org/::missing_h1 | https://asconafrica.org/::low_aeo_readiness_score | https://asconafrica.org/::no_compression_header | https://asconafrica.org/::no_cache-control_header | https://asconafrica.org/::no_etag_header | https://asconafrica.org/::no_faq_qa_schema | https://asconafrica.org/::no_question_headings | https://asconafrica.org/::no_answer-friendly_structure | https://asconafrica.org/::no_40-60_word_answer_paragraphs | BF2: 0 | BG2: FALSE | BH2: =IFERROR(HYPERLINK("#Main!A"&MATCH(A2,Main!A:A,0),"Open"),HYPERLINK("#Main!A1","Open"))
A3: https://asconafrica.org/2026-ascon-awards/ | B3: 200 | C3: 2xx | D3: 69 | E3: Warning | F3: Yes | G3: Indexable | H3: 2662.31 | I3: 2709.96 | J3: https://asconafrica.org/2026-ascon-awards/ | K3: https | L3: 0 | M3: Copy Writer | N3: Open | P3: WARN 🟡 | Q3: https | R3: 0 | S3: text/html; charset=UTF-8 | T3: HTTP/1.1 | U3: FALSE | V3: text/html; charset=UTF-8 | W3: HTTP/1.1 | X3: 236.84 | Y3: FALSE | AF3: FALSE | AG3: FALSE | AH3: 0 | AI3: FALSE | AK3: FALSE | AL3: FALSE | AM3: FALSE | AN3: FALSE | AQ3: 2026-04-24T13:56:35+00:00 | AR3: 2026-04-24T13:56:35+00:00 | AS3: weekly | AT3: 0.7 | AU3: 0 | AV3: 1 | AW3: 7 | AX3: 0 | AY3: TRUE | AZ3: FALSE | BA3: FALSE | BB3: 180 | BC3: 2368 | BE3: https://asconafrica.org/2026-ascon-awards/::low_aeo_readiness_score | https://asconafrica.org/2026-ascon-awards/::no_compression_header | https://asconafrica.org/2026-ascon-awards/::no_cache-control_header | https://asconafrica.org/2026-ascon-awards/::no_etag_header | https://asconafrica.org/2026-ascon-awards/::no_faq_qa_schema | https://asconafrica.org/2026-ascon-awards/::no_question_headings | https://asconafrica.org/2026-ascon-awards/::no_answer-friendly_structure | https://asconafrica.org/2026-ascon-awards/::no_40-60_word_answer_paragraphs | BF3: 1 | BG3: FALSE | BH3: =IFERROR(HYPERLINK("#Main!A"&MATCH(A3,Main!A:A,0),"Open"),HYPERLINK("#Main!A1","Open"))
A4: https://asconafrica.org/2026-ascon-awards/thank-you-for-your-nomination/ | B4: 200 | C4: 2xx | D4: 59 | E4: Warning | F4: Yes | G4: Indexable | H4: 581.68 | I4: 597.71 | J4: https://asconafrica.org/2026-ascon-awards/thank-you-for-your-nomination/ | K4: https | L4: 0 | M4: Copy Writer | N4: Open | P4: WARN 🟡 | Q4: https | R4: 0 | S4: text/html; charset=UTF-8 | T4: HTTP/1.1 | U4: FALSE | V4: text/html; charset=UTF-8 | W4: HTTP/1.1 | X4: 78.78 | Y4: FALSE | AF4: FALSE | AG4: FALSE | AH4: 0 | AI4: FALSE | AK4: FALSE | AL4: FALSE | AM4: FALSE | AN4: FALSE | AQ4: 2026-03-26T06:47:09+00:00 | AR4: 2026-03-26T06:47:09+00:00 | AS4: weekly | AT4: 0.7 | AU4: 0 | AV4: 2 | AW4: 7 | AX4: 0 | AY4: TRUE | AZ4: FALSE | BA4: FALSE | BB4: 374 | BC4: 1754 | BE4: https://asconafrica.org/2026-ascon-awards/thank-you-for-your-nomination/::thin_content | https://asconafrica.org/2026-ascon-awards/thank-you-for-your-nomination/::low_aeo_readiness_score | https://asconafrica.org/2026-ascon-awards/thank-you-for-your-nomination/::no_compression_header | https://asconafrica.org/2026-ascon-awards/thank-you-for-your-nomination/::no_cache-control_header | https://asconafrica.org/2026-ascon-awards/thank-you-for-your-nomination/::no_etag_header | https://asconafrica.org/2026-ascon-awards/thank-you-for-your-nomination/::no_faq_qa_schema | https://asconafrica.org/2026-ascon-awards/thank-you-for-your-nomination/::no_question_headings | https://asconafrica.org/2026-ascon-awards/thank-you-for-your-nomination/::no_answer-friendly_structure | https://asconafrica.org/2026-ascon-awards/thank-you-for-your-nomination/::no_40-60_word_answer_paragraphs | BF4: 2 | BG4: FALSE | BH4: =IFERROR(HYPERLINK("#Main!A"&MATCH(A4,Main!A:A,0),"Open"),HYPERLINK("#Main!A1","Open"))
A5: https://asconafrica.org/2026-ascon-conference/ | B5: 200 | C5: 2xx | D5: 69 | E5: Warning | F5: Yes | G5: Indexable | H5: 21.99 | I5: 56.13 | J5: https://asconafrica.org/2026-ascon-conference/ | K5: https | L5: 0 | M5: Copy Writer | N5: Open | P5: WARN 🟡 | Q5: https | R5: 0 | S5: text/html; charset=UTF-8 | T5: HTTP/1.1 | U5: FALSE | V5: text/html; charset=UTF-8 | W5: HTTP/1.1 | X5: 238.13 | Y5: FALSE | AF5: FALSE | AG5: FALSE | AH5: 0 | AI5: FALSE | AK5: FALSE | AL5: FALSE | AM5: FALSE | AN5: FALSE | AQ5: 2026-04-14T11:21:18+00:00 | AR5: 2026-04-14T11:21:18+00:00 | AS5: weekly | AT5: 0.7 | AU5: 0 | AV5: 1 | AW5: 7 | AX5: 0 | AY5: TRUE | AZ5: FALSE | BA5: FALSE | BB5: 208 | BC5: 2560 | BE5: https://asconafrica.org/2026-ascon-conference/::low_aeo_readiness_score | https://asconafrica.org/2026-ascon-conference/::no_compression_header | https://asconafrica.org/2026-ascon-conference/::no_cache-control_header | https://asconafrica.org/2026-ascon-conference/::no_etag_header | https://asconafrica.org/2026-ascon-conference/::no_faq_qa_schema | https://asconafrica.org/2026-ascon-conference/::no_question_headings | https://asconafrica.org/2026-ascon-conference/::no_answer-friendly_structure | https://asconafrica.org/2026-ascon-conference/::no_40-60_word_answer_paragraphs | BF5: 1 | BG5: FALSE | BH5: =IFERROR(HYPERLINK("#Main!A"&MATCH(A5,Main!A:A,0),"Open"),HYPERLINK("#Main!A1","Open"))
A6: https://asconafrica.org/2026-ascon-conference/thank-you-for-signing-up/ | B6: 200 | C6: 2xx | D6: 59 | E6: Warning | F6: Yes | G6: Indexable | H6: 658.66 | I6: 679.01 | J6: https://asconafrica.org/2026-ascon-conference/thank-you-for-signing-up/ | K6: https | L6: 0 | M6: Copy Writer | N6: Open | P6: WARN 🟡 | Q6: https | R6: 0 | S6: text/html; charset=UTF-8 | T6: HTTP/1.1 | U6: FALSE | V6: text/html; charset=UTF-8 | W6: HTTP/1.1 | X6: 79.23 | Y6: FALSE | AF6: FALSE | AG6: FALSE | AH6: 0 | AI6: FALSE | AK6: FALSE | AL6: FALSE | AM6: FALSE | AN6: FALSE | AQ6: 2026-03-26T07:04:42+00:00 | AR6: 2026-03-26T07:04:42+00:00 | AS6: weekly | AT6: 0.7 | AU6: 0 | AV6: 2 | AW6: 7 | AX6: 0 | AY6: TRUE | AZ6: FALSE | BA6: FALSE | BB6: 367 | BC6: 1655 | BE6: https://asconafrica.org/2026-ascon-conference/thank-you-for-signing-up/::thin_content | https://asconafrica.org/2026-ascon-conference/thank-you-for-signing-up/::low_aeo_readiness_score | https://asconafrica.org/2026-ascon-conference/thank-you-for-signing-up/::no_compression_header | https://asconafrica.org/2026-ascon-conference/thank-you-for-signing-up/::no_cache-control_header | https://asconafrica.org/2026-ascon-conference/thank-you-for-signing-up/::no_etag_header | https://asconafrica.org/2026-ascon-conference/thank-you-for-signing-up/::no_faq_qa_schema | https://asconafrica.org/2026-ascon-conference/thank-you-for-signing-up/::no_question_headings | https://asconafrica.org/2026-ascon-conference/thank-you-for-signing-up/::no_answer-friendly_structure | https://asconafrica.org/2026-ascon-conference/thank-you-for-signing-up/::no_40-60_word_answer_paragraphs | BF6: 2 | BG6: FALSE | BH6: =IFERROR(HYPERLINK("#Main!A"&MATCH(A6,Main!A:A,0),"Open"),HYPERLINK("#Main!A1","Open"))
A7: https://asconafrica.org/about-us/ | B7: 200 | C7: 2xx | D7: 69 | E7: Warning | F7: Yes | G7: Indexable | H7: 12.96 | I7: 44.48 | J7: https://asconafrica.org/about-us/ | K7: https | L7: 0 | M7: Copy Writer | N7: Open | P7: WARN 🟡 | Q7: https | R7: 0 | S7: text/html; charset=UTF-8 | T7: HTTP/1.1 | U7: FALSE | V7: text/html; charset=UTF-8 | W7: HTTP/1.1 | X7: 203.68 | Y7: FALSE | AF7: FALSE | AG7: FALSE | AH7: 0 | AI7: FALSE | AK7: FALSE | AL7: FALSE | AM7: FALSE | AN7: FALSE | AQ7: 2026-04-09T14:49:22+00:00 | AR7: 2026-04-09T14:49:22+00:00 | AS7: weekly | AT7: 0.7 | AU7: 0 | AV7: 1 | AW7: 7 | AX7: 0 | AY7: TRUE | AZ7: FALSE | BA7: FALSE | BB7: 115 | BC7: 2734 | BE7: https://asconafrica.org/about-us/::low_aeo_readiness_score | https://asconafrica.org/about-us/::no_compression_header | https://asconafrica.org/about-us/::no_cache-control_header | https://asconafrica.org/about-us/::no_etag_header | https://asconafrica.org/about-us/::no_faq_qa_schema | https://asconafrica.org/about-us/::no_question_headings | https://asconafrica.org/about-us/::no_answer-friendly_structure | https://asconafrica.org/about-us/::no_40-60_word_answer_paragraphs | BF7: 1 | BG7: FALSE | BH7: =IFERROR(HYPERLINK("#Main!A"&MATCH(A7,Main!A:A,0),"Open"),HYPERLINK("#Main!A1","Open"))
A8: https://asconafrica.org/contact-us/ | B8: 200 | C8: 2xx | D8: 49 | E8: Warning | F8: Yes | G8: Indexable | H8: 598.32 | I8: 614.01 | J8: https://asconafrica.org/contact-us/ | K8: https | L8: 0 | M8: Copy Writer | N8: Open | P8: WARN 🟡 | Q8: https | R8: 0 | S8: text/html; charset=UTF-8 | T8: HTTP/1.1 | U8: FALSE | V8: text/html; charset=UTF-8 | W8: HTTP/1.1 | X8: 101.19 | Y8: FALSE | AF8: FALSE | AG8: FALSE | AH8: 0 | AI8: FALSE | AK8: FALSE | AL8: FALSE | AM8: FALSE | AN8: FALSE | AQ8: 2026-02-13T11:31:00+00:00 | AR8: 2026-02-13T11:31:00+00:00 | AS8: weekly | AT8: 0.7 | AU8: 0 | AV8: 3 | AW8: 7 | AX8: 0 | AY8: TRUE | AZ8: FALSE | BA8: FALSE | BB8: 129 | BC8: 2343 | BE8: https://asconafrica.org/contact-us/::missing_h1 | https://asconafrica.org/contact-us/::thin_content | https://asconafrica.org/contact-us/::low_aeo_readiness_score | https://asconafrica.org/contact-us/::no_compression_header | https://asconafrica.org/contact-us/::no_cache-control_header | https://asconafrica.org/contact-us/::no_etag_header | https://asconafrica.org/contact-us/::no_faq_qa_schema | https://asconafrica.org/contact-us/::no_question_headings | https://asconafrica.org/contact-us/::no_answer-friendly_structure | https://asconafrica.org/contact-us/::no_40-60_word_answer_paragraphs | BF8: 1 | BG8: FALSE | BH8: =IFERROR(HYPERLINK("#Main!A"&MATCH(A8,Main!A:A,0),"Open"),HYPERLINK("#Main!A1","Open"))
A9: https://asconafrica.org/launch-event-2026-ascon-conference/ | B9: 200 | C9: 2xx | D9: 69 | E9: Warning | F9: Yes | G9: Indexable | H9: 26.28 | I9: 77.4 | J9: https://asconafrica.org/launch-event-2026-ascon-conference/ | K9: https | L9: 0 | M9: Copy Writer | N9: Open | P9: WARN 🟡 | Q9: https | R9: 0 | S9: text/html; charset=UTF-8 | T9: HTTP/1.1 | U9: FALSE | V9: text/html; charset=UTF-8 | W9: HTTP/1.1 | X9: 151.07 | Y9: FALSE | AF9: FALSE | AG9: FALSE | AH9: 0 | AI9: FALSE | AK9: FALSE | AL9: FALSE | AM9: FALSE | AN9: FALSE | AQ9: 2026-03-19T14:12:48+00:00 | AR9: 2026-03-19T14:12:48+00:00 | AS9: weekly | AT9: 0.7 | AU9: 0 | AV9: 1 | AW9: 7 | AX9: 0 | AY9: TRUE | AZ9: FALSE | BA9: FALSE | BB9: 316 | BC9: 2145 | BE9: https://asconafrica.org/launch-event-2026-ascon-conference/::low_aeo_readiness_score | https://asconafrica.org/launch-event-2026-ascon-conference/::no_compression_header | https://asconafrica.org/launch-event-2026-ascon-conference/::no_cache-control_header | https://asconafrica.org/launch-event-2026-ascon-conference/::no_etag_header | https://asconafrica.org/launch-event-2026-ascon-conference/::no_faq_qa_schema | https://asconafrica.org/launch-event-2026-ascon-conference/::no_question_headings | https://asconafrica.org/launch-event-2026-ascon-conference/::no_answer-friendly_structure | https://asconafrica.org/launch-event-2026-ascon-conference/::no_40-60_word_answer_paragraphs | BF9: 1 | BG9: FALSE | BH9: =IFERROR(HYPERLINK("#Main!A"&MATCH(A9,Main!A:A,0),"Open"),HYPERLINK("#Main!A1","Open"))
A10: https://asconafrica.org/launch-event-2026-ascon-conference/thank-you-for-registering-conference-launch/ | B10: 200 | C10: 2xx | D10: 59 | E10: Warning | F10: Yes | G10: Indexable | H10: 701.89 | I10: 715.92 | J10: https://asconafrica.org/launch-event-2026-ascon-conference/thank-you-for-registering-conference-launch/ | K10: https | L10: 0 | M10: Copy Writer | N10: Open | P10: WARN 🟡 | Q10: https | R10: 0 | S10: text/html; charset=UTF-8 | T10: HTTP/1.1 | U10: FALSE | V10: text/html; charset=UTF-8 | W10: HTTP/1.1 | X10: 78.42 | Y10: FALSE | AF10: FALSE | AG10: FALSE | AH10: 0 | AI10: FALSE | AK10: FALSE | AL10: FALSE | AM10: FALSE | AN10: FALSE | AQ10: 2026-03-26T06:51:40+00:00 | AR10: 2026-03-26T06:51:40+00:00 | AS10: weekly | AT10: 0.7 | AU10: 0 | AV10: 2 | AW10: 7 | AX10: 0 | AY10: TRUE | AZ10: FALSE | BA10: FALSE | BB10: 381 | BC10: 1240 | BE10: https://asconafrica.org/launch-event-2026-ascon-conference/thank-you-for-registering-conference-launch/::thin_content | https://asconafrica.org/launch-event-2026-ascon-conference/thank-you-for-registering-conference-launch/::low_aeo_readiness_score | https://asconafrica.org/launch-event-2026-ascon-conference/thank-you-for-registering-conference-launch/::no_compression_header | https://asconafrica.org/launch-event-2026-ascon-conference/thank-you-for-registering-conference-launch/::no_cache-control_header | https://asconafrica.org/launch-event-2026-ascon-conference/thank-you-for-registering-conference-launch/::no_etag_header | https://asconafrica.org/launch-event-2026-ascon-conference/thank-you-for-registering-conference-launch/::no_faq_qa_schema | https://asconafrica.org/launch-event-2026-ascon-conference/thank-you-for-registering-conference-launch/::no_question_headings | https://asconafrica.org/launch-event-2026-ascon-conference/thank-you-for-registering-conference-launch/::no_answer-friendly_structure | https://asconafrica.org/launch-event-2026-ascon-conference/thank-you-for-registering-conference-launch/::no_40-60_word_answer_paragraphs | BF10: 2 | BG10: FALSE | BH10: =IFERROR(HYPERLINK("#Main!A"&MATCH(A10,Main!A:A,0),"Open"),HYPERLINK("#Main!A1","Open"))
A11: https://asconafrica.org/news/ | B11: 200 | C11: 2xx | D11: 59 | E11: Warning | F11: Yes | G11: Indexable | H11: 16.04 | I11: 30.33 | J11: https://asconafrica.org/news/ | K11: https | L11: 0 | M11: Copy Writer | N11: Open | P11: WARN 🟡 | Q11: https | R11: 0 | S11: text/html; charset=UTF-8 | T11: HTTP/1.1 | U11: FALSE | V11: text/html; charset=UTF-8 | W11: HTTP/1.1 | X11: 101.94 | Y11: FALSE | AF11: FALSE | AG11: FALSE | AH11: 0 | AI11: FALSE | AK11: FALSE | AL11: FALSE | AM11: FALSE | AN11: FALSE | AQ11: 2026-04-14T11:49:34+00:00 | AR11: 2026-04-14T11:49:34+00:00 | AS11: weekly | AT11: 0.7 | AU11: 0 | AV11: 2 | AW11: 7 | AX11: 0 | AY11: TRUE | AZ11: FALSE | BA11: FALSE | BB11: 86 | BC11: 2523 | BE11: https://asconafrica.org/news/::missing_h1 | https://asconafrica.org/news/::low_aeo_readiness_score | https://asconafrica.org/news/::no_compression_header | https://asconafrica.org/news/::no_cache-control_header | https://asconafrica.org/news/::no_etag_header | https://asconafrica.org/news/::no_faq_qa_schema | https://asconafrica.org/news/::no_question_headings | https://asconafrica.org/news/::no_answer-friendly_structure | https://asconafrica.org/news/::no_40-60_word_answer_paragraphs | BF11: 1 | BG11: FALSE | BH11: =IFERROR(HYPERLINK("#Main!A"&MATCH(A11,Main!A:A,0),"Open"),HYPERLINK("#Main!A1","Open"))
A12: https://asconafrica.org/our-members/ | B12: 200 | C12: 2xx | D12: 59 | E12: Warning | F12: Yes | G12: Indexable | H12: 839.5 | I12: 860.49 | J12: https://asconafrica.org/our-members/ | K12: https | L12: 0 | M12: Copy Writer | N12: Open | P12: WARN 🟡 | Q12: https | R12: 0 | S12: text/html; charset=UTF-8 | T12: HTTP/1.1 | U12: FALSE | V12: text/html; charset=UTF-8 | W12: HTTP/1.1 | X12: 87.07 | Y12: FALSE | AF12: FALSE | AG12: FALSE | AH12: 0 | AI12: FALSE | AK12: FALSE | AL12: FALSE | AM12: FALSE | AN12: FALSE | AQ12: 2026-04-16T11:43:28+00:00 | AR12: 2026-04-16T11:43:28+00:00 | AS12: weekly | AT12: 0.7 | AU12: 0 | AV12: 2 | AW12: 7 | AX12: 0 | AY12: TRUE | AZ12: FALSE | BA12: FALSE | BB12: 136 | BC12: 2380 | BE12: https://asconafrica.org/our-members/::thin_content | https://asconafrica.org/our-members/::low_aeo_readiness_score | https://asconafrica.org/our-members/::no_compression_header | https://asconafrica.org/our-members/::no_cache-control_header | https://asconafrica.org/our-members/::no_etag_header | https://asconafrica.org/our-members/::no_faq_qa_schema | https://asconafrica.org/our-members/::no_question_headings | https://asconafrica.org/our-members/::no_answer-friendly_structure | https://asconafrica.org/our-members/::no_40-60_word_answer_paragraphs | BF12: 1 | BG12: FALSE | BH12: =IFERROR(HYPERLINK("#Main!A"&MATCH(A12,Main!A:A,0),"Open"),HYPERLINK("#Main!A1","Open"))
A13: https://asconafrica.org/privacy-policy/ | B13: 200 | C13: 2xx | D13: 65 | E13: Warning | F13: Yes | G13: Indexable | H13: 546.89 | I13: 558.86 | J13: https://asconafrica.org/privacy-policy/ | K13: https | L13: 0 | M13: Copy Writer | N13: Open | P13: WARN 🟡 | Q13: https | R13: 0 | S13: text/html; charset=UTF-8 | T13: HTTP/1.1 | U13: FALSE | V13: text/html; charset=UTF-8 | W13: HTTP/1.1 | X13: 135.74 | Y13: FALSE | AF13: FALSE | AG13: FALSE | AH13: 0 | AI13: FALSE | AK13: FALSE | AL13: FALSE | AM13: FALSE | AN13: FALSE | AQ13: 2026-03-26T14:35:45+00:00 | AR13: 2026-03-26T14:35:45+00:00 | AS13: weekly | AT13: 0.7 | AU13: 0 | AV13: 2 | AW13: 5 | AX13: 0 | AY13: TRUE | AZ13: FALSE | BA13: FALSE | BB13: 158 | BC13: 2455 | BE13: https://asconafrica.org/privacy-policy/::missing_h1 | https://asconafrica.org/privacy-policy/::low_aeo_readiness_score | https://asconafrica.org/privacy-policy/::no_compression_header | https://asconafrica.org/privacy-policy/::no_cache-control_header | https://asconafrica.org/privacy-policy/::no_etag_header | https://asconafrica.org/privacy-policy/::no_faq_qa_schema | https://asconafrica.org/privacy-policy/::no_answer-friendly_structure | BF13: 1 | BG13: FALSE | BH13: =IFERROR(HYPERLINK("#Main!A"&MATCH(A13,Main!A:A,0),"Open"),HYPERLINK("#Main!A1","Open"))
... A16: https://asconafrica.org/unsubscribe-form/successfully-unsubscribed/ | B16: 200 | C16: 2xx | D16: 49 | E16: Warning | F16: Yes | G16: Indexable | H16: 552.28 | I16: 573.61 | J16: https://asconafrica.org/unsubscribe-form/successfully-unsubscribed/ | K16: https | L16: 0 | M16: Copy Writer | N16: Open | P16: WARN 🟡 | Q16: https | R16: 0 | S16: text/html; charset=UTF-8 | T16: HTTP/1.1 | U16: FALSE | V16: text/html; charset=UTF-8 | W16: HTTP/1.1 | X16: 71.79 | Y16: FALSE | AF16: FALSE | AG16: FALSE | AH16: 0 | AI16: FALSE | AK16: FALSE | AL16: FALSE | AM16: FALSE | AN16: FALSE | AQ16: 2026-03-04T06:32:51+00:00 | AR16: 2026-03-04T06:32:51+00:00 | AS16: weekly | AT16: 0.7 | AU16: 0 | AV16: 3 | AW16: 7 | AX16: 0 | AY16: TRUE | AZ16: FALSE | BA16: FALSE | BB16: 237 | BC16: 713 | BE16: https://asconafrica.org/unsubscribe-form/successfully-unsubscribed/::missing_h1 | https://asconafrica.org/unsubscribe-form/successfully-unsubscribed/::thin_content | https://asconafrica.org/unsubscribe-form/successfully-unsubscribed/::low_aeo_readiness_score | https://asconafrica.org/unsubscribe-form/successfully-unsubscribed/::no_compression_header | https://asconafrica.org/unsubscribe-form/successfully-unsubscribed/::no_cache-control_header | https://asconafrica.org/unsubscribe-form/successfully-unsubscribed/::no_etag_header | https://asconafrica.org/unsubscribe-form/successfully-unsubscribed/::no_faq_qa_schema | https://asconafrica.org/unsubscribe-form/successfully-unsubscribed/::no_question_headings | https://asconafrica.org/unsubscribe-form/successfully-unsubscribed/::no_answer-friendly_structure | https://asconafrica.org/unsubscribe-form/successfully-unsubscribed/::no_40-60_word_answer_paragraphs | BF16: 2 | BG16: FALSE | BH16: =IFERROR(HYPERLINK("#Main!A"&MATCH(A16,Main!A:A,0),"Open"),HYPERLINK("#Main!A1","Open"))

Sheet FixPlan
A1: Issue Type | B1: Severity | C1: Priority Score | D1: Affected Count | E1: Affected URLs | F1: URL | G1: Recommended Fix | H1: Likely Root Cause | I1: Owner | J1: Agency Owner | K1: Effort | L1: Est. Hours | M1: Est. Sprint Points | N1: Aging/Priority | O1: Status | P1: Action Needed | Q1: Jump to Details | R1: Sprint | S1: Category | T1: View Details | U1: Open in Main | V1: BACK TO DASHBOARD
A2: Non-200 Status | B2: Critical | C2: 105 | D2: 0 | G2: Fix status code, restore page, or implement correct redirect to canonical destination. | H2: URL returns 4xx/5xx or equivalent failure. | I2: Server/Host | J2: Server/Host | K2: M | L2: 10 | M2: 5 | N2: Immediate (Current Sprint) | O2: To Do | P2: Yes | Q2: =HYPERLINK("#Main!A1","Open Main") | S2: SEO | T2: =IFERROR(HYPERLINK("#Main!A"&MATCH(F2,Main!A:A,0),"View URL Details"),HYPERLINK("#Main!A1","View URL Details")) | U2: =IFERROR(HYPERLINK("#Main!A"&MATCH(F2,Main!A:A,0),"Open"),HYPERLINK("#Main!A1","Open"))
A3: Noindex Directive | B3: Critical | C3: 105 | D3: 0 | G3: Remove unintended noindex directives on index-worthy URLs. | H3: Meta robots or X-Robots-Tag contains noindex. | I3: Dev | J3: Dev | K3: M | L3: 10 | M3: 5 | N3: Immediate (Current Sprint) | O3: To Do | P3: Yes | Q3: =HYPERLINK("#Main!A1","Open Main") | S3: SEO | T3: =IFERROR(HYPERLINK("#Main!A"&MATCH(F3,Main!A:A,0),"View URL Details"),HYPERLINK("#Main!A1","View URL Details")) | U3: =IFERROR(HYPERLINK("#Main!A"&MATCH(F3,Main!A:A,0),"Open"),HYPERLINK("#Main!A1","Open"))
A4: Canonical Points Elsewhere | B4: Critical | C4: 105 | D4: 0 | G4: Align canonical to preferred final URL and ensure internal links use canonical target. | H4: Canonical targets a different URL variant. | I4: Dev | J4: Dev | K4: M | L4: 10 | M4: 5 | N4: Immediate (Current Sprint) | O4: To Do | P4: Yes | Q4: =HYPERLINK("#Main!A1","Open Main") | S4: SEO | T4: =IFERROR(HYPERLINK("#Main!A"&MATCH(F4,Main!A:A,0),"View URL Details"),HYPERLINK("#Main!A1","View URL Details")) | U4: =IFERROR(HYPERLINK("#Main!A"&MATCH(F4,Main!A:A,0),"Open"),HYPERLINK("#Main!A1","Open"))
A5: Robots.txt Disallow Root | B5: Critical | C5: 105 | D5: 0 | G5: Apply fix based on issue type and re-run audit. | H5: Template/technical implementation quality issue. | I5: Server/Host | J5: Server/Host | K5: M | L5: 10 | M5: 5 | N5: Immediate (Current Sprint) | O5: To Do | P5: Yes | Q5: =HYPERLINK("#Main!A1","Open Main") | S5: SEO | T5: =IFERROR(HYPERLINK("#Main!A"&MATCH(F5,Main!A:A,0),"View URL Details"),HYPERLINK("#Main!A1","View URL Details")) | U5: =IFERROR(HYPERLINK("#Main!A"&MATCH(F5,Main!A:A,0),"Open"),HYPERLINK("#Main!A1","Open"))
A6: Broken Internal Links | B6: Critical | C6: 105 | D6: 0 | G6: Update internal links to valid URLs and remove dead references. | H6: Internal links resolve to missing or error pages. | I6: Dev | J6: Dev | K6: M | L6: 10 | M6: 5 | N6: Immediate (Current Sprint) | O6: To Do | P6: Yes | Q6: =HYPERLINK("#Main!A1","Open Main") | S6: SEO | T6: =IFERROR(HYPERLINK("#Main!A"&MATCH(F6,Main!A:A,0),"View URL Details"),HYPERLINK("#Main!A1","View URL Details")) | U6: =IFERROR(HYPERLINK("#Main!A"&MATCH(F6,Main!A:A,0),"Open"),HYPERLINK("#Main!A1","Open"))
A7: Redirect Chains | B7: Warning | C7: 67 | D7: 0 | G7: Apply fix based on issue type and re-run audit. | H7: Template/technical implementation quality issue. | I7: Dev | J7: Dev | K7: S | L7: 4 | M7: 2 | N7: Next Sprint | O7: To Do | P7: Yes | Q7: =HYPERLINK("#Main!A1","Open Main") | S7: SEO | T7: =IFERROR(HYPERLINK("#Main!A"&MATCH(F7,Main!A:A,0),"View URL Details"),HYPERLINK("#Main!A1","View URL Details")) | U7: =IFERROR(HYPERLINK("#Main!A"&MATCH(F7,Main!A:A,0),"Open"),HYPERLINK("#Main!A1","Open"))
A8: Missing Title | B8: Warning | C8: 67 | D8: 0 | G8: Add unique descriptive title on affected template/page type. | H8: Template/page missing title tag. | I8: Copy Writer | J8: Copy Writer | K8: S | L8: 4 | M8: 2 | N8: Next Sprint | O8: To Do | P8: Yes | Q8: =HYPERLINK("#Main!A1","Open Main") | S8: SEO | T8: =IFERROR(HYPERLINK("#Main!A"&MATCH(F8,Main!A:A,0),"View URL Details"),HYPERLINK("#Main!A1","View URL Details")) | U8: =IFERROR(HYPERLINK("#Main!A"&MATCH(F8,Main!A:A,0),"Open"),HYPERLINK("#Main!A1","Open"))
A9: Missing Meta Description | B9: Warning | C9: 67 | D9: 0 | G9: Add concise unique description aligned with user intent. | H9: Meta description missing or empty. | I9: Copy Writer | J9: Copy Writer | K9: S | L9: 4 | M9: 2 | N9: Next Sprint | O9: To Do | P9: Yes | Q9: =HYPERLINK("#Main!A1","Open Main") | S9: SEO | T9: =IFERROR(HYPERLINK("#Main!A"&MATCH(F9,Main!A:A,0),"View URL Details"),HYPERLINK("#Main!A1","View URL Details")) | U9: =IFERROR(HYPERLINK("#Main!A"&MATCH(F9,Main!A:A,0),"Open"),HYPERLINK("#Main!A1","Open"))
A10: Multiple H1 | B10: Warning | C10: 67 | D10: 0 | G10: Apply fix based on issue type and re-run audit. | H10: Template/technical implementation quality issue. | I10: Copy Writer | J10: Copy Writer | K10: S | L10: 4 | M10: 2 | N10: Next Sprint | O10: To Do | P10: Yes | Q10: =HYPERLINK("#Main!A1","Open Main") | S10: SEO | T10: =IFERROR(HYPERLINK("#Main!A"&MATCH(F10,Main!A:A,0),"View URL Details"),HYPERLINK("#Main!A1","View URL Details")) | U10: =IFERROR(HYPERLINK("#Main!A"&MATCH(F10,Main!A:A,0),"Open"),HYPERLINK("#Main!A1","Open"))
A11: Low Image Alt Coverage | B11: Warning | C11: 67 | D11: 0 | G11: Apply fix based on issue type and re-run audit. | H11: Template/technical implementation quality issue. | I11: Copy Writer | J11: Copy Writer | K11: S | L11: 4 | M11: 2 | N11: Next Sprint | O11: To Do | P11: Yes | Q11: =HYPERLINK("#Main!A1","Open Main") | S11: SEO | T11: =IFERROR(HYPERLINK("#Main!A"&MATCH(F11,Main!A:A,0),"View URL Details"),HYPERLINK("#Main!A1","View URL Details")) | U11: =IFERROR(HYPERLINK("#Main!A"&MATCH(F11,Main!A:A,0),"Open"),HYPERLINK("#Main!A1","Open"))
A12: Mixed Content | B12: Warning | C12: 67 | D12: 0 | G12: Serve all assets over HTTPS and update hardcoded URLs. | H12: HTTPS page references insecure HTTP assets. | I12: Dev | J12: Dev | K12: S | L12: 4 | M12: 2 | N12: Next Sprint | O12: To Do | P12: Yes | Q12: =HYPERLINK("#Main!A1","Open Main") | S12: SEO | T12: =IFERROR(HYPERLINK("#Main!A"&MATCH(F12,Main!A:A,0),"View URL Details"),HYPERLINK("#Main!A1","View URL Details")) | U12: =IFERROR(HYPERLINK("#Main!A"&MATCH(F12,Main!A:A,0),"Open"),HYPERLINK("#Main!A1","Open"))
A13: Canonical Missing | B13: Warning | C13: 67 | D13: 0 | G13: Apply fix based on issue type and re-run audit. | H13: Template/technical implementation quality issue. | I13: Dev | J13: Dev | K13: S | L13: 4 | M13: 2 | N13: Next Sprint | O13: To Do | P13: Yes | Q13: =HYPERLINK("#Main!A1","Open Main") | S13: SEO | T13: =IFERROR(HYPERLINK("#Main!A"&MATCH(F13,Main!A:A,0),"View URL Details"),HYPERLINK("#Main!A1","View URL Details")) | U13: =IFERROR(HYPERLINK("#Main!A"&MATCH(F13,Main!A:A,0),"Open"),HYPERLINK("#Main!A1","Open"))
A14: Hreflang Without Reciprocity | B14: Warning | C14: 67 | D14: 0 | G14: Apply fix based on issue type and re-run audit. | H14: Template/technical implementation quality issue. | I14: Copy Writer | J14: Copy Writer | K14: S | L14: 4 | M14: 2 | N14: Next Sprint | O14: To Do | P14: Yes | Q14: =HYPERLINK("#Main!A1","Open Main") | S14: SEO | T14: =IFERROR(HYPERLINK("#Main!A"&MATCH(F14,Main!A:A,0),"View URL Details"),HYPERLINK("#Main!A1","View URL Details")) | U14: =IFERROR(HYPERLINK("#Main!A"&MATCH(F14,Main!A:A,0),"Open"),HYPERLINK("#Main!A1","Open"))
A15: Missing H1 | B15: Warning | C15: 67 | D15: 6 | E15: https://asconafrica.org/ https://asconafrica.org/news/ https://asconafrica.org/privacy-policy/ https://asconafrica.org/unsubscribe-form/ https://asconafrica.org/unsubscribe-form/successfully-unsubscribed/ https://asconafrica.org/contact-us/ | F15: https://asconafrica.org/ | G15: Apply fix based on issue type and re-run audit. | H15: Template/technical implementation quality issue. | I15: Copy Writer | J15: Copy Writer | K15: S | L15: 4 | M15: 2 | N15: Next Sprint | O15: To Do | P15: Yes | Q15: =IFERROR(HYPERLINK("#Main!A"&MATCH("https://asconafrica.org/",Main!A:A,0),"Jump to Main"),HYPERLINK("#Main!A1","Open Main")) | S15: SEO | T15: =IFERROR(HYPERLINK("#Main!A"&MATCH(F15,Main!A:A,0),"View URL Details"),HYPERLINK("#Main!A1","View URL Details")) | U15: =IFERROR(HYPERLINK("#Main!A"&MATCH(F15,Main!A:A,0),"Open"),HYPERLINK("#Main!A1","Open"))
A16: Low AEO Readiness Score | B16: Warning | C16: 67 | D16: 15 | E16: https://asconafrica.org/2026-ascon-awards/ https://asconafrica.org/ https://asconafrica.org/news/ https://asconafrica.org/our-members/ https://asconafrica.org/2026-ascon-conference/ https://asconafrica.org/about-us/ https://asconafrica.org/privacy-policy/ https://asconafrica.org/2026-ascon-conference/thank-you-for-signing-up/ https://asconafrica.org/thank-you-for-signing-up-for-updates/ https://asconafrica.org/launch-event-2026-ascon-conference/thank-you-for-registering-conference-launch/ https://asconafrica.org/launch-event-2026-ascon-conference/ https://asconafrica.org/2026-ascon-awards/thank-you-for-your-nomination/ https://asconafrica.org/unsubscribe-form/ https://asconafrica.org/unsubscribe-form/successfully-unsubscribed/ https://asconafrica.org/contact-us/ | F16: https://asconafrica.org/2026-ascon-awards/ | G16: Add short direct answer blocks, question-led headings, and answer-ready formatting. | H16: Page lacks concise answer-oriented signals and structured answer patterns. | I16: Copy Writer | J16: Copy Writer | K16: S | L16: 4 | M16: 2 | N16: Next Sprint | O16: To Do | P16: Yes | Q16: =IFERROR(HYPERLINK("#Main!A"&MATCH("https://asconafrica.org/2026-ascon-awards/",Main!A:A,0),"Jump to Main"),HYPERLINK("#Main!A1","Open Main")) | S16: AEO | T16: =IFERROR(HYPERLINK("#Main!A"&MATCH(F16,Main!A:A,0),"View URL Details"),HYPERLINK("#Main!A1","View URL Details")) | U16: =IFERROR(HYPERLINK("#Main!A"&MATCH(F16,Main!A:A,0),"Open"),HYPERLINK("#Main!A1","Open"))
A17: Thin Content | B17: Warning | C17: 67 | D17: 8 | E17: https://asconafrica.org/our-members/ https://asconafrica.org/2026-ascon-conference/thank-you-for-signing-up/ https://asconafrica.org/thank-you-for-signing-up-for-updates/ https://asconafrica.org/launch-event-2026-ascon-conference/thank-you-for-registering-conference-launch/ https://asconafrica.org/2026-ascon-awards/thank-you-for-your-nomination/ https://asconafrica.org/unsubscribe-form/ https://asconafrica.org/unsubscribe-form/successfully-unsubscribed/ https://asconafrica.org/contact-us/ | F17: https://asconafrica.org/our-members/ | G17: Expand page with helpful, unique, intent-matching content. | H17: Insufficient body content for indexing confidence. | I17: Copy Writer | J17: Copy Writer | K17: S | L17: 4 | M17: 2 | N17: Next Sprint | O17: To Do | P17: Yes | Q17: =IFERROR(HYPERLINK("#Main!A"&MATCH("https://asconafrica.org/our-members/",Main!A:A,0),"Jump to Main"),HYPERLINK("#Main!A1","Open Main")) | S17: SEO | T17: =IFERROR(HYPERLINK("#Main!A"&MATCH(F17,Main!A:A,0),"View URL Details"),HYPERLINK("#Main!A1","View URL Details")) | U17: =IFERROR(HYPERLINK("#Main!A"&MATCH(F17,Main!A:A,0),"Open"),HYPERLINK("#Main!A1","Open"))
A18: Uses URL Parameters | B18: Info | C18: 37 | D18: 0 | G18: Apply fix based on issue type and re-run audit. | H18: Template/technical implementation quality issue. | I18: Dev | J18: Dev | K18: S | L18: 4 | M18: 2 | N18: Backlog | O18: In Review | P18: No | Q18: =HYPERLINK("#Main!A1","Open Main") | S18: SEO | T18: =IFERROR(HYPERLINK("#Main!A"&MATCH(F18,Main!A:A,0),"View URL Details"),HYPERLINK("#Main!A1","View URL Details")) | U18: =IFERROR(HYPERLINK("#Main!A"&MATCH(F18,Main!A:A,0),"Open"),HYPERLINK("#Main!A1","Open"))
A19: Generic Anchor Text Present | B19: Info | C19: 37 | D19: 0 | G19: Apply fix based on issue type and re-run audit. | H19: Template/technical implementation quality issue. | I19: Copy Writer | J19: Copy Writer | K19: S | L19: 4 | M19: 2 | N19: Backlog | O19: In Review | P19: No | Q19: =HYPERLINK("#Main!A1","Open Main") | S19: SEO | T19: =IFERROR(HYPERLINK("#Main!A"&MATCH(F19,Main!A:A,0),"View URL Details"),HYPERLINK("#Main!A1","View URL Details")) | U19: =IFERROR(HYPERLINK("#Main!A"&MATCH(F19,Main!A:A,0),"Open"),HYPERLINK("#Main!A1","Open"))
