Workbook

Sheet Table of Contents
A1: Table of Contents
A2: Section | B2: Open | C2: Description
A3: Dashboard | B3: =HYPERLINK("#'Dashboard'!A1","Open") -> Open | C3: Executive overview of site-wide SEO performance and critical alerts.
A4: Content Optimization Hub | B4: =HYPERLINK("#'Content Optimization Hub'!A1","Open") -> Open | C4: Interactive workspace for drafting SEO titles, descriptions, and AEO content.
A5: Quick Reference Guide | B5: =HYPERLINK("#'Quick Reference Guide'!A1","Open") -> Open | C5: In-workbook SEO and AEO copy standards and guardrails.
A6: FixPlan | B6: =HYPERLINK("#'FixPlan'!A1","Open") -> Open | C6: Prioritized list of technical and content fixes with estimated effort.
A7: Main | B7: =HYPERLINK("#'Main'!A1","Open") -> Open | C7: Primary URL inventory with titles, meta descriptions, and crawl signals.
A8: Technical | B8: =HYPERLINK("#'Technical'!A1","Open") -> Open | C8: Deep-dive diagnostic data for every crawled URL (Status, Load Time, etc.).
A9: PSI Performance | B9: =HYPERLINK("#'PSI Performance'!A1","Open") -> Open | C9: Lab PageSpeed scores and mobile CWV-related proxies.
A10: Content | B10: =HYPERLINK("#'Content'!A1","Open") -> Open | C10: Content depth, readability, headings, and thin-content flags per URL.
A11: AEO | B11: =HYPERLINK("#'AEO'!A1","Open") -> Open | C11: Answer Engine Optimization readiness scores and answer-block candidates.
A12: Schema & Metadata | B12: =HYPERLINK("#'Schema & Metadata'!A1","Open") -> Open | C12: JSON-LD, microdata, Open Graph, and Twitter card signals.
A13: Links | B13: =HYPERLINK("#'Links'!A1","Open") -> Open | C13: Internal and external link counts and anchor-text quality per URL.
A14: Indexability | B14: =HYPERLINK("#'Indexability'!A1","Open") -> Open | C14: Robots directives, canonicals, and indexability classification.
A15: Redirects | B15: =HYPERLINK("#'Redirects'!A1","Open") -> Open | C15: Redirect chains, hop lists, HTTPS upgrades, and loop detection.
A16: Priority URLs | B16: =HYPERLINK("#'Priority URLs'!A1","Open") -> Open | C16: High-value pages requiring immediate attention based on business risk.
A17: AIOSEO | B17: =HYPERLINK("#'AIOSEO'!A1","Open") -> Open | C17: Plugin-aligned recommendations and edit links for AIOSEO users.
A18: Security | B18: =HYPERLINK("#'Security'!A1","Open") -> Open | C18: Transport and hardening headers (HSTS, CSP, XFO, referrer policy, etc.).
A19: Summary | B19: =HYPERLINK("#'Summary'!A1","Open") -> Open | C19: Aggregated issue counts, AEO opportunities, and top critical URLs from the run.
A20: LinksDetail | B20: =HYPERLINK("#'LinksDetail'!A1","Open") -> Open | C20: Row-level outbound internal links with crawl resolution status.
A21: Media | B21: =HYPERLINK("#'Media'!A1","Open") -> Open | C21: Image inventory, alt coverage, filename quality, and mixed content flags.
A22: Pattern and Template Issues | B22: =HYPERLINK("#'Pattern and Template Issues'!A1","Open") -> Open | C22: Folder-level clusters and template-wide systemic issue patterns.
A23: Duplicates | B23: =HYPERLINK("#'Duplicates'!A1","Open") -> Open | C23: Near-duplicate titles and meta descriptions across the crawl set.
A24: IssueInventory | B24: =HYPERLINK("#'IssueInventory'!A1","Open") -> Open | C24: Flattened issue log with severity, owner seed, and stable IDs.
A25: RunMetadata | B25: =HYPERLINK("#'RunMetadata'!A1","Open") -> Open | C25: Run configuration, timestamps, and environment notes.
A26: DeltaFromPreviousRun | B26: =HYPERLINK("#'DeltaFromPreviousRun'!A1","Open") -> Open | C26: New, fixed, and persistent issues compared to a prior audit workbook.
A27: ResolvedIssues | B27: =HYPERLINK("#'ResolvedIssues'!A1","Open") -> Open | C27: Issues marked resolved when compared to the previous export.
A28: Glossary & Legend | B28: =HYPERLINK("#'Glossary & Legend'!A1","Open") -> Open | C28: Definitions for metrics, badges, and workbook conventions.
A29: CrawlGraph | B29: =HYPERLINK("#'CrawlGraph'!A1","Open") -> Open | C29: Derived link graph metrics (click depth, inlinks, PageRank proxy).
A30: SitemapQA | B30: =HYPERLINK("#'SitemapQA'!A1","Open") -> Open | C30: Sitemap coverage, URL membership checks, and sitemap metadata QA.

Sheet Dashboard
A1: Executive SEO & AEO Performance Report
A2: Executive SEO & AEO Dashboard
A4: EXECUTIVE METRICS | B4: Value | D4: Status | E4: Count | G4: OWNER ISSUE SUMMARY
A5: =HYPERLINK("#'Main'!A1","Total URLs") -> Total URLs | B5: 10 | D5: 200 OK | E5: 10 | G5: Owner | H5: Issue Rows | I5: Affected URLs | J5: Critical | K5: Warning
A6: =HYPERLINK("#'Summary'!A1","Overall Health Score") -> Overall Health Score | B6: =IFERROR(30.2/100,0) -> 0.302 | D6: 3xx Redirects | E6: 0 | G6: =HYPERLINK("#'FixPlan'!A1","Copy Writer") -> Copy Writer | H6: 20 | I6: 74 | J6: 1 | K6: 8
A7: =HYPERLINK("#'Summary'!A1","SEO Pass Rate %") -> SEO Pass Rate % | B7: 0 | D7: 4xx Errors | E7: 0 | G7: =HYPERLINK("#'FixPlan'!A1","Dev") -> Dev | H7: 9 | I7: 10 | J7: 4 | K7: 4
A8: =HYPERLINK("#'Technical'!A1","Pass URLs") -> Pass URLs | B8: 0 | D8: 5xx Errors | E8: 0 | G8: =HYPERLINK("#'FixPlan'!A1","Server/Host") -> Server/Host | H8: 5 | I8: 10 | J8: 2 | K8: 0
A9: =HYPERLINK("#'FixPlan'!A1","Critical URLs") -> Critical URLs | B9: 10 | D9: Other | E9: 0
A10: =HYPERLINK("#'Technical'!A1","Warning URLs") -> Warning URLs | B10: 0
A11: =HYPERLINK("#'Technical'!A1","Error Rate % (4xx/5xx)") -> Error Rate % (4xx/5xx) | B11: =IFERROR(0/10,0) -> 0
A12: =HYPERLINK("#'Technical'!A1","Crawl Success Rate % (2xx)") -> Crawl Success Rate % (2xx) | B12: =IFERROR(10/10,0) -> 1 | D12: Severity | E12: Count | J12: Quick Navigation | K12: Open
A13: =HYPERLINK("#'Technical'!A1","Critical URL Rate %") -> Critical URL Rate % | B13: =IFERROR(10/10,0) -> 1 | D13: Critical | E13: 7 | J13: Fix Plan | K13: =HYPERLINK("#FixPlan!A1","Open") -> Open
A14: =HYPERLINK("#'Technical'!A1","Warning URL Rate %") -> Warning URL Rate % | B14: =IFERROR(0/10,0) -> 0 | D14: Warning | E14: 12 | J14: Main URL Data | K14: =HYPERLINK("#Main!A1","Open") -> Open
A15: Projected Health Score % (if all To Do done) | B15: 0.9302 | D15: Medium | E15: 0 | J15: Technical Diagnostics | K15: =HYPERLINK("#Technical!A1","Open") -> Open
A16: Projected Pass Rate % (if all To Do done) | B16: 0.85 | D16: Low | E16: 15 | J16: Indexability | K16: =HYPERLINK("#Indexability!A1","Open") -> Open
A17: =HYPERLINK("#'Content Optimization Hub'!A1","Content Hub Readiness (%)") -> Content Hub Readiness (%) | B17: =IFERROR(COUNTIF('Content Optimization Hub'!A:A,"Complete")/COUNTA('Content Optimization Hub'!E:E),0) -> 0.18181818 | J17: AEO Opportunities | K17: =HYPERLINK("#AEO!A1","Open") -> Open
A18: =HYPERLINK("#'Schema & Metadata'!A1","URLs with Schema") -> URLs with Schema | B18: 0 | J18: AIOSEO Action Queue | K18: =HYPERLINK("#AIOSEO!A1","Open") -> Open
A19: =HYPERLINK("#'Links'!A1","Broken Internal Links") -> Broken Internal Links | B19: 0
E20: Traditional SEO vs. 2026 AEO Readiness | J20: BUSINESS IMPACT SUMMARY
E21: Dimension | F21: Score | J21: 0 error URLs detected (0 4xx / 0 5xx). Critical issue volume is 10 URLs and warning volume is 0. Top blocker: Broken Internal Links affecting 10 URLs.
E22: Traditional SEO | F22: 0.5812
E23: 2026 AEO Readiness | F23: 0
E24: Strategic Narrative
E25: SEO and AEO signals are moving together; continue balancing crawl health with answer-first content.
B44: TOP ISSUES TO FIX FIRST | C44: Affected URLs
B45: =HYPERLINK("#FixPlan!A2","Broken Internal Links") -> Broken Internal Links | C45: 10
B46: =HYPERLINK("#FixPlan!A9","Low AEO Readiness Score") -> Low AEO Readiness Score | C46: 10
B47: =HYPERLINK("#FixPlan!A8","Low Image Alt Coverage") -> Low Image Alt Coverage | C47: 10
B48: =HYPERLINK("#FixPlan!A7","AI Crawlers Not Explicitly Allowed") -> AI Crawlers Not Explicitly Allowed | C48: 10
B49: =HYPERLINK("#FixPlan!A6","No 40-60 Word Answer Paragraphs") -> No 40-60 Word Answer Paragraphs | C49: 10

Sheet Content Optimization Hub
A1: CONTENT HUB INSTRUCTIONS: 1. Draft in 'Proposed' columns. | 2. Watch 'Count' for Green. | 3. Click 'Elementor' link. | 4. Mark 'Status' as 'Completed'. | NOTE: If images show '#BLOCKED!', click the 'Security Warning' bar at the top of Excel and select 'Enable Content'.
A2: Action Required | B2: Status | C2: Assigned Owner | D2: Content Cluster ID | E2: URL | F2: Elementor Builder Link | G2: Target Keywords | H2: Current Page Copy Snippet | I2: Current Title | J2: Proposed Title (50-60 Chars) | K2: Title Count | L2: Current Meta Desc | M2: Proposed Meta Desc (120-160 Chars) | N2: Desc Count | O2: Current H-Tag Structure | P2: Proposed H-Tag Fixes | Q2: AEO Answer Block Draft | R2: FAQ/QA Draft | S2: Current OG-Image URL | T2: OG Image Preview | U2: Social Share Note | V2: SEO Score | W2: Technical Health | X2: Copy Score | Y2: Open in Main
A3: Needs Copy | B3: To Do | C3: Unassigned | D3: home-african-marketing-confed | E3: https://africanmarketingconfederation.org/ | F3: https://africanmarketingconfederation.org/wp-admin/post.php?post=8&action=elementor | H3: European marketers gather to choose their top achievers for 2026 Marketing associations from across Europe nominated national champions, with 10 finalists competing for the Marketer of the Year title. Read More » April 30, 2026 | I3: African Marketing Confederation - Uniting Marketers for Excellence | L3: The African Marketing Confederation is the ground-breaking Pan-African body driving the development of top marketing standards across Africa and beyond. | O3: H1: ABOUT The African Marketing Confederation H2: The 2026 AMC Conference H2: Meets the Mighty Victoria Falls H2: 23-25 September | Livingstone, Zambia H2: The 2026 AMC Conference H2: Meets the Mighty Victoria Falls | S3: https://africanmarketingconfederation.org/wp-content/uploads/2026/03/og-image.png | T3: =IF(LEN(S3)>0, _xlfn.IMAGE(S3), "") -> #VALUE! | V3: 36.75 | W3: 24 | X3: 75 | Y3: =IFERROR(HYPERLINK("#Main!A"&MATCH(E2,Main!A:A,0),"Open"),HYPERLINK("#Main!A1","Open")) -> Open
A4: Needs Copy | B4: To Do | C4: Unassigned | D4: about-us-african-marketing-confed | E4: https://africanmarketingconfederation.org/about-us | F4: https://africanmarketingconfederation.org/wp-admin/post.php?post=84&action=elementor | G4: About Us | H4: Skip to content ABOUT The African Marketing Confederation The African Marketing Confederation is the ground-breaking Pan African body of marketing professionals spearheading the ongoing development of the highest possible standards of marketing acro... | I4: African Marketing Confederation – The Leading Marketing Professional Body – African Marketing Confederation | L4: ABOUT The African Marketing Confederation The African Marketing Confederation is the ground-breaking Pan African body of marketing professionals spearheading the ongoing development of the highest possible standards of marketing across Africa. Founded in 2011, the AMC is a collaboration between the African national marketing bodies and associations to exchange expertise and information, and to promote | O4: H1: ABOUT The African Marketing Confederation H3: African Marketing Confederation PRESIDENT’S COUNCIL H2: Helen McIntee H2: President and Co-founder H2: David Balikuddembe H2: Secretary General | S4: https://africanmarketingconfederation.org/wp-content/uploads/2026/03/og-image.png | T4: =IF(LEN(S4)>0, _xlfn.IMAGE(S4), "") -> #VALUE! | V4: 46.5 | W4: 37 | X4: 75 | Y4: =IFERROR(HYPERLINK("#Main!A"&MATCH(E3,Main!A:A,0),"Open"),HYPERLINK("#Main!A1","Open")) -> Open
A5: Needs Optimization | B5: To Do | C5: Unassigned | D5: african-marketing-confederation-tourism-chapter-african-marketing-confed | E5: https://africanmarketingconfederation.org/african-marketing-confederation-tourism-chapter | F5: https://africanmarketingconfederation.org/wp-admin/post.php?post=28165&action=elementor | G5: African Marketing Confederation Tourism Chapter | H5: Skip to content African Marketing Confederation Tourism Chapter Shaping Africa’s Tourism Narrative Through Strategic Marketing Tourism is one of Africa’s most powerful economic engines – generating jobs, stimulating investment, and fostering cultural... | I5: African Marketing Confederation Tourism Chapter – African Marketing Confederation | L5: African Marketing Confederation Tourism Chapter Shaping Africa’s Tourism Narrative Through Strategic Marketing Tourism is one of Africa’s most powerful economic engines - generating jobs, stimulating investment, and fostering cultural exchange.The African Marketing Confederation is proud to launch the Tourism Chapter, a bold initiative to elevate African tourism through the lens of world-class marketing. Launched at the | O5: H1: African Marketing Confederation Tourism Chapter H3: Shaping Africa’s Tourism Narrative Through Strategic Marketing H2: Charting the Course: Purpose, Mission & Vision for Africa’s Tourism Future H2: Our Goals and Objectives: | S5: https://africanmarketingconfederation.org/wp-content/uploads/2026/03/og-image.png | T5: =IF(LEN(S5)>0, _xlfn.IMAGE(S5), "") -> #VALUE! | V5: 47.5 | W5: 30 | X5: 100 | Y5: =IFERROR(HYPERLINK("#Main!A"&MATCH(E4,Main!A:A,0),"Open"),HYPERLINK("#Main!A1","Open")) -> Open
A6: Needs Optimization | B6: To Do | C6: Unassigned | D6: amc-awards-2024-amc-awards-{n}-–-african | E6: https://africanmarketingconfederation.org/amc-awards-2024 | F6: https://africanmarketingconfederation.org/wp-admin/post.php?post=16125&action=elementor | G6: Amc Awards 2024 | H6: English Français Português Español Igbo Deutsch Kiswahili ພາສາລາວ العربية Afsoomaali Sesotho 简体中文 Русский Zulu en NOMINATIONS are Open ! AMC Awards The African Marketing Confederation Awards event is held annually as part of the African Marketing Con... | I6: AMC Awards 2024 – African Marketing Confederation | L6: NOMINATIONS are Open ! AMC Awards The African Marketing Confederation Awards event is held annually as part of the African Marketing Confederation Forum. This distinguished event celebrates and acknowledges outstanding marketing campaigns and the visionary individuals behind them. The awards presented honor not only the groundbreaking strategies and creative brilliance that set these campaigns apart but | O6: H1: NOMINATIONS are Open ! H2: Awards Categories H2: Tourism & Destination Marketing Campaign H2: of the Year H2: Best Social Media Campaign of the Year H2: Best Social Media Campaign | S6: https://africanmarketingconfederation.org/wp-content/uploads/2021/08/amc_faw.png | T6: =IF(LEN(S6)>0, _xlfn.IMAGE(S6), "") -> #VALUE! | V6: 47.5 | W6: 30 | X6: 100 | Y6: =IFERROR(HYPERLINK("#Main!A"&MATCH(E5,Main!A:A,0),"Open"),HYPERLINK("#Main!A1","Open")) -> Open
A7: Needs Copy | B7: To Do | C7: Unassigned | D7: amc-conference-2022-amc-conference-{n}-–-afr | E7: https://africanmarketingconfederation.org/amc-conference-2022 | F7: https://africanmarketingconfederation.org/wp-admin/post.php?post=4494&action=elementor | G7: Amc Conference 2022 | H7: AMC officially welcomes new member associations into the fold October 8, 2024 No Comments Angola, Botswana, Ethiopia, Mozambique and Tanzania receive their membership certificates. AMC now has 16 members. Read More » | I7: AMC Conference 2022 – African Marketing Confederation | L7: corinna kopf onlyfans leaks AMC Conference 2022 Thank you for attending19 - 22 October 2022 The African Marketing Confederation's Annual Conference brought together the best collection of marketing leaders from top companies, marketing bodies and associations to share tactics and best practices on how to build the next generation of marketing. Event Highlights Thank you for Attending! | O7: H2: AMC Conference 2022 H2: Event Highlights H3: AMC officially welcomes new member associations into the fold H3: Marketers are placing the ads where consumers don’t want to see them H3: Time for Africa to control its own narrative and image, delegates told H3: Excitement as Ghana announced as host of 2025 AMC marketing conference | S7: https://africanmarketingconfederation.org/wp-content/uploads/2026/03/og-image.png | T7: =IF(LEN(S7)>0, _xlfn.IMAGE(S7), "") -> #VALUE! | V7: 31.5 | W7: 27 | X7: 45 | Y7: =IFERROR(HYPERLINK("#Main!A"&MATCH(E6,Main!A:A,0),"Open"),HYPERLINK("#Main!A1","Open")) -> Open
A8: Needs Copy | B8: To Do | C8: Unassigned | D8: amc-conference-2022-prospectus-amc-conference-{n}-–-pro | E8: https://africanmarketingconfederation.org/amc-conference-2022-prospectus | F8: https://africanmarketingconfederation.org/wp-admin/post.php?post=5619&action=elementor | G8: Amc Conference 2022 Prospectus | H8: Skip to content AMC Conference 2022 23 - 24 March 2022 Navigating Africa’s Unique Marketing Mix BOOK NOW 00 Days 00 Hours 00 Minutes 00 Seconds download prospectus To download the AMC 2022 Conference Prospectus please complete the form below: First ... | I8: AMC Conference 2022 – Prospectus – African Marketing Confederation | L8: AMC Conference 2022 23 - 24 March 2022 Navigating Africa's Unique Marketing Mix BOOK NOW Days Hours Minutes Seconds download prospectus To download the AMC 2022 Conference Prospectus please complete the form below: First Name Last Name Email Mobile Company I've read and agree to the Privacy Policy BOOK NOW FOR THE AMC CONFERENCE 2022 | O8: H2: AMC Conference 2022 H2: download prospectus H2: BOOK NOW FOR THE AMC CONFERENCE 2022 | S8: https://africanmarketingconfederation.org/wp-content/uploads/2026/03/og-image.png | T8: =IF(LEN(S8)>0, _xlfn.IMAGE(S8), "") -> #VALUE! | V8: 31.5 | W8: 27 | X8: 45 | Y8: =IFERROR(HYPERLINK("#Main!A"&MATCH(E7,Main!A:A,0),"Open"),HYPERLINK("#Main!A1","Open")) -> Open
A9: Needs Copy | B9: To Do | C9: Unassigned | D9: amc-conference-2022-thank-you-amc-conference-{n}-–-tha | E9: https://africanmarketingconfederation.org/amc-conference-2022-thank-you | F9: https://africanmarketingconfederation.org/wp-admin/post.php?post=4941&action=elementor | G9: Amc Conference 2022 Thank You | H9: Skip to content AMC Conference 2022 23 - 24 March 2022 Navigating Africa’s Unique Marketing Mix ENQUIRE NOW 00 Days 00 Hours 00 Minutes 00 Seconds Success! Thank you for completing the enquiry form. Our team will contact you shortly! × The AMC Confer... | I9: AMC Conference 2022 – Thank You – African Marketing Confederation | L9: AMC Conference 2022 23 - 24 March 2022 Navigating Africa's Unique Marketing Mix ENQUIRE NOW Days Hours Minutes Seconds Success! Thank you for completing the enquiry form. Our team will contact you shortly! × Dismiss alert The AMC Conference is the must attend Pan African event for marketing professionals. It will focus on solutions for | O9: H2: AMC Conference 2022 H2: WHO SHOULD ATTEND H2: Countries Participating H3: South Africa H3: Nigeria H3: Morocco | S9: https://africanmarketingconfederation.org/wp-content/uploads/2026/03/og-image.png | T9: =IF(LEN(S9)>0, _xlfn.IMAGE(S9), "") -> #VALUE! | V9: 40 | W9: 30 | X9: 70 | Y9: =IFERROR(HYPERLINK("#Main!A"&MATCH(E8,Main!A:A,0),"Open"),HYPERLINK("#Main!A1","Open")) -> Open
A10: Complete | B10: To Do | C10: Unassigned | D10: amc-conference-2023-amc-conference-{n}-–-afr | E10: https://africanmarketingconfederation.org/amc-conference-2023 | F10: https://africanmarketingconfederation.org/wp-admin/post.php?post=12371&action=elementor | G10: Amc Conference 2023 | H10: AMC Conference 6 - 9 September 2023 Imperial Botanical Beach Hotel, Entebbe, Uganda Thank you for joining us! View Presentations 2nd Annual African Marketing Confederation Conference Africa's $3.4 trillion Economy: Opportunities for Marketers Welcome... | I10: AMC Conference 2023 – African Marketing Confederation | L10: AMC Conference 6 - 9 September 2023 Imperial Botanical Beach Hotel, Entebbe, Uganda Thank you for joining us! View Presentations 2nd Annual African Marketing Confederation Conference Africa's $3.4 trillion Economy: Opportunities for Marketers Welcome to the Recap of the 2nd Annual African Marketing Conference: Unveiling Africa's $3.4 Trillion EconomyOur conference was a remarkable exploration of | O10: H1: AMC Conference H2: Africa's $3.4 trillion Economy: Opportunities for Marketers H2: Thank you for joining us! H2: Topics covered H3: Africa Free Trade Area H3: Business Intelligence | S10: https://africanmarketingconfederation.org/wp-content/uploads/2021/08/amc_faw.png | T10: =IF(LEN(S10)>0, _xlfn.IMAGE(S10), "") -> #VALUE! | V10: 55 | W10: 40 | X10: 100 | Y10: =IFERROR(HYPERLINK("#Main!A"&MATCH(E9,Main!A:A,0),"Open"),HYPERLINK("#Main!A1","Open")) -> Open
A11: Complete | B11: To Do | C11: Unassigned | D11: amc-conference-2023-amc-awards-–-african-mar | E11: https://africanmarketingconfederation.org/amc-conference-2023/amc-awards | F11: https://africanmarketingconfederation.org/wp-admin/post.php?post=12954&action=elementor | G11: Amc Awards | H11: Skip to content AMC Awards Welcome to the prestigious African Marketing Confederation Awards, a distinguished event that celebrates and acknowledges the remarkable achievements, cutting-edge innovations, and exceptional leadership demonstrated by out... | I11: AMC Awards – African Marketing Confederation | L11: AMC Awards Welcome to the prestigious African Marketing Confederation Awards, a distinguished event that celebrates and acknowledges the remarkable achievements, cutting-edge innovations, and exceptional leadership demonstrated by outstanding individuals within the dynamic realm of marketing across the expansive African region.During the 2nd Annual African Marketing Confederation Conference, held from 6th to 9th September at the | O11: H1: AMC Awards H2: AMC AWARD Winners | S11: https://africanmarketingconfederation.org/wp-content/uploads/2021/08/amc_faw.png | T11: =IF(LEN(S11)>0, _xlfn.IMAGE(S11), "") -> #VALUE! | V11: 55 | W11: 40 | X11: 100 | Y11: =IFERROR(HYPERLINK("#Main!A"&MATCH(E10,Main!A:A,0),"Open"),HYPERLINK("#Main!A1","Open")) -> Open
A12: Needs Copy | B12: To Do | C12: Unassigned | D12: amc-conference-2023-amc-awards-|-book-now-–- | E12: https://africanmarketingconfederation.org/amc-conference-2023/amc-awards-book-now | F12: https://africanmarketingconfederation.org/wp-admin/post.php?post=13164&action=elementor | G12: Amc Awards Book Now | H12: Skip to content English Français Português Español Igbo Deutsch Kiswahili ພາສາລາວ العربية Afsoomaali Sesotho 简体中文 Русский Zulu en 0 Your Cart Your cart is empty Return to Shop Continue Shopping Notifications | I12: AMC Awards | Book Now – African Marketing Confederation | L12: MISSING DESCRIPTION | S12: https://africanmarketingconfederation.org/wp-content/uploads/2021/08/amc_faw.png | T12: =IF(LEN(S12)>0, _xlfn.IMAGE(S12), "") -> #VALUE! | V12: 19 | W12: 17 | X12: 25 | Y12: =IFERROR(HYPERLINK("#Main!A"&MATCH(E11,Main!A:A,0),"Open"),HYPERLINK("#Main!A1","Open")) -> Open

Sheet Quick Reference Guide
A1: Section | B1: Item | C1: Guideline | D1: Why It Matters | E1: BACK TO DASHBOARD
A2: [Meta Data Standards]
B3: Meta Title | C3: 50-60 characters. Place primary keyword at the front. Avoid brand repetition unless there is space. | D3: Improves clarity and reduces SERP truncation risk.
B4: Meta Description | C4: 120-160 characters. Must contain a clear Call-To-Action (CTA) and active verbs. | D4: Supports stronger click-through and intent alignment.
B5: Target Keywords | C5: 1 Primary, 2 Secondary per page. Do not keyword stuff; focus on user intent. | D5: Keeps copy focused on topical relevance over keyword density.
A7: [On-Page Structure (H-Tags)]
B8: H1 Tag | C8: Exactly ONE per page. Must contain the primary topic/keyword. Think of it as the 'Book Title'. | D8: Provides the clearest top-level topical signal.
B9: H2 Tags | C9: Main sections. Use question formats (Who, What, How) to trigger Answer Engine extraction. | D9: Improves structured scannability for users and LLMs.
B10: H3 Tags | C10: Sub-sections under H2s. Use for lists, steps, or detailed breakdowns. | D10: Strengthens hierarchy and supports extraction-ready formatting.
B11: H4-H6 Tags | C11: Use sparingly. Only for granular formatting within complex H3 topics. | D11: Avoids over-nesting while preserving semantic structure.
A13: [AEO (Answer Engine Optimization) & Content]
B14: AEO Answer Blocks | C14: 40-60 words. Placed directly beneath an H2 question. Must be factual, objective, and devoid of marketing fluff (e.g., 'The best way to...'). | D14: Optimizes direct extraction for answer engines and voice search.
B15: FAQ Schema | C15: Minimum 2-3 questions per informational page. Answers must be direct and stand alone without needing the rest of the page for context. | D15: Improves machine readability and rich-answer eligibility.
B16: Content Readability | C16: Keep sentences under 20 words. Use bullet points for any list of 3 or more items. | D16: Increases comprehension and snippet usability.
A18: [Visual & Social Branding]
B19: OG Image | C19: 1200 x 630 pixels. Keep text centered (safe zone) so it isn't cropped by mobile devices on LinkedIn/X. | D19: Ensures consistent social card presentation.
B20: Social Share Note | C20: Customize the message for the platform. LinkedIn = Professional insight. X (Twitter) = Quick hook. Facebook = Conversational. | D20: Improves engagement by matching platform context.

Sheet FixPlan
A1: Issue Type | B1: Severity | C1: Priority Score | D1: Affected Count | E1: Affected URLs | F1: Detail Reference Tab | G1: Resolution Type | H1: URL | I1: Recommended Fix | J1: Likely Root Cause | K1: Owner | L1: Agency Owner | M1: Effort | N1: Est. Hours | O1: Est. Sprint Points | P1: Aging/Priority | Q1: Status | R1: Verified By | S1: Date Resolved | T1: Revenue Risk | U1: Action Needed | V1: Jump to Details | W1: Sprint | X1: Category | Y1: Fix Type | Z1: Estimated Traffic Impact | AA1: Fix Effort | AB1: ROI Score | AC1: Exact Action | AD1: Open in Main | AE1: Hub Status (Content Hub) | AF1: BACK TO DASHBOARD
A2: Non-200 Status | B2: Critical | C2: 105 | D2: 0 | F2: Technical | G2: Manual Content | I2: Fix status code, restore page, or implement correct redirect to canonical destination. | J2: URL returns 4xx/5xx or equivalent failure. | K2: Server/Host | L2: Server/Host | M2: M | N2: 10 | O2: 5 | P2: Immediate (Current Sprint) | Q2: To Do | T2: High Risk | U2: Yes | V2: Open in Main Tab | X2: SEO | Y2: Technical | Z2: Low | AA2: 10 | AB2: 0 | AC2: Resolve 'Non-200 Status' using technical best practices and validate in the related detail tab. | AD2: =IFERROR(HYPERLINK("#Main!A"&MATCH(H2,Main!A:A,0),"Open"),HYPERLINK("#Main!A1","Open")) -> Open | AE2: =IFERROR(INDEX('Content Optimization Hub'!A:A,MATCH(H2,'Content Optimization Hub'!C:C,0)),"Not in Hub") -> Not in Hub
A3: Missing Title | B3: Critical | C3: 105 | D3: 0 | F3: Technical | G3: Manual Content | I3: Add unique descriptive title on affected template/page type. | J3: Template/page missing title tag. | K3: Copy Writer | L3: Copy Writer | M3: M | N3: 10 | O3: 5 | P3: Immediate (Current Sprint) | Q3: To Do | T3: High Risk | U3: Yes | V3: Open in Main Tab | X3: SEO | Y3: Content | Z3: Low | AA3: 10 | AB3: 0 | AC3: Resolve 'Missing Title' using content best practices and validate in the related detail tab. | AD3: =IFERROR(HYPERLINK("#Main!A"&MATCH(H3,Main!A:A,0),"Open"),HYPERLINK("#Main!A1","Open")) -> Open | AE3: =IFERROR(INDEX('Content Optimization Hub'!A:A,MATCH(H3,'Content Optimization Hub'!C:C,0)),"Not in Hub") -> Not in Hub
A4: Noindex Directive | B4: Critical | C4: 105 | D4: 0 | F4: Indexability | G4: Manual Content | I4: Remove unintended noindex directives on index-worthy URLs. | J4: Meta robots or X-Robots-Tag contains noindex. | K4: Dev | L4: Dev | M4: M | N4: 10 | O4: 5 | P4: Immediate (Current Sprint) | Q4: To Do | T4: High Risk | U4: Yes | V4: Open in Main Tab | X4: SEO | Y4: Technical | Z4: Low | AA4: 10 | AB4: 0 | AC4: Resolve 'Noindex Directive' using technical best practices and validate in the related detail tab. | AD4: =IFERROR(HYPERLINK("#Main!A"&MATCH(H4,Main!A:A,0),"Open"),HYPERLINK("#Main!A1","Open")) -> Open | AE4: =IFERROR(INDEX('Content Optimization Hub'!A:A,MATCH(H4,'Content Optimization Hub'!C:C,0)),"Not in Hub") -> Not in Hub
A5: Canonical Points Elsewhere | B5: Critical | C5: 105 | D5: 0 | F5: Indexability | G5: Global Template | I5: Align canonical to preferred final URL and ensure internal links use canonical target. | J5: Canonical targets a different URL variant. | K5: Dev | L5: Dev | M5: M | N5: 10 | O5: 5 | P5: Immediate (Current Sprint) | Q5: To Do | T5: High Risk | U5: Yes | V5: Open in Main Tab | X5: SEO | Y5: Technical | Z5: Low | AA5: 10 | AB5: 0 | AC5: Resolve 'Canonical Points Elsewhere' using technical best practices and validate in the related detail tab. | AD5: =IFERROR(HYPERLINK("#Main!A"&MATCH(H5,Main!A:A,0),"Open"),HYPERLINK("#Main!A1","Open")) -> Open | AE5: =IFERROR(INDEX('Content Optimization Hub'!A:A,MATCH(H5,'Content Optimization Hub'!C:C,0)),"Not in Hub") -> Not in Hub
A6: Robots.txt Disallow Root | B6: Critical | C6: 105 | D6: 0 | F6: Technical | G6: Global Template | I6: Apply fix based on issue type and re-run audit. | J6: Template/technical implementation quality issue. | K6: Server/Host | L6: Server/Host | M6: M | N6: 10 | O6: 5 | P6: Immediate (Current Sprint) | Q6: To Do | T6: High Risk | U6: Yes | V6: Open in Main Tab | X6: SEO | Y6: Content | Z6: Low | AA6: 10 | AB6: 0 | AC6: Resolve 'Robots.txt Disallow Root' using content best practices and validate in the related detail tab. | AD6: =IFERROR(HYPERLINK("#Main!A"&MATCH(H6,Main!A:A,0),"Open"),HYPERLINK("#Main!A1","Open")) -> Open | AE6: =IFERROR(INDEX('Content Optimization Hub'!A:A,MATCH(H6,'Content Optimization Hub'!C:C,0)),"Not in Hub") -> Not in Hub
A7: CWV LCP Above 4.0s | B7: Critical | C7: 105 | D7: 0 | F7: Technical | G7: Global Template | I7: Apply fix based on issue type and re-run audit. | J7: Template/technical implementation quality issue. | K7: Dev | L7: Dev | M7: M | N7: 10 | O7: 5 | P7: Immediate (Current Sprint) | Q7: To Do | T7: High Risk | U7: Yes | V7: Open in Main Tab | X7: SEO | Y7: Content | Z7: Low | AA7: 10 | AB7: 0 | AC7: Resolve 'CWV LCP Above 4.0s' using content best practices and validate in the related detail tab. | AD7: =IFERROR(HYPERLINK("#Main!A"&MATCH(H7,Main!A:A,0),"Open"),HYPERLINK("#Main!A1","Open")) -> Open | AE7: =IFERROR(INDEX('Content Optimization Hub'!A:A,MATCH(H7,'Content Optimization Hub'!C:C,0)),"Not in Hub") -> Not in Hub
A8: Broken Internal Links | B8: Critical | C8: 105 | D8: 10 | E8: https://africanmarketingconfederation.org/african-marketing-confederation-tourism-chapter https://africanmarketingconfederation.org/ https://africanmarketingconfederation.org/about-us https://africanmarketingconfederation.org/amc-awards-2024 https://africanmarketingconfederation.org/amc-conference-2022-prospectus https://africanmarketingconfederation.org/amc-conference-2022 https://africanmarketingconfederation.org/amc-conference-2022-thank-you https://africanmarketingconfederation.org/amc-conference-2023 https://africanmarketingconfederation.org/amc-conference-2023/amc-awards https://africanmarketingconfederation.org/amc-conference-2023/amc-awards-book-now | F8: Links | G8: Manual Content | H8: https://africanmarketingconfederation.org/african-marketing-confederation-tourism-chapter | I8: Update internal links to valid URLs and remove dead references. | J8: Internal links resolve to missing or error pages. | K8: Dev | L8: Dev | M8: M | N8: 10 | O8: 5 | P8: Immediate (Current Sprint) | Q8: To Do | T8: High Risk | U8: Yes | V8: Open in Main Tab | X8: SEO | Y8: Content | Z8: Low | AA8: 10 | AB8: 0 | AC8: Resolve 'Broken Internal Links' using content best practices and validate in the related detail tab. | AD8: =IFERROR(HYPERLINK("#Main!A"&MATCH(H8,Main!A:A,0),"Open"),HYPERLINK("#Main!A1","Open")) -> Open | AE8: =IFERROR(INDEX('Content Optimization Hub'!A:A,MATCH(H8,'Content Optimization Hub'!C:C,0)),"Not in Hub") -> Not in Hub
A9: Redirect Chains | B9: Warning | C9: 67 | D9: 0 | F9: Technical | G9: Global Template | I9: Apply fix based on issue type and re-run audit. | J9: Template/technical implementation quality issue. | K9: Dev | L9: Dev | M9: S | N9: 4 | O9: 2 | P9: Next Sprint | Q9: To Do | T9: Medium Risk | U9: Yes | V9: Open in Main Tab | X9: SEO | Y9: Technical | Z9: Low | AA9: 4 | AB9: 0 | AC9: Resolve 'Redirect Chains' using technical best practices and validate in the related detail tab. | AD9: =IFERROR(HYPERLINK("#Main!A"&MATCH(H9,Main!A:A,0),"Open"),HYPERLINK("#Main!A1","Open")) -> Open | AE9: =IFERROR(INDEX('Content Optimization Hub'!A:A,MATCH(H9,'Content Optimization Hub'!C:C,0)),"Not in Hub") -> Not in Hub
A10: CWV LCP Needs Improvement (2.5-4.0s) | B10: Warning | C10: 67 | D10: 0 | F10: Technical | G10: Global Template | I10: Apply fix based on issue type and re-run audit. | J10: Template/technical implementation quality issue. | K10: Copy Writer | L10: Copy Writer | M10: S | N10: 4 | O10: 2 | P10: Next Sprint | Q10: To Do | T10: Medium Risk | U10: Yes | V10: Open in Main Tab | X10: SEO | Y10: Content | Z10: Low | AA10: 4 | AB10: 0 | AC10: Resolve 'CWV LCP Needs Improvement (2.5-4.0s)' using content best practices and validate in the related detail tab. | AD10: =IFERROR(HYPERLINK("#Main!A"&MATCH(H10,Main!A:A,0),"Open"),HYPERLINK("#Main!A1","Open")) -> Open | AE10: =IFERROR(INDEX('Content Optimization Hub'!A:A,MATCH(H10,'Content Optimization Hub'!C:C,0)),"Not in Hub") -> Not in Hub
A11: Missing FAQ/QA Schema | B11: Warning | C11: 67 | D11: 0 | F11: AEO | G11: Global Template | I11: Add valid FAQPage or QAPage JSON-LD where appropriate and ensure on-page parity. | J11: No FAQPage/QAPage schema found for likely Q&A style content. | K11: Dev | L11: Dev | M11: S | N11: 4 | O11: 2 | P11: Next Sprint | Q11: To Do | T11: Medium Risk | U11: Yes | V11: Open in Main Tab | X11: AEO | Y11: Content | Z11: Low | AA11: 4 | AB11: 0 | AC11: Resolve 'Missing FAQ/QA Schema' using content best practices and validate in the related detail tab. | AD11: =IFERROR(HYPERLINK("#Main!A"&MATCH(H11,Main!A:A,0),"Open"),HYPERLINK("#Main!A1","Open")) -> Open | AE11: =IFERROR(INDEX('Content Optimization Hub'!A:A,MATCH(H11,'Content Optimization Hub'!C:C,0)),"Not in Hub") -> Not in Hub
A12: Deep URL (>3 clicks) | B12: Warning | C12: 67 | D12: 0 | F12: Technical | G12: Manual Content | I12: Apply fix based on issue type and re-run audit. | J12: Template/technical implementation quality issue. | K12: Copy Writer | L12: Copy Writer | M12: S | N12: 4 | O12: 2 | P12: Next Sprint | Q12: To Do | T12: Medium Risk | U12: Yes | V12: Open in Main Tab | X12: SEO | Y12: Content | Z12: Low | AA12: 4 | AB12: 0 | AC12: Resolve 'Deep URL (>3 clicks)' using content best practices and validate in the related detail tab. | AD12: =IFERROR(HYPERLINK("#Main!A"&MATCH(H12,Main!A:A,0),"Open"),HYPERLINK("#Main!A1","Open")) -> Open | AE12: =IFERROR(INDEX('Content Optimization Hub'!A:A,MATCH(H12,'Content Optimization Hub'!C:C,0)),"Not in Hub") -> Not in Hub
A13: Mixed Content | B13: Warning | C13: 67 | D13: 0 | F13: Technical | G13: Manual Content | I13: Serve all assets over HTTPS and update hardcoded URLs. | J13: HTTPS page references insecure HTTP assets. | K13: Dev | L13: Dev | M13: S | N13: 4 | O13: 2 | P13: Next Sprint | Q13: To Do | T13: Medium Risk | U13: Yes | V13: Open in Main Tab | X13: SEO | Y13: Content | Z13: Low | AA13: 4 | AB13: 0 | AC13: Resolve 'Mixed Content' using content best practices and validate in the related detail tab. | AD13: =IFERROR(HYPERLINK("#Main!A"&MATCH(H13,Main!A:A,0),"Open"),HYPERLINK("#Main!A1","Open")) -> Open | AE13: =IFERROR(INDEX('Content Optimization Hub'!A:A,MATCH(H13,'Content Optimization Hub'!C:C,0)),"Not in Hub") -> Not in Hub
A14: Canonical Missing | B14: Warning | C14: 67 | D14: 0 | F14: Indexability | G14: Global Template | I14: Apply fix based on issue type and re-run audit. | J14: Template/technical implementation quality issue. | K14: Dev | L14: Dev | M14: S | N14: 4 | O14: 2 | P14: Next Sprint | Q14: To Do | T14: Medium Risk | U14: Yes | V14: Open in Main Tab | X14: SEO | Y14: Technical | Z14: Low | AA14: 4 | AB14: 0 | AC14: Resolve 'Canonical Missing' using technical best practices and validate in the related detail tab. | AD14: =IFERROR(HYPERLINK("#Main!A"&MATCH(H14,Main!A:A,0),"Open"),HYPERLINK("#Main!A1","Open")) -> Open | AE14: =IFERROR(INDEX('Content Optimization Hub'!A:A,MATCH(H14,'Content Optimization Hub'!C:C,0)),"Not in Hub") -> Not in Hub
A15: Hreflang Without Reciprocity | B15: Warning | C15: 67 | D15: 0 | F15: Technical | G15: Manual Content | I15: Apply fix based on issue type and re-run audit. | J15: Template/technical implementation quality issue. | K15: Copy Writer | L15: Copy Writer | M15: S | N15: 4 | O15: 2 | P15: Next Sprint | Q15: To Do | T15: Medium Risk | U15: Yes | V15: Open in Main Tab | X15: SEO | Y15: Content | Z15: Low | AA15: 4 | AB15: 0 | AC15: Resolve 'Hreflang Without Reciprocity' using content best practices and validate in the related detail tab. | AD15: =IFERROR(HYPERLINK("#Main!A"&MATCH(H15,Main!A:A,0),"Open"),HYPERLINK("#Main!A1","Open")) -> Open | AE15: =IFERROR(INDEX('Content Optimization Hub'!A:A,MATCH(H15,'Content Optimization Hub'!C:C,0)),"Not in Hub") -> Not in Hub
A16: Low Image Alt Coverage | B16: Warning | C16: 67 | D16: 10 | E16: https://africanmarketingconfederation.org/african-marketing-confederation-tourism-chapter https://africanmarketingconfederation.org/ https://africanmarketingconfederation.org/about-us https://africanmarketingconfederation.org/amc-awards-2024 https://africanmarketingconfederation.org/amc-conference-2022-prospectus https://africanmarketingconfederation.org/amc-conference-2022 https://africanmarketingconfederation.org/amc-conference-2022-thank-you https://africanmarketingconfederation.org/amc-conference-2023 https://africanmarketingconfederation.org/amc-conference-2023/amc-awards https://africanmarketingconfederation.org/amc-conference-2023/amc-awards-book-now | F16: Technical | G16: Manual Content | H16: https://africanmarketingconfederation.org/african-marketing-confederation-tourism-chapter | I16: Apply fix based on issue type and re-run audit. | J16: Template/technical implementation quality issue. | K16: Copy Writer | L16: Copy Writer | M16: S | N16: 4 | O16: 2 | P16: Next Sprint | Q16: To Do | T16: Medium Risk | U16: Yes | V16: Open in Main Tab | X16: SEO | Y16: Content | Z16: Low | AA16: 4 | AB16: 0 | AC16: Resolve 'Low Image Alt Coverage' using content best practices and validate in the related detail tab. | AD16: =IFERROR(HYPERLINK("#Main!A"&MATCH(H16,Main!A:A,0),"Open"),HYPERLINK("#Main!A1","Open")) -> Open | AE16: =IFERROR(INDEX('Content Optimization Hub'!A:A,MATCH(H16,'Content Optimization Hub'!C:C,0)),"Not in Hub") -> Not in Hub
A17: Low AEO Readiness Score | B17: Warning | C17: 67 | D17: 10 | E17: https://africanmarketingconfederation.org/african-marketing-confederation-tourism-chapter https://africanmarketingconfederation.org/ https://africanmarketingconfederation.org/about-us https://africanmarketingconfederation.org/amc-awards-2024 https://africanmarketingconfederation.org/amc-conference-2022-prospectus https://africanmarketingconfederation.org/amc-conference-2022 https://africanmarketingconfederation.org/amc-conference-2022-thank-you https://africanmarketingconfederation.org/amc-conference-2023 https://africanmarketingconfederation.org/amc-conference-2023/amc-awards https://africanmarketingconfederation.org/amc-conference-2023/amc-awards-book-now | F17: AEO | G17: Manual Content | H17: https://africanmarketingconfederation.org/african-marketing-confederation-tourism-chapter | I17: Add short direct answer blocks, question-led headings, and answer-ready formatting. | J17: Page lacks concise answer-oriented signals and structured answer patterns. | K17: Copy Writer | L17: Copy Writer | M17: S | N17: 4 | O17: 2 | P17: Next Sprint | Q17: To Do | T17: Medium Risk | U17: Yes | V17: Open in Main Tab | X17: AEO | Y17: Content | Z17: Low | AA17: 4 | AB17: 0 | AC17: Resolve 'Low AEO Readiness Score' using content best practices and validate in the related detail tab. | AD17: =IFERROR(HYPERLINK("#Main!A"&MATCH(H17,Main!A:A,0),"Open"),HYPERLINK("#Main!A1","Open")) -> Open | AE17: =IFERROR(INDEX('Content Optimization Hub'!A:A,MATCH(H17,'Content Optimization Hub'!C:C,0)),"Not in Hub") -> Not in Hub
A18: Multiple H1 | B18: Warning | C18: 67 | D18: 3 | E18: https://africanmarketingconfederation.org/african-marketing-confederation-tourism-chapter https://africanmarketingconfederation.org/ https://africanmarketingconfederation.org/amc-awards-2024 | F18: Technical | G18: Manual Content | H18: https://africanmarketingconfederation.org/african-marketing-confederation-tourism-chapter | I18: Apply fix based on issue type and re-run audit. | J18: Template/technical implementation quality issue. | K18: Copy Writer | L18: Copy Writer | M18: S | N18: 4 | O18: 2 | P18: Next Sprint | Q18: To Do | T18: Medium Risk | U18: Yes | V18: Open in Main Tab | X18: SEO | Y18: Content | Z18: Low | AA18: 4 | AB18: 0 | AC18: Resolve 'Multiple H1' using content best practices and validate in the related detail tab. | AD18: =IFERROR(HYPERLINK("#Main!A"&MATCH(H18,Main!A:A,0),"Open"),HYPERLINK("#Main!A1","Open")) -> Open | AE18: =IFERROR(INDEX('Content Optimization Hub'!A:A,MATCH(H18,'Content Optimization Hub'!C:C,0)),"Not in Hub") -> Not in Hub
A19: Missing H1 | B19: Warning | C19: 67 | D19: 4 | E19: https://africanmarketingconfederation.org/amc-conference-2022-prospectus https://africanmarketingconfederation.org/amc-conference-2022 https://africanmarketingconfederation.org/amc-conference-2022-thank-you https://africanmarketingconfederation.org/amc-conference-2023/amc-awards-book-now | F19: Technical | G19: Manual Content | H19: https://africanmarketingconfederation.org/amc-conference-2022-prospectus | I19: Apply fix based on issue type and re-run audit. | J19: Template/technical implementation quality issue. | K19: Copy Writer | L19: Copy Writer | M19: S | N19: 4 | O19: 2 | P19: Next Sprint | Q19: To Do | T19: Medium Risk | U19: Yes | V19: Open in Main Tab | X19: SEO | Y19: Content | Z19: Low | AA19: 4 | AB19: 0 | AC19: Resolve 'Missing H1' using content best practices and validate in the related detail tab. | AD19: =IFERROR(HYPERLINK("#Main!A"&MATCH(H19,Main!A:A,0),"Open"),HYPERLINK("#Main!A1","Open")) -> Open | AE19: =IFERROR(INDEX('Content Optimization Hub'!A:A,MATCH(H19,'Content Optimization Hub'!C:C,0)),"Not in Hub") -> Not in Hub
A20: Missing Meta Description | B20: Warning | C20: 67 | D20: 1 | E20: https://africanmarketingconfederation.org/amc-conference-2023/amc-awards-book-now | F20: Technical | G20: Manual Content | H20: https://africanmarketingconfederation.org/amc-conference-2023/amc-awards-book-now | I20: Add concise unique description aligned with user intent. | J20: Meta description missing or empty. | K20: Copy Writer | L20: Copy Writer | M20: S | N20: 4 | O20: 2 | P20: Next Sprint | Q20: To Do | T20: Medium Risk | U20: Yes | V20: Open in Main Tab | X20: SEO | Y20: Content | Z20: Low | AA20: 4 | AB20: 0 | AC20: Resolve 'Missing Meta Description' using content best practices and validate in the related detail tab. | AD20: =IFERROR(HYPERLINK("#Main!A"&MATCH(H20,Main!A:A,0),"Open"),HYPERLINK("#Main!A1","Open")) -> Open | AE20: =IFERROR(INDEX('Content Optimization Hub'!A:A,MATCH(H20,'Content Optimization Hub'!C:C,0)),"Not in Hub") -> Not in Hub
A21: Uses URL Parameters | B21: Observation | C21: 37 | D21: 0 | F21: Technical | G21: Manual Content | I21: Apply fix based on issue type and re-run audit. | J21: Template/technical implementation quality issue. | K21: Dev | L21: Dev | M21: S | N21: 4 | O21: 2 | P21: Backlog | Q21: In Review | T21: Monitor | U21: No | V21: Open in Main Tab | X21: SEO | Y21: Content | Z21: Low | AA21: 4 | AB21: 0 | AC21: Resolve 'Uses URL Parameters' using content best practices and validate in the related detail tab. | AD21: =IFERROR(HYPERLINK("#Main!A"&MATCH(H21,Main!A:A,0),"Open"),HYPERLINK("#Main!A1","Open")) -> Open | AE21: =IFERROR(INDEX('Content Optimization Hub'!A:A,MATCH(H21,'Content Optimization Hub'!C:C,0)),"Not in Hub") -> Not in Hub
A22: Image Filename Quality Issues | B22: Observation | C22: 37 | D22: 0 | F22: Technical | G22: Manual Content | I22: Apply fix based on issue type and re-run audit. | J22: Template/technical implementation quality issue. | K22: Copy Writer | L22: Copy Writer | M22: S | N22: 4 | O22: 2 | P22: Backlog | Q22: In Review | T22: Monitor | U22: No | V22: Open in Main Tab | X22: SEO | Y22: Content | Z22: Low | AA22: 4 | AB22: 0 | AC22: Resolve 'Image Filename Quality Issues' using content best practices and validate in the related detail tab. | AD22: =IFERROR(HYPERLINK("#Main!A"&MATCH(H22,Main!A:A,0),"Open"),HYPERLINK("#Main!A1","Open")) -> Open | AE22: =IFERROR(INDEX('Content Optimization Hub'!A:A,MATCH(H22,'Content Optimization Hub'!C:C,0)),"Not in Hub") -> Not in Hub
A23: No Compression Header | B23: Observation | C23: 37 | D23: 0 | F23: Technical | G23: Global Template | I23: Apply fix based on issue type and re-run audit. | J23: Template/technical implementation quality issue. | K23: Server/Host | L23: Server/Host | M23: S | N23: 4 | O23: 2 | P23: Backlog | Q23: In Review | T23: Monitor | U23: No | V23: Open in Main Tab | X23: SEO | Y23: Content | Z23: Low | AA23: 4 | AB23: 0 | AC23: Resolve 'No Compression Header' using content best practices and validate in the related detail tab. | AD23: =IFERROR(HYPERLINK("#Main!A"&MATCH(H23,Main!A:A,0),"Open"),HYPERLINK("#Main!A1","Open")) -> Open | AE23: =IFERROR(INDEX('Content Optimization Hub'!A:A,MATCH(H23,'Content Optimization Hub'!C:C,0)),"Not in Hub") -> Not in Hub
A24: No Cache-Control Header | B24: Observation | C24: 37 | D24: 0 | F24: Technical | G24: Global Template | I24: Apply fix based on issue type and re-run audit. | J24: Template/technical implementation quality issue. | K24: Server/Host | L24: Server/Host | M24: S | N24: 4 | O24: 2 | P24: Backlog | Q24: In Review | T24: Monitor | U24: No | V24: Open in Main Tab | X24: SEO | Y24: Content | Z24: Low | AA24: 4 | AB24: 0 | AC24: Resolve 'No Cache-Control Header' using content best practices and validate in the related detail tab. | AD24: =IFERROR(HYPERLINK("#Main!A"&MATCH(H24,Main!A:A,0),"Open"),HYPERLINK("#Main!A1","Open")) -> Open | AE24: =IFERROR(INDEX('Content Optimization Hub'!A:A,MATCH(H24,'Content Optimization Hub'!C:C,0)),"Not in Hub") -> Not in Hub
A25: INP Above 100ms | B25: Observation | C25: 37 | D25: 0 | F25: Technical | G25: Manual Content | I25: Apply fix based on issue type and re-run audit. | J25: Template/technical implementation quality issue. | K25: Copy Writer | L25: Copy Writer | M25: S | N25: 4 | O25: 2 | P25: Backlog | Q25: In Review | T25: Monitor | U25: No | V25: Open in Main Tab | X25: SEO | Y25: Content | Z25: Low | AA25: 4 | AB25: 0 | AC25: Resolve 'INP Above 100ms' using content best practices and validate in the related detail tab. | AD25: =IFERROR(HYPERLINK("#Main!A"&MATCH(H25,Main!A:A,0),"Open"),HYPERLINK("#Main!A1","Open")) -> Open | AE25: =IFERROR(INDEX('Content Optimization Hub'!A:A,MATCH(H25,'Content Optimization Hub'!C:C,0)),"Not in Hub") -> Not in Hub
A26: CLS Above 0.1 | B26: Observation | C26: 37 | D26: 0 | F26: Technical | G26: Manual Content | I26: Apply fix based on issue type and re-run audit. | J26: Template/technical implementation quality issue. | K26: Copy Writer | L26: Copy Writer | M26: S | N26: 4 | O26: 2 | P26: Backlog | Q26: In Review | T26: Monitor | U26: No | V26: Open in Main Tab | X26: SEO | Y26: Content | Z26: Low | AA26: 4 | AB26: 0 | AC26: Resolve 'CLS Above 0.1' using content best practices and validate in the related detail tab. | AD26: =IFERROR(HYPERLINK("#Main!A"&MATCH(H26,Main!A:A,0),"Open"),HYPERLINK("#Main!A1","Open")) -> Open | AE26: =IFERROR(INDEX('Content Optimization Hub'!A:A,MATCH(H26,'Content Optimization Hub'!C:C,0)),"Not in Hub") -> Not in Hub
A27: Low Regional Authority | B27: Observation | C27: 37 | D27: 0 | F27: Technical | G27: Manual Content | I27: Apply fix based on issue type and re-run audit. | J27: Template/technical implementation quality issue. | K27: Copy Writer | L27: Copy Writer | M27: S | N27: 4 | O27: 2 | P27: Backlog | Q27: In Review | T27: Monitor | U27: No | V27: Open in Main Tab | X27: SEO | Y27: Content | Z27: Low | AA27: 4 | AB27: 0 | AC27: Resolve 'Low Regional Authority' using content best practices and validate in the related detail tab. | AD27: =IFERROR(HYPERLINK("#Main!A"&MATCH(H27,Main!A:A,0),"Open"),HYPERLINK("#Main!A1","Open")) -> Open | AE27: =IFERROR(INDEX('Content Optimization Hub'!A:A,MATCH(H27,'Content Optimization Hub'!C:C,0)),"Not in Hub") -> Not in Hub
A28: llms.txt Missing | B28: Observation | C28: 37 | D28: 0 | F28: Technical | G28: Manual Content | I28: Apply fix based on issue type and re-run audit. | J28: Template/technical implementation quality issue. | K28: Copy Writer | L28: Copy Writer | M28: S | N28: 4 | O28: 2 | P28: Backlog | Q28: In Review | T28: Monitor | U28: No | V28: Open in Main Tab | X28: SEO | Y28: Content | Z28: Low | AA28: 4 | AB28: 0 | AC28: Resolve 'llms.txt Missing' using content best practices and validate in the related detail tab. | AD28: =IFERROR(HYPERLINK("#Main!A"&MATCH(H28,Main!A:A,0),"Open"),HYPERLINK("#Main!A1","Open")) -> Open | AE28: =IFERROR(INDEX('Content Optimization Hub'!A:A,MATCH(H28,'Content Optimization Hub'!C:C,0)),"Not in Hub") -> Not in Hub
A29: Thin Content | B29: Observation | C29: 37 | D29: 5 | E29: https://africanmarketingconfederation.org/ https://africanmarketingconfederation.org/about-us https://africanmarketingconfederation.org/amc-conference-2022-prospectus https://africanmarketingconfederation.org/amc-conference-2022 https://africanmarketingconfederation.org/amc-conference-2023/amc-awards-book-now | F29: Technical | G29: Manual Content | H29: https://africanmarketingconfederation.org/ | I29: Expand page with helpful, unique, intent-matching content. | J29: Insufficient body content for indexing confidence. | K29: Copy Writer | L29: Copy Writer | M29: S | N29: 4 | O29: 2 | P29: Backlog | Q29: In Review | T29: Monitor | U29: No | V29: Open in Main Tab | X29: SEO | Y29: Content | Z29: Low | AA29: 4 | AB29: 0 | AC29: Resolve 'Thin Content' using content best practices and validate in the related detail tab. | AD29: =IFERROR(HYPERLINK("#Main!A"&MATCH(H29,Main!A:A,0),"Open"),HYPERLINK("#Main!A1","Open")) -> Open | AE29: =IFERROR(INDEX('Content Optimization Hub'!A:A,MATCH(H29,'Content Optimization Hub'!C:C,0)),"Not in Hub") -> Not in Hub
A30: Generic Anchor Text Present | B30: Observation | C30: 37 | D30: 1 | E30: https://africanmarketingconfederation.org/ | F30: Links | G30: Manual Content | H30: https://africanmarketingconfederation.org/ | I30: Apply fix based on issue type and re-run audit. | J30: Template/technical implementation quality issue. | K30: Copy Writer | L30: Copy Writer | M30: S | N30: 4 | O30: 2 | P30: Backlog | Q30: In Review | T30: Monitor | U30: No | V30: Open in Main Tab | X30: SEO | Y30: Content | Z30: Low | AA30: 4 | AB30: 0 | AC30: Resolve 'Generic Anchor Text Present' using content best practices and validate in the related detail tab. | AD30: =IFERROR(HYPERLINK("#Main!A"&MATCH(H30,Main!A:A,0),"Open"),HYPERLINK("#Main!A1","Open")) -> Open | AE30: =IFERROR(INDEX('Content Optimization Hub'!A:A,MATCH(H30,'Content Optimization Hub'!C:C,0)),"Not in Hub") -> Not in Hub
A31: No ETag Header | B31: Observation | C31: 37 | D31: 10 | E31: https://africanmarketingconfederation.org/african-marketing-confederation-tourism-chapter https://africanmarketingconfederation.org/ https://africanmarketingconfederation.org/about-us https://africanmarketingconfederation.org/amc-awards-2024 https://africanmarketingconfederation.org/amc-conference-2022-prospectus https://africanmarketingconfederation.org/amc-conference-2022 https://africanmarketingconfederation.org/amc-conference-2022-thank-you https://africanmarketingconfederation.org/amc-conference-2023 https://africanmarketingconfederation.org/amc-conference-2023/amc-awards https://africanmarketingconfederation.org/amc-conference-2023/amc-awards-book-now | F31: Technical | G31: Global Template | H31: https://africanmarketingconfederation.org/african-marketing-confederation-tourism-chapter | I31: Apply fix based on issue type and re-run audit. | J31: Template/technical implementation quality issue. | K31: Server/Host | L31: Server/Host | M31: S | N31: 4 | O31: 2 | P31: Backlog | Q31: In Review | T31: Monitor | U31: No | V31: Open in Main Tab | X31: SEO | Y31: Content | Z31: Low | AA31: 4 | AB31: 0 | AC31: Resolve 'No ETag Header' using content best practices and validate in the related detail tab. | AD31: =IFERROR(HYPERLINK("#Main!A"&MATCH(H31,Main!A:A,0),"Open"),HYPERLINK("#Main!A1","Open")) -> Open | AE31: =IFERROR(INDEX('Content Optimization Hub'!A:A,MATCH(H31,'Content Optimization Hub'!C:C,0)),"Not in Hub") -> Not in Hub
A32: No Question Headings | B32: Observation | C32: 37 | D32: 10 | E32: https://africanmarketingconfederation.org/african-marketing-confederation-tourism-chapter https://africanmarketingconfederation.org/ https://africanmarketingconfederation.org/about-us https://africanmarketingconfederation.org/amc-awards-2024 https://africanmarketingconfederation.org/amc-conference-2022-prospectus https://africanmarketingconfederation.org/amc-conference-2022 https://africanmarketingconfederation.org/amc-conference-2022-thank-you https://africanmarketingconfederation.org/amc-conference-2023 https://africanmarketingconfederation.org/amc-conference-2023/amc-awards https://africanmarketingconfederation.org/amc-conference-2023/amc-awards-book-now | F32: AEO | G32: Manual Content | H32: https://africanmarketingconfederation.org/african-marketing-confederation-tourism-chapter | I32: Add clear question-style headings (especially H2/H3) for key intents. | J32: Headings are not phrased as user questions. | K32: Copy Writer | L32: Copy Writer | M32: S | N32: 4 | O32: 2 | P32: Backlog | Q32: In Review | T32: Monitor | U32: No | V32: Open in Main Tab | X32: AEO | Y32: Content | Z32: Low | AA32: 4 | AB32: 0 | AC32: Resolve 'No Question Headings' using content best practices and validate in the related detail tab. | AD32: =IFERROR(HYPERLINK("#Main!A"&MATCH(H32,Main!A:A,0),"Open"),HYPERLINK("#Main!A1","Open")) -> Open | AE32: =IFERROR(INDEX('Content Optimization Hub'!A:A,MATCH(H32,'Content Optimization Hub'!C:C,0)),"Not in Hub") -> Not in Hub
A33: No Answer-Friendly Structure | B33: Observation | C33: 37 | D33: 10 | E33: https://africanmarketingconfederation.org/african-marketing-confederation-tourism-chapter https://africanmarketingconfederation.org/ https://africanmarketingconfederation.org/about-us https://africanmarketingconfederation.org/amc-awards-2024 https://africanmarketingconfederation.org/amc-conference-2022-prospectus https://africanmarketingconfederation.org/amc-conference-2022 https://africanmarketingconfederation.org/amc-conference-2022-thank-you https://africanmarketingconfederation.org/amc-conference-2023 https://africanmarketingconfederation.org/amc-conference-2023/amc-awards https://africanmarketingconfederation.org/amc-conference-2023/amc-awards-book-now | F33: AEO | G33: Manual Content | H33: https://africanmarketingconfederation.org/african-marketing-confederation-tourism-chapter | I33: Introduce structured bullets, ordered steps, or tables for key answers. | J33: Page lacks lists/tables that help concise answer extraction. | K33: Copy Writer | L33: Copy Writer | M33: S | N33: 4 | O33: 2 | P33: Backlog | Q33: In Review | T33: Monitor | U33: No | V33: Open in Main Tab | X33: AEO | Y33: Content | Z33: Low | AA33: 4 | AB33: 0 | AC33: Resolve 'No Answer-Friendly Structure' using content best practices and validate in the related detail tab. | AD33: =IFERROR(HYPERLINK("#Main!A"&MATCH(H33,Main!A:A,0),"Open"),HYPERLINK("#Main!A1","Open")) -> Open | AE33: =IFERROR(INDEX('Content Optimization Hub'!A:A,MATCH(H33,'Content Optimization Hub'!C:C,0)),"Not in Hub") -> Not in Hub
A34: No 40-60 Word Answer Paragraphs | B34: Observation | C34: 37 | D34: 10 | E34: https://africanmarketingconfederation.org/african-marketing-confederation-tourism-chapter https://africanmarketingconfederation.org/ https://africanmarketingconfederation.org/about-us https://africanmarketingconfederation.org/amc-awards-2024 https://africanmarketingconfederation.org/amc-conference-2022-prospectus https://africanmarketingconfederation.org/amc-conference-2022 https://africanmarketingconfederation.org/amc-conference-2022-thank-you https://africanmarketingconfederation.org/amc-conference-2023 https://africanmarketingconfederation.org/amc-conference-2023/amc-awards https://africanmarketingconfederation.org/amc-conference-2023/amc-awards-book-now | F34: AEO | G34: Manual Content | H34: https://africanmarketingconfederation.org/african-marketing-confederation-tourism-chapter | I34: Add a direct 30-60 word answer summary near question headings. | J34: No concise answer-length paragraph detected. | K34: Copy Writer | L34: Copy Writer | M34: S | N34: 4 | O34: 2 | P34: Backlog | Q34: In Review | T34: Monitor | U34: No | V34: Open in Main Tab | X34: AEO | Y34: Content | Z34: Low | AA34: 4 | AB34: 0 | AC34: Resolve 'No 40-60 Word Answer Paragraphs' using content best practices and validate in the related detail tab. | AD34: =IFERROR(HYPERLINK("#Main!A"&MATCH(H34,Main!A:A,0),"Open"),HYPERLINK("#Main!A1","Open")) -> Open | AE34: =IFERROR(INDEX('Content Optimization Hub'!A:A,MATCH(H34,'Content Optimization Hub'!C:C,0)),"Not in Hub") -> Not in Hub
A35: AI Crawlers Not Explicitly Allowed | B35: Observation | C35: 37 | D35: 10 | E35: https://africanmarketingconfederation.org/african-marketing-confederation-tourism-chapter https://africanmarketingconfederation.org/ https://africanmarketingconfederation.org/about-us https://africanmarketingconfederation.org/amc-awards-2024 https://africanmarketingconfederation.org/amc-conference-2022-prospectus https://africanmarketingconfederation.org/amc-conference-2022 https://africanmarketingconfederation.org/amc-conference-2022-thank-you https://africanmarketingconfederation.org/amc-conference-2023 https://africanmarketingconfederation.org/amc-conference-2023/amc-awards https://africanmarketingconfederation.org/amc-conference-2023/amc-awards-book-now | F35: Technical | G35: Manual Content | H35: https://africanmarketingconfederation.org/african-marketing-confederation-tourism-chapter | I35: Apply fix based on issue type and re-run audit. | J35: Template/technical implementation quality issue. | K35: Copy Writer | L35: Copy Writer | M35: S | N35: 4 | O35: 2 | P35: Backlog | Q35: In Review | T35: Monitor | U35: No | V35: Open in Main Tab | X35: SEO | Y35: Content | Z35: Low | AA35: 4 | AB35: 0 | AC35: Resolve 'AI Crawlers Not Explicitly Allowed' using content best practices and validate in the related detail tab. | AD35: =IFERROR(HYPERLINK("#Main!A"&MATCH(H35,Main!A:A,0),"Open"),HYPERLINK("#Main!A1","Open")) -> Open | AE35: =IFERROR(INDEX('Content Optimization Hub'!A:A,MATCH(H35,'Content Optimization Hub'!C:C,0)),"Not in Hub") -> Not in Hub

Sheet Main
