Workbook

Sheet Table of Contents
A1: Table of Contents
A2: Section | B2: Open | C2: Description
A3: =HYPERLINK("#'Dashboard'!A1","Dashboard") -> Dashboard | B3: =HYPERLINK("#'Dashboard'!A1","Open") -> Open | C3: Executive overview of site-wide SEO performance and critical alerts.
A4: =HYPERLINK("#'Content Optimisation Hub'!A1","Content Optimisation Hub") -> Content Optimisation Hub | B4: =HYPERLINK("#'Content Optimisation Hub'!A1","Open") -> Open | C4: Diagnostic command center: live title, meta, and H1–H6 health plus on-page score.
A5: =HYPERLINK("#'FixPlan'!A1","FixPlan") -> FixPlan | B5: =HYPERLINK("#'FixPlan'!A1","Open") -> Open | C5: Prioritized list of technical and content fixes with estimated effort.
A6: =HYPERLINK("#'Main'!A1","Main") -> Main | B6: =HYPERLINK("#'Main'!A1","Open") -> Open | C6: Primary URL inventory with titles, meta descriptions, and crawl signals.
A7: =HYPERLINK("#'Priority URLs'!A1","Priority URLs") -> Priority URLs | B7: =HYPERLINK("#'Priority URLs'!A1","Open") -> Open | C7: High-value pages requiring immediate attention based on business risk.
A8: =HYPERLINK("#'AIOSEO'!A1","AIOSEO") -> AIOSEO | B8: =HYPERLINK("#'AIOSEO'!A1","Open") -> Open | C8: Plugin-aligned recommendations and edit links for AIOSEO users.
A9: =HYPERLINK("#'Link Inventory'!A1","Link Inventory") -> Link Inventory | B9: =HYPERLINK("#'Link Inventory'!A1","Open") -> Open | C9: Every anchor-level outbound link with type, rel attributes, status codes, and generic-anchor flags.
A10: =HYPERLINK("#'SitemapQA'!A1","SitemapQA") -> SitemapQA | B10: =HYPERLINK("#'SitemapQA'!A1","Open") -> Open | C10: Sitemap coverage, URL membership checks, and sitemap metadata QA.
A11: =HYPERLINK("#'ResolvedIssues'!A1","ResolvedIssues") -> ResolvedIssues | B11: =HYPERLINK("#'ResolvedIssues'!A1","Open") -> Open | C11: Issues marked resolved when compared to the previous export.
A12: =HYPERLINK("#'DeltaFromPreviousRun'!A1","DeltaFromPreviousRun") -> DeltaFromPreviousRun | B12: =HYPERLINK("#'DeltaFromPreviousRun'!A1","Open") -> Open | C12: New, fixed, and persistent issues compared to a prior audit workbook.
A13: =HYPERLINK("#'RunMetadata'!A1","RunMetadata") -> RunMetadata | B13: =HYPERLINK("#'RunMetadata'!A1","Open") -> Open | C13: Run configuration, timestamps, and environment notes.
A14: =HYPERLINK("#'Issue Register'!A1","Issue Register") -> Issue Register | B14: =HYPERLINK("#'Issue Register'!A1","Open") -> Open | C14: Diagnostic metrics for Issue Register.
A15: =HYPERLINK("#'Technical Diagnostics'!A1","Technical Diagnostics") -> Technical Diagnostics | B15: =HYPERLINK("#'Technical Diagnostics'!A1","Open") -> Open | C15: Diagnostic metrics for Technical Diagnostics.
A16: =HYPERLINK("#'Content & AI Readiness'!A1","Content & AI Readiness") -> Content & AI Readiness | B16: =HYPERLINK("#'Content & AI Readiness'!A1","Open") -> Open | C16: Diagnostic metrics for Content & AI Readiness.
A17: =HYPERLINK("#'Link Intelligence'!A1","Link Intelligence") -> Link Intelligence | B17: =HYPERLINK("#'Link Intelligence'!A1","Open") -> Open | C17: Diagnostic metrics for Link Intelligence.
A18: =HYPERLINK("#'Template & Duplication Risks'!A1","Template & Duplication Risks") -> Template & Duplication Risks | B18: =HYPERLINK("#'Template & Duplication Risks'!A1","Open") -> Open | C18: Diagnostic metrics for Template & Duplication Risks.
A19: =HYPERLINK("#'Playbook'!A1","Playbook") -> Playbook | B19: =HYPERLINK("#'Playbook'!A1","Open") -> Open | C19: Diagnostic metrics for Playbook.

Sheet Dashboard
A1: Executive SEO & AEO Performance Report
A2: Executive SEO & AEO Dashboard
A4: EXECUTIVE METRICS | B4: Value | D4: Status | E4: Count | G4: Traditional SEO vs. 2026 AEO Readiness | I4: BUSINESS IMPACT SUMMARY | M4: PRIORITY SNAPSHOT | N4: Value
A5: =HYPERLINK("#'Main'!A1","Average SEO Score") -> Average SEO Score | B5: =IFERROR(AVERAGE(INDEX(Main!$1:$1048576,0,MATCH("SEO Score",Main!$1:$1,0))),IFERROR(AVERAGE(INDEX(Main!$1:$1048576,0,MATCH("SEO Health Score",Main!$1:$1,0))),0))/100 -> 0.70312 | D5: 200 OK | E5: 0 | G5: Dimension | H5: Score | I5: ⚠️ Link Integrity Risk: 47 broken links found. The most impacted destination is https://africanmarketingconfederation.org/amc-confer ence-2025-delegate-packages. ⚡ Performance Audit: PSI data was not collected in this run. A full Performance Pass is recommended to identify mobile load-time bottlenecks. 🤖 AEO Opportunity: Your content is currently 55% optimized for AI-Search, leaving a 45% opportunity for improvement. | M5: Primary blocking issue | N5: No ETag Header
A6: =HYPERLINK("#'Technical Diagnostics'!A1","Technical Health") -> Technical Health | B6: =AVERAGE('Technical Diagnostics'!E:E)/100 -> 0.665 | D6: 3xx Redirects | E6: 0 | G6: Traditional SEO | H6: 0 | M6: Top Issue Affected URLs | N6: 20
A7: =HYPERLINK("#'Technical Diagnostics'!A1","Performance (PSI)") -> Performance (PSI) | B7: =IFERROR((IFERROR(AVERAGE(INDEX('Technical Diagnostics'!$1:$1048576,0,MATCH("Mobile PSI Score",'Technical Diagnostics'!$1:$1,0))),0)+IFERROR(AVERAGE(INDEX('Technical Diagnostics'!$1:$1048576,0,MATCH("Desktop PSI Score",'Technical Diagnostics'!$1:$1,0))),0))/2,0)/100 -> 0 | D7: 4xx Errors | E7: 0 | G7: 2026 AEO Readiness | H7: 0 | M7: 4xx/5xx URLs | N7: 0
A8: =HYPERLINK("#'Technical Diagnostics'!A1","Mobile vs. Desktop Variance") -> Mobile vs. Desktop Variance | B8: =IFERROR(AVERAGE('Technical Diagnostics'!S:S)-AVERAGE('Technical Diagnostics'!R:R),0) -> 0 | D8: 5xx Errors | E8: 0 | M8: Avg TTFB (ms) | N8: 0
A9: =HYPERLINK("#'Priority URLs'!A1","Critical URLs") -> Critical URLs | B9: =COUNTIFS('Technical Diagnostics'!$D:$D,"Critical") -> 0 | D9: Other | E9: 0 | G9: Strategic Narrative
A10: =HYPERLINK("#'Technical Diagnostics'!A1","Warning URLs") -> Warning URLs | B10: =COUNTIFS('Technical Diagnostics'!$D:$D,"Warning")+COUNTIFS('Technical Diagnostics'!$D:$D,"Needs Work") -> 20 | G10: Critical technical debt is currently the primary barrier to growth.
A11: =HYPERLINK("#'Technical Diagnostics'!A1","Error Rate % (4xx/5xx)") -> Error Rate % (4xx/5xx) | B11: =IFERROR((COUNTIFS('Technical Diagnostics'!$C:$C,">=400",'Technical Diagnostics'!$C:$C,"<500")+COUNTIFS('Technical Diagnostics'!$C:$C,">=500",'Technical Diagnostics'!$C:$C,"<600"))/COUNTIFS('Technical Diagnostics'!$C:$C,">0"),0) -> 0
A12: =HYPERLINK("#'Technical Diagnostics'!A1","Crawl Success Rate % (2xx)") -> Crawl Success Rate % (2xx) | B12: =IFERROR(COUNTIFS('Technical Diagnostics'!$C:$C,">=200",'Technical Diagnostics'!$C:$C,"<300")/COUNTIFS('Technical Diagnostics'!$C:$C,">0"),0) -> 1 | D12: Severity | E12: Count | I12: Quick Navigation | J12: Open
A13: =HYPERLINK("#'Technical Diagnostics'!A1","Critical URL Rate %") -> Critical URL Rate % | B13: =IFERROR(B9/(COUNTA('Technical Diagnostics'!$A:$A)-1),0) -> 0 | D13: Critical | E13: 7 | I13: Fix Plan | J13: =HYPERLINK("#FixPlan!A1","Open") -> Open
A14: =HYPERLINK("#'Technical Diagnostics'!A1","Warning URL Rate %") -> Warning URL Rate % | B14: =IFERROR(B10/(COUNTA('Technical Diagnostics'!$A:$A)-1),0) -> 1 | D14: Warning | E14: 12 | G14: TOP ISSUES TO FIX FIRST | H14: Affected URLs | I14: Main URL Data | J14: =HYPERLINK("#Main!A1","Open") -> Open
A15: Projected Health Score % (if all To Do done) | B15: =MIN(1,B5+(B9*0.01)) -> 0.70312 | D15: Medium | E15: 0 | G15: =HYPERLINK("#FixPlan!A6","Low AEO Readiness Score") -> Low AEO Readiness Score | H15: 20 | I15: Technical Diagnostics | J15: =HYPERLINK("#'Technical Diagnostics'!A1","Open") -> Open
A16: Projected Pass Rate % (if all To Do done) | B16: =MIN(1,B7+(B9*0.01)) -> 0 | D16: Low | E16: 15 | G16: =HYPERLINK("#FixPlan!A5","AI Crawlers Not Explicitly Allowed") -> AI Crawlers Not Explicitly Allowed | H16: 20 | I16: Indexability | J16: =HYPERLINK("#'Technical Diagnostics'!A1","Open") -> Open
A17: =HYPERLINK("#'Content Optimisation Hub'!A1","Content Hub Readiness (%)") -> Content Hub Readiness (%) | B17: =IF(COUNTA('Content Optimisation Hub'!F3:F10000)=0,0,COUNTIF('Content Optimisation Hub'!F3:F10000,"Completed")/COUNTA('Content Optimisation Hub'!F3:F10000)) -> 0 | G17: =HYPERLINK("#FixPlan!A4","No 40-60 Word Answer Paragraphs") -> No 40-60 Word Answer Paragraphs | H17: 20 | I17: AEO Opportunities | J17: =HYPERLINK("#'Content & AI Readiness'!A1","Open") -> Open
A18: =HYPERLINK("#'Main'!A1","URLs with Schema") -> URLs with Schema | B18: =COUNTIF(Main!Q2:Q10000,TRUE) -> 0 | G18: =HYPERLINK("#FixPlan!A3","No Question Headings") -> No Question Headings | H18: 20 | I18: AIOSEO Action Queue | J18: =HYPERLINK("#AIOSEO!A1","Open") -> Open
A19: =HYPERLINK("#'Content & AI Readiness'!A1","AEO Opportunity Gap") -> AEO Opportunity Gap | B19: =MAX(0, IF(IFERROR(AVERAGE(INDEX('Content & AI Readiness'!$1:$1048576,0,MATCH("AEO Extractability Score",'Content & AI Readiness'!$1:$1,0))),0)>0, 100-IFERROR(AVERAGE(INDEX('Content & AI Readiness'!$1:$1048576,0,MATCH("AEO Extractability Score",'Content & AI Readiness'!$1:$1,0))),0), (1-IFERROR(B5,0))*100)) -> 45 | G19: =HYPERLINK("#FixPlan!A2","No ETag Header") -> No ETag Header | H19: 20 | I19: Content Hub | J19: =HYPERLINK("#'Content Optimisation Hub'!A1","Open") -> Open
A20: =HYPERLINK("#'Link Inventory'!A1","Broken Internal Links") -> Broken Internal Links | B20: =SUM(COUNTIFS('Link Inventory'!$E:$E,"Internal",'Link Inventory'!$F:$F,404),COUNTIFS('Link Inventory'!$E:$E,"Internal",'Link Inventory'!$F:$F,"404")) -> 94 | I20: Tech Diagnostics | J20: =HYPERLINK("#'Technical Diagnostics'!A1","Open") -> Open
A21: =HYPERLINK("#'Link Intelligence'!A1","Generic Anchor Links (Total)") -> Generic Anchor Links (Total) | B21: =SUMIFS('Link Intelligence'!$O:$O,'Link Intelligence'!$B:$B,"Summary") -> 2 | I21: Issue Register | J21: =HYPERLINK("#'Issue Register'!A1","Open") -> Open
A22: =HYPERLINK("#'Link Inventory'!A1","External Link Health %") -> External Link Health % | B22: =IF(IFERROR(INDEX(RunMetadata!$B:$B,MATCH("External Sniff Performed",RunMetadata!$A:$A,0)),0)=0,"",IF(IFERROR(INDEX(RunMetadata!$B:$B,MATCH("External Link Unique Denominator",RunMetadata!$A:$A,0)),0)=0,"",IFERROR(IFERROR(INDEX(RunMetadata!$B:$B,MATCH("External Link Unique 200 OK",RunMetadata!$A:$A,0)),0)/IFERROR(INDEX(RunMetadata!$B:$B,MATCH("External Link Unique Denominator",RunMetadata!$A:$A,0)),1),0))) -> 0.89552239 | G22: OWNER ISSUE SUMMARY
G23: Owner | H23: Issue Rows | I23: Affected URLs | J23: Critical | K23: Warning
G24: =HYPERLINK("#'FixPlan'!A1","Copy Writer") -> Copy Writer | H24: 20 | I24: 121 | J24: 1 | K24: 8
A25: CRAWL METADATA | B25: Value | G25: =HYPERLINK("#'FixPlan'!A1","Server/Host") -> Server/Host | H25: 5 | I25: 20 | J25: 2 | K25: 0
A26: Run Date | B26: =IFERROR(INDEX(RunMetadata!$B:$B,MATCH("Run Timestamp",RunMetadata!$A:$A,0)),"") -> 2026-05-09 14:58:03 | G26: =HYPERLINK("#'FixPlan'!A1","Dev") -> Dev | H26: 9 | I26: 0 | J26: 4 | K26: 4
A27: URL Count | B27: =IFERROR(INDEX(RunMetadata!$B:$B,MATCH("Total URLs",RunMetadata!$A:$A,0)),B5) -> 20
A28: Duration | B28: =IFERROR(INDEX(RunMetadata!$B:$B,MATCH("Duration (s)",RunMetadata!$A:$A,0)),"")

Sheet FixPlan
A1: Issue Type | B1: Severity | C1: Priority Score | D1: Affected Count | E1: Affected URLs | F1: Detail Reference Tab | G1: Resolution Type | H1: URL | I1: Recommended Fix | J1: Likely Root Cause | K1: Owner | L1: Agency Owner | M1: Effort | N1: Est. Hours | O1: Est. Sprint Points | P1: Aging/Priority | Q1: Status | R1: Verified By | S1: Date Resolved | T1: Revenue Risk | U1: Action Needed | V1: Jump to Details | W1: Sprint | X1: Category | Y1: Open in Main | Z1: Hub Status (Content Hub) | AA1: BACK TO DASHBOARD
A2: Non-200 Status | B2: Critical | C2: 105 | D2: 0 | F2: Technical Diagnostics | G2: Manual Content | I2: Fix status code, restore page, or implement correct redirect to canonical destination. | J2: URL returns 4xx/5xx or equivalent failure. | K2: Server/Host | L2: Server/Host | M2: M | N2: 10 | O2: 5 | P2: Immediate (Current Sprint) | Q2: To Do | T2: High Risk | U2: Yes | V2: Open in Main Tab | X2: SEO | Y2: =IFERROR(HYPERLINK("#'Main'!B"&MATCH(TRIM(H2),Main!B:B,0),"Open"),HYPERLINK("#'Main'!B1","Open")) -> Open | Z2: =IFERROR(INDEX('Content Optimisation Hub'!C:C,MATCH(H2,'Content Optimisation Hub'!F:F,0)),"Not in Hub") -> Not in Hub
A3: Missing Title | B3: Critical | C3: 105 | D3: 0 | F3: Technical Diagnostics | G3: Manual Content | I3: Add unique descriptive title on affected template/page type. | J3: Template/page missing title tag. | K3: Copy Writer | L3: Copy Writer | M3: M | N3: 10 | O3: 5 | P3: Immediate (Current Sprint) | Q3: To Do | T3: High Risk | U3: Yes | V3: Open in Main Tab | X3: SEO | Y3: =IFERROR(HYPERLINK("#'Main'!B"&MATCH(TRIM(H3),Main!B:B,0),"Open"),HYPERLINK("#'Main'!B1","Open")) -> Open | Z3: =IFERROR(INDEX('Content Optimisation Hub'!C:C,MATCH(H3,'Content Optimisation Hub'!F:F,0)),"Not in Hub") -> Not in Hub
A4: Noindex Directive | B4: Critical | C4: 105 | D4: 0 | F4: Technical Diagnostics | G4: Manual Content | I4: Remove unintended noindex directives on index-worthy URLs. | J4: Meta robots or X-Robots-Tag contains noindex. | K4: Dev | L4: Dev | M4: M | N4: 10 | O4: 5 | P4: Immediate (Current Sprint) | Q4: To Do | T4: High Risk | U4: Yes | V4: Open in Main Tab | X4: SEO | Y4: =IFERROR(HYPERLINK("#'Main'!B"&MATCH(TRIM(H4),Main!B:B,0),"Open"),HYPERLINK("#'Main'!B1","Open")) -> Open | Z4: =IFERROR(INDEX('Content Optimisation Hub'!C:C,MATCH(H4,'Content Optimisation Hub'!F:F,0)),"Not in Hub") -> Not in Hub
A5: Canonical Points Elsewhere | B5: Critical | C5: 105 | D5: 0 | F5: Technical Diagnostics | G5: Global Template | I5: Align canonical to preferred final URL and ensure internal links use canonical target. | J5: Canonical targets a different URL variant. | K5: Dev | L5: Dev | M5: M | N5: 10 | O5: 5 | P5: Immediate (Current Sprint) | Q5: To Do | T5: High Risk | U5: Yes | V5: Open in Main Tab | X5: SEO | Y5: =IFERROR(HYPERLINK("#'Main'!B"&MATCH(TRIM(H5),Main!B:B,0),"Open"),HYPERLINK("#'Main'!B1","Open")) -> Open | Z5: =IFERROR(INDEX('Content Optimisation Hub'!C:C,MATCH(H5,'Content Optimisation Hub'!F:F,0)),"Not in Hub") -> Not in Hub
A6: Robots.txt Disallow Root | B6: Critical | C6: 105 | D6: 0 | F6: Technical Diagnostics | G6: Global Template | I6: Apply fix based on issue type and re-run audit. | J6: Template/technical implementation quality issue. | K6: Server/Host | L6: Server/Host | M6: M | N6: 10 | O6: 5 | P6: Immediate (Current Sprint) | Q6: To Do | T6: High Risk | U6: Yes | V6: Open in Main Tab | X6: SEO | Y6: =IFERROR(HYPERLINK("#'Main'!B"&MATCH(TRIM(H6),Main!B:B,0),"Open"),HYPERLINK("#'Main'!B1","Open")) -> Open | Z6: =IFERROR(INDEX('Content Optimisation Hub'!C:C,MATCH(H6,'Content Optimisation Hub'!F:F,0)),"Not in Hub") -> Not in Hub
A7: CWV LCP Above 4.0s | B7: Critical | C7: 105 | D7: 0 | F7: Technical Diagnostics | G7: Global Template | I7: Apply fix based on issue type and re-run audit. | J7: Template/technical implementation quality issue. | K7: Dev | L7: Dev | M7: M | N7: 10 | O7: 5 | P7: Immediate (Current Sprint) | Q7: To Do | T7: High Risk | U7: Yes | V7: Open in Main Tab | X7: SEO | Y7: =IFERROR(HYPERLINK("#'Main'!B"&MATCH(TRIM(H7),Main!B:B,0),"Open"),HYPERLINK("#'Main'!B1","Open")) -> Open | Z7: =IFERROR(INDEX('Content Optimisation Hub'!C:C,MATCH(H7,'Content Optimisation Hub'!F:F,0)),"Not in Hub") -> Not in Hub
A8: Broken Internal Links | B8: Critical | C8: 105 | D8: 0 | F8: Link Intelligence | G8: Manual Content | I8: Update internal links to valid URLs and remove dead references. | J8: Internal links resolve to missing or error pages. | K8: Dev | L8: Dev | M8: M | N8: 10 | O8: 5 | P8: Immediate (Current Sprint) | Q8: To Do | T8: High Risk | U8: Yes | V8: Open in Main Tab | X8: SEO | Y8: =IFERROR(HYPERLINK("#'Main'!B"&MATCH(TRIM(H8),Main!B:B,0),"Open"),HYPERLINK("#'Main'!B1","Open")) -> Open | Z8: =IFERROR(INDEX('Content Optimisation Hub'!C:C,MATCH(H8,'Content Optimisation Hub'!F:F,0)),"Not in Hub") -> Not in Hub
A9: Redirect Chains | B9: Warning | C9: 67 | D9: 0 | F9: Technical Diagnostics | G9: Global Template | I9: Apply fix based on issue type and re-run audit. | J9: Template/technical implementation quality issue. | K9: Dev | L9: Dev | M9: S | N9: 4 | O9: 2 | P9: Next Sprint | Q9: To Do | T9: Medium Risk | U9: Yes | V9: Open in Main Tab | X9: SEO | Y9: =IFERROR(HYPERLINK("#'Main'!B"&MATCH(TRIM(H9),Main!B:B,0),"Open"),HYPERLINK("#'Main'!B1","Open")) -> Open | Z9: =IFERROR(INDEX('Content Optimisation Hub'!C:C,MATCH(H9,'Content Optimisation Hub'!F:F,0)),"Not in Hub") -> Not in Hub
A10: CWV LCP Needs Improvement (2.5-4.0s) | B10: Warning | C10: 67 | D10: 0 | F10: Technical Diagnostics | G10: Global Template | I10: Apply fix based on issue type and re-run audit. | J10: Template/technical implementation quality issue. | K10: Copy Writer | L10: Copy Writer | M10: S | N10: 4 | O10: 2 | P10: Next Sprint | Q10: To Do | T10: Medium Risk | U10: Yes | V10: Open in Main Tab | X10: SEO | Y10: =IFERROR(HYPERLINK("#'Main'!B"&MATCH(TRIM(H10),Main!B:B,0),"Open"),HYPERLINK("#'Main'!B1","Open")) -> Open | Z10: =IFERROR(INDEX('Content Optimisation Hub'!C:C,MATCH(H10,'Content Optimisation Hub'!F:F,0)),"Not in Hub") -> Not in Hub
A11: Missing FAQ/QA Schema | B11: Warning | C11: 67 | D11: 0 | F11: Content & AI Readiness | G11: Global Template | I11: Publish machine-readable FAQPage or QAPage JSON-LD that mirrors visible Q&A text so answer engines can treat schema as a stable API surface. | J11: Question-style content without matching FAQPage/QAPage JSON-LD. | K11: Dev | L11: Dev | M11: S | N11: 4 | O11: 2 | P11: Next Sprint | Q11: To Do | T11: Medium Risk | U11: Yes | V11: Open in Main Tab | X11: AEO | Y11: =IFERROR(HYPERLINK("#'Main'!B"&MATCH(TRIM(H11),Main!B:B,0),"Open"),HYPERLINK("#'Main'!B1","Open")) -> Open | Z11: =IFERROR(INDEX('Content Optimisation Hub'!C:C,MATCH(H11,'Content Optimisation Hub'!F:F,0)),"Not in Hub") -> Not in Hub
A12: Deep URL (>3 clicks) | B12: Warning | C12: 67 | D12: 0 | F12: Technical Diagnostics | G12: Manual Content | I12: Apply fix based on issue type and re-run audit. | J12: Template/technical implementation quality issue. | K12: Copy Writer | L12: Copy Writer | M12: S | N12: 4 | O12: 2 | P12: Next Sprint | Q12: To Do | T12: Medium Risk | U12: Yes | V12: Open in Main Tab | X12: SEO | Y12: =IFERROR(HYPERLINK("#'Main'!B"&MATCH(TRIM(H12),Main!B:B,0),"Open"),HYPERLINK("#'Main'!B1","Open")) -> Open | Z12: =IFERROR(INDEX('Content Optimisation Hub'!C:C,MATCH(H12,'Content Optimisation Hub'!F:F,0)),"Not in Hub") -> Not in Hub
A13: Mixed Content | B13: Warning | C13: 67 | D13: 0 | F13: Technical Diagnostics | G13: Manual Content | I13: Serve all assets over HTTPS and update hardcoded URLs. | J13: HTTPS page references insecure HTTP assets. | K13: Dev | L13: Dev | M13: S | N13: 4 | O13: 2 | P13: Next Sprint | Q13: To Do | T13: Medium Risk | U13: Yes | V13: Open in Main Tab | X13: SEO | Y13: =IFERROR(HYPERLINK("#'Main'!B"&MATCH(TRIM(H13),Main!B:B,0),"Open"),HYPERLINK("#'Main'!B1","Open")) -> Open | Z13: =IFERROR(INDEX('Content Optimisation Hub'!C:C,MATCH(H13,'Content Optimisation Hub'!F:F,0)),"Not in Hub") -> Not in Hub
... A15: Hreflang Without Reciprocity | B15: Warning | C15: 67 | D15: 0 | F15: Technical Diagnostics | G15: Manual Content | I15: Apply fix based on issue type and re-run audit. | J15: Template/technical implementation quality issue. | K15: Copy Writer | L15: Copy Writer | M15: S | N15: 4 | O15: 2 | P15: Next Sprint | Q15: To Do | T15: Medium Risk | U15: Yes | V15: Open in Main Tab | X15: SEO | Y15: =IFERROR(HYPERLINK("#'Main'!B"&MATCH(TRIM(H15),Main!B:B,0),"Open"),HYPERLINK("#'Main'!B1","Open")) -> Open | Z15: =IFERROR(INDEX('Content Optimisation Hub'!C:C,MATCH(H15,'Content Optimisation Hub'!F:F,0)),"Not in Hub") -> Not in Hub
A16: Low AEO Readiness Score | B16: Warning | C16: 67 | D16: 20 | E16: SEE DETAILS IN Content & AI Readiness | F16: Content & AI Readiness | G16: Global Template | H16: https://africanmarketingconfederation.org/amc-awards-2024 | I16: Raise the weighted mix: add a 40–60 word factual paragraph under each question H2/H3, add FAQPage/HowTo/Speakable JSON-LD, tune copy to FK grade 7–10, add ul/ol/table for key facts, and ensure robots.txt explicitly allows GPTBot, PerplexityBot, and CCBot. | J16: Weighted AEO score is below the 70-point extraction-confidence band. | K16: Copy Writer | L16: Copy Writer | M16: S | N16: 4 | O16: 2 | P16: Next Sprint | Q16: To Do | T16: Medium Risk | U16: Yes | V16: Open in Main Tab | X16: AEO | Y16: =IFERROR(HYPERLINK("#'Main'!B"&MATCH(TRIM(H16),Main!B:B,0),"Open"),HYPERLINK("#'Main'!B1","Open")) -> Open | Z16: =IFERROR(INDEX('Content Optimisation Hub'!C:C,MATCH(H16,'Content Optimisation Hub'!F:F,0)),"Not in Hub") -> Not in Hub
A17: Low Image Alt Coverage | B17: Warning | C17: 67 | D17: 16 | E17: SEE DETAILS IN Technical Diagnostics | F17: Technical Diagnostics | G17: Global Template | H17: https://africanmarketingconfederation.org/amc-awards-2024 | I17: Apply fix based on issue type and re-run audit. | J17: Template/technical implementation quality issue. | K17: Copy Writer | L17: Copy Writer | M17: S | N17: 4 | O17: 2 | P17: Next Sprint | Q17: To Do | T17: Medium Risk | U17: Yes | V17: Open in Main Tab | X17: SEO | Y17: =IFERROR(HYPERLINK("#'Main'!B"&MATCH(TRIM(H17),Main!B:B,0),"Open"),HYPERLINK("#'Main'!B1","Open")) -> Open | Z17: =IFERROR(INDEX('Content Optimisation Hub'!C:C,MATCH(H17,'Content Optimisation Hub'!F:F,0)),"Not in Hub") -> Not in Hub
A18: Multiple H1 | B18: Warning | C18: 67 | D18: 5 | E18: https://africanmarketingconfederation.org/amc-awards-2024 https://africanmarketingconfederation.org/ https://africanmarketingconfederation.org/african-marketing-confederation-tourism-chapter https://africanmarketingconfederation.org/amc-conference-2024-recap https://africanmarketingconfederation.org/amc-conference-2025-highlights | F18: Technical Diagnostics | G18: Manual Content | H18: https://africanmarketingconfederation.org/amc-awards-2024 | I18: Apply fix based on issue type and re-run audit. | J18: Template/technical implementation quality issue. | K18: Copy Writer | L18: Copy Writer | M18: S | N18: 4 | O18: 2 | P18: Next Sprint | Q18: To Do | T18: Medium Risk | U18: Yes | V18: Open in Main Tab | X18: SEO | Y18: =IFERROR(HYPERLINK("#'Main'!B"&MATCH(TRIM(H18),Main!B:B,0),"Open"),HYPERLINK("#'Main'!B1","Open")) -> Open | Z18: =IFERROR(INDEX('Content Optimisation Hub'!C:C,MATCH(H18,'Content Optimisation Hub'!F:F,0)),"Not in Hub") -> Not in Hub
A19: Missing H1 | B19: Warning | C19: 67 | D19: 5 | E19: https://africanmarketingconfederation.org/amc-conference-2022-prospectus https://africanmarketingconfederation.org/amc-conference-2022-thank-you https://africanmarketingconfederation.org/amc-conference-2022 https://africanmarketingconfederation.org/amc-conference-2023/amc-awards-book-now https://africanmarketingconfederation.org/amc-conference-2023/book-now-thank-you | F19: Technical Diagnostics | G19: Manual Content | H19: https://africanmarketingconfederation.org/amc-conference-2022-prospectus | I19: Apply fix based on issue type and re-run audit. | J19: Template/technical implementation quality issue. | K19: Copy Writer | L19: Copy Writer | M19: S | N19: 4 | O19: 2 | P19: Next Sprint | Q19: To Do | T19: Medium Risk | U19: Yes | V19: Open in Main Tab | X19: SEO | Y19: =IFERROR(HYPERLINK("#'Main'!B"&MATCH(TRIM(H19),Main!B:B,0),"Open"),HYPERLINK("#'Main'!B1","Open")) -> Open | Z19: =IFERROR(INDEX('Content Optimisation Hub'!C:C,MATCH(H19,'Content Optimisation Hub'!F:F,0)),"Not in Hub") -> Not in Hub
A20: Missing Meta Description | B20: Warning | C20: 67 | D20: 1 | E20: https://africanmarketingconfederation.org/amc-conference-2023/amc-awards-book-now | F20: Technical Diagnostics | G20: Manual Content | H20: https://africanmarketingconfederation.org/amc-conference-2023/amc-awards-book-now | I20: Add concise unique description aligned with user intent. | J20: Meta description missing or empty. | K20: Copy Writer | L20: Copy Writer | M20: S | N20: 4 | O20: 2 | P20: Next Sprint | Q20: To Do | T20: Medium Risk | U20: Yes | V20: Open in Main Tab | X20: SEO | Y20: =IFERROR(HYPERLINK("#'Main'!B"&MATCH(TRIM(H20),Main!B:B,0),"Open"),HYPERLINK("#'Main'!B1","Open")) -> Open | Z20: =IFERROR(INDEX('Content Optimisation Hub'!C:C,MATCH(H20,'Content Optimisation Hub'!F:F,0)),"Not in Hub") -> Not in Hub
A21: Uses URL Parameters | B21: Observation | C21: 37 | D21: 0 | F21: Technical Diagnostics | G21: Manual Content | I21: Apply fix based on issue type and re-run audit. | J21: Template/technical implementation quality issue. | K21: Dev | L21: Dev | M21: S | N21: 4 | O21: 2 | P21: Backlog | Q21: In Review | T21: Monitor | U21: No | V21: Open in Main Tab | X21: SEO | Y21: =IFERROR(HYPERLINK("#'Main'!B"&MATCH(TRIM(H21),Main!B:B,0),"Open"),HYPERLINK("#'Main'!B1","Open")) -> Open | Z21: =IFERROR(INDEX('Content Optimisation Hub'!C:C,MATCH(H21,'Content Optimisation Hub'!F:F,0)),"Not in Hub") -> Not in Hub
A22: No Compression Header | B22: Observation | C22: 37 | D22: 0 | F22: Technical Diagnostics | G22: Global Template | I22: Apply fix based on issue type and re-run audit. | J22: Template/technical implementation quality issue. | K22: Server/Host | L22: Server/Host | M22: S | N22: 4 | O22: 2 | P22: Backlog | Q22: In Review | T22: Monitor | U22: No | V22: Open in Main Tab | X22: SEO | Y22: =IFERROR(HYPERLINK("#'Main'!B"&MATCH(TRIM(H22),Main!B:B,0),"Open"),HYPERLINK("#'Main'!B1","Open")) -> Open | Z22: =IFERROR(INDEX('Content Optimisation Hub'!C:C,MATCH(H22,'Content Optimisation Hub'!F:F,0)),"Not in Hub") -> Not in Hub
A23: No Cache-Control Header | B23: Observation | C23: 37 | D23: 0 | F23: Technical Diagnostics | G23: Global Template | I23: Apply fix based on issue type and re-run audit. | J23: Template/technical implementation quality issue. | K23: Server/Host | L23: Server/Host | M23: S | N23: 4 | O23: 2 | P23: Backlog | Q23: In Review | T23: Monitor | U23: No | V23: Open in Main Tab | X23: SEO | Y23: =IFERROR(HYPERLINK("#'Main'!B"&MATCH(TRIM(H23),Main!B:B,0),"Open"),HYPERLINK("#'Main'!B1","Open")) -> Open | Z23: =IFERROR(INDEX('Content Optimisation Hub'!C:C,MATCH(H23,'Content Optimisation Hub'!F:F,0)),"Not in Hub") -> Not in Hub
A24: No Answer-Friendly Structure | B24: Observation | C24: 37 | D24: 0 | F24: Content & AI Readiness | G24: Manual Content | I24: Break data-heavy explanations into ul/ol steps or a comparison table so LLMs can cite discrete facts without re-parsing long paragraphs. | J24: Dense prose without lists or tables where facts could be chunked. | K24: Copy Writer | L24: Copy Writer | M24: S | N24: 4 | O24: 2 | P24: Backlog | Q24: In Review | T24: Monitor | U24: No | V24: Open in Main Tab | X24: AEO | Y24: =IFERROR(HYPERLINK("#'Main'!B"&MATCH(TRIM(H24),Main!B:B,0),"Open"),HYPERLINK("#'Main'!B1","Open")) -> Open | Z24: =IFERROR(INDEX('Content Optimisation Hub'!C:C,MATCH(H24,'Content Optimisation Hub'!F:F,0)),"Not in Hub") -> Not in Hub
A25: INP Above 100ms | B25: Observation | C25: 37 | D25: 0 | F25: Technical Diagnostics | G25: Manual Content | I25: Apply fix based on issue type and re-run audit. | J25: Template/technical implementation quality issue. | K25: Copy Writer | L25: Copy Writer | M25: S | N25: 4 | O25: 2 | P25: Backlog | Q25: In Review | T25: Monitor | U25: No | V25: Open in Main Tab | X25: SEO | Y25: =IFERROR(HYPERLINK("#'Main'!B"&MATCH(TRIM(H25),Main!B:B,0),"Open"),HYPERLINK("#'Main'!B1","Open")) -> Open | Z25: =IFERROR(INDEX('Content Optimisation Hub'!C:C,MATCH(H25,'Content Optimisation Hub'!F:F,0)),"Not in Hub") -> Not in Hub
A26: CLS Above 0.1 | B26: Observation | C26: 37 | D26: 0 | F26: Technical Diagnostics | G26: Manual Content | I26: Apply fix based on issue type and re-run audit. | J26: Template/technical implementation quality issue. | K26: Copy Writer | L26: Copy Writer | M26: S | N26: 4 | O26: 2 | P26: Backlog | Q26: In Review | T26: Monitor | U26: No | V26: Open in Main Tab | X26: SEO | Y26: =IFERROR(HYPERLINK("#'Main'!B"&MATCH(TRIM(H26),Main!B:B,0),"Open"),HYPERLINK("#'Main'!B1","Open")) -> Open | Z26: =IFERROR(INDEX('Content Optimisation Hub'!C:C,MATCH(H26,'Content Optimisation Hub'!F:F,0)),"Not in Hub") -> Not in Hub
A27: Low Regional Authority | B27: Observation | C27: 37 | D27: 0 | F27: Technical Diagnostics | G27: Manual Content | I27: Apply fix based on issue type and re-run audit. | J27: Template/technical implementation quality issue. | K27: Copy Writer | L27: Copy Writer | M27: S | N27: 4 | O27: 2 | P27: Backlog | Q27: In Review | T27: Monitor | U27: No | V27: Open in Main Tab | X27: SEO | Y27: =IFERROR(HYPERLINK("#'Main'!B"&MATCH(TRIM(H27),Main!B:B,0),"Open"),HYPERLINK("#'Main'!B1","Open")) -> Open | Z27: =IFERROR(INDEX('Content Optimisation Hub'!C:C,MATCH(H27,'Content Optimisation Hub'!F:F,0)),"Not in Hub") -> Not in Hub
A28: llms.txt Missing | B28: Observation | C28: 37 | D28: 0 | F28: Technical Diagnostics | G28: Manual Content | I28: Apply fix based on issue type and re-run audit. | J28: Template/technical implementation quality issue. | K28: Copy Writer | L28: Copy Writer | M28: S | N28: 4 | O28: 2 | P28: Backlog | Q28: In Review | T28: Monitor | U28: No | V28: Open in Main Tab | X28: SEO | Y28: =IFERROR(HYPERLINK("#'Main'!B"&MATCH(TRIM(H28),Main!B:B,0),"Open"),HYPERLINK("#'Main'!B1","Open")) -> Open | Z28: =IFERROR(INDEX('Content Optimisation Hub'!C:C,MATCH(H28,'Content Optimisation Hub'!F:F,0)),"Not in Hub") -> Not in Hub
A29: Generic Anchor Text Present | B29: Observation | C29: 37 | D29: 1 | E29: https://africanmarketingconfederation.org/ | F29: Link Intelligence | G29: Manual Content | H29: https://africanmarketingconfederation.org/ | I29: Apply fix based on issue type and re-run audit. | J29: Template/technical implementation quality issue. | K29: Copy Writer | L29: Copy Writer | M29: S | N29: 4 | O29: 2 | P29: Backlog | Q29: In Review | T29: Monitor | U29: No | V29: Open in Main Tab | X29: SEO | Y29: =IFERROR(HYPERLINK("#'Main'!B"&MATCH(TRIM(H29),Main!B:B,0),"Open"),HYPERLINK("#'Main'!B1","Open")) -> Open | Z29: =IFERROR(INDEX('Content Optimisation Hub'!C:C,MATCH(H29,'Content Optimisation Hub'!F:F,0)),"Not in Hub") -> Not in Hub
A30: Thin Content | B30: Observation | C30: 37 | D30: 12 | E30: SEE DETAILS IN Technical Diagnostics | F30: Technical Diagnostics | G30: Global Template | H30: https://africanmarketingconfederation.org/about-us | I30: Expand page with helpful, unique, intent-matching content. | J30: Insufficient body content for indexing confidence. | K30: Copy Writer | L30: Copy Writer | M30: S | N30: 4 | O30: 2 | P30: Backlog | Q30: In Review | T30: Monitor | U30: No | V30: Open in Main Tab | X30: SEO | Y30: =IFERROR(HYPERLINK("#'Main'!B"&MATCH(TRIM(H30),Main!B:B,0),"Open"),HYPERLINK("#'Main'!B1","Open")) -> Open | Z30: =IFERROR(INDEX('Content Optimisation Hub'!C:C,MATCH(H30,'Content Optimisation Hub'!F:F,0)),"Not in Hub") -> Not in Hub
A31: No ETag Header | B31: Observation | C31: 37 | D31: 20 | E31: SEE DETAILS IN Technical Diagnostics | F31: Technical Diagnostics | G31: Global Template | H31: https://africanmarketingconfederation.org/amc-awards-2024 | I31: Apply fix based on issue type and re-run audit. | J31: Template/technical implementation quality issue. | K31: Server/Host | L31: Server/Host | M31: S | N31: 4 | O31: 2 | P31: Backlog | Q31: In Review | T31: Monitor | U31: No | V31: Open in Main Tab | X31: SEO | Y31: =IFERROR(HYPERLINK("#'Main'!B"&MATCH(TRIM(H31),Main!B:B,0),"Open"),HYPERLINK("#'Main'!B1","Open")) -> Open | Z31: =IFERROR(INDEX('Content Optimisation Hub'!C:C,MATCH(H31,'Content Optimisation Hub'!F:F,0)),"Not in Hub") -> Not in Hub
A32: No Question Headings | B32: Observation | C32: 37 | D32: 20 | E32: SEE DETAILS IN Content & AI Readiness | F32: Content & AI Readiness | G32: Global Template | H32: https://africanmarketingconfederation.org/amc-awards-2024 | I32: Rewrite priority H2/H3 headings into natural-language questions (Who/What/How) so the following paragraph can serve as a direct extractable answer. | J32: Headings are not phrased as user questions. | K32: Copy Writer | L32: Copy Writer | M32: S | N32: 4 | O32: 2 | P32: Backlog | Q32: In Review | T32: Monitor | U32: No | V32: Open in Main Tab | X32: AEO | Y32: =IFERROR(HYPERLINK("#'Main'!B"&MATCH(TRIM(H32),Main!B:B,0),"Open"),HYPERLINK("#'Main'!B1","Open")) -> Open | Z32: =IFERROR(INDEX('Content Optimisation Hub'!C:C,MATCH(H32,'Content Optimisation Hub'!F:F,0)),"Not in Hub") -> Not in Hub
A33: No 40-60 Word Answer Paragraphs | B33: Observation | C33: 37 | D33: 20 | E33: SEE DETAILS IN Content & AI Readiness | F33: Content & AI Readiness | G33: Global Template | H33: https://africanmarketingconfederation.org/amc-awards-2024 | I33: Refactor each target section to lead with a ~45-word factual definition (no fluff) immediately under the question heading to improve LLM Position Zero retrieval. | J33: No 40–60 word definitional paragraph directly under a question-style H2/H3. | K33: Copy Writer | L33: Copy Writer | M33: S | N33: 4 | O33: 2 | P33: Backlog | Q33: In Review | T33: Monitor | U33: No | V33: Open in Main Tab | X33: AEO | Y33: =IFERROR(HYPERLINK("#'Main'!B"&MATCH(TRIM(H33),Main!B:B,0),"Open"),HYPERLINK("#'Main'!B1","Open")) -> Open | Z33: =IFERROR(INDEX('Content Optimisation Hub'!C:C,MATCH(H33,'Content Optimisation Hub'!F:F,0)),"Not in Hub") -> Not in Hub
A34: AI Crawlers Not Explicitly Allowed | B34: Observation | C34: 37 | D34: 20 | E34: SEE DETAILS IN Technical Diagnostics | F34: Technical Diagnostics | G34: Global Template | H34: https://africanmarketingconfederation.org/amc-awards-2024 | I34: Apply fix based on issue type and re-run audit. | J34: Template/technical implementation quality issue. | K34: Copy Writer | L34: Copy Writer | M34: S | N34: 4 | O34: 2 | P34: Backlog | Q34: In Review | T34: Monitor | U34: No | V34: Open in Main Tab | X34: SEO | Y34: =IFERROR(HYPERLINK("#'Main'!B"&MATCH(TRIM(H34),Main!B:B,0),"Open"),HYPERLINK("#'Main'!B1","Open")) -> Open | Z34: =IFERROR(INDEX('Content Optimisation Hub'!C:C,MATCH(H34,'Content Optimisation Hub'!F:F,0)),"Not in Hub") -> Not in Hub
A35: Image Filename Quality Issues | B35: Observation | C35: 37 | D35: 1 | E35: https://africanmarketingconfederation.org/amc-conference-2025-highlights | F35: Technical Diagnostics | G35: Manual Content | H35: https://africanmarketingconfederation.org/amc-conference-2025-highlights | I35: Apply fix based on issue type and re-run audit. | J35: Template/technical implementation quality issue. | K35: Copy Writer | L35: Copy Writer | M35: S | N35: 4 | O35: 2 | P35: Backlog | Q35: In Review | T35: Monitor | U35: No | V35: Open in Main Tab | X35: SEO | Y35: =IFERROR(HYPERLINK("#'Main'!B"&MATCH(TRIM(H35),Main!B:B,0),"Open"),HYPERLINK("#'Main'!B1","Open")) -> Open | Z35: =IFERROR(INDEX('Content Optimisation Hub'!C:C,MATCH(H35,'Content Optimisation Hub'!F:F,0)),"Not in Hub") -> Not in Hub

Sheet Priority URLs
A1: URL | B1: Business Risk Score | C1: Severity Badge | D1: SEO Health Score | E1: GSC Impressions | F1: GSC CTR | G1: Revenue Intent | H1: Critical Issues Count | I1: Warning Issues Count | J1: Action Needed | K1: Why Prioritized | L1: Owner | M1: Status | N1: Sprint | O1: Indexability Reason | P1: Broken Internal Links Count | Q1: Canonical Type | R1: Open in Main | S1: Open in Technical | T1: BACK TO DASHBOARD
A2: https://africanmarketingconfederation.org/amc-conference-2023/amc-awards-book-now | B2: 90 | C2: Warning | D2: 50 | E2: 0 | F2: 0 | G2: Standard | H2: 0 | I2: 4 | J2: Yes | K2: Monitor | L2: Copy Writer | M2: Open | O2: Indexable | Q2: self | R2: =IFERROR(HYPERLINK("#'Main'!B"&MATCH(TRIM(A2),Main!B:B,0),"Open"),HYPERLINK("#'Main'!B1","Open")) -> Open | S2: =IFERROR(HYPERLINK("#'Technical Diagnostics'!A"&MATCH(A2,'Technical Diagnostics'!A:A,0),"Open"),HYPERLINK("#'Technical Diagnostics'!A1","Open")) -> Open
A3: https://africanmarketingconfederation.org/amc-awards-2024 | B3: 70 | C3: Warning | D3: 60 | E3: 0 | F3: 0 | G3: Standard | H3: 0 | I3: 3 | J3: Yes | K3: Monitor | L3: Copy Writer | M3: Open | O3: Indexable | Q3: self | R3: =IFERROR(HYPERLINK("#'Main'!B"&MATCH(TRIM(A3),Main!B:B,0),"Open"),HYPERLINK("#'Main'!B1","Open")) -> Open | S3: =IFERROR(HYPERLINK("#'Technical Diagnostics'!A"&MATCH(A3,'Technical Diagnostics'!A:A,0),"Open"),HYPERLINK("#'Technical Diagnostics'!A1","Open")) -> Open
A4: https://africanmarketingconfederation.org/ | B4: 70 | C4: Warning | D4: 60 | E4: 1257 | F4: 0.058074781 | G4: Standard | H4: 0 | I4: 3 | J4: Yes | K4: Monitor | L4: Copy Writer | M4: Open | O4: Indexable | Q4: self | R4: =IFERROR(HYPERLINK("#'Main'!B"&MATCH(TRIM(A4),Main!B:B,0),"Open"),HYPERLINK("#'Main'!B1","Open")) -> Open | S4: =IFERROR(HYPERLINK("#'Technical Diagnostics'!A"&MATCH(A4,'Technical Diagnostics'!A:A,0),"Open"),HYPERLINK("#'Technical Diagnostics'!A1","Open")) -> Open
A5: https://africanmarketingconfederation.org/amc-conference-2022-prospectus | B5: 70 | C5: Warning | D5: 60 | E5: 0 | F5: 0 | G5: Standard | H5: 0 | I5: 3 | J5: Yes | K5: Monitor | L5: Copy Writer | M5: Open | O5: Indexable | Q5: self | R5: =IFERROR(HYPERLINK("#'Main'!B"&MATCH(TRIM(A5),Main!B:B,0),"Open"),HYPERLINK("#'Main'!B1","Open")) -> Open | S5: =IFERROR(HYPERLINK("#'Technical Diagnostics'!A"&MATCH(A5,'Technical Diagnostics'!A:A,0),"Open"),HYPERLINK("#'Technical Diagnostics'!A1","Open")) -> Open
A6: https://africanmarketingconfederation.org/amc-conference-2022-thank-you | B6: 70 | C6: Warning | D6: 60 | E6: 0 | F6: 0 | G6: Standard | H6: 0 | I6: 3 | J6: Yes | K6: Monitor | L6: Copy Writer | M6: Open | O6: Indexable | Q6: self | R6: =IFERROR(HYPERLINK("#'Main'!B"&MATCH(TRIM(A6),Main!B:B,0),"Open"),HYPERLINK("#'Main'!B1","Open")) -> Open | S6: =IFERROR(HYPERLINK("#'Technical Diagnostics'!A"&MATCH(A6,'Technical Diagnostics'!A:A,0),"Open"),HYPERLINK("#'Technical Diagnostics'!A1","Open")) -> Open
A7: https://africanmarketingconfederation.org/amc-conference-2022 | B7: 70 | C7: Warning | D7: 60 | E7: 11 | F7: 0 | G7: Standard | H7: 0 | I7: 3 | J7: Yes | K7: Monitor | L7: Copy Writer | M7: Open | O7: Indexable | Q7: self | R7: =IFERROR(HYPERLINK("#'Main'!B"&MATCH(TRIM(A7),Main!B:B,0),"Open"),HYPERLINK("#'Main'!B1","Open")) -> Open | S7: =IFERROR(HYPERLINK("#'Technical Diagnostics'!A"&MATCH(A7,'Technical Diagnostics'!A:A,0),"Open"),HYPERLINK("#'Technical Diagnostics'!A1","Open")) -> Open
A8: https://africanmarketingconfederation.org/amc-conference-2025-highlights | B8: 70 | C8: Warning | D8: 60 | E8: 32 | F8: 0 | G8: Standard | H8: 0 | I8: 3 | J8: Yes | K8: Monitor | L8: Copy Writer | M8: Open | O8: Indexable | Q8: self | R8: =IFERROR(HYPERLINK("#'Main'!B"&MATCH(TRIM(A8),Main!B:B,0),"Open"),HYPERLINK("#'Main'!B1","Open")) -> Open | S8: =IFERROR(HYPERLINK("#'Technical Diagnostics'!A"&MATCH(A8,'Technical Diagnostics'!A:A,0),"Open"),HYPERLINK("#'Technical Diagnostics'!A1","Open")) -> Open
A9: https://africanmarketingconfederation.org/about-us | B9: 50 | C9: Warning | D9: 70 | E9: 235 | F9: 0.042553191 | G9: Standard | H9: 0 | I9: 2 | J9: Yes | K9: Monitor | L9: Copy Writer | M9: Open | O9: Indexable | Q9: self | R9: =IFERROR(HYPERLINK("#'Main'!B"&MATCH(TRIM(A9),Main!B:B,0),"Open"),HYPERLINK("#'Main'!B1","Open")) -> Open | S9: =IFERROR(HYPERLINK("#'Technical Diagnostics'!A"&MATCH(A9,'Technical Diagnostics'!A:A,0),"Open"),HYPERLINK("#'Technical Diagnostics'!A1","Open")) -> Open
A10: https://africanmarketingconfederation.org/african-marketing-confederation-tourism-chapter | B10: 50 | C10: Warning | D10: 70 | E10: 18 | F10: 0 | G10: Standard | H10: 0 | I10: 2 | J10: Yes | K10: Monitor | L10: Copy Writer | M10: Open | O10: Indexable | Q10: self | R10: =IFERROR(HYPERLINK("#'Main'!B"&MATCH(TRIM(A10),Main!B:B,0),"Open"),HYPERLINK("#'Main'!B1","Open")) -> Open | S10: =IFERROR(HYPERLINK("#'Technical Diagnostics'!A"&MATCH(A10,'Technical Diagnostics'!A:A,0),"Open"),HYPERLINK("#'Technical Diagnostics'!A1","Open")) -> Open
A11: https://africanmarketingconfederation.org/amc-conference-2023 | B11: 50 | C11: Warning | D11: 70 | E11: 24 | F11: 0.041666667 | G11: Standard | H11: 0 | I11: 2 | J11: Yes | K11: Monitor | L11: Copy Writer | M11: Open | O11: Indexable | Q11: self | R11: =IFERROR(HYPERLINK("#'Main'!B"&MATCH(TRIM(A11),Main!B:B,0),"Open"),HYPERLINK("#'Main'!B1","Open")) -> Open | S11: =IFERROR(HYPERLINK("#'Technical Diagnostics'!A"&MATCH(A11,'Technical Diagnostics'!A:A,0),"Open"),HYPERLINK("#'Technical Diagnostics'!A1","Open")) -> Open
A12: https://africanmarketingconfederation.org/amc-conference-2023/amc-awards | B12: 50 | C12: Warning | D12: 70 | E12: 30 | F12: 0.033333333 | G12: Standard | H12: 0 | I12: 2 | J12: Yes | K12: Monitor | L12: Copy Writer | M12: Open | O12: Indexable | Q12: self | R12: =IFERROR(HYPERLINK("#'Main'!B"&MATCH(TRIM(A12),Main!B:B,0),"Open"),HYPERLINK("#'Main'!B1","Open")) -> Open | S12: =IFERROR(HYPERLINK("#'Technical Diagnostics'!A"&MATCH(A12,'Technical Diagnostics'!A:A,0),"Open"),HYPERLINK("#'Technical Diagnostics'!A1","Open")) -> Open
A13: https://africanmarketingconfederation.org/amc-conference-2023/book-now-thank-you | B13: 50 | C13: Warning | D13: 70 | E13: 0 | F13: 0 | G13: Standard | H13: 0 | I13: 2 | J13: Yes | K13: Monitor | L13: Copy Writer | M13: Open | O13: Indexable | Q13: self | R13: =IFERROR(HYPERLINK("#'Main'!B"&MATCH(TRIM(A13),Main!B:B,0),"Open"),HYPERLINK("#'Main'!B1","Open")) -> Open | S13: =IFERROR(HYPERLINK("#'Technical Diagnostics'!A"&MATCH(A13,'Technical Diagnostics'!A:A,0),"Open"),HYPERLINK("#'Technical Diagnostics'!A1","Open")) -> Open
... A21: https://africanmarketingconfederation.org/amc-conference-2023/speakers | B21: 30 | C21: Warning | D21: 80 | E21: 29 | F21: 0 | G21: Standard | H21: 0 | I21: 1 | J21: Yes | K21: Monitor | L21: Copy Writer | M21: Open | O21: Indexable | Q21: self | R21: =IFERROR(HYPERLINK("#'Main'!B"&MATCH(TRIM(A21),Main!B:B,0),"Open"),HYPERLINK("#'Main'!B1","Open")) -> Open | S21: =IFERROR(HYPERLINK("#'Technical Diagnostics'!A"&MATCH(A21,'Technical Diagnostics'!A:A,0),"Open"),HYPERLINK("#'Technical Diagnostics'!A1","Open")) -> Open

Sheet Content Optimisation Hub
A1: CONTENT HUB (DIAGNOSTIC): Edit Title, Meta, and H1–H6 in-place; health columns and On-Page score update live. | Use Elementor link for CMS edits. | Set Status to Completed when done. | NOTE: If images show '#BLOCKED!', enable external content in Excel security. | AD1: BACK TO DASHBOARD
A2: Action Required | B2: On-Page Optimization Score | C2: SEO Score | D2: Technical Health | E2: Copy Score | F2: Status | G2: Assigned Owner | H2: URL | I2: URL Slug Normalization | J2: Proposed URL Slug | K2: Current Title | L2: Title Health | M2: Current Meta Desc | N2: Meta Health | O2: H1 | P2: H1 Health | Q2: H2 | R2: H2 Health | S2: H3 | T2: H3 Health | U2: H4 | V2: H4 Health | W2: H5 | X2: H5 Health | Y2: H6 | Z2: H6 Health | AA2: Elementor Builder Link | AB2: Current OG-Image URL | AC2: OG Image Preview | AD2: Open in Main
A3: =IF(B3>=85,"Complete","Needs Copy") -> Needs Copy | B3: =MIN(100,ROUND(0.3*(IF(L3="",0,IF(LEFT(L3,7)="MISSING",0,IF(ISNUMBER(SEARCH("OK",L3)),100,IF(ISNUMBER(SEARCH("SHORT",L3)),65,IF(ISNUMBER(SEARCH("LONG",L3)),50,70))))))+0.25*(IF(N3="",0,IF(LEFT(N3,7)="MISSING",0,IF(ISNUMBER(SEARCH("OK",N3)),100,IF(ISNUMBER(SEARCH("SHORT",N3)),65,IF(ISNUMBER(SEARCH("LONG",N3)),50,70))))))+0.2*(IF(P3="",0,IF(LEFT(P3,2)="OK",100,0)))+0.08*(IF(R3="",0,IF(LEFT(R3,2)="OK",100,0)))+0.06*(IF(T3="",0,IF(LEFT(T3,2)="OK",100,0)))+0.05*(IF(V3="",0,IF(LEFT(V3,2)="OK",100,0)))+0.03*(IF(X3="",0,IF(LEFT(X3,2)="OK",100,0)))+0.03*(IF(Z3="",0,IF(LEFT(Z3,2)="OK",100,0))),0)) -> 68 | C3: 64.52 | D3: 60 | E3: 78.08 | F3: To Do | G3: Copy Writer | H3: =HYPERLINK("https://africanmarketingconfederation.org/","https://africanmarketingconfederation.org/") -> https://africanmarketingconfederation.org/ | I3: =HYPERLINK("https://africanmarketingconfederation.org/","https://africanmarketingconfederation.org/") -> https://africanmarketingconfederation.org/ | K3: African Marketing Confederation - Uniting Marketers for Excellence | L3: =IF(K3="","MISSING",IF(AND(LEN(K3)>=50,LEN(K3)<=60),"OK 50-60 chars",IF(LEN(K3)<50,"SHORT: "&LEN(K3),"LONG: "&LEN(K3)))) -> LONG: 66 | M3: The African Marketing Confederation is the ground-breaking Pan-African body driving the development of top marketing standards across Africa and beyond. | N3: =IF(M3="","MISSING",IF(AND(LEN(M3)>=120,LEN(M3)<=160),"OK 120-160 chars",IF(LEN(M3)<120,"SHORT: "&LEN(M3),"LONG: "&LEN(M3)))) -> OK 120-160 chars | O3: ABOUT The African Marketing Confederation | P3: =IF(OR(ISBLANK(O3),ISNUMBER(SEARCH("|",O3))),"FIX: MULTIPLE/MISSING","OK") -> OK | Q3: The 2026 AMC Conference | Meets the Mighty Victoria Falls | 23-25 September | Livingstone, Zambia | Certified Professional Marketer (Africa) - CPM(A) | The designation where global marketing standards meet African realities | R3: =IF(ISBLANK(Q3),"MISSING","OK") -> OK | T3: =IF(ISBLANK(S3),"MISSING","OK") -> MISSING | V3: =IF(ISBLANK(U3),"MISSING","OK") -> MISSING | X3: =IF(ISBLANK(W3),"MISSING","OK") -> MISSING | Z3: =IF(ISBLANK(Y3),"MISSING","OK") -> MISSING | AA3: =HYPERLINK("https://africanmarketingconfederation.org/wp-admin/post.php?post=8&action=elementor","Open in Elementor") -> Open in Elementor | AB3: =HYPERLINK("https://africanmarketingconfederation.org/wp-content/uploads/2026/03/og-image.png","View Image") -> View Image | AC3: =IF(LEN("https://africanmarketingconfederation.org/wp-content/uploads/2026/03/og-image.png")>0, _xlfn.IMAGE("https://africanmarketingconfederation.org/wp-content/uploads/2026/03/og-image.png"), "") -> #VALUE! | AD3: =IFERROR(HYPERLINK("#'Main'!B"&MATCH(TRIM(H3),Main!B:B,0),"Open in Main"),IFERROR(HYPERLINK("#'Technical Diagnostics'!A"&MATCH(TRIM(H3),'Technical Diagnostics'!A:A,0),"Open in Technical"),"Not Found")) -> Open in Main
A4: =IF(B4>=85,"Complete","Needs Copy") -> Needs Copy | B4: =MIN(100,ROUND(0.3*(IF(L4="",0,IF(LEFT(L4,7)="MISSING",0,IF(ISNUMBER(SEARCH("OK",L4)),100,IF(ISNUMBER(SEARCH("SHORT",L4)),65,IF(ISNUMBER(SEARCH("LONG",L4)),50,70))))))+0.25*(IF(N4="",0,IF(LEFT(N4,7)="MISSING",0,IF(ISNUMBER(SEARCH("OK",N4)),100,IF(ISNUMBER(SEARCH("SHORT",N4)),65,IF(ISNUMBER(SEARCH("LONG",N4)),50,70))))))+0.2*(IF(P4="",0,IF(LEFT(P4,2)="OK",100,0)))+0.08*(IF(R4="",0,IF(LEFT(R4,2)="OK",100,0)))+0.06*(IF(T4="",0,IF(LEFT(T4,2)="OK",100,0)))+0.05*(IF(V4="",0,IF(LEFT(V4,2)="OK",100,0)))+0.03*(IF(X4="",0,IF(LEFT(X4,2)="OK",100,0)))+0.03*(IF(Z4="",0,IF(LEFT(Z4,2)="OK",100,0))),0)) -> 62 | C4: 76.15 | D4: 70 | E4: 94.58 | F4: To Do | G4: Copy Writer | H4: =HYPERLINK("https://africanmarketingconfederation.org/about-us","https://africanmarketingconfederation.org/about-us") -> https://africanmarketingconfederation.org/about-us | I4: =HYPERLINK("https://africanmarketingconfederation.org/about-us","About Us") -> About Us | J4: about-us | K4: African Marketing Confederation – The Leading Marketing Professional Body – African Marketing Confederation | L4: =IF(K4="","MISSING",IF(AND(LEN(K4)>=50,LEN(K4)<=60),"OK 50-60 chars",IF(LEN(K4)<50,"SHORT: "&LEN(K4),"LONG: "&LEN(K4)))) -> LONG: 107 | M4: ABOUT The African Marketing Confederation​ The African Marketing Confederation is the ground-breaking Pan African body of marketing professionals spearheading the ongoing development of the highest possible standards of marketing across Africa. Founded in 2011, the AMC is a collaboration between the African national marketing bodies and associations to exchange expertise and information, and to promote | N4: =IF(M4="","MISSING",IF(AND(LEN(M4)>=120,LEN(M4)<=160),"OK 120-160 chars",IF(LEN(M4)<120,"SHORT: "&LEN(M4),"LONG: "&LEN(M4)))) -> LONG: 405 | O4: ABOUT The African Marketing Confederation​ | P4: =IF(OR(ISBLANK(O4),ISNUMBER(SEARCH("|",O4))),"FIX: MULTIPLE/MISSING","OK") -> OK | Q4: Helen McIntee | President and Co-founder | David Balikuddembe | Secretary General | R4: =IF(ISBLANK(Q4),"MISSING","OK") -> OK | S4: African Marketing Confederation ​ PRESIDENT’S COUNCIL | T4: =IF(ISBLANK(S4),"MISSING","OK") -> OK | V4: =IF(ISBLANK(U4),"MISSING","OK") -> MISSING | X4: =IF(ISBLANK(W4),"MISSING","OK") -> MISSING | Z4: =IF(ISBLANK(Y4),"MISSING","OK") -> MISSING | AA4: =HYPERLINK("https://africanmarketingconfederation.org/wp-admin/post.php?post=84&action=elementor","Open in Elementor") -> Open in Elementor | AB4: =HYPERLINK("https://africanmarketingconfederation.org/wp-content/uploads/2026/03/og-image.png","View Image") -> View Image | AC4: =IF(LEN("https://africanmarketingconfederation.org/wp-content/uploads/2026/03/og-image.png")>0, _xlfn.IMAGE("https://africanmarketingconfederation.org/wp-content/uploads/2026/03/og-image.png"), "") -> #VALUE! | AD4: =IFERROR(HYPERLINK("#'Main'!B"&MATCH(TRIM(H4),Main!B:B,0),"Open in Main"),IFERROR(HYPERLINK("#'Technical Diagnostics'!A"&MATCH(TRIM(H4),'Technical Diagnostics'!A:A,0),"Open in Technical"),"Not Found")) -> Open in Main
A5: =IF(B5>=85,"Complete","Needs Copy") -> Needs Copy | B5: =MIN(100,ROUND(0.3*(IF(L5="",0,IF(LEFT(L5,7)="MISSING",0,IF(ISNUMBER(SEARCH("OK",L5)),100,IF(ISNUMBER(SEARCH("SHORT",L5)),65,IF(ISNUMBER(SEARCH("LONG",L5)),50,70))))))+0.25*(IF(N5="",0,IF(LEFT(N5,7)="MISSING",0,IF(ISNUMBER(SEARCH("OK",N5)),100,IF(ISNUMBER(SEARCH("SHORT",N5)),65,IF(ISNUMBER(SEARCH("LONG",N5)),50,70))))))+0.2*(IF(P5="",0,IF(LEFT(P5,2)="OK",100,0)))+0.08*(IF(R5="",0,IF(LEFT(R5,2)="OK",100,0)))+0.06*(IF(T5="",0,IF(LEFT(T5,2)="OK",100,0)))+0.05*(IF(V5="",0,IF(LEFT(V5,2)="OK",100,0)))+0.03*(IF(X5="",0,IF(LEFT(X5,2)="OK",100,0)))+0.03*(IF(Z5="",0,IF(LEFT(Z5,2)="OK",100,0))),0)) -> 62 | C5: 77.5 | D5: 70 | E5: 100 | F5: To Do | G5: Copy Writer | H5: =HYPERLINK("https://africanmarketingconfederation.org/african-marketing-confederation-tourism-chapter","https://africanmarketingconfederation.org/african-marketing-confederation-tourism-chapter") -> https://africanmarketingconfederation.org/african-marketing-confederation-tourism-chapter | I5: =HYPERLINK("https://africanmarketingconfederation.org/african-marketing-confederation-tourism-chapter","African Marketing Confederation Tourism Chapter") -> African Marketing Confederation Tourism Chapter | J5: african-marketing-confederation-tourism-chapter | K5: African Marketing Confederation Tourism Chapter – African Marketing Confederation | L5: =IF(K5="","MISSING",IF(AND(LEN(K5)>=50,LEN(K5)<=60),"OK 50-60 chars",IF(LEN(K5)<50,"SHORT: "&LEN(K5),"LONG: "&LEN(K5)))) -> LONG: 81 | M5: African Marketing Confederation Tourism Chapter Shaping Africa’s Tourism Narrative Through Strategic Marketing Tourism is one of Africa’s most powerful economic engines - generating jobs, stimulating investment, and fostering cultural exchange.The African Marketing Confederation is proud to launch the Tourism Chapter, a bold initiative to elevate African tourism through the lens of world-class marketing. Launched at the | N5: =IF(M5="","MISSING",IF(AND(LEN(M5)>=120,LEN(M5)<=160),"OK 120-160 chars",IF(LEN(M5)<120,"SHORT: "&LEN(M5),"LONG: "&LEN(M5)))) -> LONG: 423 | O5: African Marketing Confederation Tourism Chapter | P5: =IF(OR(ISBLANK(O5),ISNUMBER(SEARCH("|",O5))),"FIX: MULTIPLE/MISSING","OK") -> OK | Q5: Charting the Course: Purpose, Mission & Vision for Africa’s Tourism Future | Our Goals and Objectives: | R5: =IF(ISBLANK(Q5),"MISSING","OK") -> OK | S5: Shaping Africa’s Tourism Narrative Through Strategic Marketing | T5: =IF(ISBLANK(S5),"MISSING","OK") -> OK | V5: =IF(ISBLANK(U5),"MISSING","OK") -> MISSING | X5: =IF(ISBLANK(W5),"MISSING","OK") -> MISSING | Z5: =IF(ISBLANK(Y5),"MISSING","OK") -> MISSING | AA5: =HYPERLINK("https://africanmarketingconfederation.org/wp-admin/post.php?post=28165&action=elementor","Open in Elementor") -> Open in Elementor | AB5: =HYPERLINK("https://africanmarketingconfederation.org/wp-content/uploads/2026/03/og-image.png","View Image") -> View Image | AC5: =IF(LEN("https://africanmarketingconfederation.org/wp-content/uploads/2026/03/og-image.png")>0, _xlfn.IMAGE("https://africanmarketingconfederation.org/wp-content/uploads/2026/03/og-image.png"), "") -> #VALUE! | AD5: =IFERROR(HYPERLINK("#'Main'!B"&MATCH(TRIM(H5),Main!B:B,0),"Open in Main"),IFERROR(HYPERLINK("#'Technical Diagnostics'!A"&MATCH(TRIM(H5),'Technical Diagnostics'!A:A,0),"Open in Technical"),"Not Found")) -> Open in Main
A6: =IF(B6>=85,"Complete","Needs Copy") -> Needs Copy | B6: =MIN(100,ROUND(0.3*(IF(L6="",0,IF(LEFT(L6,7)="MISSING",0,IF(ISNUMBER(SEARCH("OK",L6)),100,IF(ISNUMBER(SEARCH("SHORT",L6)),65,IF(ISNUMBER(SEARCH("LONG",L6)),50,70))))))+0.25*(IF(N6="",0,IF(LEFT(N6,7)="MISSING",0,IF(ISNUMBER(SEARCH("OK",N6)),100,IF(ISNUMBER(SEARCH("SHORT",N6)),65,IF(ISNUMBER(SEARCH("LONG",N6)),50,70))))))+0.2*(IF(P6="",0,IF(LEFT(P6,2)="OK",100,0)))+0.08*(IF(R6="",0,IF(LEFT(R6,2)="OK",100,0)))+0.06*(IF(T6="",0,IF(LEFT(T6,2)="OK",100,0)))+0.05*(IF(V6="",0,IF(LEFT(V6,2)="OK",100,0)))+0.03*(IF(X6="",0,IF(LEFT(X6,2)="OK",100,0)))+0.03*(IF(Z6="",0,IF(LEFT(Z6,2)="OK",100,0))),0)) -> 60 | C6: 70 | D6: 60 | E6: 100 | F6: To Do | G6: Copy Writer | H6: =HYPERLINK("https://africanmarketingconfederation.org/amc-awards-2024","https://africanmarketingconfederation.org/amc-awards-2024") -> https://africanmarketingconfederation.org/amc-awards-2024 | I6: =HYPERLINK("https://africanmarketingconfederation.org/amc-awards-2024","Amc Awards 2024") -> Amc Awards 2024 | J6: amc-awards-2024 | K6: AMC Awards 2024 – African Marketing Confederation | L6: =IF(K6="","MISSING",IF(AND(LEN(K6)>=50,LEN(K6)<=60),"OK 50-60 chars",IF(LEN(K6)<50,"SHORT: "&LEN(K6),"LONG: "&LEN(K6)))) -> SHORT: 49 | M6: NOMINATIONS are Open ! AMC Awards The African Marketing Confederation Awards event is held annually as part of the African Marketing Confederation Forum. This distinguished event celebrates and acknowledges outstanding marketing campaigns and the visionary individuals behind them. The awards presented honor not only the groundbreaking strategies and creative brilliance that set these campaigns apart but | N6: =IF(M6="","MISSING",IF(AND(LEN(M6)>=120,LEN(M6)<=160),"OK 120-160 chars",IF(LEN(M6)<120,"SHORT: "&LEN(M6),"LONG: "&LEN(M6)))) -> LONG: 406 | O6: NOMINATIONS are Open ! | P6: =IF(OR(ISBLANK(O6),ISNUMBER(SEARCH("|",O6))),"FIX: MULTIPLE/MISSING","OK") -> OK | Q6: Awards Categories | Tourism & Destination Marketing Campaign | of the Year | Best Social Media Campaign | R6: =IF(ISBLANK(Q6),"MISSING","OK") -> OK | T6: =IF(ISBLANK(S6),"MISSING","OK") -> MISSING | V6: =IF(ISBLANK(U6),"MISSING","OK") -> MISSING | X6: =IF(ISBLANK(W6),"MISSING","OK") -> MISSING | Z6: =IF(ISBLANK(Y6),"MISSING","OK") -> MISSING | AA6: =HYPERLINK("https://africanmarketingconfederation.org/wp-admin/post.php?post=16125&action=elementor","Open in Elementor") -> Open in Elementor | AB6: =HYPERLINK("https://africanmarketingconfederation.org/wp-content/uploads/2021/08/amc_faw.png","View Image") -> View Image | AC6: =IF(LEN("https://africanmarketingconfederation.org/wp-content/uploads/2021/08/amc_faw.png")>0, _xlfn.IMAGE("https://africanmarketingconfederation.org/wp-content/uploads/2021/08/amc_faw.png"), "") -> #VALUE! | AD6: =IFERROR(HYPERLINK("#'Main'!B"&MATCH(TRIM(H6),Main!B:B,0),"Open in Main"),IFERROR(HYPERLINK("#'Technical Diagnostics'!A"&MATCH(TRIM(H6),'Technical Diagnostics'!A:A,0),"Open in Technical"),"Not Found")) -> Open in Main
A7: =IF(B7>=85,"Complete","Needs Copy") -> Needs Copy | B7: =MIN(100,ROUND(0.3*(IF(L7="",0,IF(LEFT(L7,7)="MISSING",0,IF(ISNUMBER(SEARCH("OK",L7)),100,IF(ISNUMBER(SEARCH("SHORT",L7)),65,IF(ISNUMBER(SEARCH("LONG",L7)),50,70))))))+0.25*(IF(N7="",0,IF(LEFT(N7,7)="MISSING",0,IF(ISNUMBER(SEARCH("OK",N7)),100,IF(ISNUMBER(SEARCH("SHORT",N7)),65,IF(ISNUMBER(SEARCH("LONG",N7)),50,70))))))+0.2*(IF(P7="",0,IF(LEFT(P7,2)="OK",100,0)))+0.08*(IF(R7="",0,IF(LEFT(R7,2)="OK",100,0)))+0.06*(IF(T7="",0,IF(LEFT(T7,2)="OK",100,0)))+0.05*(IF(V7="",0,IF(LEFT(V7,2)="OK",100,0)))+0.03*(IF(X7="",0,IF(LEFT(X7,2)="OK",100,0)))+0.03*(IF(Z7="",0,IF(LEFT(Z7,2)="OK",100,0))),0)) -> 57 | C7: 56.92 | D7: 60 | E7: 47.67 | F7: To Do | G7: Copy Writer | H7: =HYPERLINK("https://africanmarketingconfederation.org/amc-conference-2022","https://africanmarketingconfederation.org/amc-conference-2022") -> https://africanmarketingconfederation.org/amc-conference-2022 | I7: =HYPERLINK("https://africanmarketingconfederation.org/amc-conference-2022","Amc Conference 2022") -> Amc Conference 2022 | J7: amc-conference-2022 | K7: AMC Conference 2022 – African Marketing Confederation | L7: =IF(K7="","MISSING",IF(AND(LEN(K7)>=50,LEN(K7)<=60),"OK 50-60 chars",IF(LEN(K7)<50,"SHORT: "&LEN(K7),"LONG: "&LEN(K7)))) -> OK 50-60 chars | M7: corinna kopf onlyfans leaks AMC Conference 2022 Thank you for attending19 - 22 October 2022 The African Marketing Confederation's Annual Conference brought together the best collection of marketing leaders from top companies, marketing bodies and associations to share tactics and best practices on how to build the next generation of marketing. Event Highlights Thank you for Attending! | N7: =IF(M7="","MISSING",IF(AND(LEN(M7)>=120,LEN(M7)<=160),"OK 120-160 chars",IF(LEN(M7)<120,"SHORT: "&LEN(M7),"LONG: "&LEN(M7)))) -> LONG: 387 | P7: =IF(OR(ISBLANK(O7),ISNUMBER(SEARCH("|",O7))),"FIX: MULTIPLE/MISSING","OK") -> FIX: MULTIPLE/MISSING | Q7: AMC Conference 2022 | Event Highlights | R7: =IF(ISBLANK(Q7),"MISSING","OK") -> OK | S7: AMC officially welcomes new member associations into the fold | Marketers are placing the ads where consumers don’t want to see them | Time for Africa to control its own narrative and image, delegates told | Excitement as Ghana announced as host of 2025 AMC marketing conference | T7: =IF(ISBLANK(S7),"MISSING","OK") -> OK | V7: =IF(ISBLANK(U7),"MISSING","OK") -> MISSING | X7: =IF(ISBLANK(W7),"MISSING","OK") -> MISSING | Z7: =IF(ISBLANK(Y7),"MISSING","OK") -> MISSING | AA7: =HYPERLINK("https://africanmarketingconfederation.org/wp-admin/post.php?post=4494&action=elementor","Open in Elementor") -> Open in Elementor | AB7: =HYPERLINK("https://africanmarketingconfederation.org/wp-content/uploads/2026/03/og-image.png","View Image") -> View Image | AC7: =IF(LEN("https://africanmarketingconfederation.org/wp-content/uploads/2026/03/og-image.png")>0, _xlfn.IMAGE("https://africanmarketingconfederation.org/wp-content/uploads/2026/03/og-image.png"), "") -> #VALUE! | AD7: =IFERROR(HYPERLINK("#'Main'!B"&MATCH(TRIM(H7),Main!B:B,0),"Open in Main"),IFERROR(HYPERLINK("#'Technical Diagnostics'!A"&MATCH(TRIM(H7),'Technical Diagnostics'!A:A,0),"Open in Technical"),"Not Found")) -> Open in Main
